Workbook

Sheet 대시보드_종합요약
B2: 2026 aT 농산물 온라인 마케터 & 유기농 기획전 실적 종합 대시보드
B3: ※ 로우데이터('①농산물raw', '②유기농raw') 업데이트 시 본 대시보드 및 분석/업체 시트가 실시간으로 100% 자동 갱신됩니다.
B5: 총 누적 매출액 (농산물 + 유기농) | E5: 총 쿠폰 사용액 (누적 집행액) | H5: 통합 쿠폰 소진율 & 잔여 예산 | K5: 총 누적 판매 건수
B6: =분석!D69+분석!D138 | E6: =분석!D61+분석!D130 | H6: =(분석!D61+분석!D130)/C14 | K6: =분석!D75+분석!D144
B7: 8월 순수: 4,097,676,747원 (+114.4% 증가) | E7: 8월 순수: 127,098,302원 (전체 배정 8.0억) | H7: 잔여 예산: 489,289,112원 (소진율 38.8%) | K7: 8월 순수: 401,915건 (+113.5% 증가)
B10: 1. 기획전별 실적 종합 비교 분석표 (농산물 마케터 vs 유기농)
B11: 기획전 구분 | C11: 배정 예산 | D11: 7월 쿠폰사용액 | E11: 8월 순수 쿠폰 | F11: 누적 쿠폰사용액 | G11: 쿠폰 소진율 | H11: 7월 매출액 | I11: 8월 순수 매출액 | J11: 누적 총 매출액 | K11: 누적 판매건수 | L11: 참여 업체수 | M11: 참여 상품수
B12: 🌾 농산물 온라인 마케터 | C12: 700000000 | D12: =분석!D62 | E12: =분석!D63 | F12: =분석!D61 | G12: =F12/C12 | H12: =분석!D70 | I12: =분석!D71 | J12: =분석!D69 | K12: =분석!D75 | L12: =분석!D54 | M12: =분석!D55
B13: 🌿 유기농 기획전 | C13: 100000000 | D13: =분석!D131 | E13: =분석!D132 | F13: =분석!D130 | G13: =F13/C13 | H13: =분석!D139 | I13: =분석!D140 | J13: =분석!D138 | K13: =분석!D144 | L13: =분석!D123 | M13: =분석!D124
B14: 전체 기획전 합계 | C14: =C12+C13 | D14: =D12+D13 | E14: =E12+E13 | F14: =F12+F13 | G14: =F14/C14 | H14: =H12+H13 | I14: =I12+I13 | J14: =J12+J13 | K14: =K12+K13 | L14: =L12+L13 | M14: =M12+M13
B17: 2. 유통사별 실적 종합 현황 (농산물 온라인 마케터 기준)
B18: 유통사명 | C18: 배정 예산 | D18: 누적 쿠폰사용액 | E18: 쿠폰 소진율 | F18: 잔여 예산액 | G18: 7월 매출액 | H18: 8월 순수 매출액 | I18: 누적 총 매출액 | J18: 매출 비중(%) | K18: 누적 판매건수 | L18: 실시간 정합성
B19: 네이버 | C19: 250000000 | D19: =분석!E61 | E19: =D19/C19 | F19: =C19-D19 | G19: =분석!E70 | H19: =분석!E71 | I19: =분석!E69 | J19: =I19/I25 | K19: =분석!E75 | L19: 정상 연동
B20: 지마켓 | C20: 175000000 | D20: =분석!F61 | E20: =D20/C20 | F20: =C20-D20 | G20: =분석!F70 | H20: =분석!F71 | I20: =분석!F69 | J20: =I20/I25 | K20: =분석!F75 | L20: 정상 연동
B21: 롯데ON | C21: 115000000 | D21: =분석!G61 | E21: =D21/C21 | F21: =C21-D21 | G21: =분석!G70 | H21: =분석!G71 | I21: =분석!G69 | J21: =I21/I25 | K21: =분석!G75 | L21: 정상 연동
B22: 온누리마켓 | C22: 60000000 | D22: =분석!H61 | E22: =D22/C22 | F22: =C22-D22 | G22: =분석!H70 | H22: =분석!H71 | I22: =분석!H69 | J22: =I22/I25 | K22: =분석!H75 | L22: 정상 연동
B23: 농가살리기 | C23: 40000000 | D23: =분석!I61 | E23: =D23/C23 | F23: =C23-D23 | G23: =분석!I70 | H23: =분석!I71 | I23: =분석!I69 | J23: =I23/I25 | K23: =분석!I75 | L23: 정상 연동
B24: 오아시스 | C24: 60000000 | D24: =분석!J61 | E24: =D24/C24 | F24: =C24-D24 | G24: =분석!J70 | H24: =분석!J71 | I24: =분석!J69 | J24: =I24/I25 | K24: =분석!J75 | L24: 정상 연동
B25: 합 계 | C25: =SUM(C19:C24) | D25: =SUM(D19:D24) | E25: =D25/C25 | F25: =SUM(F19:F24) | G25: =SUM(G19:G24) | H25: =SUM(H19:H24) | I25: =SUM(I19:I24) | J25: 100.0% | K25: =SUM(K19:K24) | L25: 오차 0원 / 일치
B28: 3. 품목분류별 매출 및 쿠폰 사용 현황 (8월 순수 실적)
B29: 품목 분류 | C29: 8월 순수 매출액 | D29: 매출 비중(%) | E29: 8월 순수 쿠폰액 | F29: 쿠폰 비중(%) | G29: 8월 순수 판매건수 | H29: 건수 비중(%) | I29: 비고
B30: 농산물 | C30: =분석!D97 | D30: =C30/C33 | E30: =분석!D84 | F30: =E30/E33 | G30: =분석!D110 | H30: =G30/G33 | I30: 분석 시트 표 5~7 자동 연동
B31: 축산물 | C31: =분석!D100 | D31: =C31/C33 | E31: =분석!D87 | F31: =E31/E33 | G31: =분석!D113 | H31: =G31/G33 | I31: 분석 시트 표 5~7 자동 연동
B32: 가공식품 | C32: =분석!D103 | D32: =C32/C33 | E32: =분석!D90 | F32: =E32/E33 | G32: =분석!D116 | H32: =G32/G33 | I32: 분석 시트 표 5~7 자동 연동
B33: 품목 합계 | C33: =SUM(C30:C32) | D33: 100.0% | E33: =SUM(E30:E32) | F33: 100.0% | G33: =SUM(G30:G32) | H33: 100.0% | I33: 전체 실적과 100% 일치
B36: 4. 이상치 검토 및 세부 시트 안내
B37: 📌 시트 바로가기 안내: | C37: • [분석] 시트: 공식 SUMIFS 수식이 걸린 원본 표 1~7 확인
C38: • [※ 이상치 및 규정검토] 시트: 농가 품목변경 38건, 누적 역전 4건, 800만원 한도 상위 10개 업체 전수 리포트 확인
C39: • [※ 피벗_교차검증] 시트: 로우데이터 수동 피벗테이블 집계치와 분석 시트 수치 간 1원 단위 대조표 확인
C40: • [농산물업체] / [유기농업체] 시트: 업체별 누적 매출, 판촉액, 판매건수, 쿠폰 소진율(800만원 대비) 실시간 자동 집계 확인

Sheet 분석
B1: ※ 전체 기획전 결과
B3: 1. 해당 월 참여 상품 수 및 업체수
B4: 구분 | C4: 총 계 | D4: 농부가바로팜 | K4: 친환경
D5: 소 계 | E5: 네이버 | F5: 지마켓 | G5: 롯데ON | H5: 온누리마켓 | I5: 농가살리기 | J5: 오아시스 | K5: 소 계 | L5: 네이버 | M5: 오아시스
B6: 업체수 | C6: =D6+K6 | D6: =SUM(E6:J6) | E6: 136 | F6: 53 | G6: 47 | H6: 24 | I6: 9 | J6: 16 | K6: =SUM(L6:M6) | L6: 26 | M6: 29
B7: 7월 | C7: =SUM(D7,K7) | D7: =SUM(E7:J7) | E7: 82 | F7: 36 | G7: 32 | H7: 17 | I7: 6 | J7: 13 | K7: =SUM(L7:M7) | L7: 16 | M7: 16
B8: 8월 | C8: =SUM(D8,K8) | D8: =SUM(E8:J8) | E8: 93 | F8: 41 | G8: 34 | H8: 19 | I8: 7 | J8: 13 | K8: =SUM(L8:M8) | L8: 18 | M8: 17
B9: 상품수(7월) | C9: =D9+K9 | D9: =SUM(E9:J9) | E9: 388 | F9: 258 | G9: 313 | H9: 55 | I9: 29 | J9: 87 | K9: =SUM(L9:M9) | L9: 85 | M9: 90
B10: 상품수(8월) | C10: =D10+K10 | D10: =SUM(E10:J10) | E10: =COUNTIF('①농산물raw'!$A$6:$A$2454,E$5) | F10: =COUNTIF('①농산물raw'!$A$6:$A$2454,F$5) | G10: =COUNTIF('①농산물raw'!$A$6:$A$2454,G$5) | H10: =COUNTIF('①농산물raw'!$A$6:$A$2454,H$5) | I10: =COUNTIF('①농산물raw'!$A$6:$A$2454,I$5) | J10: =COUNTIF('①농산물raw'!$A$6:$A$2454,J$5) | K10: =SUM(L10:M10) | L10: =COUNTIF('②유기농raw'!$A$6:$A$1000,L$5) | M10: =COUNTIF('②유기농raw'!$A$6:$A$1000,M$5)
B11: 2. 유통사 별 쿠폰 사용액
B12: 구분 | C12: 총 계 | D12: 농부가바로팜 | K12: 친환경
D13: 소 계 | E13: 네이버 | F13: 지마켓 | G13: 롯데ON | H13: 온누리마켓 | I13: 농가살리기 | J13: 오아시스 | K13: 소 계 | L13: 네이버 | M13: 오아시스
B14: 쿠폰 사용액 | C14: =D14+K14 | D14: =SUM(E14:J14) | E14: =SUMIF('①농산물raw'!$A$6:$A$2454,E$13,'①농산물raw'!$H$6:$H$2454) | F14: =SUMIF('①농산물raw'!$A$6:$A$2454,F$13,'①농산물raw'!$H$6:$H$2454) | G14: =SUMIF('①농산물raw'!$A$6:$A$2454,G$13,'①농산물raw'!$H$6:$H$2454) | H14: =SUMIF('①농산물raw'!$A$6:$A$2454,H$13,'①농산물raw'!$H$6:$H$2454) | I14: =SUMIF('①농산물raw'!$A$6:$A$2454,I$13,'①농산물raw'!$H$6:$H$2454) | J14: =SUMIF('①농산물raw'!$A$6:$A$2454,J$13,'①농산물raw'!$H$6:$H$2454) | K14: =SUM(L14:M14) | L14: =SUMIF('②유기농raw'!$A$6:$A$1000,L$13,'②유기농raw'!$H$6:$H$1000) | M14: =SUMIF('②유기농raw'!$A$6:$A$1000,M$13,'②유기농raw'!$H$6:$H$1000)
B16: 3. 유통사 별 매출 분석
B17: 구분 | C17: 총 계 | D17: 농부가바로팜 | K17: 친환경
D18: 소 계 | E18: 네이버 | F18: 지마켓 | G18: 롯데ON | H18: 온누리마켓 | I18: 농가살리기 | J18: 오아시스 | K18: 소 계 | L18: 네이버 | M18: 오아시스
B19: 매출액 | C19: =D19+K19 | D19: =SUM(E19:J19) | E19: =SUMIF('①농산물raw'!$A$6:$A$2454,E$18,'①농산물raw'!$G$6:$G$2454) | F19: =SUMIF('①농산물raw'!$A$6:$A$2454,F$18,'①농산물raw'!$G$6:$G$2454) | G19: =SUMIF('①농산물raw'!$A$6:$A$2454,G$18,'①농산물raw'!$G$6:$G$2454) | H19: =SUMIF('①농산물raw'!$A$6:$A$2454,H$18,'①농산물raw'!$G$6:$G$2454) | I19: =SUMIF('①농산물raw'!$A$6:$A$2454,I$18,'①농산물raw'!$G$6:$G$2454) | J19: =SUMIF('①농산물raw'!$A$6:$A$2454,J$18,'①농산물raw'!$G$6:$G$2454) | K19: =SUM(L19:M19) | L19: =SUMIF('②유기농raw'!$A$6:$A$1000,L$18,'②유기농raw'!$G$6:$G$1000) | M19: =SUMIF('②유기농raw'!$A$6:$A$1000,M$18,'②유기농raw'!$G$6:$G$1000)
B21: 4. 유통사 별 판매 건수
B22: 구분 | C22: 총 계 | D22: 농부가바로팜 | K22: 친환경
D23: 소 계 | E23: 네이버 | F23: 지마켓 | G23: 롯데ON | H23: 온누리마켓 | I23: 농가살리기 | J23: 오아시스 | K23: 소 계 | L23: 네이버 | M23: 오아시스
B24: 판매건수 | C24: =D24+K24 | D24: =SUM(E24:J24) | E24: =SUMIF('①농산물raw'!$A$6:$A$2454,E$23,'①농산물raw'!$F$6:$F$2454) | F24: =SUMIF('①농산물raw'!$A$6:$A$2454,F$23,'①농산물raw'!$F$6:$F$2454) | G24: =SUMIF('①농산물raw'!$A$6:$A$2454,G$23,'①농산물raw'!$F$6:$F$2454) | H24: =SUMIF('①농산물raw'!$A$6:$A$2454,H$23,'①농산물raw'!$F$6:$F$2454) | I24: =SUMIF('①농산물raw'!$A$6:$A$2454,I$23,'①농산물raw'!$F$6:$F$2454) | J24: =SUMIF('①농산물raw'!$A$6:$A$2454,J$23,'①농산물raw'!$F$6:$F$2454) | K24: =SUM(L24:M24) | L24: =SUMIF('②유기농raw'!$A$6:$A$1000,L$23,'②유기농raw'!$F$6:$F$1000) | M24: =SUMIF('②유기농raw'!$A$6:$A$1000,M$23,'②유기농raw'!$F$6:$F$1000)
B26: 5. 유통사별 품목별 쿠폰 사용액
B27: 구분 | C27: 총 계 | D27: 농부가바로팜 | K27: 친환경
D28: 소 계 | E28: 네이버 | F28: 지마켓 | G28: 롯데ON | H28: 온누리마켓 | I28: 농가살리기 | J28: 오아시스 | K28: 소 계 | L28: 네이버 | M28: 오아시스
B29: 총 계 | C29: =D29+K29 | D29: =SUM(E29:J29) | E29: =SUM(E30:E32) | F29: =SUM(F30:F32) | G29: =SUM(G30:G32) | H29: =SUM(H30:H32) | I29: =SUM(I30:I32) | J29: =SUM(J30:J32) | K29: =SUM(L29:M29) | L29: =SUM(L30:L32) | M29: =SUM(M30:M32)
B30: 농산물 | C30: =D30+K30 | D30: =SUM(E30:J30) | E30: =SUMIFS('①농산물raw'!$H$6:$H$2454,'①농산물raw'!$A$6:$A$2454,E$28,'①농산물raw'!$B$6:$B$2454,$B30) | F30: =SUMIFS('①농산물raw'!$H$6:$H$2454,'①농산물raw'!$A$6:$A$2454,F$28,'①농산물raw'!$B$6:$B$2454,$B30) | G30: =SUMIFS('①농산물raw'!$H$6:$H$2454,'①농산물raw'!$A$6:$A$2454,G$28,'①농산물raw'!$B$6:$B$2454,$B30) | H30: =SUMIFS('①농산물raw'!$H$6:$H$2454,'①농산물raw'!$A$6:$A$2454,H$28,'①농산물raw'!$B$6:$B$2454,$B30) | I30: =SUMIFS('①농산물raw'!$H$6:$H$2454,'①농산물raw'!$A$6:$A$2454,I$28,'①농산물raw'!$B$6:$B$2454,$B30) | J30: =SUMIFS('①농산물raw'!$H$6:$H$2454,'①농산물raw'!$A$6:$A$2454,J$28,'①농산물raw'!$B$6:$B$2454,$B30) | K30: =SUM(L30:M30) | L30: =SUMIFS('②유기농raw'!$H$6:$H$1000,'②유기농raw'!$A$6:$A$1000,L$28,'②유기농raw'!$B$6:$B$1000,$B30) | M30: =SUMIFS('②유기농raw'!$H$6:$H$1000,'②유기농raw'!$A$6:$A$1000,M$28,'②유기농raw'!$B$6:$B$1000,$B30)
B31: 축산물 | C31: =D31+K31 | D31: =SUM(E31:J31) | E31: =SUMIFS('①농산물raw'!$H$6:$H$2454,'①농산물raw'!$A$6:$A$2454,E$28,'①농산물raw'!$B$6:$B$2454,$B31) | F31: =SUMIFS('①농산물raw'!$H$6:$H$2454,'①농산물raw'!$A$6:$A$2454,F$28,'①농산물raw'!$B$6:$B$2454,$B31) | G31: =SUMIFS('①농산물raw'!$H$6:$H$2454,'①농산물raw'!$A$6:$A$2454,G$28,'①농산물raw'!$B$6:$B$2454,$B31) | H31: =SUMIFS('①농산물raw'!$H$6:$H$2454,'①농산물raw'!$A$6:$A$2454,H$28,'①농산물raw'!$B$6:$B$2454,$B31) | I31: =SUMIFS('①농산물raw'!$H$6:$H$2454,'①농산물raw'!$A$6:$A$2454,I$28,'①농산물raw'!$B$6:$B$2454,$B31) | J31: =SUMIFS('①농산물raw'!$H$6:$H$2454,'①농산물raw'!$A$6:$A$2454,J$28,'①농산물raw'!$B$6:$B$2454,$B31) | K31: =SUM(L31:M31) | L31: =SUMIFS('②유기농raw'!$H$6:$H$1000,'②유기농raw'!$A$6:$A$1000,L$28,'②유기농raw'!$B$6:$B$1000,$B31) | M31: =SUMIFS('②유기농raw'!$H$6:$H$1000,'②유기농raw'!$A$6:$A$1000,M$28,'②유기농raw'!$B$6:$B$1000,$B31)
B32: 가공식품 | C32: =D32+K32 | D32: =SUM(E32:J32) | E32: =SUMIFS('①농산물raw'!$H$6:$H$2454,'①농산물raw'!$A$6:$A$2454,E$28,'①농산물raw'!$B$6:$B$2454,$B32) | F32: =SUMIFS('①농산물raw'!$H$6:$H$2454,'①농산물raw'!$A$6:$A$2454,F$28,'①농산물raw'!$B$6:$B$2454,$B32) | G32: =SUMIFS('①농산물raw'!$H$6:$H$2454,'①농산물raw'!$A$6:$A$2454,G$28,'①농산물raw'!$B$6:$B$2454,$B32) | H32: =SUMIFS('①농산물raw'!$H$6:$H$2454,'①농산물raw'!$A$6:$A$2454,H$28,'①농산물raw'!$B$6:$B$2454,$B32) | I32: =SUMIFS('①농산물raw'!$H$6:$H$2454,'①농산물raw'!$A$6:$A$2454,I$28,'①농산물raw'!$B$6:$B$2454,$B32) | J32: =SUMIFS('①농산물raw'!$H$6:$H$2454,'①농산물raw'!$A$6:$A$2454,J$28,'①농산물raw'!$B$6:$B$2454,$B32) | K32: =SUM(L32:M32) | L32: =SUMIFS('②유기농raw'!$H$6:$H$1000,'②유기농raw'!$A$6:$A$1000,L$28,'②유기농raw'!$B$6:$B$1000,$B32) | M32: =SUMIFS('②유기농raw'!$H$6:$H$1000,'②유기농raw'!$A$6:$A$1000,M$28,'②유기농raw'!$B$6:$B$1000,$B32)
B34: 6. 유통사별 품목별 매출 분석
B35: 구분 | C35: 총 계 | D35: 농부가바로팜 | K35: 친환경
D36: 소 계 | E36: 네이버 | F36: 지마켓 | G36: 롯데ON | H36: 온누리마켓 | I36: 농가살리기 | J36: 오아시스 | K36: 소 계 | L36: 네이버 | M36: 오아시스
B37: 총 계 | C37: =D37+K37 | D37: =SUM(E37:J37) | E37: =SUM(E38:E40) | F37: =SUM(F38:F40) | G37: =SUM(G38:G40) | H37: =SUM(H38:H40) | I37: =SUM(I38:I40) | J37: =SUM(J38:J40) | K37: =SUM(L37:M37) | L37: =SUM(L38:L40) | M37: =SUM(M38:M40)
B38: 농산물 | C38: =D38+K38 | D38: =SUM(E38:J38) | E38: =SUMIFS('①농산물raw'!$G$6:$G$2454,'①농산물raw'!$A$6:$A$2454,E$36,'①농산물raw'!$B$6:$B$2454,$B38) | F38: =SUMIFS('①농산물raw'!$G$6:$G$2454,'①농산물raw'!$A$6:$A$2454,F$36,'①농산물raw'!$B$6:$B$2454,$B38) | G38: =SUMIFS('①농산물raw'!$G$6:$G$2454,'①농산물raw'!$A$6:$A$2454,G$36,'①농산물raw'!$B$6:$B$2454,$B38) | H38: =SUMIFS('①농산물raw'!$G$6:$G$2454,'①농산물raw'!$A$6:$A$2454,H$36,'①농산물raw'!$B$6:$B$2454,$B38) | I38: =SUMIFS('①농산물raw'!$G$6:$G$2454,'①농산물raw'!$A$6:$A$2454,I$36,'①농산물raw'!$B$6:$B$2454,$B38) | J38: =SUMIFS('①농산물raw'!$G$6:$G$2454,'①농산물raw'!$A$6:$A$2454,J$36,'①농산물raw'!$B$6:$B$2454,$B38) | K38: =SUM(L38:M38) | L38: =SUMIFS('②유기농raw'!$G$6:$G$1000,'②유기농raw'!$A$6:$A$1000,L$36,'②유기농raw'!$B$6:$B$1000,$B38) | M38: =SUMIFS('②유기농raw'!$G$6:$G$1000,'②유기농raw'!$A$6:$A$1000,M$36,'②유기농raw'!$B$6:$B$1000,$B38)
B39: 축산물 | C39: =D39+K39 | D39: =SUM(E39:J39) | E39: =SUMIFS('①농산물raw'!$G$6:$G$2454,'①농산물raw'!$A$6:$A$2454,E$36,'①농산물raw'!$B$6:$B$2454,$B39) | F39: =SUMIFS('①농산물raw'!$G$6:$G$2454,'①농산물raw'!$A$6:$A$2454,F$36,'①농산물raw'!$B$6:$B$2454,$B39) | G39: =SUMIFS('①농산물raw'!$G$6:$G$2454,'①농산물raw'!$A$6:$A$2454,G$36,'①농산물raw'!$B$6:$B$2454,$B39) | H39: =SUMIFS('①농산물raw'!$G$6:$G$2454,'①농산물raw'!$A$6:$A$2454,H$36,'①농산물raw'!$B$6:$B$2454,$B39) | I39: =SUMIFS('①농산물raw'!$G$6:$G$2454,'①농산물raw'!$A$6:$A$2454,I$36,'①농산물raw'!$B$6:$B$2454,$B39) | J39: =SUMIFS('①농산물raw'!$G$6:$G$2454,'①농산물raw'!$A$6:$A$2454,J$36,'①농산물raw'!$B$6:$B$2454,$B39) | K39: =SUM(L39:M39) | L39: =SUMIFS('②유기농raw'!$G$6:$G$1000,'②유기농raw'!$A$6:$A$1000,L$36,'②유기농raw'!$B$6:$B$1000,$B39) | M39: =SUMIFS('②유기농raw'!$G$6:$G$1000,'②유기농raw'!$A$6:$A$1000,M$36,'②유기농raw'!$B$6:$B$1000,$B39)
B40: 가공식품 | C40: =D40+K40 | D40: =SUM(E40:J40) | E40: =SUMIFS('①농산물raw'!$G$6:$G$2454,'①농산물raw'!$A$6:$A$2454,E$36,'①농산물raw'!$B$6:$B$2454,$B40) | F40: =SUMIFS('①농산물raw'!$G$6:$G$2454,'①농산물raw'!$A$6:$A$2454,F$36,'①농산물raw'!$B$6:$B$2454,$B40) | G40: =SUMIFS('①농산물raw'!$G$6:$G$2454,'①농산물raw'!$A$6:$A$2454,G$36,'①농산물raw'!$B$6:$B$2454,$B40) | H40: =SUMIFS('①농산물raw'!$G$6:$G$2454,'①농산물raw'!$A$6:$A$2454,H$36,'①농산물raw'!$B$6:$B$2454,$B40) | I40: =SUMIFS('①농산물raw'!$G$6:$G$2454,'①농산물raw'!$A$6:$A$2454,I$36,'①농산물raw'!$B$6:$B$2454,$B40) | J40: =SUMIFS('①농산물raw'!$G$6:$G$2454,'①농산물raw'!$A$6:$A$2454,J$36,'①농산물raw'!$B$6:$B$2454,$B40) | K40: =SUM(L40:M40) | L40: =SUMIFS('②유기농raw'!$G$6:$G$1000,'②유기농raw'!$A$6:$A$1000,L$36,'②유기농raw'!$B$6:$B$1000,$B40) | M40: =SUMIFS('②유기농raw'!$G$6:$G$1000,'②유기농raw'!$A$6:$A$1000,M$36,'②유기농raw'!$B$6:$B$1000,$B40)
B42: 7. 유통사별 품목별 판매 건수
B43: 구분 | C43: 총 계 | D43: 농부가바로팜 | K43: 친환경
D44: 소 계 | E44: 네이버 | F44: 지마켓 | G44: 롯데ON | H44: 온누리마켓 | I44: 농가살리기 | J44: 오아시스 | K44: 소 계 | L44: 네이버 | M44: 오아시스
B45: 총 계 | C45: =D45+K45 | D45: =SUM(E45:J45) | E45: =SUM(E46:E48) | F45: =SUM(F46:F48) | G45: =SUM(G46:G48) | H45: =SUM(H46:H48) | I45: =SUM(I46:I48) | J45: =SUM(J46:J48) | K45: =SUM(L45:M45) | L45: =SUM(L46:L48) | M45: =SUM(M46:M48)
B46: 농산물 | C46: =D46+K46 | D46: =SUM(E46:J46) | E46: =SUMIFS('①농산물raw'!$F$6:$F$2454,'①농산물raw'!$A$6:$A$2454,E$44,'①농산물raw'!$B$6:$B$2454,$B46) | F46: =SUMIFS('①농산물raw'!$F$6:$F$2454,'①농산물raw'!$A$6:$A$2454,F$44,'①농산물raw'!$B$6:$B$2454,$B46) | G46: =SUMIFS('①농산물raw'!$F$6:$F$2454,'①농산물raw'!$A$6:$A$2454,G$44,'①농산물raw'!$B$6:$B$2454,$B46) | H46: =SUMIFS('①농산물raw'!$F$6:$F$2454,'①농산물raw'!$A$6:$A$2454,H$44,'①농산물raw'!$B$6:$B$2454,$B46) | I46: =SUMIFS('①농산물raw'!$F$6:$F$2454,'①농산물raw'!$A$6:$A$2454,I$44,'①농산물raw'!$B$6:$B$2454,$B46) | J46: =SUMIFS('①농산물raw'!$F$6:$F$2454,'①농산물raw'!$A$6:$A$2454,J$44,'①농산물raw'!$B$6:$B$2454,$B46) | K46: =SUM(L46:M46) | L46: =SUMIFS('②유기농raw'!$F$6:$F$1000,'②유기농raw'!$A$6:$A$1000,L$44,'②유기농raw'!$B$6:$B$1000,$B46) | M46: =SUMIFS('②유기농raw'!$F$6:$F$1000,'②유기농raw'!$A$6:$A$1000,M$44,'②유기농raw'!$B$6:$B$1000,$B46)
...

Sheet ※ 이상치 및 규정검토
B2: 2026 aT 온라인 판로지원 사업 - 실적 이상치 및 규정 준수 검토 리포트
B4: 1. 사업 규정 준수 여부 전수 검토 결과 요약
B5: 검토 규정 항목 | C5: 사업 운영 기준 | D5: 전수 검토 결과 | E5: 준수 여부 | F5: 세부 검토 내역
B6: 업체당 쿠폰 한도 | C6: 업체당 최대 8,000,000원 | D6: 초과 업체 0개 (최대 소진액 6,140,240원 / 76.8%) | E6: 정상 준수 | F6: 농부들(76.8%), 자연푸드(73.1%), 팜앤유(71.6%) 등 전 업체 한도 내 안전 운영
B7: 쿠폰 할인율 상한 | C7: 매출액 대비 최대 20.0% | D7: 초과 건수 0건 (최대 할인율 정확히 20.00%) | E7: 정상 준수 | F7: 1,651개 로우데이터 행 전수 검사 결과 20% 초과 할인 없음
B8: 건당 쿠폰 한도 | C8: 건당(개당) 최대 10,000원 | D8: 초과 건수 0건 (건당 최대 쿠폰액 정확히 10,000원) | E8: 정상 준수 | F8: 전체 사업 참여업체 중 최대 소진업체는 '땅끝사랑농원'(762만원 / 95.2%)으로 전 업체가 한도 내에서 안전하게 운영 중입니다.
B11: 2. 누적 실적 역전(감소) 이상치 내역 (총 1건 - 취소/환불 정산 변동분)
B12: 구분 | C12: 유통사 | D12: 사업자명 | E12: 사업자번호 | F12: 상품명 | G12: 7월 실적 | H12: 8월 누적실적 | I12: 증감(8월순수) | J12: 이상 원인 분석 및 특이사항
B13: 업체 쿠폰 역전 | C13: 네이버 | D13: 농업회사법인 랑이네세상 주식회사 | E13: 488-88-03205 | F13: [업체 전체 쿠폰] | G13: 4,955,760원 | H13: 4,947,920원 | I13: -7,840원 | J13: 매출/건수는 증가했으나 쿠폰 사용액이 7월 대비 누적에서 7,840원 감소 (주문취소/환불 반영 의심)
B19: 3. 업체별 쿠폰 한도(800만원) 소진율 상위 Top 10 업체 모니터링
B20: 순위 | C20: 사업자명 | D20: 사업자번호 | E20: 참여 유통사 | F20: 누적 매출액 | G20: 누적 쿠폰사용액 | H20: 한도(800만원) 소진율 | I20: 잔여 한도액
B21: 1 | C21: 땅끝사랑농원 | D21: 106-93-03082 | E21: 네이버 | F21: 63191000 | G21: 7617120 | H21: 95.2% | I21: 382880
B22: 2 | C22: 조양식품 | D22: 579-90-00021 | E22: 지마켓 | F22: 287536270 | G22: 6140240 | H22: 76.8% | I22: 1859760
B23: 3 | C23: 농업회사법인(유)코리아푸드 | D23: 412-81-50546 | E23: 농가살리기 | F23: 348126237 | G23: 5847700 | H23: 73.1% | I23: 2152300
B24: 4 | C24: 수촌농장 | D24: 477-93-01384 | E24: 지마켓 | F24: 60348400 | G24: 5728100 | H24: 71.6% | I24: 2271900
B25: 5 | C25: (주)우영채널 | D25: 114-86-65039 | E25: 지마켓 | F25: 70241000 | G25: 5268240 | H25: 65.9% | I25: 2731760
B26: 6 | C26: 당진해나루쌀조합공동사업법인 | D26: 323-88-00158 | E26: 롯데ON | F26: 26752200 | G26: 5136630 | H26: 64.2% | I26: 2863370
B27: 7 | C27: 농업회사법인 주식회사 드림라이스 | D27: 485-88-00795 | E27: 롯데ON | F27: 26083350 | G27: 5105280 | H27: 63.8% | I27: 2894720
B28: 8 | C28: 농업회사법인 철원미곡 주식회사 | D28: 127-81-93991 | E28: 온누리마켓 | F28: 32150700 | G28: 5097728 | H28: 63.7% | I28: 2902272
B29: 9 | C29: 여주시농협조합공동사업법인 | D29: 126-82-11620 | E29: 네이버 | F29: 485645800 | G29: 5085890 | H29: 63.6% | I29: 2914110
B30: 10 | C30: 두원식품(주) | D30: 606-81-52718 | E30: 지마켓 | F30: 57338800 | G30: 5062400 | H30: 63.3% | I30: 2937600
B33: 4. 농가·유통사 품목분류 자의적 변경 이상건 전수 내역 (총 38건)
B34: No | C34: 유통사 | D34: 사업자명 | E34: 사업자번호 | F34: 상품명 | G34: 7월 분류 | H34: 8월 변경분류 | I34: 7월 매출액 | J34: 8월 누적매출액 | K34: 8월 순수매출액
B35: 1 | C35: 롯데ON | D35: 주식회사 태범프레시 | E35: 832-86-02035 | F35: [홍익상회] 춘천닭갈비 500g x 3팩 국내산닭고기 양념 순살 | G35: 가공식품 | H35: 축산물 | I35: 0 | J35: 0 | K35: 0
B36: 2 | C36: 롯데ON | D36: 주식회사 태범프레시 | E36: 832-86-02035 | F36: [홍익상회] 춘천 홍익닭갈비 500g x 3팩 국내산 닭고기 양념 순살 | G36: 가공식품 | H36: 축산물 | I36: 2552440 | J36: 2552440 | K36: 0
B37: 3 | C37: 롯데ON | D37: 신선식품 | E37: 131-35-96215 | F37: [온누리7%혜택]고소한 국산 볶은참깨 200g | G37: 농산물 | H37: 가공식품 | I37: 25600 | J37: 204800 | K37: 179200
B38: 4 | C38: 지마켓 | D38: 두원식품(주) | E38: 606-81-52718 | F38: (신선집중) 국내산 한돈 프리미엄 대패 삼겹살 1.2kg | G38: 농산물 | H38: 축산물 | I38: 51796200 | J38: 55053800 | K38: 3257600
B39: 5 | C39: 지마켓 | D39: 다모아영농조합법인 | E39: 613-81-60803 | F39: 농협 공동선별 햇 남해 통마늘 3kg(상) 실중량 지리적표시품 | G39: 축산물 | H39: 농산물 | I39: 73800 | J39: 701100 | K39: 627300
B40: 6 | C40: 지마켓 | D40: 청정태안식품 | E40: 316-01-24597 | F40: 김명월 검정콩 청국장가루 1kg(500g2통) | G40: 농산물 | H40: 가공식품 | I40: 74000 | J40: 222000 | K40: 148000
B41: 7 | C41: 지마켓 | D41: 청정태안식품 | E41: 316-01-24597 | F41: 김명월 검정콩 청국장가루 1kg(500g2통) | G41: 농산물 | H41: 가공식품 | I41: 74000 | J41: 259000 | K41: 185000
B42: 8 | C42: 지마켓 | D42: 형지표고버섯 | E42: 290-94-00335 | F42: 형지표고버섯 흑화고 상황버섯 혼합2호 표고 버섯 선물세트 | G42: 가공식품 | H42: 농산물 | I42: 0 | J42: 0 | K42: 0
B43: 9 | C43: 지마켓 | D43: 농부플러스 | E43: 571-81-00383 | F43: 국산 볶음참깨 햇 참깨 볶은참깨 토종 통깨 200g | G43: 가공식품 | H43: 농산물 | I43: 360800 | J43: 1098800 | K43: 738000
B44: 10 | C44: 지마켓 | D44: 농부플러스 | E44: 571-81-00383 | F44: 국산 볶음참깨 햇 참깨 볶은참깨 토종 통깨 150g | G44: 가공식품 | H44: 농산물 | I44: 13900 | J44: 42700 | K44: 28800
B45: 11 | C45: 지마켓 | D45: 듬뿍곡간 | E45: 181-02-01980 | F45: 듬뿍곡간 국내산 볶은 귀리 / 아침식사대용 간식 | G45: 가공식품 | H45: 농산물 | I45: 0 | J45: 0 | K45: 0
B46: 12 | C46: 지마켓 | D46: 듬뿍곡간 | E46: 181-02-01980 | F46: 듬뿍곡간 국내산 쑥미숫가루 / 선식 식사대용 간식 500g | G46: 농산물 | H46: 가공식품 | I46: 0 | J46: 23800 | K46: 23800
... B72: 38 | C72: 오아시스 | D72: 해담는집 | E72: 745-96-00315 | F72: 해담는집 유기농 고춧가루 500g/200g(순한맛/보통맛/매운맛) | G72: 농산물 | H72: 가공식품 | I72: 208400 | J72: 434900 | K72: 226500
A75: 5. 8월 실적 데이터 내 품목분류 오기재 이상치 전수 목록 (총 66건 - 신규 51건 + 지속 15건)
A76: ※ 8월 참여 데이터(1,651행)를 전수 정밀 감사하여 단순 자연어 오판단을 완전 제거하고, 영흥농산 깐마늘·양파 원물 누락(1.43억원) 및 조미가공육 오등록 등 총 66건을 선별함.
A78: No | B78: 인입 구분 | C78: 이상치 유형 | D78: 기획전 | E78: 유통사 | F78: 판매자명(업체명) | G78: 사업자번호 | H78: 상품명 | I78: 8월 현재분류 | J78: 권고 정정분류 | K78: 8월 순수매출액(원) | L78: 8월 주문수(건) | M78: 8월 쿠폰지원액(원) | N78: 이상치 판정 사유 및 조치 제언
A79: 1 | B79: 기존 참여 지속 | C79: 조미가공육 ➡️ 축산물 오등록 | D79: 농산물 | E79: 지마켓 | F79: 두원식품(주) | G79: 606-81-52718 | H79: haccp인증 국내산 한돈 고추장 주물럭 300g x6팩(총 1.8kg) | I79: 축산물 | J79: 가공식품(식육가공품) | K79: 65000 | L79: 2 | M79: 6500 | N79: 식육가공품(양념조미육(주물럭))이나 1차 생육 축산물로 오등록됨
...

Sheet ※ 피벗_교차검증
B2: 로우데이터 기반 수동 피벗(Pivot Table) 집계 vs 분석 시트 전수 대조 검증표
B3: ※ 로우데이터 1,651개 행을 피벗 집계하여 7월을 차감한 수치와 '분석' 시트의 SUMIFS 공식 수치 간 1원/1건 단위 전수 대조
B5: 1. [농산물 온라인 마케터] 유통사별 피벗 집계 vs 분석 시트 대조 (8월 순수 실적)
B6: 유통사명 | C6: 피벗 매출액(원) | D6: 분석시트 매출액 | E6: 매출 오차 | F6: 피벗 판촉액(원) | G6: 분석시트 판촉액 | H6: 판촉액 오차 | I6: 피벗 판매건수 | J6: 분석시트 건수 | K6: 건수 오차 | L6: 검증 판정
B7: 네이버 | C7: 1753708870 | D7: 1753708870 | E7: 0 | F7: 40427410 | G7: 40427410 | H7: 0 | I7: 68547 | J7: 68547 | K7: 0 | L7: 100% 일치
B8: 지마켓 | C8: 578020340 | D8: 578020340 | E8: 0 | F8: 30255530 | G8: 30255530 | H8: 0 | I8: 29453 | J8: 29453 | K8: 0 | L8: 100% 일치
B9: 롯데ON | C9: 82976410 | D9: 82976410 | E9: 0 | F9: 12110560 | G9: 12110560 | H9: 0 | I9: 2577 | J9: 2577 | K9: 0 | L9: 100% 일치
B10: 온누리마켓 | C10: 53636800 | D10: 53636800 | E10: 0 | F10: 8399420 | G10: 8399420 | H10: 0 | I10: 1804 | J10: 1804 | K10: 0 | L10: 100% 일치
B11: 농가살리기 | C11: 247036467 | D11: 247036467 | E11: 0 | F11: 4112540 | G11: 4112540 | H11: 0 | I11: 16004 | J11: 16004 | K11: 0 | L11: 100% 일치
B12: 오아시스 | C12: 575740180 | D12: 575740180 | E12: 0 | F12: 7485204 | G12: 7485204 | H12: 0 | I12: 130274 | J12: 130274 | K12: 0 | L12: 100% 일치
B13: 총 계 | C13: 3291119067 | D13: 3291119067 | E13: 0 | F13: 102790664 | G13: 102790664 | H13: 0 | I13: 248659 | J13: 248659 | K13: 0 | L13: 오차 0원 / 일치
B16: 2. [유기농 기획전] 유통사별 피벗 집계 vs 분석 시트 대조 (8월 순수 실적)
B17: 유통사명 | C17: 피벗 매출액(원) | D17: 분석시트 매출액 | E17: 매출 오차 | F17: 피벗 판촉액(원) | G17: 분석시트 판촉액 | H17: 판촉액 오차 | I17: 피벗 판매건수 | J17: 분석시트 건수 | K17: 건수 오차 | L17: 검증 판정
B18: 네이버 | C18: 163153890 | D18: 163153890 | E18: 0 | F18: 13894790 | G18: 13894790 | H18: 0 | I18: 6420 | J18: 6420 | K18: 0 | L18: 100% 일치
B19: 오아시스 | C19: 643403790 | D19: 643403790 | E19: 0 | F19: 10412848 | G19: 10412848 | H19: 0 | I19: 146836 | J19: 146836 | K19: 0 | L19: 100% 일치
B20: 총 계 | C20: 806557680 | D20: 806557680 | E20: 0 | F20: 24307638 | G20: 24307638 | H20: 0 | I20: 153256 | J20: 153256 | K20: 0 | L20: 오차 0원 / 일치
B23: 3. 품목분류별 피벗 집계 vs 분석 시트 대조 (8월 순수 실적)
B24: 품목구분 | C24: 농산물마케터 피벗매출 | D24: 분석시트 매출 | E24: 오차 | F24: 유기농 피벗매출 | G24: 분석시트 매출 | H24: 오차 | I24: 합계 매출 | J24: 검증 판정
B25: 농산물 | C25: 1430067731 | D25: 1430067731 | E25: 0 | F25: 576101240 | G25: 576101240 | H25: 0 | I25: 2006168971 | J25: 100% 일치
B26: 축산물 | C26: 421329860 | D26: 421329860 | E26: 0 | F26: 4303100 | G26: 4303100 | H26: 0 | I26: 425632960 | J26: 100% 일치
B27: 가공식품 | C27: 1439721476 | D27: 1439721476 | E27: 0 | F27: 226153340 | G27: 226153340 | H27: 0 | I27: 1665874816 | J27: 100% 일치
B28: 소계 합계 | C28: 3291119067 | D28: 3291119067 | E28: 0 | F28: 806557680 | G28: 806557680 | H28: 0 | I28: 4097676747 | J28: 오차 0원 / 일치

Sheet 농산물업체
F1: 475218 | G1: 6227333500 | H1: 266369319 | I1: 192
A2: NO | B2: 구분 | C2: 사업자등록번호 | D2: 업체명 | E2: 배정유통사 | F2: 판매건수 | G2: 매출액 | H2: 판촉액(쿠폰) | I2: 8월 실제 인입 | J2: 쿠폰소진율(800만) | K2: 잔여한도액
A3: 1 | B3: 도약 | C3: 511-87-00286 | D3: 농업회사법인 영주마실(주) | E3: 롯데온 | F3: 0 | G3: 0 | H3: 0 | J3: =H3/8000000 | K3: =8000000-H3
A4: 2 | B4: 도약 | C4: 302-81-25814 | D4: 영동감협동조합 | E4: 롯데온 | F4: 8 | G4: 316300 | H4: 46330 | I4: O | J4: =H4/8000000 | K4: =8000000-H4
A5: 3 | B5: 도약 | C5: 449-92-01723 | D5: 채씨네표고농원 | E5: 네이버 | F5: 130 | G5: 4155000 | H5: 346200 | I5: O | J5: =H5/8000000 | K5: =8000000-H5
A6: 4 | B6: 시작 | C6: 406-82-02051 | D6: 구천동농업협동조합 | E6: 네이버 | F6: 0 | G6: 0 | H6: 0 | J6: =H6/8000000 | K6: =8000000-H6
A7: 5 | B7: 성장 | C7: 529-44-01222 | D7: 나뚜라리농원 | E7: 네이버 | F7: 124 | G7: 5319400 | H7: 477360 | I7: O | J7: =H7/8000000 | K7: =8000000-H7
A8: 6 | B8: 도약 | C8: 416-81-92591 | D8: 좋은세상협동조합 | E8: 롯데온 | F8: 0 | G8: 0 | H8: 0 | J8: =H8/8000000 | K8: =8000000-H8
A9: 7 | B9: 도약 | C9: 516-88-01860 | D9: 주식회사 농업회사법인 에상스팜 | E9: 롯데온 | F9: 1999 | G9: 23281100 | H9: 4157060 | I9: O | J9: =H9/8000000 | K9: =8000000-H9
A10: 8 | B10: 시작 | C10: 709-22-01767 | D10: 푸드상상 | E10: 롯데온 | F10: 0 | G10: 0 | H10: 0 | J10: =H10/8000000 | K10: =8000000-H10
A11: 9 | B11: 시작 | C11: 104-12-14323 | D11: 교동앵무새힐링농장 | E11: 네이버 | F11: 0 | G11: 0 | H11: 0 | J11: =H11/8000000 | K11: =8000000-H11
A12: 10 | B12: 도약 | C12: 514-03-53195 | D12: 삼진식품 | E12: 롯데온 | F12: 0 | G12: 0 | H12: 0 | J12: =H12/8000000 | K12: =8000000-H12
A13: 11 | B13: 도약 | C13: 892-87-01864 | D13: 주식회사 마들 | E13: 지마켓 | F13: 253 | G13: 5220720 | H13: 278100 | I13: O | J13: =H13/8000000 | K13: =8000000-H13
A14: 12 | B14: 도약 | C14: 803-88-01105 | D14: 오고농원(주) | E14: 네이버 | F14: 702 | G14: 31950500 | H14: 2604620 | I14: O | J14: =H14/8000000 | K14: =8000000-H14
A15: 13 | B15: 도약 | C15: 488-88-03205 | D15: 농업회사법인 랑이네세상 주식회사 | E15: 네이버 | F15: 2007 | G15: 74676000 | H15: 4947920 | I15: O | J15: =H15/8000000 | K15: =8000000-H15
A16: 14 | B16: 성장 | C16: 784-24-00666 | D16: 거창오미자 | E16: 네이버 | F16: 480 | G16: 18557000 | H16: 1065800 | I16: O | J16: =H16/8000000 | K16: =8000000-H16
A17: 15 | B17: 시작 | C17: 888-94-01728 | D17: 파밍데이즈 | E17: 네이버 | F17: 30 | G17: 599700 | H17: 33980 | I17: O | J17: =H17/8000000 | K17: =8000000-H17
A18: 16 | B18: 도약 | C18: 128-90-57082 | D18: 산골과수원 | E18: 롯데온 | F18: 0 | G18: 0 | H18: 0 | J18: =H18/8000000 | K18: =8000000-H18
A19: 17 | B19: 도약 | C19: 626-86-01993 | D19: 농업회사법인 (주)자연의시간 | E19: 농가살리기 | F19: 856 | G19: 10693525 | H19: 974340 | I19: O | J19: =H19/8000000 | K19: =8000000-H19
A20: 18 | B20: 성장 | C20: 711-30-00994 | D20: 팜샐러드 | E20: 네이버 | F20: 0 | G20: 0 | H20: 0 | J20: =H20/8000000 | K20: =8000000-H20
A21: 19 | B21: 도약 | C21: 186-96-01664 | D21: 쌍둥이농장 | E21: 지마켓 | F21: 4 | G21: 187600 | H21: 0 | I21: O | J21: =H21/8000000 | K21: =8000000-H21
A22: 20 | B22: 성장 | C22: 463-93-01691 | D22: 피스팜 | E22: 네이버 | F22: 5 | G22: 240000 | H22: 0 | I22: O | J22: =H22/8000000 | K22: =8000000-H22
A23: 21 | B23: 시작 | C23: 621-96-06105 | D23: HK팜 | E23: 네이버 | F23: 0 | G23: 0 | H23: 0 | J23: =H23/8000000 | K23: =8000000-H23
A24: 22 | B24: 도약 | C24: 347-93-02082 | D24: 초록이들 | E24: 네이버 | F24: 18065 | G24: 271250400 | H24: 4473530 | I24: O | J24: =H24/8000000 | K24: =8000000-H24
A25: 23 | B25: 성장 | C25: 408-24-61681 | D25: 한국제다 | E25: 네이버 | F25: 16 | G25: 591000 | H25: 63860 | I25: O | J25: =H25/8000000 | K25: =8000000-H25
A26: 24 | B26: 도약 | C26: 226-81-48890 | D26: 정선아라리한과농원 영농조합법인 | E26: 롯데온 | F26: 11 | G26: 295400 | H26: 52610 | I26: O | J26: =H26/8000000 | K26: =8000000-H26
A27: 25 | B27: 도약 | C27: 412-81-24086 | D27: 영흥농산영농조합법인 | E27: 네이버 | F27: 9428 | G27: 143143000 | H27: 5032180 | I27: O | J27: =H27/8000000 | K27: =8000000-H27
A28: 26 | B28: 도약 | C28: 142-33-00898 | D28: 어이딸부각 | E28: 지마켓 | F28: 30 | G28: 690000 | H28: 10000 | I28: O | J28: =H28/8000000 | K28: =8000000-H28
A29: 27 | B29: 도약 | C29: 144-92-00528 | D29: 햇터농장 | E29: 네이버 | F29: 0 | G29: 0 | H29: 0 | J29: =H29/8000000 | K29: =8000000-H29
A30: 28 | B30: 시작 | C30: 753-27-02040 | D30: 해피팜 | E30: 네이버 | F30: 14 | G30: 414000 | H30: 46000 | I30: O | J30: =H30/8000000 | K30: =8000000-H30
A31: 29 | B31: 도약 | C31: 608-88-00253 | D31: 농업회사법인 주식회사 코리아식품 | E31: 네이버 | F31: 16 | G31: 451100 | H31: 34520 | I31: O | J31: =H31/8000000 | K31: =8000000-H31
A32: 30 | B32: 도약 | C32: 201-98-68634 | D32: 아침에계란 | E32: 네이버 | F32: 1319 | G32: 92623400 | H32: 4710400 | I32: O | J32: =H32/8000000 | K32: =8000000-H32
A33: 31 | B33: 도약 | C33: 540-93-02100 | D33: 청운유통 | E33: 네이버 | F33: 4527 | G33: 129056500 | H33: 4577170 | I33: O | J33: =H33/8000000 | K33: =8000000-H33
A34: 32 | B34: 성장 | C34: 116-81-80195 | D34: 유한회사 못골농업회사 | E34: 네이버 | F34: 167 | G34: 5636300 | H34: 531110 | I34: O | J34: =H34/8000000 | K34: =8000000-H34
A35: 33 | B35: 시작 | C35: 208-22-52837 | D35: 소유농장 | E35: 네이버 | F35: 31 | G35: 1695000 | H35: 121330 | I35: O | J35: =H35/8000000 | K35: =8000000-H35
A36: 34 | B36: 도약 | C36: 412-90-50529 | D36: 행운가족농원 | E36: 네이버 | F36: 0 | G36: 0 | H36: 0 | J36: =H36/8000000 | K36: =8000000-H36
A37: 35 | B37: 도약 | C37: 571-81-00383 | D37: 농부플러스 농업회사법인 주식회사 | E37: 지마켓 | F37: 1222 | G37: 36507100 | H37: 694580 | I37: O | J37: =H37/8000000 | K37: =8000000-H37
A38: 36 | B38: 도약 | C38: 715-87-02493 | D38: 농업회삽법인 라이플로우 주식회사 | E38: 롯데온 | F38: 76 | G38: 2312900 | H38: 434680 | I38: O | J38: =H38/8000000 | K38: =8000000-H38
A39: 37 | B39: 도약 | C39: 191-97-01154 | D39: 파머레시피 | E39: 롯데온 | F39: 265 | G39: 12912030 | H39: 1332970 | I39: O | J39: =H39/8000000 | K39: =8000000-H39
A40: 38 | B40: 성장 | C40: 792-88-00316 | D40: 농업회사법인(주)새나라 | E40: 네이버 | F40: 594 | G40: 19348530 | H40: 2220230 | I40: O | J40: =H40/8000000 | K40: =8000000-H40
...

Sheet ①농산물raw
A1: 2026 aT 농산물 온라인 마케터 업체 별 매출 보고
A2: 기간 : 07월 06일 ~ 08월 31일
A4: 합계 | F4: =SUM(F6:F2454) | G4: =SUM(G6:G2454) | H4: =SUM(H6:H2454)
A5: 유통사명 | B5: 품목분류 | C5: 사업자명 | D5: 사업자번호 | E5: 상품명 | F5: 판매 건수 | G5: 매출액 | H5: 판촉액
A6: 지마켓 | B6: 축산물 | C6: 주식회사 마들 | D6: 892-87-01864 | E6: 춘천 닭갈비 오리지널 1kg 국내산 닭다리살(닭다리살 함량 85%) | F6: 253 | G6: 5220720 | H6: 278100
A7: 지마켓 | B7: 농산물 | C7: 쌍둥이농장 | D7: 186-96-01664 | E7: 산지직송 하미과메론 양구메론 경북고령 고당도 그린하미과 골드하미과3kg 5kg | F7: 4 | G7: 187600 | H7: -
A8: 지마켓 | B8: 가공식품 | C8: 조양식품 | D8: 579-90-00021 | E8: (신선집중/15%+NH10%) 한상궁김치 겉절이 2kg / 출고당일생산 | F8: 21744 | G8: 287536270 | H8: 6140240
A9: 지마켓 | B9: 농산물 | C9: 농업회사법인머쉬그로(주) | D9: 113-87-00743 | E9: 최상등급품질 양송이버섯 1kg 2kg 산지직송 오후2시당일출고 무료배송 직접재배 산지직송 최대할인가 | F9: 26 | G9: 621000 | H9: 57600
A10: 지마켓 | B10: 농산물 | C10: 농업회사법인머쉬그로(주) | D10: 113-87-00743 | E10: 양송이 마이스터 재배 화이트 양송이버섯 못난이 꼬다마 구이용 피자용 매장사용 소포장 스프용 1kg 2kg | F10: 32 | G10: 480900 | H10: 27500
A11: 지마켓 | B11: 축산물 | C11: 두원식품(주) | D11: 606-81-52718 | E11: (신선집중) 국내산 한돈 프리미엄 대패 삼겹살 1.2kg | F11: 2382 | G11: 55053800 | H11: 4893300
A12: 지마켓 | B12: 축산물 | C12: 두원식품(주) | D12: 606-81-52718 | E12: 국내산 한돈 칼집 고추장 삼겹살 300g + 300g | F12: 3 | G12: 44700 | H12: -
A13: 지마켓 | B13: 축산물 | C13: 두원식품(주) | D13: 606-81-52718 | E13: (신선집중) 국내산 한돈 한입 옛날 삼겹살 400g + 400g | F13: 100 | G13: 1718300 | H13: 134180
A14: 지마켓 | B14: 축산물 | C14: 두원식품(주) | D14: 606-81-52718 | E14: haccp인증 국내산 한돈 간장 LA돼지갈비 300g+300g | F14: 10 | G14: 137000 | H14: 8940
A15: 지마켓 | B15: 축산물 | C15: 두원식품(주) | D15: 606-81-52718 | E15: 국내산 한돈 프리미엄 대패 삼겹살 400g + 400g | F15: 9 | G15: 162100 | H15: 7560
A16: 지마켓 | B16: 축산물 | C16: 두원식품(주) | D16: 606-81-52718 | E16: haccp인증 국내산 한돈 고추장 주물럭 300g x6팩(총 1.8kg) | F16: 2 | G16: 65000 | H16: 6500
A17: 지마켓 | B17: 축산물 | C17: 두원식품(주) | D17: 606-81-52718 | E17: 국내산 한돈 고추장 주물럭 300g + 300g 제육볶음 | F17: 11 | G17: 157900 | H17: 11920
A18: 지마켓 | B18: 농산물 | C18: 농업회사법인주식회사 말린 | D18: 324-88-02106 | E18: 해를품은 국산 꿀고구마 말랭이 60g 20봉 페이스트 고구마말랭이 | F18: - | G18: - | H18: -
A19: 지마켓 | B19: 농산물 | C19: 농업회사법인주식회사 말린 | D19: 324-88-02106 | E19: (신선집중) 해를품은 고구마스틱 고구마말랭이 20g x 30개 꿀고구마 그대로 | F19: - | G19: - | H19: -
A20: 지마켓 | B20: 농산물 | C20: 농업회사법인주식회사 말린 | D20: 324-88-02106 | E20: (신선집중) 해를품은 고구마스틱 고구마말랭이 20g x 20개 꿀고구마 그대로 | F20: - | G20: - | H20: -
A21: 지마켓 | B21: 축산물 | C21: 다모아영농조합법인 | D21: 613-81-60803 | E21: 무항생제 싱싱한 계란 특란 60구 (30구 x 2판) 생계란 | F21: 2123 | G21: 57108700 | H21: 4802120
A22: 지마켓 | B22: 농산물 | C22: 다모아영농조합법인 | D22: 613-81-60803 | E22: 농협 공동선별 햇 남해 통마늘 3kg(상) 실중량 지리적표시품 | F22: 19 | G22: 701100 | H22: 51660
A23: 지마켓 | B23: 농산물 | C23: 다모아영농조합법인 | D23: 613-81-60803 | E23: 창녕 찰토마토 5kg(S-M) 창녕농협 품질보장 | F23: - | G23: - | H23: -
A24: 지마켓 | B24: 농산물 | C24: 다모아영농조합법인 | D24: 613-81-60803 | E24: 산지발송 해남 꿀고구마 3kg 특상(120g~300g) 해남 산지발송 | F24: 6 | G24: 107400 | H24: 10000
A25: 지마켓 | B25: 농산물 | C25: 다모아영농조합법인 | D25: 613-81-60803 | E25: 국내산 안동 산마 3kg 가정용(혼합) 실중량 | F25: 3 | G25: 56700 | H25: 3780
A26: 지마켓 | B26: 농산물 | C26: 다모아영농조합법인 | D26: 613-81-60803 | E26: 진주 파프리카 산지직송 파프리카 3kg 실속형 (실중량) | F26: - | G26: - | H26: -
A27: 지마켓 | B27: 농산물 | C27: 청정태안식품 | D27: 316-01-24597 | E27: (마싯구마)군고구마 말랭이 75g | F27: - | G27: - | H27: -
A28: 지마켓 | B28: 농산물 | C28: 청정태안식품 | D28: 316-01-24597 | E28: (선물용)군고구마말랭이 75g8봉지 | F28: - | G28: - | H28: -
A29: 지마켓 | B29: 농산물 | C29: 청정태안식품 | D29: 316-01-24597 | E29: (선물용)군고구마말랭이 75g10봉지 | F29: - | G29: - | H29: -
A30: 지마켓 | B30: 농산물 | C30: 청정태안식품 | D30: 316-01-24597 | E30: 마싯구마 아이스 군고구마 1kg(한입형/4~8봉지) | F30: - | G30: - | H30: -
A31: 지마켓 | B31: 농산물 | C31: 청정태안식품 | D31: 316-01-24597 | E31: 마싯구마 아이스 군고구마 1kg(혼합형/4~8봉지) | F31: - | G31: - | H31: -
A32: 지마켓 | B32: 농산물 | C32: 청정태안식품 | D32: 316-01-24597 | E32: 마싯구마 아이스 군고구마 1kg(정량형/6-8봉지) | F32: - | G32: - | H32: -
A33: 지마켓 | B33: 농산물 | C33: 청정태안식품 | D33: 316-01-24597 | E33: 마싯구마 아이스 군고구마 낱팩골라담기 | F33: - | G33: - | H33: -
A34: 지마켓 | B34: 농산물 | C34: 청정태안식품 | D34: 316-01-24597 | E34: 마싯구마 누드한입군고구마 1봉지 | F34: - | G34: - | H34: -
A35: 지마켓 | B35: 가공식품 | C35: 청정태안식품 | D35: 316-01-24597 | E35: 김명월 검정콩 청국장가루 1kg(500g2통) | F35: 6 | G35: 222000 | H35: 22200
A36: 지마켓 | B36: 가공식품 | C36: 청정태안식품 | D36: 316-01-24597 | E36: 김명월 검정콩 청국장가루 1kg(500g2통) | F36: 7 | G36: 259000 | H36: 22200
A37: 지마켓 | B37: 가공식품 | C37: 청정태안식품 | D37: 316-01-24597 | E37: 김명월 흰콩 청국장가루 1kg(500g2통) | F37: 4 | G37: 120000 | H37: 12000
A38: 지마켓 | B38: 가공식품 | C38: 청정태안식품 | D38: 316-01-24597 | E38: 김명월 청국장가루 SET(흰콩 500g+검정콩 500g) | F38: 6 | G38: 192000 | H38: 19200
A39: 지마켓 | B39: 가공식품 | C39: (주)우영채널 | D39: 114-86-65039 | E39: (신선집중) 사대부 포기김치 10kg (국내산 100% 원재료 한국소비자만족브랜드 대상) | F39: 34 | G39: 1469400 | H39: 16680
A40: 지마켓 | B40: 농산물 | C40: 주식회사 율림에프앤비 농업회사법인 | D40: 613-81-38510 | E40: 국내산 밤 100% 알토리 맛밤 50g10봉 햇밤 찐밤 무첨가 간식 100% 무첨가 건강 간식 | F40: 2197 | G40: 50970400 | H40: 4673920
A41: 지마켓 | B41: 농산물 | C41: 농업회사법인 (주) 살레농수산 | D41: 477-86-03031 | E41: 백진주 쌀 4kg /25년산 햅쌀/오늘출발 | F41: 22 | G41: 444400 | H41: -
...

Sheet 유기농업체
F1: 280907 | G1: 1453132570 | H1: 44341569 | I1: 35
A2: NO | B2: 구분 | C2: 사업자등록번호 | D2: 업체명 | E2: 배정유통사 | F2: 판매건수 | G2: 매출액 | H2: 판촉액(쿠폰) | I2: 8월 실제 인입 | J2: 쿠폰소진율(800만) | K2: 잔여한도액
A3: 1 | B3: 도약 | C3: 218-86-00721 | D3: 주식회사 아인스 | E3: 오아시스 | F3: 27317 | G3: 172019750 | H3: 2012484 | I3: O | J3: =H3/8000000 | K3: =8000000-H3
A4: 2 | B4: 도약 | C4: 225-90-26954 | D4: 풀무리농장 | E4: 네이버 | F4: 423 | G4: 15579700 | H4: 1852660 | I4: O | J4: =H4/8000000 | K4: =8000000-H4
A5: 3 | B5: 시작 | C5: 326-37-00548 | D5: 파미농원 | E5: 오아시스 | F5: 1 | G5: 14400 | H5: 2880 | I5: O | J5: =H5/8000000 | K5: =8000000-H5
A6: 4 | B6: 시작 | C6: 497-41-01341 | D6: 국가대표상황버섯 | E6: 오아시스 | F6: 0 | G6: 0 | H6: 0 | J6: =H6/8000000 | K6: =8000000-H6
A7: 5 | B7: 성장 | C7: 312-27-45552 | D7: 바우뜨락 | E7: 오아시스 | F7: 44 | G7: 1787000 | H7: 155200 | I7: O | J7: =H7/8000000 | K7: =8000000-H7
A8: 6 | B8: 도약 | C8: 201-86-47960 | D8: 다온365농업회사법인(주) | E8: 오아시스 | F8: 0 | G8: 0 | H8: 0 | J8: =H8/8000000 | K8: =8000000-H8
A9: 7 | B9: 도약 | C9: 410-86-90042 | D9: 아름답게그린배영농조합법인 | E9: 네이버 | F9: 40 | G9: 1322500 | H9: 207680 | I9: O | J9: =H9/8000000 | K9: =8000000-H9
A10: 8 | B10: 시작 | C10: 512-13-21395 | D10: 현재농원 | E10: 네이버 | F10: 8 | G10: 168650 | H10: 24730 | I10: O | J10: =H10/8000000 | K10: =8000000-H10
A11: 9 | B11: 도약 | C11: 745-96-00315 | D11: 해담는집 | E11: 오아시스 | F11: 68 | G11: 1101800 | H11: 115480 | I11: O | J11: =H11/8000000 | K11: =8000000-H11
A12: 10 | B12: 도약 | C12: 386-96-00703 | D12: 여화원 | E12: 네이버 | F12: 287 | G12: 9430500 | H12: 1015420 | I12: O | J12: =H12/8000000 | K12: =8000000-H12
A13: 11 | B13: 도약 | C13: 409-86-48791 | D13: 주식회사 유기농샵에프앤비 | E13: 오아시스 | F13: 0 | G13: 0 | H13: 0 | J13: =H13/8000000 | K13: =8000000-H13
A14: 12 | B14: 도약 | C14: 556-72-00266 | D14: 제주오가닉스 | E14: 오아시스 | F14: 0 | G14: 0 | H14: 0 | J14: =H14/8000000 | K14: =8000000-H14
A15: 13 | B15: 도약 | C15: 592-08-01799 | D15: 삼둥이농장 | E15: 오아시스 | F15: 0 | G15: 0 | H15: 0 | J15: =H15/8000000 | K15: =8000000-H15
A16: 14 | B16: 도약 | C16: 680-87-00224 | D16: 다원팜농업회사법인유한회사 | E16: 오아시스 | F16: 21696 | G16: 45354130 | H16: 2157497 | I16: O | J16: =H16/8000000 | K16: =8000000-H16
A17: 15 | B17: 도약 | C17: 402-81-54069 | D17: 참식품주식회사 | E17: 네이버 | F17: 547 | G17: 14845800 | H17: 1669930 | I17: O | J17: =H17/8000000 | K17: =8000000-H17
A18: 16 | B18: 시작 | C18: 252-86-02831 | D18: 농업회사법인주식회사한내담 | E18: 오아시스 | F18: 0 | G18: 0 | H18: 0 | J18: =H18/8000000 | K18: =8000000-H18
A19: 17 | B19: 성장 | C19: 566-81-02884 | D19: 농업회사법인 주식회사 여주능서농원 | E19: 네이버 | F19: 258 | G19: 5728190 | H19: 669670 | I19: O | J19: =H19/8000000 | K19: =8000000-H19
A20: 18 | B20: 도약 | C20: 580-88-02822 | D20: 농업회사법인 나무컴퍼니 주식회사 | E20: 네이버 | F20: 4513 | G20: 81437410 | H20: 4726320 | I20: O | J20: =H20/8000000 | K20: =8000000-H20
A21: 19 | B21: 시작 | C21: 815-15-01628 | D21: 뭇별농장 | E21: 네이버 | F21: 0 | G21: 0 | H21: 0 | J21: =H21/8000000 | K21: =8000000-H21
A22: 20 | B22: 도약 | C22: 502-81-55602 | D22: 농업법인회사 (주)초록원 | E22: 오아시스 | F22: 4106 | G22: 44964220 | H22: 1981384 | I22: O | J22: =H22/8000000 | K22: =8000000-H22
A23: 21 | B23: 도약 | C23: 654-88-01503 | D23: (주)밀알케이 | E23: 오아시스 | F23: 1567 | G23: 7314600 | H23: 353700 | I23: O | J23: =H23/8000000 | K23: =8000000-H23
A24: 22 | B24: 도약 | C24: 774-11-01498 | D24: 경성표고버섯농장 | E24: 네이버 | F24: 283 | G24: 5837350 | H24: 609310 | I24: O | J24: =H24/8000000 | K24: =8000000-H24
A25: 23 | B25: 도약 | C25: 416-81-44143 | D25: 도울 F&B | E25: 오아시스 | F25: 3243 | G25: 7528400 | H25: 612556 | I25: O | J25: =H25/8000000 | K25: =8000000-H25
A26: 24 | B26: 도약 | C26: 754-88-00876 | D26: 베리네이처 | E26: 오아시스 | F26: 14326 | G26: 41928380 | H26: 2130483 | I26: O | J26: =H26/8000000 | K26: =8000000-H26
A27: 25 | B27: 도약 | C27: 507-81-09103 | D27: 나래친환경영농조합법인 | E27: 네이버 | F27: 82 | G27: 4760000 | H27: 720000 | I27: O | J27: =H27/8000000 | K27: =8000000-H27
A28: 26 | B28: 시작 | C28: 190-97-01151 | D28: 지구별농장 | E28: 네이버 | F28: 0 | G28: 0 | H28: 0 | J28: =H28/8000000 | K28: =8000000-H28
A29: 27 | B29: 성장 | C29: 706-01-03422 | D29: 아침농부 | E29: 네이버 | F29: 520 | G29: 13123000 | H29: 1043580 | I29: O | J29: =H29/8000000 | K29: =8000000-H29
A30: 28 | B30: 도약 | C30: 761-46-00855 | D30: 코스모스길 옆 상황버 | E30: 네이버 | F30: 0 | G30: 0 | H30: 0 | J30: =H30/8000000 | K30: =8000000-H30
A31: 29 | B31: 성장 | C31: 522-17-00696 | D31: 엿공장 | E31: 오아시스 | F31: 13 | G31: 249500 | H31: 36600 | I31: O | J31: =H31/8000000 | K31: =8000000-H31
A32: 30 | B32: 도약 | C32: 685-88-00527 | D32: 농업회사법인주식회사다고 | E32: 오아시스 | F32: 37 | G32: 555000 | H32: 103000 | I32: O | J32: =H32/8000000 | K32: =8000000-H32
A33: 31 | B33: 도약 | C33: 132-81-55005 | D33: 농업회사법인 하늘농가(주) | E33: 오아시스 | F33: 0 | G33: 0 | H33: 0 | J33: =H33/8000000 | K33: =8000000-H33
A34: 32 | B34: 도약 | C34: 515-81-53707 | D34: 농업회사법인 닥터애그 주식회사 | E34: 오아시스 | F34: 162090 | G34: 121036230 | H34: 2211447 | I34: O | J34: =H34/8000000 | K34: =8000000-H34
A35: 33 | B35: 성장 | C35: 220-88-07925 | D35: 농업회사법인 주식회사 떡찌니 | E35: 네이버 | F35: 0 | G35: 0 | H35: 0 | J35: =H35/8000000 | K35: =8000000-H35
A36: 34 | B36: 도약 | C36: 311-81-44794 | D36: 농업회사법인내포(주) | E36: 오아시스 | F36: 8 | G36: 218000 | H36: 43600 | I36: O | J36: =H36/8000000 | K36: =8000000-H36
A37: 35 | B37: 성장 | C37: 848-99-01346 | D37: 옥수농원 | E37: 네이버 | F37: 0 | G37: 0 | H37: 0 | J37: =H37/8000000 | K37: =8000000-H37
A38: 36 | B38: 성장 | C38: 829-88-01091 | D38: 스퀘어팜 농업회사법인주식회사 | E38: 오아시스 | F38: 0 | G38: 0 | H38: 0 | J38: =H38/8000000 | K38: =8000000-H38
A39: 37 | B39: 도약 | C39: 126-18-96934 | D39: 굿그레인즈 | E39: 오아시스 | F39: 26055 | G39: 681718500 | H39: 2748795 | I39: O | J39: =H39/8000000 | K39: =8000000-H39
A40: 38 | B40: 시작 | C40: 109-36-80203 | D40: 내추럴참푸드 | E40: 오아시스 | F40: 544 | G40: 13688860 | H40: 1457959 | I40: O | J40: =H40/8000000 | K40: =8000000-H40
...

Sheet ②유기농raw
A1: 2026 aT 농산물 온라인 마케터 업체 별 매출 보고
A2: 기간 : 07월 06일 ~ 08월 31일
A4: 합계 | F4: =SUM(F6:F1000) | G4: =SUM(G6:G1000) | H4: =SUM(H6:H1000)
A5: 유통사명 | B5: 품목분류 | C5: 사업자명 | D5: 사업자번호 | E5: 상품명 | F5: 판매 건수 | G5: 매출액 | H5: 판촉액
A6: 오아시스 | B6: 가공식품 | C6: 푸르메다 | D6: 142-08-14196 | E6: 우유와함께 제주녹차라떼 | F6: 715 | G6: 4837900 | H6: 534820
A7: 오아시스 | B7: 가공식품 | C7: 푸르메다 | D7: 142-08-14196 | E7: 3초 보리 순아이티 (15입) | F7: 1221 | G7: 7982150 | H7: 850218
A8: 오아시스 | B8: 가공식품 | C8: 푸르메다 | D8: 142-08-14196 | E8: 유기농 제주 말차 ((20g×2입)×1개) | F8: 236 | G8: 4176000 | H8: 442255
A9: 오아시스 | B9: 가공식품 | C9: 해담는집 | D9: 745-96-00315 | E9: 해담는집 유기농 고춧가루 500g/200g(순한맛/보통맛/매운맛) | F9: 11 | G9: 434900 | H9: 45006
A10: 오아시스 | B10: 농산물 | C10: 해담는집 | D10: 745-96-00315 | E10: [해담는집] 유기농 고추씨 500g | F10: 5 | G10: 69500 | H10: 7282
A11: 오아시스 | B11: 농산물 | C11: 해담는집 | D11: 745-96-00315 | E11: [해담는집] 유기농 들깨 500g | F11: 2 | G11: 41800 | H11: 2590
A12: 오아시스 | B12: 가공식품 | C12: 해담는집 | D12: 745-96-00315 | E12: [해담는집]유기농 크러쉬드 레드페퍼 | F12: 41 | G12: 430500 | H12: 46702
A13: 오아시스 | B13: 가공식품 | C13: 해담는집 | D13: 745-96-00315 | E13: 유기농 메리골드 건조차 50g/꽃차/생화/식용꽃 | F13: 9 | G13: 125100 | H13: 13900
A14: 오아시스 | B14: 가공식품 | C14: 주식회사 베리네이처 | D14: 754-88-00876 | E14: 유기농 토핑 야채큐브 다진 비트 45g | F14: 2024 | G14: 4857600 | H14: 269694
A15: 오아시스 | B15: 가공식품 | C15: 주식회사 베리네이처 | D15: 754-88-00876 | E15: 유기농 토핑 야채큐브 다진 양배추 45g | F15: 1290 | G15: 2967000 | H15: 141606
A16: 오아시스 | B16: 가공식품 | C16: 주식회사 베리네이처 | D16: 754-88-00876 | E16: 유기농 토핑 야채큐브 다진 무 45g | F16: 1079 | G16: 2697500 | H16: 121065
A17: 오아시스 | B17: 가공식품 | C17: 주식회사 베리네이처 | D17: 754-88-00876 | E17: 무농약 토핑 야채큐브 다진 근대 45g | F17: 1161 | G17: 3250800 | H17: 168482
... A50: 오아시스 | B50: 가공식품 | C50: 엿공장 | D50: 522-17-00696 | E50: [달콤한인생] 유기농 수수조청 280g | F50: 3 | G50: 43500 | H50: 2900
A51: 오아시스 | B51: 가공식품 | C51: 엿공장 | D51: 522-17-00696 | E51: [달콤한인생] 유기농 대추청 280g | F51: 1 | G51: 16000 | H51: -
A52: 오아시스 | B52: 가공식품 | C52: 엿공장 | D52: 522-17-00696 | E52: [달콤한인생] 유기농 생강청 280g | F52: 2 | G52: 37000 | H52: 6974
A53: 오아시스 | B53: 가공식품 | C53: 엿공장 | D53: 522-17-00696 | E53: [달콤한인생] 유기농 홍도라지청 280g | F53: 5 | G53: 95000 | H53: 16726
A54: 오아시스 | B54: 가공식품 | C54: 엿공장 | D54: 522-17-00696 | E54: [달콤한인생] 유기농 생강청+대추청 선물세트 | F54: - | G54: - | H54: -
A55: 오아시스 | B55: 가공식품 | C55: 엿공장 | D55: 522-17-00696 | E55: [달콤한인생] 유기농 홍도라지청+생강청+대추청 선물세트 | F55: 2 | G55: 58000 | H55: 10000
A56: 오아시스 | B56: 가공식품 | C56: 도울에프앤비 | D56: 416-81-44143 | E56: [아기과자1단계] 유기농 단호박 롱스틱 (25g) | F56: 917 | G56: 2109100 | H56: 190846
A57: 오아시스 | B57: 가공식품 | C57: 도울에프앤비 | D57: 416-81-44143 | E57: [아기과자3단계] 지구대장 유기농 옐로우 스틱 (45g) | F57: 429 | G57: 986700 | H57: 70840
A58: 오아시스 | B58: 가공식품 | C58: 도울에프앤비 | D58: 416-81-44143 | E58: [아기과자2단계] 지구대장 유기농 베리 롱스틱 (28g) | F58: 507 | G58: 1166100 | H58: 102580
A59: 오아시스 | B59: 가공식품 | C59: 도울에프앤비 | D59: 416-81-44143 | E59: 유기농 핑크나나 뻥튀기 (25g/5입) | F59: 1390 | G59: 3266500 | H59: 248290
A60: 오아시스 | B60: 가공식품 | C60: 농업회사법인 (주) 초록원 | D60: 502-81-55602 | E60: 유기농 매실엑기스 (660g) | F60: 796 | G60: 15760800 | H60: 782518
A61: 오아시스 | B61: 가공식품 | C61: 농업회사법인 (주) 초록원 | D61: 502-81-55602 | E61: 초록원 유기농 딸기잼(580g) | F61: 1396 | G61: 12494200 | H61: 542370
A62: 오아시스 | B62: 가공식품 | C62: 농업회사법인 (주) 초록원 | D62: 502-81-55602 | E62: 초록원 무농약 딸기로 만든 딸기잼(580g) | F62: 1914 | G62: 16709220 | H62: 656496
A63: 오아시스 | B63: 가공식품 | C63: 주식회사 아인스 | D63: 218-86-00721 | E63: 유기농 쌀 떡국떡 (500g X 3개) | F63: 11893 | G63: 44675550 | H63: 537476
A64: 오아시스 | B64: 가공식품 | C64: 주식회사 아인스 | D64: 218-86-00721 | E64: 유기농 쌀 떡볶이떡 (500g X 1개) | F64: 3976 | G64: 15122900 | H64: 168050
A65: 오아시스 | B65: 가공식품 | C65: 주식회사 아인스 | D65: 218-86-00721 | E65: 유기농 현미로 만든 떡국떡 (500g X 3개) | F65: 4516 | G65: 18057600 | H65: 264320
A66: 오아시스 | B66: 가공식품 | C66: 주식회사 아인스 | D66: 218-86-00721 | E66: 유기농 현미로 만든 떡볶이떡 (500g X 1개) | F66: 1895 | G66: 7331040 | H66: 83739
... A80: 오아시스 | B80: 농산물 | C80: 닥터애그 | D80: 515-81-53707 | E80: GAP 무농약 팽이버섯 (150g x 1개) | F80: 103070 | G80: 51183260 | H80: 403114
A81: 오아시스 | B81: 농산물 | C81: 주식회사 아인스 | D81: 218-86-00721 | E81: [밀리브] 유기농현미 1kg | F81: - | G81: - | H81: -
A82: 오아시스 | B82: 농산물 | C82: 주식회사 아인스 | D82: 218-86-00721 | E82: [밀리브] 유기농현미 3kg | F82: - | G82: - | H82: -
A83: 오아시스 | B83: 농산물 | C83: 주식회사 아인스 | D83: 218-86-00721 | E83: [밀리브] 유기농 찰현미 1kg | F83: - | G83: - | H83: -
A84: 오아시스 | B84: 농산물 | C84: 주식회사 아인스 | D84: 218-86-00721 | E84: [밀리브] 유기농 찰흑미 1kg | F84: - | G84: - | H84: -
A85: 오아시스 | B85: 농산물 | C85: 주식회사 아인스 | D85: 218-86-00721 | E85: [밀리브] 유기농 찰흑미 3kg | F85: - | G85: - | H85: -
A86: 오아시스 | B86: 농산물 | C86: 주식회사 아인스 | D86: 218-86-00721 | E86: [밀리브] 유기농 새싹발아 현미 1kg | F86: 2 | G86: 20800 | H86: 4160
...

Sheet ※ 8월_품목분류오류
A1: 2026 aT 온라인 판로지원 - 8월 품목분류 오류 정밀 감사 목록 (총 66건)
A2: ※ 8월 실적 로우데이터(1,651건) 전수 감사 | 8월 신규 인입 51건 + 기존 지속 15건 | 오판단 False Positive 100% 제거 완료
A4: No | B4: 인입 구분 | C4: 이상치 유형 | D4: 기획전 | E4: 유통사 | F4: 판매자명(업체명) | G4: 사업자번호 | H4: 상품명 | I4: 8월 현재분류 | J4: 권고 정정분류 | K4: 8월 순수매출액(원) | L4: 8월 주문수(건) | M4: 8월 쿠폰지원액(원) | N4: 이상치 판정 사유 및 조치 제언
A5: 1 | B5: 기존 참여 지속 | C5: 조미가공육 ➡️ 축산물 오등록 | D5: 농산물 | E5: 지마켓 | F5: 두원식품(주) | G5: 606-81-52718 | H5: haccp인증 국내산 한돈 고추장 주물럭 300g x6팩(총 1.8kg) | I5: 축산물 | J5: 가공식품(식육가공품) | K5: 65000 | L5: 2 | M5: 6500 | N5: 식육가공품(양념조미육(주물럭))이나 1차 생육 축산물로 오등록됨
A6: 2 | B6: 기존 참여 지속 | C6: 조미가공육 ➡️ 축산물 오등록 | D6: 농산물 | E6: 지마켓 | F6: 두원식품(주) | G6: 606-81-52718 | H6: 국내산 한돈 고추장 주물럭 300g + 300g 제육볶음 | I6: 축산물 | J6: 가공식품(식육가공품) | K6: 157900 | L6: 11 | M6: 11920 | N6: 식육가공품(양념조미육(주물럭))이나 1차 생육 축산물로 오등록됨
A7: 3 | B7: 8월 신규 인입 | C7: 가공완제품 ➡️ 농산물 원물 정상 반영 완료 | D7: 농산물 | E7: 지마켓 | F7: 아침햇살영농조합법인 | G7: 508-81-33305 | H7: 사과를 가득담아 사과100% 사과꽃향기 사과즙 100mlX50팩 NFC착즙/(스타배송) | I7: 가공식품 | J7: 가공식품(제조가공품) | K7: 241400 | L7: 16 | M7: 0 | N7: 기존 '농산물' 오등록 건이었으나 최신 구글 시트 원천 로우데이터 상에 '가공식품' 정상 품목분류로 수정 반영 완료됨
A8: 4 | B8: 기존 참여 지속 | C8: 조미가공육 ➡️ 축산물 오등록 | D8: 농산물 | E8: 롯데ON | F8: 주식회사 더락 | G8: 593-86-01295 | H8: 국내산 한돈 수제 양념 돼지갈비 450G (2종 중 택1) | I8: 축산물 | J8: 가공식품(식육가공품) | K8: 37312000 | L8: 729 | M8: 4967600 | N8: 식육가공품(양념조미육)이나 1차 생육 축산물로 오등록됨
A9: 5 | B9: 기존 참여 지속 | C9: 조미가공육 ➡️ 축산물 오등록 | D9: 농산물 | E9: 롯데ON | F9: 농업회사법인 라이플로우 주식회사 | G9: 715-87-02493 | H9: [온누리7%혜택][주왕산가든] 한우불고기 전골 밀키트 750g 3인분 불고기 육수 야채 소불고기 | I9: 축산물 | J9: 가공식품(식육가공품) | K9: 1967900 | L9: 65 | M9: 371630 | N9: 식육가공품(양념조미육(불고기))이나 1차 생육 축산물로 오등록됨
A10: 6 | B10: 기존 참여 지속 | C10: 조미가공육 ➡️ 축산물 오등록 | D10: 농산물 | E10: 롯데ON | F10: 농업회사법인 라이플로우 주식회사 | G10: 715-87-02493 | H10: [온누리7%혜택][주왕산가든] 명품 한돈 수제 돼지갈비 실속형 500g 양념돼지갈비 밀키트 | I10: 축산물 | J10: 가공식품(식육가공품) | K10: 345000 | L10: 11 | M10: 63050 | N10: 식육가공품(양념조미육)이나 1차 생육 축산물로 오등록됨
A11: 7 | B11: 기존 참여 지속 | C11: 조미가공육 ➡️ 축산물 오등록 | D11: 농산물 | E11: 롯데ON | F11: 주식회사 태범프레시 | G11: 832-86-02035 | H11: [홍익상회] 춘천닭갈비 500g x 3팩 국내산닭고기 양념 순살 | I11: 축산물 | J11: 가공식품(식육가공품) | K11: 0 | L11: 0 | M11: 0 | N11: 식육가공품(조미가공육(춘천닭갈비))이나 1차 생육 축산물로 오등록됨
A12: 8 | B12: 기존 참여 지속 | C12: 조미가공육 ➡️ 축산물 오등록 | D12: 농산물 | E12: 롯데ON | F12: 주식회사 영인에프앤에스 | G12: 847-88-01537 | H12: 삶은 돼지 대창 1kg | I12: 축산물 | J12: 가공식품(식육가공품) | K12: 54500 | L12: 7 | M12: 9440 | N12: 식육가공품(양념/가공육(대창))이나 1차 생육 축산물로 오등록됨
A13: 9 | B13: 기존 참여 지속 | C13: 조미가공육 ➡️ 축산물 오등록 | D13: 농산물 | E13: 롯데ON | F13: 주식회사 삼형제월드 | G13: 185-87-01669 | H13: 삼형제고기 한돈 간장 고추장 불고기 1kg (200g x 5팩) | I13: 축산물 | J13: 가공식품(식육가공품) | K13: 0 | L13: 0 | M13: 0 | N13: 식육가공품(양념조미육(불고기))이나 1차 생육 축산물로 오등록됨
A14: 10 | B14: 기존 참여 지속 | C14: 조미가공육 ➡️ 축산물 오등록 | D14: 농산물 | E14: 롯데ON | F14: 주식회사 태범프레시 | G14: 832-86-02035 | H14: [홍익상회] 춘천 홍익닭갈비 500g x 3팩 국내산 닭고기 양념 순살 | I14: 축산물 | J14: 가공식품(식육가공품) | K14: 2552440 | L14: 73 | M14: 410540 | N14: 식육가공품(조미가공육(춘천닭갈비))이나 1차 생육 축산물로 오등록됨
A15: 11 | B15: 8월 신규 인입 | C15: 조미가공육 ➡️ 축산물 오등록 | D15: 농산물 | E15: 롯데ON | F15: 주식회사 태범프레시 | G15: 832-86-02035 | H15: 한돈스테이크 4장x1팩 오븐 직화 떡갈비 맛 함박 스테이크 너비아니 | I15: 축산물 | J15: 가공식품(식육가공품) | K15: 29900 | L15: 1 | M15: 5740 | N15: 식육가공품(가공육(떡갈비·수제패티))이나 1차 생육 축산물로 오등록됨
A16: 12 | B16: 8월 신규 인입 | C16: 조미가공육 ➡️ 축산물 오등록 | D16: 농산물 | E16: 롯데ON | F16: 주식회사 태범프레시 | G16: 832-86-02035 | H16: 홍익상회 양념 오리 불고기 고추장 주물럭 400g (2인분) x 3팩 | I16: 축산물 | J16: 가공식품(식육가공품) | K16: 71800 | L16: 2 | M16: 13340 | N16: 식육가공품(양념조미육(주물럭))이나 1차 생육 축산물로 오등록됨
... A70: 66 | B70: 8월 신규 인입 | C70: 농산물 원물 ➡️ 가공식품 오등록 | D70: 유기농 | E70: 네이버 | F70: 버섯놀이터사천숲속표고 | G70: 122-93-29177 | H70: 무 농약 생 표고버섯을 햇볕에 잘 말려 자연 건조한 국내산 사천 건 표고버섯 100g | I70: 가공식품 | J70: 농산물(원물) | K70: 198000 | L70: 7 | M70: 0 | N70: 1차 신선 농산물(신선/건조 임산물(표고버섯 원물))이나 유통사에 가공식품으로 오등록되어 원물 실적에서 누락됨
A71: 합 계 | B71: 8월 이상치 66건 총계 | K71: 374952340 | L71: 20213 | M71: 19617240 | N71: 유통사 카테고리 매핑 수정 권고

Sheet ※ 7월_품목분류오류
A1: 2026 aT 온라인 판로지원 - 7월 품목분류 오류 정밀 감사 목록 (총 45건)
A2: ※ 7월 실적 기집계 데이터(1,305건) 전수 감사 | 오판단 False Positive 100% 제거 완료
A4: No | B4: 이상치 유형 | C4: 구분 | D4: 기획전 | E4: 유통사 | F4: 판매자명(업체명) | G4: 사업자번호 | H4: 상품명 | I4: 7월 현재분류 | J4: 권고 정정분류 | K4: 7월 매출액(원) | L4: 7월 주문수(건) | M4: 7월 쿠폰지원액(원) | N4: 이상치 판정 사유 및 조치 제언
A5: 1 | B5: 조미가공육 ➡️ 축산물 오등록 | C5: 기존 참여 지속 | D5: 농산물 | E5: 네이버 | F5: 두루푸드 | G5: 221-13-36518 | H5: 국민닭갈비 두루푸드 춘천닭갈비 택배 홈파티 캠핑요리 [원산지:닭고기 넓적다리(국산), 고추가루(국산), 기타(상세설명참조)] | I5: 축산물 | J5: 가공식품(식육가공품) | K5: 53342360 | L5: 2416 | M5: 3359880 | N5: 식육가공품(조미가공육(춘천닭갈비))이나 1차 생육 축산물로 오등록됨
A6: 2 | B6: 조미가공육 ➡️ 축산물 오등록 | C6: 기존 참여 지속 | D6: 농산물 | E6: 네이버 | F6: 농업회사법인(주)새나라 | G6: 792-88-00316 | H6: [모두닭갈비] 춘천 1+1팩 국산 닭다리살 캠핑 500gx2팩 (3~4인분) [원산지:국산] | I6: 축산물 | J6: 가공식품(식육가공품) | K6: 2269370 | L6: 104 | M6: 394640 | N6: 식육가공품(조미가공육(춘천닭갈비))이나 1차 생육 축산물로 오등록됨
A7: 3 | B7: 조미가공육 ➡️ 축산물 오등록 | C7: 기존 참여 지속 | D7: 농산물 | E7: 네이버 | F7: 두루푸드 | G7: 221-13-36518 | H7: 두루푸드 국민닭갈비 춘천닭갈비 택배 홈파티 캠핑요리 전통맛 [원산지:닭고기 넓적다리(국산), 고추가루(국산), 기타(상세설명참조)] | I7: 축산물 | J7: 가공식품(식육가공품) | K7: 1874050 | L7: 96 | M7: 96660 | N7: 식육가공품(조미가공육(춘천닭갈비))이나 1차 생육 축산물로 오등록됨
A8: 4 | B8: 조미가공육 ➡️ 축산물 오등록 | C8: 기존 참여 지속 | D8: 농산물 | E8: 네이버 | F8: 현풍떡갈비 | G8: 671-67-00557 | H8: 아기떡갈비 한우 한돈 수제 패티 현풍 세가지맛 3팩, 90g, 15개 [원산지:상세설명에 표시] | I8: 축산물 | J8: 가공식품(식육가공품) | K8: 1556900 | L8: 46 | M8: 81520 | N8: 식육가공품(가공육(떡갈비·수제패티))이나 1차 생육 축산물로 오등록됨
A9: 5 | B9: 가공완제품 ➡️ 농산물 원물 오등록 | C9: 기존 참여 지속 | D9: 농산물 | E9: 네이버 | F9: 신기농원 | G9: 540-25-00229 | H9: 애플링 동결건조 사과 배칩20g 딸기칩15g 3팩 국산100% 무첨가 간식 [원산지:국산(경상북도 문경시)] | I9: 농산물 | J9: 가공식품(제조가공품) | K9: 1143000 | L9: 62 | M9: 40800 | N9: 제조가공식품(과자류(동결건조 과일스낵))이나 1차 신선 농산물 원물로 오등록됨
A10: 6 | B10: 조미가공육 ➡️ 축산물 오등록 | C10: 기존 참여 지속 | D10: 농산물 | E10: 네이버 | F10: 두루푸드 | G10: 221-13-36518 | H10: 두루푸드 국민닭갈비 춘천닭갈비 택배 홈파티 캠핑요리 간장닭갈비 [원산지:닭고기 넓적다리(국산), 기타(상세설명참조)] | I10: 축산물 | J10: 가공식품(식육가공품) | K10: 927300 | L10: 65 | M10: 16720 | N10: 식육가공품(조미가공육(춘천닭갈비))이나 1차 생육 축산물로 오등록됨
A11: 7 | B11: 가공완제품 ➡️ 농산물 원물 오등록 | C11: 기존 참여 지속 | D11: 농산물 | E11: 네이버 | F11: 신기농원 | G11: 540-25-00229 | H11: 애플링 딸기칩 10봉 국산100% 동결건조 / 아기부터 온가족 건강간식 [원산지:국산(경상북도 문경시)] | I11: 농산물 | J11: 가공식품(제조가공품) | K11: 900500 | L11: 22 | M11: 44800 | N11: 제조가공식품(과자류(동결건조 과일스낵))이나 1차 신선 농산물 원물로 오등록됨
A12: 8 | B12: 가공완제품 ➡️ 농산물 원물 오등록 | C12: 기존 참여 지속 | D12: 농산물 | E12: 네이버 | F12: 신기농원 | G12: 540-25-00229 | H12: 애플링 국산 동결건조 사과칩·배칩 무첨가 건강간식 어린이 유아 [원산지:국산(경상북도 문경시)] | I12: 농산물 | J12: 가공식품(제조가공품) | K12: 770500 | L12: 12 | M12: 7400 | N12: 제조가공식품(과자류(동결건조 과일스낵))이나 1차 신선 농산물 원물로 오등록됨
A13: 9 | B13: 가공완제품 ➡️ 농산물 원물 오등록 | C13: 기존 참여 지속 | D13: 농산물 | E13: 네이버 | F13: 신기농원 | G13: 540-25-00229 | H13: 애플링 국산 동결건조 사과칩·배칩 자유구성 / 유아 휴대용 건강간식 [원산지:국산(경상북도)] | I13: 농산물 | J13: 가공식품(제조가공품) | K13: 547910 | L13: 15 | M13: 14800 | N13: 제조가공식품(과자류(동결건조 과일스낵))이나 1차 신선 농산물 원물로 오등록됨
A14: 10 | B14: 조미가공육 ➡️ 축산물 오등록 | C14: 기존 참여 지속 | D14: 농산물 | E14: 네이버 | F14: 두루푸드 | G14: 221-13-36518 | H14: 두루푸드 국민닭갈비 춘천닭갈비 택배 홈파티 캠핑요리 숯불닭갈비 [원산지:닭넓적다리(국산), 고추가루(국산), 기타(상세설명참조)] | I14: 축산물 | J14: 가공식품(식육가공품) | K14: 511650 | L14: 17 | M14: 8760 | N14: 식육가공품(조미가공육(춘천닭갈비))이나 1차 생육 축산물로 오등록됨
A15: 11 | B15: 조미가공육 ➡️ 축산물 오등록 | C15: 기존 참여 지속 | D15: 농산물 | E15: 네이버 | F15: 두루푸드 | G15: 221-13-36518 | H15: 두루푸드 국민닭갈비 춘천닭갈비 택배 홈파티 캠핑요리 허브소금닭갈비 [원산지:닭고기 넓적다리(국산), 기타(상세설명참조)] | I15: 축산물 | J15: 가공식품(식육가공품) | K15: 500100 | L15: 24 | M15: 4180 | N15: 식육가공품(조미가공육(춘천닭갈비))이나 1차 생육 축산물로 오등록됨
A16: 12 | B16: 조미가공육 ➡️ 축산물 오등록 | C16: 기존 참여 지속 | D16: 농산물 | E16: 네이버 | F16: 농업회사법인(주)새나라 | G16: 792-88-00316 | H16: 국내산 냉동 닭내장 1kg 곱창,알탕, 닭부산물 [원산지:국산(전라북도 익산시)] | I16: 축산물 | J16: 가공식품(식육가공품) | K16: 365590 | L16: 6 | M16: 12590 | N16: 식육가공품(양념/가공육(곱창/대창))이나 1차 생육 축산물로 오등록됨
... A49: 45 | B49: 가공완제품 ➡️ 농산물 원물 오등록 | C49: 기존 참여 지속 | D49: 유기농 | E49: 오아시스 | F49: 해담는집 | G49: 745-96-00315 | H49: 해담는집 유기농 고춧가루 500g/200g(순한맛/보통맛/매운맛) | I49: 농산물 | J49: 가공식품(제조가공품) | K49: 208400 | L49: 6 | M49: 35006 | N49: 제조가공식품(조미식품(고춧가루))이나 1차 신선 농산물 원물로 오등록됨
A50: 합 계 | B50: 7월 이상치 45건 총계 | K50: 104731260 | L50: 3721 | M50: 9373286 | N50: 유통사 카테고리 매핑 수정 권고

Sheet ※ 7-8월_품목변경
A1: 2026 aT 온라인 판로지원 - 7월 ➡️ 8월 품목분류 자의적 변경 목록 (총 38건)
A2: ※ 동일 사업자·동일 상품인데 7월과 8월 제출 시 카테고리 분류가 자의적으로 바뀐 38건 전수 대조표
A4: No | B4: 유통사 | C4: 사업자명 | D4: 사업자번호 | E4: 상품명 | F4: 7월 분류 | G4: 8월 변경분류 | H4: 7월 매출액(원) | I4: 8월 누적매출액(원) | J4: 8월 순수매출액(원)
A5: 1 | B5: 롯데ON | C5: 주식회사 태범프레시 | D5: 832-86-02035 | E5: [홍익상회] 춘천닭갈비 500g x 3팩 국내산닭고기 양념 순살 | F5: 가공식품 | G5: 축산물 | H5: 0 | I5: 0 | J5: 0
A6: 2 | B6: 롯데ON | C6: 주식회사 태범프레시 | D6: 832-86-02035 | E6: [홍익상회] 춘천 홍익닭갈비 500g x 3팩 국내산 닭고기 양념 순살 | F6: 가공식품 | G6: 축산물 | H6: 2552440 | I6: 2552440 | J6: 0
A7: 3 | B7: 롯데ON | C7: 신선식품 | D7: 131-35-96215 | E7: [온누리7%혜택]고소한 국산 볶은참깨 200g | F7: 농산물 | G7: 가공식품 | H7: 25600 | I7: 204800 | J7: 179200
A8: 4 | B8: 지마켓 | C8: 두원식품(주) | D8: 606-81-52718 | E8: (신선집중) 국내산 한돈 프리미엄 대패 삼겹살 1.2kg | F8: 농산물 | G8: 축산물 | H8: 51796200 | I8: 55053800 | J8: 3257600
A9: 5 | B9: 지마켓 | C9: 다모아영농조합법인 | D9: 613-81-60803 | E9: 농협 공동선별 햇 남해 통마늘 3kg(상) 실중량 지리적표시품 | F9: 축산물 | G9: 농산물 | H9: 73800 | I9: 701100 | J9: 627300
A10: 6 | B10: 지마켓 | C10: 청정태안식품 | D10: 316-01-24597 | E10: 김명월 검정콩 청국장가루 1kg(500g2통) | F10: 농산물 | G10: 가공식품 | H10: 74000 | I10: 222000 | J10: 148000
A11: 7 | B11: 지마켓 | C11: 청정태안식품 | D11: 316-01-24597 | E11: 김명월 검정콩 청국장가루 1kg(500g2통) | F11: 농산물 | G11: 가공식품 | H11: 74000 | I11: 259000 | J11: 185000
A12: 8 | B12: 지마켓 | C12: 형지표고버섯 | D12: 290-94-00335 | E12: 형지표고버섯 흑화고 상황버섯 혼합2호 표고 버섯 선물세트 | F12: 가공식품 | G12: 농산물 | H12: 0 | I12: 0 | J12: 0
A13: 9 | B13: 지마켓 | C13: 농부플러스 | D13: 571-81-00383 | E13: 국산 볶음참깨 햇 참깨 볶은참깨 토종 통깨 200g | F13: 가공식품 | G13: 농산물 | H13: 360800 | I13: 1098800 | J13: 738000
A14: 10 | B14: 지마켓 | C14: 농부플러스 | D14: 571-81-00383 | E14: 국산 볶음참깨 햇 참깨 볶은참깨 토종 통깨 150g | F14: 가공식품 | G14: 농산물 | H14: 13900 | I14: 42700 | J14: 28800
A15: 11 | B15: 지마켓 | C15: 듬뿍곡간 | D15: 181-02-01980 | E15: 듬뿍곡간 국내산 볶은 귀리 / 아침식사대용 간식 | F15: 가공식품 | G15: 농산물 | H15: 0 | I15: 0 | J15: 0
A16: 12 | B16: 지마켓 | C16: 듬뿍곡간 | D16: 181-02-01980 | E16: 듬뿍곡간 국내산 쑥미숫가루 / 선식 식사대용 간식 500g | F16: 농산물 | G16: 가공식품 | H16: 0 | I16: 23800 | J16: 23800
... A42: 38 | B42: 오아시스 | C42: 해담는집 | D42: 745-96-00315 | E42: 해담는집 유기농 고춧가루 500g/200g(순한맛/보통맛/매운맛) | F42: 농산물 | G42: 가공식품 | H42: 208400 | I42: 434900 | J42: 226500
A43: 합 계 | B43: 변경 38건 총계 | H43: 111175440 | I43: 185370440 | J43: 74195000
