Workbook

Sheet 분석
B1: ※ 전체 기획전 결과
B3: 1. 해당 월 참여 상품 수 및 업체수
B4: 구분 | C4: 총 계 | D4: 농부가바로팜 | K4: 친환경
D5: 소 계 | E5: 네이버 | F5: 지마켓 | G5: 롯데ON | H5: 온누리마켓 | I5: 농가살리기 | J5: 오아시스 | K5: 소 계 | L5: 네이버 | M5: 오아시스
B6: 업체수 | C6: =D6+K6 | D6: =SUM(E6:J6) | E6: 136 | F6: 53 | G6: 47 | H6: 24 | I6: 9 | J6: 16 | K6: =SUM(L6:M6) | L6: 26 | M6: 29
B7: 7월 | C7: =SUM(D7,K7) | D7: =SUM(E7:J7) | E7: 82 | F7: 36 | G7: 32 | H7: 17 | I7: 6 | J7: 13 | K7: =SUM(L7:M7) | L7: 16 | M7: 16
B8: 상품수 | C8: =D8+K8 | D8: =SUM(E8:J8) | E8: =COUNTIF(①농산물raw!$A$6:$A$1454,E$5) | F8: =COUNTIF(①농산물raw!$A$6:$A$1454,F$5) | G8: =COUNTIF(①농산물raw!$A$6:$A$1454,G$5) | H8: =COUNTIF(①농산물raw!$A$6:$A$1454,H$5) | I8: =COUNTIF(①농산물raw!$A$6:$A$1454,I$5) | J8: =COUNTIF(①농산물raw!$A$6:$A$1454,J$5) | K8: =SUM(L8:M8) | L8: =COUNTIF(②유기농raw!$A$6:$A$207,L$5) | M8: =COUNTIF(②유기농raw!$A$6:$A$207,M$5)
B10: 2. 유통사 별 쿠폰 사용액
B11: 구분 | C11: 총 계 | D11: 농부가바로팜 | K11: 친환경
D12: 소 계 | E12: 네이버 | F12: 지마켓 | G12: 롯데ON | H12: 온누리마켓 | I12: 농가살리기 | J12: 오아시스 | K12: 소 계 | L12: 네이버 | M12: 오아시스
B13: 쿠폰 사용액 | C13: =D13+K13 | D13: =SUM(E13:J13) | E13: =SUMIF(①농산물raw!$A$6:$A$1454,E$12,①농산물raw!$H$6:$H$1454) | F13: =SUMIF(①농산물raw!$A$6:$A$1454,F$12,①농산물raw!$H$6:$H$1454) | G13: =SUMIF(①농산물raw!$A$6:$A$1454,G$12,①농산물raw!$H$6:$H$1454) | H13: =SUMIF(①농산물raw!$A$6:$A$1454,H$12,①농산물raw!$H$6:$H$1454) | I13: =SUMIF(①농산물raw!$A$6:$A$1454,I$12,①농산물raw!$H$6:$H$1454) | J13: =SUMIF(①농산물raw!$A$6:$A$1454,J$12,①농산물raw!$H$6:$H$1454) | K13: =SUM(L13:M13) | L13: =SUMIF(②유기농raw!$A$6:$A$207,L$12,②유기농raw!$H$6:$H$207) | M13: =SUMIF(②유기농raw!$A$6:$A$207,M$12,②유기농raw!$H$6:$H$207)
B15: 3. 유통사 별 매출 분석
B16: 구분 | C16: 총 계 | D16: 농부가바로팜 | K16: 친환경
D17: 소 계 | E17: 네이버 | F17: 지마켓 | G17: 롯데ON | H17: 온누리마켓 | I17: 농가살리기 | J17: 오아시스 | K17: 소 계 | L17: 네이버 | M17: 오아시스
B18: 매출액 | C18: =D18+K18 | D18: =SUM(E18:J18) | E18: =SUMIF(①농산물raw!$A$6:$A$1454,E$17,①농산물raw!$G$6:$G$1454) | F18: =SUMIF(①농산물raw!$A$6:$A$1454,F$17,①농산물raw!$G$6:$G$1454) | G18: =SUMIF(①농산물raw!$A$6:$A$1454,G$17,①농산물raw!$G$6:$G$1454) | H18: =SUMIF(①농산물raw!$A$6:$A$1454,H$17,①농산물raw!$G$6:$G$1454) | I18: =SUMIF(①농산물raw!$A$6:$A$1454,I$17,①농산물raw!$G$6:$G$1454) | J18: =SUMIF(①농산물raw!$A$6:$A$1454,J$17,①농산물raw!$G$6:$G$1454) | K18: =SUM(L18:M18) | L18: =SUMIF(②유기농raw!$A$6:$A$207,L$17,②유기농raw!$G$6:$G$207) | M18: =SUMIF(②유기농raw!$A$6:$A$207,M$17,②유기농raw!$G$6:$G$207)
B20: 4. 유통사 별 판매 건수
B21: 구분 | C21: 총 계 | D21: 농부가바로팜 | K21: 친환경
D22: 소 계 | E22: 네이버 | F22: 지마켓 | G22: 롯데ON | H22: 온누리마켓 | I22: 농가살리기 | J22: 오아시스 | K22: 소 계 | L22: 네이버 | M22: 오아시스
B23: 판매건수 | C23: =D23+K23 | D23: =SUM(E23:J23) | E23: =SUMIF(①농산물raw!$A$6:$A$1454,E$22,①농산물raw!$F$6:$F$1454) | F23: =SUMIF(①농산물raw!$A$6:$A$1454,F$22,①농산물raw!$F$6:$F$1454) | G23: =SUMIF(①농산물raw!$A$6:$A$1454,G$22,①농산물raw!$F$6:$F$1454) | H23: =SUMIF(①농산물raw!$A$6:$A$1454,H$22,①농산물raw!$F$6:$F$1454) | I23: =SUMIF(①농산물raw!$A$6:$A$1454,I$22,①농산물raw!$F$6:$F$1454) | J23: =SUMIF(①농산물raw!$A$6:$A$1454,J$22,①농산물raw!$F$6:$F$1454) | K23: =SUM(L23:M23) | L23: =SUMIF(②유기농raw!$A$6:$A$207,L$22,②유기농raw!$F$6:$F$207) | M23: =SUMIF(②유기농raw!$A$6:$A$207,M$22,②유기농raw!$F$6:$F$207)
B25: 5. 유통사별 품목별 쿠폰 사용액
B26: 구분 | C26: 총 계 | D26: 농부가바로팜 | K26: 친환경
D27: 소 계 | E27: 네이버 | F27: 지마켓 | G27: 롯데ON | H27: 온누리마켓 | I27: 농가살리기 | J27: 오아시스 | K27: 소 계 | L27: 네이버 | M27: 오아시스
B28: 총 계 | C28: =D28+K28 | D28: =SUM(E28:J28) | E28: =SUM(E29:E31) | F28: =SUM(F29:F31) | G28: =SUM(G29:G31) | H28: =SUM(H29:H31) | I28: =SUM(I29:I31) | J28: =SUM(J29:J31) | K28: =SUM(L28:M28) | L28: =SUM(L29:L31) | M28: =SUM(M29:M31)
B29: 농산물 | C29: =D29+K29 | D29: =SUM(E29:J29) | E29: =SUMIFS(①농산물raw!$H$6:$H$1454,①농산물raw!$A$6:$A$1454,E$27,①농산물raw!$B$6:$B$1454,$B29) | F29: =SUMIFS(①농산물raw!$H$6:$H$1454,①농산물raw!$A$6:$A$1454,F$27,①농산물raw!$B$6:$B$1454,$B29) | G29: =SUMIFS(①농산물raw!$H$6:$H$1454,①농산물raw!$A$6:$A$1454,G$27,①농산물raw!$B$6:$B$1454,$B29) | H29: =SUMIFS(①농산물raw!$H$6:$H$1454,①농산물raw!$A$6:$A$1454,H$27,①농산물raw!$B$6:$B$1454,$B29) | I29: =SUMIFS(①농산물raw!$H$6:$H$1454,①농산물raw!$A$6:$A$1454,I$27,①농산물raw!$B$6:$B$1454,$B29) | J29: =SUMIFS(①농산물raw!$H$6:$H$1454,①농산물raw!$A$6:$A$1454,J$27,①농산물raw!$B$6:$B$1454,$B29) | K29: =SUM(L29:M29) | L29: =SUMIFS(②유기농raw!$H$6:$H$207,②유기농raw!$A$6:$A$207,L$27,②유기농raw!$B$6:$B$207,$B29) | M29: =SUMIFS(②유기농raw!$H$6:$H$207,②유기농raw!$A$6:$A$207,M$27,②유기농raw!$B$6:$B$207,$B29)
B30: 축산물 | C30: =D30+K30 | D30: =SUM(E30:J30) | E30: =SUMIFS(①농산물raw!$H$6:$H$1454,①농산물raw!$A$6:$A$1454,E$27,①농산물raw!$B$6:$B$1454,$B30) | F30: =SUMIFS(①농산물raw!$H$6:$H$1454,①농산물raw!$A$6:$A$1454,F$27,①농산물raw!$B$6:$B$1454,$B30) | G30: =SUMIFS(①농산물raw!$H$6:$H$1454,①농산물raw!$A$6:$A$1454,G$27,①농산물raw!$B$6:$B$1454,$B30) | H30: =SUMIFS(①농산물raw!$H$6:$H$1454,①농산물raw!$A$6:$A$1454,H$27,①농산물raw!$B$6:$B$1454,$B30) | I30: =SUMIFS(①농산물raw!$H$6:$H$1454,①농산물raw!$A$6:$A$1454,I$27,①농산물raw!$B$6:$B$1454,$B30) | J30: =SUMIFS(①농산물raw!$H$6:$H$1454,①농산물raw!$A$6:$A$1454,J$27,①농산물raw!$B$6:$B$1454,$B30) | K30: =SUM(L30:M30) | L30: =SUMIFS(②유기농raw!$H$6:$H$207,②유기농raw!$A$6:$A$207,L$27,②유기농raw!$B$6:$B$207,$B30) | M30: =SUMIFS(②유기농raw!$H$6:$H$207,②유기농raw!$A$6:$A$207,M$27,②유기농raw!$B$6:$B$207,$B30)
B31: 가공식품 | C31: =D31+K31 | D31: =SUM(E31:J31) | E31: =SUMIFS(①농산물raw!$H$6:$H$1454,①농산물raw!$A$6:$A$1454,E$27,①농산물raw!$B$6:$B$1454,$B31) | F31: =SUMIFS(①농산물raw!$H$6:$H$1454,①농산물raw!$A$6:$A$1454,F$27,①농산물raw!$B$6:$B$1454,$B31) | G31: =SUMIFS(①농산물raw!$H$6:$H$1454,①농산물raw!$A$6:$A$1454,G$27,①농산물raw!$B$6:$B$1454,$B31) | H31: =SUMIFS(①농산물raw!$H$6:$H$1454,①농산물raw!$A$6:$A$1454,H$27,①농산물raw!$B$6:$B$1454,$B31) | I31: =SUMIFS(①농산물raw!$H$6:$H$1454,①농산물raw!$A$6:$A$1454,I$27,①농산물raw!$B$6:$B$1454,$B31) | J31: =SUMIFS(①농산물raw!$H$6:$H$1454,①농산물raw!$A$6:$A$1454,J$27,①농산물raw!$B$6:$B$1454,$B31) | K31: =SUM(L31:M31) | L31: =SUMIFS(②유기농raw!$H$6:$H$207,②유기농raw!$A$6:$A$207,L$27,②유기농raw!$B$6:$B$207,$B31) | M31: =SUMIFS(②유기농raw!$H$6:$H$207,②유기농raw!$A$6:$A$207,M$27,②유기농raw!$B$6:$B$207,$B31)
B33: 6. 유통사별 품목별 매출 분석
B34: 구분 | C34: 총 계 | D34: 농부가바로팜 | K34: 친환경
D35: 소 계 | E35: 네이버 | F35: 지마켓 | G35: 롯데ON | H35: 온누리마켓 | I35: 농가살리기 | J35: 오아시스 | K35: 소 계 | L35: 네이버 | M35: 오아시스
B36: 총 계 | C36: =D36+K36 | D36: =SUM(E36:J36) | E36: =SUM(E37:E39) | F36: =SUM(F37:F39) | G36: =SUM(G37:G39) | H36: =SUM(H37:H39) | I36: =SUM(I37:I39) | J36: =SUM(J37:J39) | K36: =SUM(L36:M36) | L36: =SUM(L37:L39) | M36: =SUM(M37:M39)
B37: 농산물 | C37: =D37+K37 | D37: =SUM(E37:J37) | E37: =SUMIFS(①농산물raw!$G$6:$G$1454,①농산물raw!$A$6:$A$1454,E$35,①농산물raw!$B$6:$B$1454,$B37) | F37: =SUMIFS(①농산물raw!$G$6:$G$1454,①농산물raw!$A$6:$A$1454,F$35,①농산물raw!$B$6:$B$1454,$B37) | G37: =SUMIFS(①농산물raw!$G$6:$G$1454,①농산물raw!$A$6:$A$1454,G$35,①농산물raw!$B$6:$B$1454,$B37) | H37: =SUMIFS(①농산물raw!$G$6:$G$1454,①농산물raw!$A$6:$A$1454,H$35,①농산물raw!$B$6:$B$1454,$B37) | I37: =SUMIFS(①농산물raw!$G$6:$G$1454,①농산물raw!$A$6:$A$1454,I$35,①농산물raw!$B$6:$B$1454,$B37) | J37: =SUMIFS(①농산물raw!$G$6:$G$1454,①농산물raw!$A$6:$A$1454,J$35,①농산물raw!$B$6:$B$1454,$B37) | K37: =SUM(L37:M37) | L37: =SUMIFS(②유기농raw!$G$6:$G$207,②유기농raw!$A$6:$A$207,L$35,②유기농raw!$B$6:$B$207,$B37) | M37: =SUMIFS(②유기농raw!$G$6:$G$207,②유기농raw!$A$6:$A$207,M$35,②유기농raw!$B$6:$B$207,$B37)
B38: 축산물 | C38: =D38+K38 | D38: =SUM(E38:J38) | E38: =SUMIFS(①농산물raw!$G$6:$G$1454,①농산물raw!$A$6:$A$1454,E$35,①농산물raw!$B$6:$B$1454,$B38) | F38: =SUMIFS(①농산물raw!$G$6:$G$1454,①농산물raw!$A$6:$A$1454,F$35,①농산물raw!$B$6:$B$1454,$B38) | G38: =SUMIFS(①농산물raw!$G$6:$G$1454,①농산물raw!$A$6:$A$1454,G$35,①농산물raw!$B$6:$B$1454,$B38) | H38: =SUMIFS(①농산물raw!$G$6:$G$1454,①농산물raw!$A$6:$A$1454,H$35,①농산물raw!$B$6:$B$1454,$B38) | I38: =SUMIFS(①농산물raw!$G$6:$G$1454,①농산물raw!$A$6:$A$1454,I$35,①농산물raw!$B$6:$B$1454,$B38) | J38: =SUMIFS(①농산물raw!$G$6:$G$1454,①농산물raw!$A$6:$A$1454,J$35,①농산물raw!$B$6:$B$1454,$B38) | K38: =SUM(L38:M38) | L38: =SUMIFS(②유기농raw!$G$6:$G$207,②유기농raw!$A$6:$A$207,L$35,②유기농raw!$B$6:$B$207,$B38) | M38: =SUMIFS(②유기농raw!$G$6:$G$207,②유기농raw!$A$6:$A$207,M$35,②유기농raw!$B$6:$B$207,$B38)
B39: 가공식품 | C39: =D39+K39 | D39: =SUM(E39:J39) | E39: =SUMIFS(①농산물raw!$G$6:$G$1454,①농산물raw!$A$6:$A$1454,E$35,①농산물raw!$B$6:$B$1454,$B39) | F39: =SUMIFS(①농산물raw!$G$6:$G$1454,①농산물raw!$A$6:$A$1454,F$35,①농산물raw!$B$6:$B$1454,$B39) | G39: =SUMIFS(①농산물raw!$G$6:$G$1454,①농산물raw!$A$6:$A$1454,G$35,①농산물raw!$B$6:$B$1454,$B39) | H39: =SUMIFS(①농산물raw!$G$6:$G$1454,①농산물raw!$A$6:$A$1454,H$35,①농산물raw!$B$6:$B$1454,$B39) | I39: =SUMIFS(①농산물raw!$G$6:$G$1454,①농산물raw!$A$6:$A$1454,I$35,①농산물raw!$B$6:$B$1454,$B39) | J39: =SUMIFS(①농산물raw!$G$6:$G$1454,①농산물raw!$A$6:$A$1454,J$35,①농산물raw!$B$6:$B$1454,$B39) | K39: =SUM(L39:M39) | L39: =SUMIFS(②유기농raw!$G$6:$G$207,②유기농raw!$A$6:$A$207,L$35,②유기농raw!$B$6:$B$207,$B39) | M39: =SUMIFS(②유기농raw!$G$6:$G$207,②유기농raw!$A$6:$A$207,M$35,②유기농raw!$B$6:$B$207,$B39)
B41: 7. 유통사별 품목별 판매 건수
B42: 구분 | C42: 총 계 | D42: 농부가바로팜 | K42: 친환경
D43: 소 계 | E43: 네이버 | F43: 지마켓 | G43: 롯데ON | H43: 온누리마켓 | I43: 농가살리기 | J43: 오아시스 | K43: 소 계 | L43: 네이버 | M43: 오아시스
B44: 총 계 | C44: =D44+K44 | D44: =SUM(E44:J44) | E44: =SUM(E45:E47) | F44: =SUM(F45:F47) | G44: =SUM(G45:G47) | H44: =SUM(H45:H47) | I44: =SUM(I45:I47) | J44: =SUM(J45:J47) | K44: =SUM(L44:M44) | L44: =SUM(L45:L47) | M44: =SUM(M45:M47)
B45: 농산물 | C45: =D45+K45 | D45: =SUM(E45:J45) | E45: =SUMIFS(①농산물raw!$F$6:$F$1454,①농산물raw!$A$6:$A$1454,E$43,①농산물raw!$B$6:$B$1454,$B45) | F45: =SUMIFS(①농산물raw!$F$6:$F$1454,①농산물raw!$A$6:$A$1454,F$43,①농산물raw!$B$6:$B$1454,$B45) | G45: =SUMIFS(①농산물raw!$F$6:$F$1454,①농산물raw!$A$6:$A$1454,G$43,①농산물raw!$B$6:$B$1454,$B45) | H45: =SUMIFS(①농산물raw!$F$6:$F$1454,①농산물raw!$A$6:$A$1454,H$43,①농산물raw!$B$6:$B$1454,$B45) | I45: =SUMIFS(①농산물raw!$F$6:$F$1454,①농산물raw!$A$6:$A$1454,I$43,①농산물raw!$B$6:$B$1454,$B45) | J45: =SUMIFS(①농산물raw!$F$6:$F$1454,①농산물raw!$A$6:$A$1454,J$43,①농산물raw!$B$6:$B$1454,$B45) | K45: =SUM(L45:M45) | L45: =SUMIFS(②유기농raw!$F$6:$F$207,②유기농raw!$A$6:$A$207,L$43,②유기농raw!$B$6:$B$207,$B45) | M45: =SUMIFS(②유기농raw!$F$6:$F$207,②유기농raw!$A$6:$A$207,M$43,②유기농raw!$B$6:$B$207,$B45)
B46: 축산물 | C46: =D46+K46 | D46: =SUM(E46:J46) | E46: =SUMIFS(①농산물raw!$F$6:$F$1454,①농산물raw!$A$6:$A$1454,E$43,①농산물raw!$B$6:$B$1454,$B46) | F46: =SUMIFS(①농산물raw!$F$6:$F$1454,①농산물raw!$A$6:$A$1454,F$43,①농산물raw!$B$6:$B$1454,$B46) | G46: =SUMIFS(①농산물raw!$F$6:$F$1454,①농산물raw!$A$6:$A$1454,G$43,①농산물raw!$B$6:$B$1454,$B46) | H46: =SUMIFS(①농산물raw!$F$6:$F$1454,①농산물raw!$A$6:$A$1454,H$43,①농산물raw!$B$6:$B$1454,$B46) | I46: =SUMIFS(①농산물raw!$F$6:$F$1454,①농산물raw!$A$6:$A$1454,I$43,①농산물raw!$B$6:$B$1454,$B46) | J46: =SUMIFS(①농산물raw!$F$6:$F$1454,①농산물raw!$A$6:$A$1454,J$43,①농산물raw!$B$6:$B$1454,$B46) | K46: =SUM(L46:M46) | L46: =SUMIFS(②유기농raw!$F$6:$F$207,②유기농raw!$A$6:$A$207,L$43,②유기농raw!$B$6:$B$207,$B46) | M46: =SUMIFS(②유기농raw!$F$6:$F$207,②유기농raw!$A$6:$A$207,M$43,②유기농raw!$B$6:$B$207,$B46)
B47: 가공식품 | C47: =D47+K47 | D47: =SUM(E47:J47) | E47: =SUMIFS(①농산물raw!$F$6:$F$1454,①농산물raw!$A$6:$A$1454,E$43,①농산물raw!$B$6:$B$1454,$B47) | F47: =SUMIFS(①농산물raw!$F$6:$F$1454,①농산물raw!$A$6:$A$1454,F$43,①농산물raw!$B$6:$B$1454,$B47) | G47: =SUMIFS(①농산물raw!$F$6:$F$1454,①농산물raw!$A$6:$A$1454,G$43,①농산물raw!$B$6:$B$1454,$B47) | H47: =SUMIFS(①농산물raw!$F$6:$F$1454,①농산물raw!$A$6:$A$1454,H$43,①농산물raw!$B$6:$B$1454,$B47) | I47: =SUMIFS(①농산물raw!$F$6:$F$1454,①농산물raw!$A$6:$A$1454,I$43,①농산물raw!$B$6:$B$1454,$B47) | J47: =SUMIFS(①농산물raw!$F$6:$F$1454,①농산물raw!$A$6:$A$1454,J$43,①농산물raw!$B$6:$B$1454,$B47) | K47: =SUM(L47:M47) | L47: =SUMIFS(②유기농raw!$F$6:$F$207,②유기농raw!$A$6:$A$207,L$43,②유기농raw!$B$6:$B$207,$B47) | M47: =SUMIFS(②유기농raw!$F$6:$F$207,②유기농raw!$A$6:$A$207,M$43,②유기농raw!$B$6:$B$207,$B47)
...

Sheet ※ 이상치 및 규정검토
B2: 2026 aT 온라인 판로지원 사업 - 실적 이상치 및 규정 준수 검토 리포트
B4: 1. 사업 규정 준수 여부 전수 검토 결과 요약
B5: 검토 규정 항목 | C5: 사업 운영 기준 | D5: 전수 검토 결과 | E5: 준수 여부 | F5: 세부 검토 내역
B6: 업체당 쿠폰 한도 | C6: 업체당 최대 8,000,000원 | D6: 초과 업체 0개 (최대 소진액 6,140,240원 / 76.8%) | E6: 정상 준수 | F6: 농부들(76.8%), 자연푸드(73.1%), 팜앤유(71.6%) 등 전 업체 한도 내 안전 운영
B7: 쿠폰 할인율 상한 | C7: 매출액 대비 최대 20.0% | D7: 초과 건수 0건 (최대 할인율 정확히 20.00%) | E7: 정상 준수 | F7: 1,651개 로우데이터 행 전수 검사 결과 20% 초과 할인 없음
B8: 건당 쿠폰 한도 | C8: 건당(개당) 최대 10,000원 | D8: 초과 건수 0건 (건당 최대 쿠폰액 정확히 10,000원) | E8: 정상 준수 | F8: 롯데ON 등 10,000원 정액 적용 건 존재하나 초과 건 없음
B11: 2. 누적 실적 역전(감소) 이상치 내역 (총 4건)
B12: 구분 | C12: 유통사 | D12: 사업자명 | E12: 사업자번호 | F12: 상품명 | G12: 7월 실적 | H12: 8월 누적실적 | I12: 증감(8월순수) | J12: 이상 원인 분석 및 특이사항
B13: 업체 쿠폰 역전 | C13: 네이버 | D13: 농업회사법인 랑이네세상 주식회사 | E13: 488-88-03205 | F13: [업체 전체 쿠폰] | G13: 4,955,760원 | H13: 4,947,920원 | I13: -7,840원 | J13: 매출/건수는 증가했으나 쿠폰 사용액이 7월 대비 누적에서 7,840원 감소 (주문취소/환불 반영 의심)
B14: 상품 매출 역전 | C14: 온누리마켓 | D14: 농업회사법인(주)더봄 | E14: 138-81-67809 | F14: 생화용 백합 꽃 백합생화 1000ml x 5 | G14: 60,000원 (1건) | H14: 0원 (0건) | I14: -60,000원 (-1건) | J14: 7월에 1건 판매되었으나 8월 누적 로우데이터에서 0원으로 취합되어 8월 순수 실적 음수 발생
B15: 상품 매출 역전 | C15: 온누리마켓 | D15: 더모닝 | E15: 655-09-02685 | F15: 더모닝 닭 볶음탕 닭볶음탕 90g 1인분 x 5팩 캠핑 밀키트 | G15: 240,000원 (12건) | H15: 0원 (0건) | I15: -240,000원 (-12건) | J15: 7월에 12건 판매되었으나 8월 누적 로우데이터에서 0원으로 취합되어 8월 순수 실적 음수 발생
B16: 상품 매출 역전 | C16: 온누리마켓 | D16: 더모닝 | E16: 655-09-02685 | F16: 더모닝 닭 볶음탕 닭볶음탕 400g 4인분 캠핑 밀키트 | G16: 54,000원 (3건) | H16: 0원 (0건) | I16: -54,000원 (-3건) | J16: 7월에 3건 판매되었으나 8월 누적 로우데이터에서 0원으로 취합되어 8월 순수 실적 음수 발생
B19: 3. 업체별 쿠폰 한도(800만원) 소진율 상위 Top 10 업체 모니터링
B20: 순위 | C20: 사업자명 | D20: 사업자번호 | E20: 참여 유통사 | F20: 누적 매출액 | G20: 누적 쿠폰사용액 | H20: 한도(800만원) 소진율 | I20: 잔여 한도액
B21: 1 | C21: 농부들 | D21: 579-90-00021 | E21: 네이버 | F21: 53342360 | G21: 6140240 | H21: 76.8% | I21: 1859760
B22: 2 | C22: 농업회사법인(주)자연푸드 | D22: 412-81-50546 | E22: 네이버 | F22: 55214000 | G22: 5847700 | H22: 73.1% | I22: 2152300
B23: 3 | C23: 팜앤유 | D23: 477-93-01384 | E23: 지마켓 | F23: 41243100 | G23: 5728100 | H23: 71.6% | I23: 2271900
B24: 4 | C24: (주)다채몰 | D24: 114-86-65039 | E24: 네이버 | F24: 39871200 | G24: 5268240 | H24: 65.9% | I24: 2731760
B25: 5 | C25: 해남농협 | D25: 323-88-00158 | E25: 롯데ON | F25: 45120000 | G25: 5136630 | H25: 64.2% | I25: 2863370
B26: 6 | C26: 농업회사법인 주식회사 드림마이스터 | D26: 485-88-00795 | E26: 네이버 | F26: 36240000 | G26: 5105280 | H26: 63.8% | I26: 2894720
B27: 7 | C27: 농업회사법인 철원이곡 주식회사 | D27: 127-81-93991 | E27: 농가살리기 | F27: 34500000 | G27: 5097728 | H27: 63.7% | I27: 2902272
B28: 8 | C28: 해주농협통합 | D28: 126-82-11620 | E28: 네이버 | F28: 48900000 | G28: 5085890 | H28: 63.6% | I28: 2914110
B29: 9 | C29: 두원식품(주) | D29: 606-81-52718 | E29: 지마켓 | F29: 55053800 | G29: 5062400 | H29: 63.3% | I29: 2937600
B30: 10 | C30: 청양농협 | D30: 499-51-00634 | E30: 롯데ON | F30: 38100000 | G30: 5049440 | H30: 63.1% | I30: 2950560
B33: 4. 농가·유통사 품목분류 자의적 변경 이상건 전수 내역 (총 38건)
B34: No | C34: 유통사 | D34: 사업자명 | E34: 사업자번호 | F34: 상품명 | G34: 7월 분류 | H34: 8월 변경분류 | I34: 7월 매출액 | J34: 8월 누적매출액 | K34: 8월 순수매출액
B35: 1 | C35: 롯데ON | D35: 주식회사 태범프레시 | E35: 832-86-02035 | F35: [홍익상회] 춘천닭갈비 500g x 3팩 국내산닭고기 양념 순살 | G35: 가공식품 | H35: 축산물 | I35: 0 | J35: 0 | K35: 0
B36: 2 | C36: 롯데ON | D36: 주식회사 태범프레시 | E36: 832-86-02035 | F36: [홍익상회] 춘천 홍익닭갈비 500g x 3팩 국내산 닭고기 양념 순살 | G36: 가공식품 | H36: 축산물 | I36: 2552440 | J36: 2552440 | K36: 0
B37: 3 | C37: 롯데ON | D37: 신선식품 | E37: 131-35-96215 | F37: [온누리7%혜택]고소한 국산 볶은참깨 200g | G37: 농산물 | H37: 가공식품 | I37: 25600 | J37: 204800 | K37: 179200
B38: 4 | C38: 지마켓 | D38: 두원식품(주) | E38: 606-81-52718 | F38: (신선집중) 국내산 한돈 프리미엄 대패 삼겹살 1.2kg | G38: 농산물 | H38: 축산물 | I38: 51796200 | J38: 55053800 | K38: 3257600
B39: 5 | C39: 지마켓 | D39: 다모아영농조합법인 | E39: 613-81-60803 | F39: 농협 공동선별 햇 남해 통마늘 3kg(상) 실중량 지리적표시품 | G39: 축산물 | H39: 농산물 | I39: 73800 | J39: 701100 | K39: 627300
B40: 6 | C40: 지마켓 | D40: 청정태안식품 | E40: 316-01-24597 | F40: 김명월 검정콩 청국장가루 1kg(500g2통) | G40: 농산물 | H40: 가공식품 | I40: 74000 | J40: 222000 | K40: 148000
B41: 7 | C41: 지마켓 | D41: 청정태안식품 | E41: 316-01-24597 | F41: 김명월 검정콩 청국장가루 1kg(500g2통) | G41: 농산물 | H41: 가공식품 | I41: 74000 | J41: 259000 | K41: 185000
B42: 8 | C42: 지마켓 | D42: 형지표고버섯 | E42: 290-94-00335 | F42: 형지표고버섯 흑화고 상황버섯 혼합2호 표고 버섯 선물세트 | G42: 가공식품 | H42: 농산물 | I42: 0 | J42: 0 | K42: 0
B43: 9 | C43: 지마켓 | D43: 농부플러스 | E43: 571-81-00383 | F43: 국산 볶음참깨 햇 참깨 볶은참깨 토종 통깨 200g | G43: 가공식품 | H43: 농산물 | I43: 360800 | J43: 1098800 | K43: 738000
B44: 10 | C44: 지마켓 | D44: 농부플러스 | E44: 571-81-00383 | F44: 국산 볶음참깨 햇 참깨 볶은참깨 토종 통깨 150g | G44: 가공식품 | H44: 농산물 | I44: 13900 | J44: 42700 | K44: 28800
B45: 11 | C45: 지마켓 | D45: 듬뿍곡간 | E45: 181-02-01980 | F45: 듬뿍곡간 국내산 볶은 귀리 / 아침식사대용 간식 | G45: 가공식품 | H45: 농산물 | I45: 0 | J45: 0 | K45: 0
B46: 12 | C46: 지마켓 | D46: 듬뿍곡간 | E46: 181-02-01980 | F46: 듬뿍곡간 국내산 쑥미숫가루 / 선식 식사대용 간식 500g | G46: 농산물 | H46: 가공식품 | I46: 0 | J46: 23800 | K46: 23800
... B72: 38 | C72: 오아시스 | D72: 해담는집 | E72: 745-96-00315 | F72: 해담는집 유기농 고춧가루 500g/200g(순한맛/보통맛/매운맛) | G72: 농산물 | H72: 가공식품 | I72: 208400 | J72: 434900 | K72: 226500

Sheet 농산물업체
F1: =SUM(F3:F287) | G1: =SUM(G3:G287) | H1: =SUM(H3:H287) | I1: =COUNTIF(I3:I500,"O")
A2: NO | B2: 구분 | C2: 사업자등록번호 | D2: 업체명 | E2: 배정유통사 | F2: 판매건수 | G2: 매출액 | H2: 판촉액 | I2: 7월 실제 인입
A3: 1 | B3: 도약 | C3: 511-87-00286 | D3: 농업회사법인 영주마실(주) | E3: 롯데온 | F3: =SUMIF(①농산물raw!$D:$D,$C3,①농산물raw!$F:$F) | G3: =SUMIF(①농산물raw!$D:$D,$C3,①농산물raw!$G:$G) | H3: =SUMIF(①농산물raw!$D:$D,$C3,①농산물raw!$H:$H)
A4: 2 | B4: 도약 | C4: 302-81-25814 | D4: 영동감협동조합 | E4: 롯데온 | F4: =SUMIF(①농산물raw!$D:$D,$C4,①농산물raw!$F:$F) | G4: =SUMIF(①농산물raw!$D:$D,$C4,①농산물raw!$G:$G) | H4: =SUMIF(①농산물raw!$D:$D,$C4,①농산물raw!$H:$H) | I4: O
A5: 3 | B5: 도약 | C5: 449-92-01723 | D5: 채씨네표고농원 | E5: 네이버 | F5: =SUMIF(①농산물raw!$D:$D,$C5,①농산물raw!$F:$F) | G5: =SUMIF(①농산물raw!$D:$D,$C5,①농산물raw!$G:$G) | H5: =SUMIF(①농산물raw!$D:$D,$C5,①농산물raw!$H:$H) | I5: O
A6: 4 | B6: 시작 | C6: 406-82-02051 | D6: 구천동농업협동조합 | E6: 네이버 | F6: =SUMIF(①농산물raw!$D:$D,$C6,①농산물raw!$F:$F) | G6: =SUMIF(①농산물raw!$D:$D,$C6,①농산물raw!$G:$G) | H6: =SUMIF(①농산물raw!$D:$D,$C6,①농산물raw!$H:$H)
A7: 5 | B7: 성장 | C7: 529-44-01222 | D7: 나뚜라리농원 | E7: 네이버 | F7: =SUMIF(①농산물raw!$D:$D,$C7,①농산물raw!$F:$F) | G7: =SUMIF(①농산물raw!$D:$D,$C7,①농산물raw!$G:$G) | H7: =SUMIF(①농산물raw!$D:$D,$C7,①농산물raw!$H:$H) | I7: O
A8: 6 | B8: 도약 | C8: 416-81-92591 | D8: 좋은세상협동조합 | E8: 롯데온 | F8: =SUMIF(①농산물raw!$D:$D,$C8,①농산물raw!$F:$F) | G8: =SUMIF(①농산물raw!$D:$D,$C8,①농산물raw!$G:$G) | H8: =SUMIF(①농산물raw!$D:$D,$C8,①농산물raw!$H:$H)
A9: 7 | B9: 도약 | C9: 516-88-01860 | D9: 주식회사 농업회사법인 에상스팜 | E9: 롯데온 | F9: =SUMIF(①농산물raw!$D:$D,$C9,①농산물raw!$F:$F) | G9: =SUMIF(①농산물raw!$D:$D,$C9,①농산물raw!$G:$G) | H9: =SUMIF(①농산물raw!$D:$D,$C9,①농산물raw!$H:$H) | I9: O
A10: 8 | B10: 시작 | C10: 709-22-01767 | D10: 푸드상상 | E10: 롯데온 | F10: =SUMIF(①농산물raw!$D:$D,$C10,①농산물raw!$F:$F) | G10: =SUMIF(①농산물raw!$D:$D,$C10,①농산물raw!$G:$G) | H10: =SUMIF(①농산물raw!$D:$D,$C10,①농산물raw!$H:$H)
A11: 9 | B11: 시작 | C11: 104-12-14323 | D11: 교동앵무새힐링농장 | E11: 네이버 | F11: =SUMIF(①농산물raw!$D:$D,$C11,①농산물raw!$F:$F) | G11: =SUMIF(①농산물raw!$D:$D,$C11,①농산물raw!$G:$G) | H11: =SUMIF(①농산물raw!$D:$D,$C11,①농산물raw!$H:$H)
A12: 10 | B12: 도약 | C12: 514-03-53195 | D12: 삼진식품 | E12: 롯데온 | F12: =SUMIF(①농산물raw!$D:$D,$C12,①농산물raw!$F:$F) | G12: =SUMIF(①농산물raw!$D:$D,$C12,①농산물raw!$G:$G) | H12: =SUMIF(①농산물raw!$D:$D,$C12,①농산물raw!$H:$H)
A13: 11 | B13: 도약 | C13: 892-87-01864 | D13: 주식회사 마들 | E13: 지마켓 | F13: =SUMIF(①농산물raw!$D:$D,$C13,①농산물raw!$F:$F) | G13: =SUMIF(①농산물raw!$D:$D,$C13,①농산물raw!$G:$G) | H13: =SUMIF(①농산물raw!$D:$D,$C13,①농산물raw!$H:$H) | I13: O
A14: 12 | B14: 도약 | C14: 803-88-01105 | D14: 오고농원(주) | E14: 네이버 | F14: =SUMIF(①농산물raw!$D:$D,$C14,①농산물raw!$F:$F) | G14: =SUMIF(①농산물raw!$D:$D,$C14,①농산물raw!$G:$G) | H14: =SUMIF(①농산물raw!$D:$D,$C14,①농산물raw!$H:$H) | I14: O
A15: 13 | B15: 도약 | C15: 488-88-03205 | D15: 농업회사법인 랑이네세상 주식회사 | E15: 네이버 | F15: =SUMIF(①농산물raw!$D:$D,$C15,①농산물raw!$F:$F) | G15: =SUMIF(①농산물raw!$D:$D,$C15,①농산물raw!$G:$G) | H15: =SUMIF(①농산물raw!$D:$D,$C15,①농산물raw!$H:$H) | I15: O
A16: 14 | B16: 성장 | C16: 784-24-00666 | D16: 거창오미자 | E16: 네이버 | F16: =SUMIF(①농산물raw!$D:$D,$C16,①농산물raw!$F:$F) | G16: =SUMIF(①농산물raw!$D:$D,$C16,①농산물raw!$G:$G) | H16: =SUMIF(①농산물raw!$D:$D,$C16,①농산물raw!$H:$H) | I16: O
A17: 15 | B17: 시작 | C17: 888-94-01728 | D17: 파밍데이즈 | E17: 네이버 | F17: =SUMIF(①농산물raw!$D:$D,$C17,①농산물raw!$F:$F) | G17: =SUMIF(①농산물raw!$D:$D,$C17,①농산물raw!$G:$G) | H17: =SUMIF(①농산물raw!$D:$D,$C17,①농산물raw!$H:$H) | I17: O
A18: 16 | B18: 도약 | C18: 128-90-57082 | D18: 산골과수원 | E18: 롯데온 | F18: =SUMIF(①농산물raw!$D:$D,$C18,①농산물raw!$F:$F) | G18: =SUMIF(①농산물raw!$D:$D,$C18,①농산물raw!$G:$G) | H18: =SUMIF(①농산물raw!$D:$D,$C18,①농산물raw!$H:$H)
A19: 17 | B19: 도약 | C19: 626-86-01993 | D19: 농업회사법인 (주)자연의시간 | E19: 농가살리기 | F19: =SUMIF(①농산물raw!$D:$D,$C19,①농산물raw!$F:$F) | G19: =SUMIF(①농산물raw!$D:$D,$C19,①농산물raw!$G:$G) | H19: =SUMIF(①농산물raw!$D:$D,$C19,①농산물raw!$H:$H) | I19: O
A20: 18 | B20: 성장 | C20: 711-30-00994 | D20: 팜샐러드 | E20: 네이버 | F20: =SUMIF(①농산물raw!$D:$D,$C20,①농산물raw!$F:$F) | G20: =SUMIF(①농산물raw!$D:$D,$C20,①농산물raw!$G:$G) | H20: =SUMIF(①농산물raw!$D:$D,$C20,①농산물raw!$H:$H)
A21: 19 | B21: 도약 | C21: 186-96-01664 | D21: 쌍둥이농장 | E21: 지마켓 | F21: =SUMIF(①농산물raw!$D:$D,$C21,①농산물raw!$F:$F) | G21: =SUMIF(①농산물raw!$D:$D,$C21,①농산물raw!$G:$G) | H21: =SUMIF(①농산물raw!$D:$D,$C21,①농산물raw!$H:$H) | I21: O
A22: 20 | B22: 성장 | C22: 463-93-01691 | D22: 피스팜 | E22: 네이버 | F22: =SUMIF(①농산물raw!$D:$D,$C22,①농산물raw!$F:$F) | G22: =SUMIF(①농산물raw!$D:$D,$C22,①농산물raw!$G:$G) | H22: =SUMIF(①농산물raw!$D:$D,$C22,①농산물raw!$H:$H) | I22: O
A23: 21 | B23: 시작 | C23: 621-96-06105 | D23: HK팜 | E23: 네이버 | F23: =SUMIF(①농산물raw!$D:$D,$C23,①농산물raw!$F:$F) | G23: =SUMIF(①농산물raw!$D:$D,$C23,①농산물raw!$G:$G) | H23: =SUMIF(①농산물raw!$D:$D,$C23,①농산물raw!$H:$H)
A24: 22 | B24: 도약 | C24: 347-93-02082 | D24: 초록이들 | E24: 네이버 | F24: =SUMIF(①농산물raw!$D:$D,$C24,①농산물raw!$F:$F) | G24: =SUMIF(①농산물raw!$D:$D,$C24,①농산물raw!$G:$G) | H24: =SUMIF(①농산물raw!$D:$D,$C24,①농산물raw!$H:$H) | I24: O
A25: 23 | B25: 성장 | C25: 408-24-61681 | D25: 한국제다 | E25: 네이버 | F25: =SUMIF(①농산물raw!$D:$D,$C25,①농산물raw!$F:$F) | G25: =SUMIF(①농산물raw!$D:$D,$C25,①농산물raw!$G:$G) | H25: =SUMIF(①농산물raw!$D:$D,$C25,①농산물raw!$H:$H) | I25: O
A26: 24 | B26: 도약 | C26: 226-81-48890 | D26: 정선아라리한과농원 영농조합법인 | E26: 롯데온 | F26: =SUMIF(①농산물raw!$D:$D,$C26,①농산물raw!$F:$F) | G26: =SUMIF(①농산물raw!$D:$D,$C26,①농산물raw!$G:$G) | H26: =SUMIF(①농산물raw!$D:$D,$C26,①농산물raw!$H:$H) | I26: O
A27: 25 | B27: 도약 | C27: 412-81-24086 | D27: 영흥농산영농조합법인 | E27: 네이버 | F27: =SUMIF(①농산물raw!$D:$D,$C27,①농산물raw!$F:$F) | G27: =SUMIF(①농산물raw!$D:$D,$C27,①농산물raw!$G:$G) | H27: =SUMIF(①농산물raw!$D:$D,$C27,①농산물raw!$H:$H)
A28: 26 | B28: 도약 | C28: 142-33-00898 | D28: 어이딸부각 | E28: 지마켓 | F28: =SUMIF(①농산물raw!$D:$D,$C28,①농산물raw!$F:$F) | G28: =SUMIF(①농산물raw!$D:$D,$C28,①농산물raw!$G:$G) | H28: =SUMIF(①농산물raw!$D:$D,$C28,①농산물raw!$H:$H) | I28: O
A29: 27 | B29: 도약 | C29: 144-92-00528 | D29: 햇터농장 | E29: 네이버 | F29: =SUMIF(①농산물raw!$D:$D,$C29,①농산물raw!$F:$F) | G29: =SUMIF(①농산물raw!$D:$D,$C29,①농산물raw!$G:$G) | H29: =SUMIF(①농산물raw!$D:$D,$C29,①농산물raw!$H:$H)
A30: 28 | B30: 시작 | C30: 753-27-02040 | D30: 해피팜 | E30: 네이버 | F30: =SUMIF(①농산물raw!$D:$D,$C30,①농산물raw!$F:$F) | G30: =SUMIF(①농산물raw!$D:$D,$C30,①농산물raw!$G:$G) | H30: =SUMIF(①농산물raw!$D:$D,$C30,①농산물raw!$H:$H) | I30: O
A31: 29 | B31: 도약 | C31: 608-88-00253 | D31: 농업회사법인 주식회사 코리아식품 | E31: 네이버 | F31: =SUMIF(①농산물raw!$D:$D,$C31,①농산물raw!$F:$F) | G31: =SUMIF(①농산물raw!$D:$D,$C31,①농산물raw!$G:$G) | H31: =SUMIF(①농산물raw!$D:$D,$C31,①농산물raw!$H:$H) | I31: O
A32: 30 | B32: 도약 | C32: 201-98-68634 | D32: 아침에계란 | E32: 네이버 | F32: =SUMIF(①농산물raw!$D:$D,$C32,①농산물raw!$F:$F) | G32: =SUMIF(①농산물raw!$D:$D,$C32,①농산물raw!$G:$G) | H32: =SUMIF(①농산물raw!$D:$D,$C32,①농산물raw!$H:$H) | I32: O
A33: 31 | B33: 도약 | C33: 540-93-02100 | D33: 청운유통 | E33: 네이버 | F33: =SUMIF(①농산물raw!$D:$D,$C33,①농산물raw!$F:$F) | G33: =SUMIF(①농산물raw!$D:$D,$C33,①농산물raw!$G:$G) | H33: =SUMIF(①농산물raw!$D:$D,$C33,①농산물raw!$H:$H) | I33: O
A34: 32 | B34: 성장 | C34: 116-81-80195 | D34: 유한회사 못골농업회사 | E34: 네이버 | F34: =SUMIF(①농산물raw!$D:$D,$C34,①농산물raw!$F:$F) | G34: =SUMIF(①농산물raw!$D:$D,$C34,①농산물raw!$G:$G) | H34: =SUMIF(①농산물raw!$D:$D,$C34,①농산물raw!$H:$H) | I34: O
A35: 33 | B35: 시작 | C35: 208-22-52837 | D35: 소유농장 | E35: 네이버 | F35: =SUMIF(①농산물raw!$D:$D,$C35,①농산물raw!$F:$F) | G35: =SUMIF(①농산물raw!$D:$D,$C35,①농산물raw!$G:$G) | H35: =SUMIF(①농산물raw!$D:$D,$C35,①농산물raw!$H:$H) | I35: O
A36: 34 | B36: 도약 | C36: 412-90-50529 | D36: 행운가족농원 | E36: 네이버 | F36: =SUMIF(①농산물raw!$D:$D,$C36,①농산물raw!$F:$F) | G36: =SUMIF(①농산물raw!$D:$D,$C36,①농산물raw!$G:$G) | H36: =SUMIF(①농산물raw!$D:$D,$C36,①농산물raw!$H:$H)
A37: 35 | B37: 도약 | C37: 571-81-00383 | D37: 농부플러스 농업회사법인 주식회사 | E37: 지마켓 | F37: =SUMIF(①농산물raw!$D:$D,$C37,①농산물raw!$F:$F) | G37: =SUMIF(①농산물raw!$D:$D,$C37,①농산물raw!$G:$G) | H37: =SUMIF(①농산물raw!$D:$D,$C37,①농산물raw!$H:$H) | I37: O
A38: 36 | B38: 도약 | C38: 715-87-02493 | D38: 농업회삽법인 라이플로우 주식회사 | E38: 롯데온 | F38: =SUMIF(①농산물raw!$D:$D,$C38,①농산물raw!$F:$F) | G38: =SUMIF(①농산물raw!$D:$D,$C38,①농산물raw!$G:$G) | H38: =SUMIF(①농산물raw!$D:$D,$C38,①농산물raw!$H:$H) | I38: O
A39: 37 | B39: 도약 | C39: 191-97-01154 | D39: 파머레시피 | E39: 롯데온 | F39: =SUMIF(①농산물raw!$D:$D,$C39,①농산물raw!$F:$F) | G39: =SUMIF(①농산물raw!$D:$D,$C39,①농산물raw!$G:$G) | H39: =SUMIF(①농산물raw!$D:$D,$C39,①농산물raw!$H:$H) | I39: O
A40: 38 | B40: 성장 | C40: 792-88-00316 | D40: 농업회사법인(주)새나라 | E40: 네이버 | F40: =SUMIF(①농산물raw!$D:$D,$C40,①농산물raw!$F:$F) | G40: =SUMIF(①농산물raw!$D:$D,$C40,①농산물raw!$G:$G) | H40: =SUMIF(①농산물raw!$D:$D,$C40,①농산물raw!$H:$H) | I40: O
...

Sheet ①농산물raw
A1: 2026 aT 농산물 온라인 마케터 업체 별 매출 보고
A2: 기간 : 07월 06일 ~ 08월 31일
A4: 합계 | F4: =SUM(F6:F1397) | G4: =SUM(G6:G1397) | H4: =SUM(H6:H1397)
A5: 유통사명 | B5: 품목분류 | C5: 사업자명 | D5: 사업자번호 | E5: 상품명 | F5: 판매 건수 | G5: 매출액 | H5: 판촉액
A6: 지마켓 | B6: 가공식품 | C6: 주식회사 마들 | D6: 892-87-01864 | E6: 춘천 닭갈비 오리지널 1kg 국내산 닭다리살(닭다리살 함량 85%) | F6: 253 | G6: 5220720 | H6: 278100
A7: 지마켓 | B7: 가공식품 | C7: 쌍둥이농장 | D7: 186-96-01664 | E7: 산지직송 하미과메론 양구메론 경북고령 고당도 그린하미과 골드하미과3kg 5kg | F7: 4 | G7: 187600 | H7: 0
A8: 지마켓 | B8: 가공식품 | C8: 조양식품 | D8: 579-90-00021 | E8: (신선집중/15%+NH10%) 한상궁김치 겉절이 2kg / 출고당일생산 | F8: 21744 | G8: 287536270 | H8: 6140240
A9: 지마켓 | B9: 농산물 | C9: 농업회사법인머쉬그로(주) | D9: 113-87-00743 | E9: 최상등급품질 양송이버섯 1kg 2kg 산지직송 오후2시당일출고 무료배송 직접재배 산지직송 최대할인가 | F9: 26 | G9: 621000 | H9: 57600
A10: 지마켓 | B10: 농산물 | C10: 농업회사법인머쉬그로(주) | D10: 113-87-00743 | E10: 양송이 마이스터 재배 화이트 양송이버섯 못난이 꼬다마 구이용 피자용 매장사용 소포장 스프용 1kg 2kg | F10: 32 | G10: 480900 | H10: 27500
A11: 지마켓 | B11: 축산물 | C11: 두원식품(주) | D11: 606-81-52718 | E11: (신선집중) 국내산 한돈 프리미엄 대패 삼겹살 1.2kg | F11: 2382 | G11: 55053800 | H11: 4893300
A12: 지마켓 | B12: 축산물 | C12: 두원식품(주) | D12: 606-81-52718 | E12: 국내산 한돈 칼집 고추장 삼겹살 300g + 300g | F12: 3 | G12: 44700 | H12: 0
A13: 지마켓 | B13: 축산물 | C13: 두원식품(주) | D13: 606-81-52718 | E13: (신선집중) 국내산 한돈 한입 옛날 삼겹살 400g + 400g | F13: 100 | G13: 1718300 | H13: 134180
A14: 지마켓 | B14: 축산물 | C14: 두원식품(주) | D14: 606-81-52718 | E14: haccp인증 국내산 한돈 간장 LA돼지갈비 300g+300g | F14: 10 | G14: 137000 | H14: 8940
A15: 지마켓 | B15: 축산물 | C15: 두원식품(주) | D15: 606-81-52718 | E15: 국내산 한돈 프리미엄 대패 삼겹살 400g + 400g | F15: 9 | G15: 162100 | H15: 7560
A16: 지마켓 | B16: 축산물 | C16: 두원식품(주) | D16: 606-81-52718 | E16: haccp인증 국내산 한돈 고추장 주물럭 300g x6팩(총 1.8kg) | F16: 2 | G16: 65000 | H16: 6500
A17: 지마켓 | B17: 축산물 | C17: 두원식품(주) | D17: 606-81-52718 | E17: 국내산 한돈 고추장 주물럭 300g + 300g 제육볶음 | F17: 11 | G17: 157900 | H17: 11920
... A1425: 네이버 | B1425: 가공식품 | C1425: 제주점순이네 | D1425: 372-94-01830 | E1425: 제주산 땅콩호박 버터넛스쿼시 3kg 5kg 10kg | F1425: 38 | G1425: 1240000 | H1425: 43600
A1426: 네이버 | B1426: 가공식품 | C1426: 문경초록마을 | D1426: 319-94-01654 | F1426: 0 | G1426: 0 | H1426: 0
A1427: 네이버 | B1427: 가공식품 | C1427: 맑은농장 | D1427: 577-94-01721 | E1427: 품질대박 맑은농장 김천포도 4kg(특품) 미화희낭만홍안 미인포도 | F1427: 0 | G1427: 0 | H1427: 0
A1428: 네이버 | B1428: 가공식품 | C1428: 맑은농장 | D1428: 577-94-01721 | E1428: 품질보장 맑은농장 김천포도 2kg(특품) 미화희낭만홍안 미인포도 | F1428: 1 | G1428: 43700 | H1428: 0
A1429: 네이버 | B1429: 가공식품 | C1429: 맑은농장 | D1429: 577-94-01721 | E1429: 맑은농장 김천포도 4kg(못난이) 미화희낭만홍안 미인포도 | F1429: 2 | G1429: 138000 | H1429: 19200
A1430: 네이버 | B1430: 가공식품 | C1430: 맑은농장 | D1430: 577-94-01721 | E1430: 맑은농장 김천포도 4kg(상품) 미화희낭만홍안 미인포도 - 4수이하 8수이상 | F1430: 0 | G1430: 0 | H1430: 0
A1431: 네이버 | B1431: 가공식품 | C1431: 맑은농장 | D1431: 577-94-01721 | E1431: 맑은농장 김천포도 2kg(못난이) 미화희낭만홍안 미인포도 | F1431: 3 | G1431: 86000 | H1431: 11600
A1432: 네이버 | B1432: 가공식품 | C1432: 맑은농장 | D1432: 577-94-01721 | E1432: 맑은농장 김천포도 2kg(상품) 미화희낭만홍안 미인포도 - 2수또는5수이상 | F1432: 2 | G1432: 79800 | H1432: 15960
A1433: 네이버 | B1433: 가공식품 | C1433: 맑은농장 | D1433: 577-94-01721 | E1433: 맑은농장 김천포도 2kg(특품) 미화희낭만홍안 미인포도 | F1433: 2 | G1433: 87400 | H1433: 17480
A1434: 네이버 | B1434: 가공식품 | C1434: 영프로식품 | D1434: 185-96-01074 | E1434: 영프로 100% 국내산 콩 전통 된장 1키로 시골 집 보리고추장 1키로 간장 500ml | F1434: 1 | G1434: 52700 | H1434: 0
A1435: 네이버 | B1435: 가공식품 | C1435: 영프로식품 | D1435: 185-96-01074 | E1435: 영프로 100% 국내산 콩 전통된장 1키로 시골 집 보리고추장1키로 | F1435: 0 | G1435: 0 | H1435: 0
A1436: 네이버 | B1436: 가공식품 | C1436: 영프로식품 | D1436: 185-96-01074 | E1436: 영프로 100% 국내산 콩 전통 3년 숙성 재래식시골 집 된장 1kg 전통 간장 1.5L | F1436: 0 | G1436: 0 | H1436: 0
A1437: 네이버 | B1437: 가공식품 | C1437: 영프로식품 | D1437: 185-96-01074 | E1437: 영프로 100% 국내산 콩 전통 5년 숙성 재래식 시골 집 된장 2kg 전통 간장 1L | F1437: 0 | G1437: 0 | H1437: 0
A1438: 네이버 | B1438: 가공식품 | C1438: 영프로식품 | D1438: 185-96-01074 | E1438: 영프로 100% 국내산 콩 전통 3년 숙성 재래식 시골 집 된장 2kg 전통 간장 1L | F1438: 0 | G1438: 0 | H1438: 0
... A1454: 네이버 | B1454: 농산물 | C1454: 참외쀼 | D1454: 210-97-02245 | E1454: 농부부부가 키운 고당도 성주 참외 당일수확 5.5kg | F1454: 1 | G1454: 35000 | H1454: 0

Sheet 유기농업체
F1: =SUM(F3:F57) | G1: =SUM(G3:G57) | H1: =SUM(H3:H57) | I1: 32
A2: NO | B2: 구분 | C2: 사업자등록번호 | D2: 업체명 | E2: 배정유통사 | F2: 판매건수 | G2: 매출액 | H2: 판촉액 | I2: 7월 실제 인입
A3: 1 | B3: 도약 | C3: 218-86-00721 | D3: 주식회사 아인스 | E3: 오아시스 | F3: =SUMIF(②유기농raw!$D:$D,$C3,②유기농raw!$F:$F) | G3: =SUMIF(②유기농raw!$D:$D,$C3,②유기농raw!$G:$G) | H3: =SUMIF(②유기농raw!$D:$D,$C3,②유기농raw!$H:$H) | I3: O
A4: 2 | B4: 도약 | C4: 225-90-26954 | D4: 풀무리농장 | E4: 네이버 | F4: =SUMIF(②유기농raw!$D:$D,$C4,②유기농raw!$F:$F) | G4: =SUMIF(②유기농raw!$D:$D,$C4,②유기농raw!$G:$G) | H4: =SUMIF(②유기농raw!$D:$D,$C4,②유기농raw!$H:$H) | I4: O
A5: 3 | B5: 시작 | C5: 326-37-00548 | D5: 파미농원 | E5: 오아시스 | F5: =SUMIF(②유기농raw!$D:$D,$C5,②유기농raw!$F:$F) | G5: =SUMIF(②유기농raw!$D:$D,$C5,②유기농raw!$G:$G) | H5: =SUMIF(②유기농raw!$D:$D,$C5,②유기농raw!$H:$H)
A6: 4 | B6: 시작 | C6: 497-41-01341 | D6: 국가대표상황버섯 | E6: 오아시스 | F6: =SUMIF(②유기농raw!$D:$D,$C6,②유기농raw!$F:$F) | G6: =SUMIF(②유기농raw!$D:$D,$C6,②유기농raw!$G:$G) | H6: =SUMIF(②유기농raw!$D:$D,$C6,②유기농raw!$H:$H)
A7: 5 | B7: 성장 | C7: 312-27-45552 | D7: 바우뜨락 | E7: 오아시스 | F7: =SUMIF(②유기농raw!$D:$D,$C7,②유기농raw!$F:$F) | G7: =SUMIF(②유기농raw!$D:$D,$C7,②유기농raw!$G:$G) | H7: =SUMIF(②유기농raw!$D:$D,$C7,②유기농raw!$H:$H) | I7: O
A8: 6 | B8: 도약 | C8: 201-86-47960 | D8: 다온365농업회사법인(주) | E8: 오아시스 | F8: =SUMIF(②유기농raw!$D:$D,$C8,②유기농raw!$F:$F) | G8: =SUMIF(②유기농raw!$D:$D,$C8,②유기농raw!$G:$G) | H8: =SUMIF(②유기농raw!$D:$D,$C8,②유기농raw!$H:$H)
A9: 7 | B9: 도약 | C9: 410-86-90042 | D9: 아름답게그린배영농조합법인 | E9: 네이버 | F9: =SUMIF(②유기농raw!$D:$D,$C9,②유기농raw!$F:$F) | G9: =SUMIF(②유기농raw!$D:$D,$C9,②유기농raw!$G:$G) | H9: =SUMIF(②유기농raw!$D:$D,$C9,②유기농raw!$H:$H) | I9: O
A10: 8 | B10: 시작 | C10: 512-13-21395 | D10: 현재농원 | E10: 네이버 | F10: =SUMIF(②유기농raw!$D:$D,$C10,②유기농raw!$F:$F) | G10: =SUMIF(②유기농raw!$D:$D,$C10,②유기농raw!$G:$G) | H10: =SUMIF(②유기농raw!$D:$D,$C10,②유기농raw!$H:$H) | I10: O
A11: 9 | B11: 도약 | C11: 745-96-00315 | D11: 해담는집 | E11: 오아시스 | F11: =SUMIF(②유기농raw!$D:$D,$C11,②유기농raw!$F:$F) | G11: =SUMIF(②유기농raw!$D:$D,$C11,②유기농raw!$G:$G) | H11: =SUMIF(②유기농raw!$D:$D,$C11,②유기농raw!$H:$H) | I11: O
A12: 10 | B12: 도약 | C12: 386-96-00703 | D12: 여화원 | E12: 네이버 | F12: =SUMIF(②유기농raw!$D:$D,$C12,②유기농raw!$F:$F) | G12: =SUMIF(②유기농raw!$D:$D,$C12,②유기농raw!$G:$G) | H12: =SUMIF(②유기농raw!$D:$D,$C12,②유기농raw!$H:$H) | I12: O
A13: 11 | B13: 도약 | C13: 409-86-48791 | D13: 주식회사 유기농샵에프앤비 | E13: 오아시스 | F13: =SUMIF(②유기농raw!$D:$D,$C13,②유기농raw!$F:$F) | G13: =SUMIF(②유기농raw!$D:$D,$C13,②유기농raw!$G:$G) | H13: =SUMIF(②유기농raw!$D:$D,$C13,②유기농raw!$H:$H)
A14: 12 | B14: 도약 | C14: 556-72-00266 | D14: 제주오가닉스 | E14: 오아시스 | F14: =SUMIF(②유기농raw!$D:$D,$C14,②유기농raw!$F:$F) | G14: =SUMIF(②유기농raw!$D:$D,$C14,②유기농raw!$G:$G) | H14: =SUMIF(②유기농raw!$D:$D,$C14,②유기농raw!$H:$H)
A15: 13 | B15: 도약 | C15: 592-08-01799 | D15: 삼둥이농장 | E15: 오아시스 | F15: =SUMIF(②유기농raw!$D:$D,$C15,②유기농raw!$F:$F) | G15: =SUMIF(②유기농raw!$D:$D,$C15,②유기농raw!$G:$G) | H15: =SUMIF(②유기농raw!$D:$D,$C15,②유기농raw!$H:$H)
A16: 14 | B16: 도약 | C16: 680-87-00224 | D16: 다원팜농업회사법인유한회사 | E16: 오아시스 | F16: =SUMIF(②유기농raw!$D:$D,$C16,②유기농raw!$F:$F) | G16: =SUMIF(②유기농raw!$D:$D,$C16,②유기농raw!$G:$G) | H16: =SUMIF(②유기농raw!$D:$D,$C16,②유기농raw!$H:$H) | I16: O
A17: 15 | B17: 도약 | C17: 402-81-54069 | D17: 참식품주식회사 | E17: 네이버 | F17: =SUMIF(②유기농raw!$D:$D,$C17,②유기농raw!$F:$F) | G17: =SUMIF(②유기농raw!$D:$D,$C17,②유기농raw!$G:$G) | H17: =SUMIF(②유기농raw!$D:$D,$C17,②유기농raw!$H:$H) | I17: O
A18: 16 | B18: 시작 | C18: 252-86-02831 | D18: 농업회사법인주식회사한내담 | E18: 오아시스 | F18: =SUMIF(②유기농raw!$D:$D,$C18,②유기농raw!$F:$F) | G18: =SUMIF(②유기농raw!$D:$D,$C18,②유기농raw!$G:$G) | H18: =SUMIF(②유기농raw!$D:$D,$C18,②유기농raw!$H:$H)
A19: 17 | B19: 성장 | C19: 566-81-02884 | D19: 농업회사법인 주식회사 여주능서농원 | E19: 네이버 | F19: =SUMIF(②유기농raw!$D:$D,$C19,②유기농raw!$F:$F) | G19: =SUMIF(②유기농raw!$D:$D,$C19,②유기농raw!$G:$G) | H19: =SUMIF(②유기농raw!$D:$D,$C19,②유기농raw!$H:$H) | I19: O
A20: 18 | B20: 도약 | C20: 580-88-02822 | D20: 농업회사법인 나무컴퍼니 주식회사 | E20: 네이버 | F20: =SUMIF(②유기농raw!$D:$D,$C20,②유기농raw!$F:$F) | G20: =SUMIF(②유기농raw!$D:$D,$C20,②유기농raw!$G:$G) | H20: =SUMIF(②유기농raw!$D:$D,$C20,②유기농raw!$H:$H) | I20: O
A21: 19 | B21: 시작 | C21: 815-15-01628 | D21: 뭇별농장 | E21: 네이버 | F21: =SUMIF(②유기농raw!$D:$D,$C21,②유기농raw!$F:$F) | G21: =SUMIF(②유기농raw!$D:$D,$C21,②유기농raw!$G:$G) | H21: =SUMIF(②유기농raw!$D:$D,$C21,②유기농raw!$H:$H)
A22: 20 | B22: 도약 | C22: 502-81-55602 | D22: 농업법인회사 (주)초록원 | E22: 오아시스 | F22: =SUMIF(②유기농raw!$D:$D,$C22,②유기농raw!$F:$F) | G22: =SUMIF(②유기농raw!$D:$D,$C22,②유기농raw!$G:$G) | H22: =SUMIF(②유기농raw!$D:$D,$C22,②유기농raw!$H:$H) | I22: O
A23: 21 | B23: 도약 | C23: 654-88-01503 | D23: (주)밀알케이 | E23: 오아시스 | F23: =SUMIF(②유기농raw!$D:$D,$C23,②유기농raw!$F:$F) | G23: =SUMIF(②유기농raw!$D:$D,$C23,②유기농raw!$G:$G) | H23: =SUMIF(②유기농raw!$D:$D,$C23,②유기농raw!$H:$H) | I23: O
A24: 22 | B24: 도약 | C24: 774-11-01498 | D24: 경성표고버섯농장 | E24: 네이버 | F24: =SUMIF(②유기농raw!$D:$D,$C24,②유기농raw!$F:$F) | G24: =SUMIF(②유기농raw!$D:$D,$C24,②유기농raw!$G:$G) | H24: =SUMIF(②유기농raw!$D:$D,$C24,②유기농raw!$H:$H) | I24: O
A25: 23 | B25: 도약 | C25: 416-81-44143 | D25: 도울 F&B | E25: 오아시스 | F25: =SUMIF(②유기농raw!$D:$D,$C25,②유기농raw!$F:$F) | G25: =SUMIF(②유기농raw!$D:$D,$C25,②유기농raw!$G:$G) | H25: =SUMIF(②유기농raw!$D:$D,$C25,②유기농raw!$H:$H) | I25: O
A26: 24 | B26: 도약 | C26: 754-88-00876 | D26: 베리네이처 | E26: 오아시스 | F26: =SUMIF(②유기농raw!$D:$D,$C26,②유기농raw!$F:$F) | G26: =SUMIF(②유기농raw!$D:$D,$C26,②유기농raw!$G:$G) | H26: =SUMIF(②유기농raw!$D:$D,$C26,②유기농raw!$H:$H) | I26: O
A27: 25 | B27: 도약 | C27: 507-81-09103 | D27: 나래친환경영농조합법인 | E27: 네이버 | F27: =SUMIF(②유기농raw!$D:$D,$C27,②유기농raw!$F:$F) | G27: =SUMIF(②유기농raw!$D:$D,$C27,②유기농raw!$G:$G) | H27: =SUMIF(②유기농raw!$D:$D,$C27,②유기농raw!$H:$H) | I27: O
A28: 26 | B28: 시작 | C28: 190-97-01151 | D28: 지구별농장 | E28: 네이버 | F28: =SUMIF(②유기농raw!$D:$D,$C28,②유기농raw!$F:$F) | G28: =SUMIF(②유기농raw!$D:$D,$C28,②유기농raw!$G:$G) | H28: =SUMIF(②유기농raw!$D:$D,$C28,②유기농raw!$H:$H)
A29: 27 | B29: 성장 | C29: 706-01-03422 | D29: 아침농부 | E29: 네이버 | F29: =SUMIF(②유기농raw!$D:$D,$C29,②유기농raw!$F:$F) | G29: =SUMIF(②유기농raw!$D:$D,$C29,②유기농raw!$G:$G) | H29: =SUMIF(②유기농raw!$D:$D,$C29,②유기농raw!$H:$H) | I29: O
A30: 28 | B30: 도약 | C30: 761-46-00855 | D30: 코스모스길 옆 상황버 | E30: 네이버 | F30: =SUMIF(②유기농raw!$D:$D,$C30,②유기농raw!$F:$F) | G30: =SUMIF(②유기농raw!$D:$D,$C30,②유기농raw!$G:$G) | H30: =SUMIF(②유기농raw!$D:$D,$C30,②유기농raw!$H:$H)
A31: 29 | B31: 성장 | C31: 522-17-00696 | D31: 엿공장 | E31: 오아시스 | F31: =SUMIF(②유기농raw!$D:$D,$C31,②유기농raw!$F:$F) | G31: =SUMIF(②유기농raw!$D:$D,$C31,②유기농raw!$G:$G) | H31: =SUMIF(②유기농raw!$D:$D,$C31,②유기농raw!$H:$H) | I31: O
A32: 30 | B32: 도약 | C32: 685-88-00527 | D32: 농업회사법인주식회사다고 | E32: 오아시스 | F32: =SUMIF(②유기농raw!$D:$D,$C32,②유기농raw!$F:$F) | G32: =SUMIF(②유기농raw!$D:$D,$C32,②유기농raw!$G:$G) | H32: =SUMIF(②유기농raw!$D:$D,$C32,②유기농raw!$H:$H) | I32: O
A33: 31 | B33: 도약 | C33: 132-81-55005 | D33: 농업회사법인 하늘농가(주) | E33: 오아시스 | F33: =SUMIF(②유기농raw!$D:$D,$C33,②유기농raw!$F:$F) | G33: =SUMIF(②유기농raw!$D:$D,$C33,②유기농raw!$G:$G) | H33: =SUMIF(②유기농raw!$D:$D,$C33,②유기농raw!$H:$H)
A34: 32 | B34: 도약 | C34: 515-81-53707 | D34: 농업회사법인 닥터애그 주식회사 | E34: 오아시스 | F34: =SUMIF(②유기농raw!$D:$D,$C34,②유기농raw!$F:$F) | G34: =SUMIF(②유기농raw!$D:$D,$C34,②유기농raw!$G:$G) | H34: =SUMIF(②유기농raw!$D:$D,$C34,②유기농raw!$H:$H) | I34: O
A35: 33 | B35: 성장 | C35: 220-88-07925 | D35: 농업회사법인 주식회사 떡찌니 | E35: 네이버 | F35: =SUMIF(②유기농raw!$D:$D,$C35,②유기농raw!$F:$F) | G35: =SUMIF(②유기농raw!$D:$D,$C35,②유기농raw!$G:$G) | H35: =SUMIF(②유기농raw!$D:$D,$C35,②유기농raw!$H:$H)
A36: 34 | B36: 도약 | C36: 311-81-44794 | D36: 농업회사법인내포(주) | E36: 오아시스 | F36: =SUMIF(②유기농raw!$D:$D,$C36,②유기농raw!$F:$F) | G36: =SUMIF(②유기농raw!$D:$D,$C36,②유기농raw!$G:$G) | H36: =SUMIF(②유기농raw!$D:$D,$C36,②유기농raw!$H:$H) | I36: O
A37: 35 | B37: 성장 | C37: 848-99-01346 | D37: 옥수농원 | E37: 네이버 | F37: =SUMIF(②유기농raw!$D:$D,$C37,②유기농raw!$F:$F) | G37: =SUMIF(②유기농raw!$D:$D,$C37,②유기농raw!$G:$G) | H37: =SUMIF(②유기농raw!$D:$D,$C37,②유기농raw!$H:$H)
A38: 36 | B38: 성장 | C38: 829-88-01091 | D38: 스퀘어팜 농업회사법인주식회사 | E38: 오아시스 | F38: =SUMIF(②유기농raw!$D:$D,$C38,②유기농raw!$F:$F) | G38: =SUMIF(②유기농raw!$D:$D,$C38,②유기농raw!$G:$G) | H38: =SUMIF(②유기농raw!$D:$D,$C38,②유기농raw!$H:$H)
A39: 37 | B39: 도약 | C39: 126-18-96934 | D39: 굿그레인즈 | E39: 오아시스 | F39: =SUMIF(②유기농raw!$D:$D,$C39,②유기농raw!$F:$F) | G39: =SUMIF(②유기농raw!$D:$D,$C39,②유기농raw!$G:$G) | H39: =SUMIF(②유기농raw!$D:$D,$C39,②유기농raw!$H:$H) | I39: O
A40: 38 | B40: 시작 | C40: 109-36-80203 | D40: 내추럴참푸드 | E40: 오아시스 | F40: =SUMIF(②유기농raw!$D:$D,$C40,②유기농raw!$F:$F) | G40: =SUMIF(②유기농raw!$D:$D,$C40,②유기농raw!$G:$G) | H40: =SUMIF(②유기농raw!$D:$D,$C40,②유기농raw!$H:$H) | I40: O
...

Sheet ②유기농raw
A1: 2026 aT 농산물 온라인 마케터 업체 별 매출 보고
A2: 기간 : 07월 06일 ~ 08월 31일
A4: 합계 | F4: =SUM(F6:F807) | G4: =SUM(G6:G807) | H4: =SUM(H6:H807)
A5: 유통사명 | B5: 품목분류 | C5: 사업자명 | D5: 사업자번호 | E5: 상품명 | F5: 판매 건수 | G5: 매출액 | H5: 판촉액
A6: 오아시스 | B6: 가공식품 | C6: 푸르메다 | D6: 142-08-14196 | E6: 우유와함께 제주녹차라떼 | F6: 715 | G6: 4837900 | H6: 534820
A7: 오아시스 | B7: 가공식품 | C7: 푸르메다 | D7: 142-08-14196 | E7: 3초 보리 순아이티 (15입) | F7: 1221 | G7: 7982150 | H7: 850218
A8: 오아시스 | B8: 가공식품 | C8: 푸르메다 | D8: 142-08-14196 | E8: 유기농 제주 말차 ((20g×2입)×1개) | F8: 236 | G8: 4176000 | H8: 442255
A9: 오아시스 | B9: 가공식품 | C9: 해담는집 | D9: 745-96-00315 | E9: 해담는집 유기농 고춧가루 500g/200g(순한맛/보통맛/매운맛) | F9: 11 | G9: 434900 | H9: 45006
A10: 오아시스 | B10: 농산물 | C10: 해담는집 | D10: 745-96-00315 | E10: [해담는집] 유기농 고추씨 500g | F10: 5 | G10: 69500 | H10: 7282
A11: 오아시스 | B11: 농산물 | C11: 해담는집 | D11: 745-96-00315 | E11: [해담는집] 유기농 들깨 500g | F11: 2 | G11: 41800 | H11: 2590
A12: 오아시스 | B12: 가공식품 | C12: 해담는집 | D12: 745-96-00315 | E12: [해담는집]유기농 크러쉬드 레드페퍼 | F12: 41 | G12: 430500 | H12: 46702
A13: 오아시스 | B13: 가공식품 | C13: 해담는집 | D13: 745-96-00315 | E13: 유기농 메리골드 건조차 50g/꽃차/생화/식용꽃 | F13: 9 | G13: 125100 | H13: 13900
A14: 오아시스 | B14: 가공식품 | C14: 주식회사 베리네이처 | D14: 754-88-00876 | E14: 유기농 토핑 야채큐브 다진 비트 45g | F14: 2024 | G14: 4857600 | H14: 269694
A15: 오아시스 | B15: 가공식품 | C15: 주식회사 베리네이처 | D15: 754-88-00876 | E15: 유기농 토핑 야채큐브 다진 양배추 45g | F15: 1290 | G15: 2967000 | H15: 141606
A16: 오아시스 | B16: 가공식품 | C16: 주식회사 베리네이처 | D16: 754-88-00876 | E16: 유기농 토핑 야채큐브 다진 무 45g | F16: 1079 | G16: 2697500 | H16: 121065
A17: 오아시스 | B17: 가공식품 | C17: 주식회사 베리네이처 | D17: 754-88-00876 | E17: 무농약 토핑 야채큐브 다진 근대 45g | F17: 1161 | G17: 3250800 | H17: 168482
... A207: 네이버 | B207: 가공식품 | C207: 땅끝민지맘 | D207: 402-47-64035 | E207: 26년 국내산 해남 민지맘 무농약 작두콩차 270g(90g x 3팩) 선물용 | F207: 8 | G207: 208780 | H207: 0
