Workbook

Sheet 분석
B1: ※ 전체 기획전 결과
B3: 1. 해당 월 참여 상품 수 및 업체수
B4: 구분 | C4: 총 계 | D4: 농부가바로팜 | K4: 친환경
D5: 소 계 | E5: 네이버 | F5: 지마켓 | G5: 롯데ON | H5: 온누리마켓 | I5: 농가살리기 | J5: 오아시스 | K5: 소 계 | L5: 네이버 | M5: 오아시스
B6: 업체수 | C6: =D6+K6 -> 340 | D6: =SUM(E6:J6) -> 285 | E6: 136 | F6: 53 | G6: 47 | H6: 24 | I6: 9 | J6: 16 | K6: =SUM(L6:M6) -> 55 | L6: 26 | M6: 29
B7: 7월 | C7: =SUM(D7,K7) -> 218 | D7: =SUM(E7:J7) -> 186 | E7: 82 | F7: 36 | G7: 32 | H7: 17 | I7: 6 | J7: 13 | K7: =SUM(L7:M7) -> 32 | L7: 16 | M7: 16
B8: 상품수 | C8: =D8+K8 -> 1305 | D8: =SUM(E8:J8) -> 1130 | E8: 388 | F8: 258 | G8: 313 | H8: 55 | I8: 29 | J8: 87 | K8: =SUM(L8:M8) -> 175 | L8: 85 | M8: 90
B10: 2. 유통사 별 쿠폰 사용액
B11: 구분 | C11: 총 계 | D11: 농부가바로팜 | K11: 친환경
D12: 소 계 | E12: 네이버 | F12: 지마켓 | G12: 롯데ON | H12: 온누리마켓 | I12: 농가살리기 | J12: 오아시스 | K12: 소 계 | L12: 네이버 | M12: 오아시스
B13: 쿠폰 사용액 | C13: =D13+K13 -> 183612586 | D13: =SUM(E13:J13) -> 163578655 | E13: =SUMIF(①농산물raw!$A$6:$A$1135,E$12,①농산물raw!$H$6:$H$1135) -> 50215680 | F13: =SUMIF(①농산물raw!$A$6:$A$1135,F$12,①농산물raw!$H$6:$H$1135) -> 46392390 | G13: =SUMIF(①농산물raw!$A$6:$A$1135,G$12,①농산물raw!$H$6:$H$1135) -> 40018660 | H13: =SUMIF(①농산물raw!$A$6:$A$1135,H$12,①농산물raw!$H$6:$H$1135) -> 7101680 | I13: =SUMIF(①농산물raw!$A$6:$A$1135,I$12,①농산물raw!$H$6:$H$1135) -> 11487420 | J13: =SUMIF(①농산물raw!$A$6:$A$1135,J$12,①농산물raw!$H$6:$H$1135) -> 8362825 | K13: =SUM(L13:M13) -> 20033931 | L13: =SUMIF(②유기농raw!$A$6:$A$180,L$12,②유기농raw!$H$6:$H$180) -> 10413500 | M13: =SUMIF(②유기농raw!$A$6:$A$180,M$12,②유기농raw!$H$6:$H$180) -> 9620431
B15: 3. 유통사 별 매출 분석
B16: 구분 | C16: 총 계 | D16: 농부가바로팜 | K16: 친환경
D17: 소 계 | E17: 네이버 | F17: 지마켓 | G17: 롯데ON | H17: 온누리마켓 | I17: 농가살리기 | J17: 오아시스 | K17: 소 계 | L17: 네이버 | M17: 오아시스
B18: 매출액 | C18: =D18+K18 -> 3582789323 | D18: =SUM(E18:J18) -> 2936214433 | E18: =SUMIF(①농산물raw!$A$6:$A$1135,E$17,①농산물raw!$G$6:$G$1135) -> 1148483700 | F18: =SUMIF(①농산물raw!$A$6:$A$1135,F$17,①농산물raw!$G$6:$G$1135) -> 770420430 | G18: =SUMIF(①농산물raw!$A$6:$A$1135,G$17,①농산물raw!$G$6:$G$1135) -> 261077210 | H18: =SUMIF(①농산물raw!$A$6:$A$1135,H$17,①농산물raw!$G$6:$G$1135) -> 46371200 | I18: =SUMIF(①농산물raw!$A$6:$A$1135,I$17,①농산물raw!$G$6:$G$1135) -> 223305203 | J18: =SUMIF(①농산물raw!$A$6:$A$1135,J$17,①농산물raw!$G$6:$G$1135) -> 486556690 | K18: =SUM(L18:M18) -> 646574890 | L18: =SUMIF(②유기농raw!$A$6:$A$180,L$17,②유기농raw!$G$6:$G$180) -> 108372830 | M18: =SUMIF(②유기농raw!$A$6:$A$180,M$17,②유기농raw!$G$6:$G$180) -> 538202060
B20: 4. 유통사 별 판매 건수
B21: 구분 | C21: 총 계 | D21: 농부가바로팜 | K21: 친환경
D22: 소 계 | E22: 네이버 | F22: 지마켓 | G22: 롯데ON | H22: 온누리마켓 | I22: 농가살리기 | J22: 오아시스 | K22: 소 계 | L22: 네이버 | M22: 오아시스
B23: 판매건수 | C23: =D23+K23 -> 354210 | D23: =SUM(E23:J23) -> 226559 | E23: =SUMIF(①농산물raw!$A$6:$A$1135,E$22,①농산물raw!$F$6:$F$1135) -> 39593 | F23: =SUMIF(①농산물raw!$A$6:$A$1135,F$22,①농산물raw!$F$6:$F$1135) -> 38640 | G23: =SUMIF(①농산물raw!$A$6:$A$1135,G$22,①농산물raw!$F$6:$F$1135) -> 11018 | H23: =SUMIF(①농산물raw!$A$6:$A$1135,H$22,①농산물raw!$F$6:$F$1135) -> 1296 | I23: =SUMIF(①농산물raw!$A$6:$A$1135,I$22,①농산물raw!$F$6:$F$1135) -> 14679 | J23: =SUMIF(①농산물raw!$A$6:$A$1135,J$22,①농산물raw!$F$6:$F$1135) -> 121333 | K23: =SUM(L23:M23) -> 127651 | L23: =SUMIF(②유기농raw!$A$6:$A$180,L$22,②유기농raw!$F$6:$F$180) -> 4478 | M23: =SUMIF(②유기농raw!$A$6:$A$180,M$22,②유기농raw!$F$6:$F$180) -> 123173
B25: 5. 유통사별 품목별 쿠폰 사용액
B26: 구분 | C26: 총 계 | D26: 농부가바로팜 | K26: 친환경
D27: 소 계 | E27: 네이버 | F27: 지마켓 | G27: 롯데ON | H27: 온누리마켓 | I27: 농가살리기 | J27: 오아시스 | K27: 소 계 | L27: 네이버 | M27: 오아시스
B28: 총 계 | C28: =D28+K28 -> 183612586 | D28: =SUM(E28:J28) -> 163578655 | E28: =SUM(E29:E31) -> 50215680 | F28: =SUM(F29:F31) -> 46392390 | G28: =SUM(G29:G31) -> 40018660 | H28: =SUM(H29:H31) -> 7101680 | I28: =SUM(I29:I31) -> 11487420 | J28: =SUM(J29:J31) -> 8362825 | K28: =SUM(L28:M28) -> 20033931 | L28: =SUM(L29:L31) -> 10413500 | M28: =SUM(M29:M31) -> 9620431
B29: 농산물 | C29: =D29+K29 -> 101664919 | D29: =SUM(E29:J29) -> 88236310 | E29: =SUMIFS(①농산물raw!$H$6:$H$1135,①농산물raw!$A$6:$A$1135,E$27,①농산물raw!$B$6:$B$1135,$B29) -> 27521390 | F29: =SUMIFS(①농산물raw!$H$6:$H$1135,①농산물raw!$A$6:$A$1135,F$27,①농산물raw!$B$6:$B$1135,$B29) -> 29495180 | G29: =SUMIFS(①농산물raw!$H$6:$H$1135,①농산물raw!$A$6:$A$1135,G$27,①농산물raw!$B$6:$B$1135,$B29) -> 16472440 | H29: =SUMIFS(①농산물raw!$H$6:$H$1135,①농산물raw!$A$6:$A$1135,H$27,①농산물raw!$B$6:$B$1135,$B29) -> 6561353 | I29: =SUMIFS(①농산물raw!$H$6:$H$1135,①농산물raw!$A$6:$A$1135,I$27,①농산물raw!$B$6:$B$1135,$B29) -> 3731960 | J29: =SUMIFS(①농산물raw!$H$6:$H$1135,①농산물raw!$A$6:$A$1135,J$27,①농산물raw!$B$6:$B$1135,$B29) -> 4453987 | K29: =SUM(L29:M29) -> 13428609 | L29: =SUMIFS(②유기농raw!$H$6:$H$180,②유기농raw!$A$6:$A$180,L$27,②유기농raw!$B$6:$B$180,$B29) -> 8603490 | M29: =SUMIFS(②유기농raw!$H$6:$H$180,②유기농raw!$A$6:$A$180,M$27,②유기농raw!$B$6:$B$180,$B29) -> 4825119
B30: 축산물 | C30: =D30+K30 -> 27107280 | D30: =SUM(E30:J30) -> 26830360 | E30: =SUMIFS(①농산물raw!$H$6:$H$1135,①농산물raw!$A$6:$A$1135,E$27,①농산물raw!$B$6:$B$1135,$B30) -> 11806670 | F30: =SUMIFS(①농산물raw!$H$6:$H$1135,①농산물raw!$A$6:$A$1135,F$27,①농산물raw!$B$6:$B$1135,$B30) -> 2182750 | G30: =SUMIFS(①농산물raw!$H$6:$H$1135,①농산물raw!$A$6:$A$1135,G$27,①농산물raw!$B$6:$B$1135,$B30) -> 12810140 | H30: =SUMIFS(①농산물raw!$H$6:$H$1135,①농산물raw!$A$6:$A$1135,H$27,①농산물raw!$B$6:$B$1135,$B30) -> 0 | I30: =SUMIFS(①농산물raw!$H$6:$H$1135,①농산물raw!$A$6:$A$1135,I$27,①농산물raw!$B$6:$B$1135,$B30) -> 0 | J30: =SUMIFS(①농산물raw!$H$6:$H$1135,①농산물raw!$A$6:$A$1135,J$27,①농산물raw!$B$6:$B$1135,$B30) -> 30800 | K30: =SUM(L30:M30) -> 276920 | L30: =SUMIFS(②유기농raw!$H$6:$H$180,②유기농raw!$A$6:$A$180,L$27,②유기농raw!$B$6:$B$180,$B30) -> 25800 | M30: =SUMIFS(②유기농raw!$H$6:$H$180,②유기농raw!$A$6:$A$180,M$27,②유기농raw!$B$6:$B$180,$B30) -> 251120
B31: 가공식품 | C31: =D31+K31 -> 54840387 | D31: =SUM(E31:J31) -> 48511985 | E31: =SUMIFS(①농산물raw!$H$6:$H$1135,①농산물raw!$A$6:$A$1135,E$27,①농산물raw!$B$6:$B$1135,$B31) -> 10887620 | F31: =SUMIFS(①농산물raw!$H$6:$H$1135,①농산물raw!$A$6:$A$1135,F$27,①농산물raw!$B$6:$B$1135,$B31) -> 14714460 | G31: =SUMIFS(①농산물raw!$H$6:$H$1135,①농산물raw!$A$6:$A$1135,G$27,①농산물raw!$B$6:$B$1135,$B31) -> 10736080 | H31: =SUMIFS(①농산물raw!$H$6:$H$1135,①농산물raw!$A$6:$A$1135,H$27,①농산물raw!$B$6:$B$1135,$B31) -> 540327 | I31: =SUMIFS(①농산물raw!$H$6:$H$1135,①농산물raw!$A$6:$A$1135,I$27,①농산물raw!$B$6:$B$1135,$B31) -> 7755460 | J31: =SUMIFS(①농산물raw!$H$6:$H$1135,①농산물raw!$A$6:$A$1135,J$27,①농산물raw!$B$6:$B$1135,$B31) -> 3878038 | K31: =SUM(L31:M31) -> 6328402 | L31: =SUMIFS(②유기농raw!$H$6:$H$180,②유기농raw!$A$6:$A$180,L$27,②유기농raw!$B$6:$B$180,$B31) -> 1784210 | M31: =SUMIFS(②유기농raw!$H$6:$H$180,②유기농raw!$A$6:$A$180,M$27,②유기농raw!$B$6:$B$180,$B31) -> 4544192
B33: 6. 유통사별 품목별 매출 분석
B34: 구분 | C34: 총 계 | D34: 농부가바로팜 | K34: 친환경
D35: 소 계 | E35: 네이버 | F35: 지마켓 | G35: 롯데ON | H35: 온누리마켓 | I35: 농가살리기 | J35: 오아시스 | K35: 소 계 | L35: 네이버 | M35: 오아시스
B36: 총 계 | C36: =D36+K36 -> 3582789323 | D36: =SUM(E36:J36) -> 2936214433 | E36: =SUM(E37:E39) -> 1148483700 | F36: =SUM(F37:F39) -> 770420430 | G36: =SUM(G37:G39) -> 261077210 | H36: =SUM(H37:H39) -> 46371200 | I36: =SUM(I37:I39) -> 223305203 | J36: =SUM(J37:J39) -> 486556690 | K36: =SUM(L36:M36) -> 646574890 | L36: =SUM(L37:L39) -> 108372830 | M36: =SUM(M37:M39) -> 538202060
B37: 농산물 | C37: =D37+K37 -> 1978414600 | D37: =SUM(E37:J37) -> 1450442240 | E37: =SUMIFS(①농산물raw!$G$6:$G$1135,①농산물raw!$A$6:$A$1135,E$35,①농산물raw!$B$6:$B$1135,$B37) -> 563900600 | F37: =SUMIFS(①농산물raw!$G$6:$G$1135,①농산물raw!$A$6:$A$1135,F$35,①농산물raw!$B$6:$B$1135,$B37) -> 401364480 | G37: =SUMIFS(①농산물raw!$G$6:$G$1135,①농산물raw!$A$6:$A$1135,G$35,①농산물raw!$B$6:$B$1135,$B37) -> 86153550 | H37: =SUMIFS(①농산물raw!$G$6:$G$1135,①농산물raw!$A$6:$A$1135,H$35,①농산물raw!$B$6:$B$1135,$B37) -> 42349200 | I37: =SUMIFS(①농산물raw!$G$6:$G$1135,①농산물raw!$A$6:$A$1135,I$35,①농산물raw!$B$6:$B$1135,$B37) -> 41187820 | J37: =SUMIFS(①농산물raw!$G$6:$G$1135,①농산물raw!$A$6:$A$1135,J$35,①농산물raw!$B$6:$B$1135,$B37) -> 315486590 | K37: =SUM(L37:M37) -> 527972360 | L37: =SUMIFS(②유기농raw!$G$6:$G$180,②유기농raw!$A$6:$A$180,L$35,②유기농raw!$B$6:$B$180,$B37) -> 92842530 | M37: =SUMIFS(②유기농raw!$G$6:$G$180,②유기농raw!$A$6:$A$180,M$35,②유기농raw!$B$6:$B$180,$B37) -> 435129830
B38: 축산물 | C38: =D38+K38 -> 301846920 | D38: =SUM(E38:J38) -> 298266220 | E38: =SUMIFS(①농산물raw!$G$6:$G$1135,①농산물raw!$A$6:$A$1135,E$35,①농산물raw!$B$6:$B$1135,$B38) -> 174615900 | F38: =SUMIFS(①농산물raw!$G$6:$G$1135,①농산물raw!$A$6:$A$1135,F$35,①농산물raw!$B$6:$B$1135,$B38) -> 28591600 | G38: =SUMIFS(①농산물raw!$G$6:$G$1135,①농산물raw!$A$6:$A$1135,G$35,①농산물raw!$B$6:$B$1135,$B38) -> 94872920 | H38: =SUMIFS(①농산물raw!$G$6:$G$1135,①농산물raw!$A$6:$A$1135,H$35,①농산물raw!$B$6:$B$1135,$B38) -> 0 | I38: =SUMIFS(①농산물raw!$G$6:$G$1135,①농산물raw!$A$6:$A$1135,I$35,①농산물raw!$B$6:$B$1135,$B38) -> 0 | J38: =SUMIFS(①농산물raw!$G$6:$G$1135,①농산물raw!$A$6:$A$1135,J$35,①농산물raw!$B$6:$B$1135,$B38) -> 185800 | K38: =SUM(L38:M38) -> 3580700 | L38: =SUMIFS(②유기농raw!$G$6:$G$180,②유기농raw!$A$6:$A$180,L$35,②유기농raw!$B$6:$B$180,$B38) -> 132000 | M38: =SUMIFS(②유기농raw!$G$6:$G$180,②유기농raw!$A$6:$A$180,M$35,②유기농raw!$B$6:$B$180,$B38) -> 3448700
B39: 가공식품 | C39: =D39+K39 -> 1302527803 | D39: =SUM(E39:J39) -> 1187505973 | E39: =SUMIFS(①농산물raw!$G$6:$G$1135,①농산물raw!$A$6:$A$1135,E$35,①농산물raw!$B$6:$B$1135,$B39) -> 409967200 | F39: =SUMIFS(①농산물raw!$G$6:$G$1135,①농산물raw!$A$6:$A$1135,F$35,①농산물raw!$B$6:$B$1135,$B39) -> 340464350 | G39: =SUMIFS(①농산물raw!$G$6:$G$1135,①농산물raw!$A$6:$A$1135,G$35,①농산물raw!$B$6:$B$1135,$B39) -> 80050740 | H39: =SUMIFS(①농산물raw!$G$6:$G$1135,①농산물raw!$A$6:$A$1135,H$35,①농산물raw!$B$6:$B$1135,$B39) -> 4022000 | I39: =SUMIFS(①농산물raw!$G$6:$G$1135,①농산물raw!$A$6:$A$1135,I$35,①농산물raw!$B$6:$B$1135,$B39) -> 182117383 | J39: =SUMIFS(①농산물raw!$G$6:$G$1135,①농산물raw!$A$6:$A$1135,J$35,①농산물raw!$B$6:$B$1135,$B39) -> 170884300 | K39: =SUM(L39:M39) -> 115021830 | L39: =SUMIFS(②유기농raw!$G$6:$G$180,②유기농raw!$A$6:$A$180,L$35,②유기농raw!$B$6:$B$180,$B39) -> 15398300 | M39: =SUMIFS(②유기농raw!$G$6:$G$180,②유기농raw!$A$6:$A$180,M$35,②유기농raw!$B$6:$B$180,$B39) -> 99623530
B41: 7. 유통사별 품목별 판매 건수
B42: 구분 | C42: 총 계 | D42: 농부가바로팜 | K42: 친환경
D43: 소 계 | E43: 네이버 | F43: 지마켓 | G43: 롯데ON | H43: 온누리마켓 | I43: 농가살리기 | J43: 오아시스 | K43: 소 계 | L43: 네이버 | M43: 오아시스
B44: 총 계 | C44: =D44+K44 -> 354210 | D44: =SUM(E44:J44) -> 226559 | E44: =SUM(E45:E47) -> 39593 | F44: =SUM(F45:F47) -> 38640 | G44: =SUM(G45:G47) -> 11018 | H44: =SUM(H45:H47) -> 1296 | I44: =SUM(I45:I47) -> 14679 | J44: =SUM(J45:J47) -> 121333 | K44: =SUM(L44:M44) -> 127651 | L44: =SUM(L45:L47) -> 4478 | M44: =SUM(M45:M47) -> 123173
B45: 농산물 | C45: =D45+K45 -> 241523 | D45: =SUM(E45:J45) -> 136969 | E45: =SUMIFS(①농산물raw!$F$6:$F$1135,①농산물raw!$A$6:$A$1135,E$43,①농산물raw!$B$6:$B$1135,$B45) -> 18947 | F45: =SUMIFS(①농산물raw!$F$6:$F$1135,①농산물raw!$A$6:$A$1135,F$43,①농산물raw!$B$6:$B$1135,$B45) -> 16003 | G45: =SUMIFS(①농산물raw!$F$6:$F$1135,①농산물raw!$A$6:$A$1135,G$43,①농산물raw!$B$6:$B$1135,$B45) -> 5393 | H45: =SUMIFS(①농산물raw!$F$6:$F$1135,①농산물raw!$A$6:$A$1135,H$43,①농산물raw!$B$6:$B$1135,$B45) -> 1136 | I45: =SUMIFS(①농산물raw!$F$6:$F$1135,①농산물raw!$A$6:$A$1135,I$43,①농산물raw!$B$6:$B$1135,$B45) -> 2619 | J45: =SUMIFS(①농산물raw!$F$6:$F$1135,①농산물raw!$A$6:$A$1135,J$43,①농산물raw!$B$6:$B$1135,$B45) -> 92871 | K45: =SUM(L45:M45) -> 104554 | L45: =SUMIFS(②유기농raw!$F$6:$F$180,②유기농raw!$A$6:$A$180,L$43,②유기농raw!$B$6:$B$180,$B45) -> 3893 | M45: =SUMIFS(②유기농raw!$F$6:$F$180,②유기농raw!$A$6:$A$180,M$43,②유기농raw!$B$6:$B$180,$B45) -> 100661
B46: 축산물 | C46: =D46+K46 -> 10687 | D46: =SUM(E46:J46) -> 10084 | E46: =SUMIFS(①농산물raw!$F$6:$F$1135,①농산물raw!$A$6:$A$1135,E$43,①농산물raw!$B$6:$B$1135,$B46) -> 5918 | F46: =SUMIFS(①농산물raw!$F$6:$F$1135,①농산물raw!$A$6:$A$1135,F$43,①농산물raw!$B$6:$B$1135,$B46) -> 1102 | G46: =SUMIFS(①농산물raw!$F$6:$F$1135,①농산물raw!$A$6:$A$1135,G$43,①농산물raw!$B$6:$B$1135,$B46) -> 3058 | H46: =SUMIFS(①농산물raw!$F$6:$F$1135,①농산물raw!$A$6:$A$1135,H$43,①농산물raw!$B$6:$B$1135,$B46) -> 0 | I46: =SUMIFS(①농산물raw!$F$6:$F$1135,①농산물raw!$A$6:$A$1135,I$43,①농산물raw!$B$6:$B$1135,$B46) -> 0 | J46: =SUMIFS(①농산물raw!$F$6:$F$1135,①농산물raw!$A$6:$A$1135,J$43,①농산물raw!$B$6:$B$1135,$B46) -> 6 | K46: =SUM(L46:M46) -> 603 | L46: =SUMIFS(②유기농raw!$F$6:$F$180,②유기농raw!$A$6:$A$180,L$43,②유기농raw!$B$6:$B$180,$B46) -> 5 | M46: =SUMIFS(②유기농raw!$F$6:$F$180,②유기농raw!$A$6:$A$180,M$43,②유기농raw!$B$6:$B$180,$B46) -> 598
B47: 가공식품 | C47: =D47+K47 -> 102000 | D47: =SUM(E47:J47) -> 79506 | E47: =SUMIFS(①농산물raw!$F$6:$F$1135,①농산물raw!$A$6:$A$1135,E$43,①농산물raw!$B$6:$B$1135,$B47) -> 14728 | F47: =SUMIFS(①농산물raw!$F$6:$F$1135,①농산물raw!$A$6:$A$1135,F$43,①농산물raw!$B$6:$B$1135,$B47) -> 21535 | G47: =SUMIFS(①농산물raw!$F$6:$F$1135,①농산물raw!$A$6:$A$1135,G$43,①농산물raw!$B$6:$B$1135,$B47) -> 2567 | H47: =SUMIFS(①농산물raw!$F$6:$F$1135,①농산물raw!$A$6:$A$1135,H$43,①농산물raw!$B$6:$B$1135,$B47) -> 160 | I47: =SUMIFS(①농산물raw!$F$6:$F$1135,①농산물raw!$A$6:$A$1135,I$43,①농산물raw!$B$6:$B$1135,$B47) -> 12060 | J47: =SUMIFS(①농산물raw!$F$6:$F$1135,①농산물raw!$A$6:$A$1135,J$43,①농산물raw!$B$6:$B$1135,$B47) -> 28456 | K47: =SUM(L47:M47) -> 22494 | L47: =SUMIFS(②유기농raw!$F$6:$F$180,②유기농raw!$A$6:$A$180,L$43,②유기농raw!$B$6:$B$180,$B47) -> 580 | M47: =SUMIFS(②유기농raw!$F$6:$F$180,②유기농raw!$A$6:$A$180,M$43,②유기농raw!$B$6:$B$180,$B47) -> 21914
...

Sheet 농산물업체
F1: =SUM(F3:F287) -> 226559 | G1: =SUM(G3:G287) -> 2936214433 | H1: =SUM(H3:H287) -> 163578655 | I1: =COUNTIF(I3:I500,"O") -> 186
A2: NO | B2: 구분 | C2: 사업자등록번호 | D2: 업체명 | E2: 배정유통사 | F2: 판매건수 | G2: 매출액 | H2: 판촉액 | I2: 7월 실제 인입
A3: 1 | B3: 도약 | C3: 511-87-00286 | D3: 농업회사법인 영주마실(주) | E3: 롯데온 | F3: =SUMIF(①농산물raw!$D$6:$D$1135,$C3,①농산물raw!$F$6:$F$1135) -> 0 | G3: =SUMIF(①농산물raw!$D$6:$D$1135,$C3,①농산물raw!$G$6:$G$1135) -> 0 | H3: =SUMIF(①농산물raw!$D$6:$D$1135,$C3,①농산물raw!$H$6:$H$1135) -> 0
A4: 2 | B4: 도약 | C4: 302-81-25814 | D4: 영동감협동조합 | E4: 롯데온 | F4: =SUMIF(①농산물raw!$D$6:$D$1135,$C4,①농산물raw!$F$6:$F$1135) -> 0 | G4: =SUMIF(①농산물raw!$D$6:$D$1135,$C4,①농산물raw!$G$6:$G$1135) -> 0 | H4: =SUMIF(①농산물raw!$D$6:$D$1135,$C4,①농산물raw!$H$6:$H$1135) -> 0 | I4: O
A5: 3 | B5: 도약 | C5: 449-92-01723 | D5: 채씨네표고농원 | E5: 네이버 | F5: =SUMIF(①농산물raw!$D$6:$D$1135,$C5,①농산물raw!$F$6:$F$1135) -> 40 | G5: =SUMIF(①농산물raw!$D$6:$D$1135,$C5,①농산물raw!$G$6:$G$1135) -> 1031000 | H5: =SUMIF(①농산물raw!$D$6:$D$1135,$C5,①농산물raw!$H$6:$H$1135) -> 43900 | I5: O
A6: 4 | B6: 시작 | C6: 406-82-02051 | D6: 구천동농업협동조합 | E6: 네이버 | F6: =SUMIF(①농산물raw!$D$6:$D$1135,$C6,①농산물raw!$F$6:$F$1135) -> 0 | G6: =SUMIF(①농산물raw!$D$6:$D$1135,$C6,①농산물raw!$G$6:$G$1135) -> 0 | H6: =SUMIF(①농산물raw!$D$6:$D$1135,$C6,①농산물raw!$H$6:$H$1135) -> 0
A7: 5 | B7: 성장 | C7: 529-44-01222 | D7: 나뚜라리농원 | E7: 네이버 | F7: =SUMIF(①농산물raw!$D$6:$D$1135,$C7,①농산물raw!$F$6:$F$1135) -> 68 | G7: =SUMIF(①농산물raw!$D$6:$D$1135,$C7,①농산물raw!$G$6:$G$1135) -> 2967200 | H7: =SUMIF(①농산물raw!$D$6:$D$1135,$C7,①농산물raw!$H$6:$H$1135) -> 206920 | I7: O
A8: 6 | B8: 도약 | C8: 416-81-92591 | D8: 좋은세상협동조합 | E8: 롯데온 | F8: =SUMIF(①농산물raw!$D$6:$D$1135,$C8,①농산물raw!$F$6:$F$1135) -> 0 | G8: =SUMIF(①농산물raw!$D$6:$D$1135,$C8,①농산물raw!$G$6:$G$1135) -> 0 | H8: =SUMIF(①농산물raw!$D$6:$D$1135,$C8,①농산물raw!$H$6:$H$1135) -> 0
A9: 7 | B9: 도약 | C9: 516-88-01860 | D9: 주식회사 농업회사법인 에상스팜 | E9: 롯데온 | F9: =SUMIF(①농산물raw!$D$6:$D$1135,$C9,①농산물raw!$F$6:$F$1135) -> 1662 | G9: =SUMIF(①농산물raw!$D$6:$D$1135,$C9,①농산물raw!$G$6:$G$1135) -> 18805800 | H9: =SUMIF(①농산물raw!$D$6:$D$1135,$C9,①농산물raw!$H$6:$H$1135) -> 3349800 | I9: O
A10: 8 | B10: 시작 | C10: 709-22-01767 | D10: 푸드상상 | E10: 롯데온 | F10: =SUMIF(①농산물raw!$D$6:$D$1135,$C10,①농산물raw!$F$6:$F$1135) -> 0 | G10: =SUMIF(①농산물raw!$D$6:$D$1135,$C10,①농산물raw!$G$6:$G$1135) -> 0 | H10: =SUMIF(①농산물raw!$D$6:$D$1135,$C10,①농산물raw!$H$6:$H$1135) -> 0
A11: 9 | B11: 시작 | C11: 104-12-14323 | D11: 교동앵무새힐링농장 | E11: 네이버 | F11: =SUMIF(①농산물raw!$D$6:$D$1135,$C11,①농산물raw!$F$6:$F$1135) -> 0 | G11: =SUMIF(①농산물raw!$D$6:$D$1135,$C11,①농산물raw!$G$6:$G$1135) -> 0 | H11: =SUMIF(①농산물raw!$D$6:$D$1135,$C11,①농산물raw!$H$6:$H$1135) -> 0
A12: 10 | B12: 도약 | C12: 514-03-53195 | D12: 삼진식품 | E12: 롯데온 | F12: =SUMIF(①농산물raw!$D$6:$D$1135,$C12,①농산물raw!$F$6:$F$1135) -> 0 | G12: =SUMIF(①농산물raw!$D$6:$D$1135,$C12,①농산물raw!$G$6:$G$1135) -> 0 | H12: =SUMIF(①농산물raw!$D$6:$D$1135,$C12,①농산물raw!$H$6:$H$1135) -> 0
A13: 11 | B13: 도약 | C13: 892-87-01864 | D13: 주식회사 마들 | E13: 지마켓 | F13: =SUMIF(①농산물raw!$D$6:$D$1135,$C13,①농산물raw!$F$6:$F$1135) -> 92 | G13: =SUMIF(①농산물raw!$D$6:$D$1135,$C13,①농산물raw!$G$6:$G$1135) -> 1980500 | H13: =SUMIF(①농산물raw!$D$6:$D$1135,$C13,①농산물raw!$H$6:$H$1135) -> 58200 | I13: O
A14: 12 | B14: 도약 | C14: 803-88-01105 | D14: 오고농원(주) | E14: 네이버 | F14: =SUMIF(①농산물raw!$D$6:$D$1135,$C14,①농산물raw!$F$6:$F$1135) -> 355 | G14: =SUMIF(①농산물raw!$D$6:$D$1135,$C14,①농산물raw!$G$6:$G$1135) -> 16347500 | H14: =SUMIF(①농산물raw!$D$6:$D$1135,$C14,①농산물raw!$H$6:$H$1135) -> 1074020 | I14: O
A15: 13 | B15: 도약 | C15: 488-88-03205 | D15: 농업회사법인 랑이네세상 주식회사 | E15: 네이버 | F15: =SUMIF(①농산물raw!$D$6:$D$1135,$C15,①농산물raw!$F$6:$F$1135) -> 1492 | G15: =SUMIF(①농산물raw!$D$6:$D$1135,$C15,①농산물raw!$G$6:$G$1135) -> 56675800 | H15: =SUMIF(①농산물raw!$D$6:$D$1135,$C15,①농산물raw!$H$6:$H$1135) -> 4955760 | I15: O
A16: 14 | B16: 성장 | C16: 784-24-00666 | D16: 거창오미자 | E16: 네이버 | F16: =SUMIF(①농산물raw!$D$6:$D$1135,$C16,①농산물raw!$F$6:$F$1135) -> 309 | G16: =SUMIF(①농산물raw!$D$6:$D$1135,$C16,①농산물raw!$G$6:$G$1135) -> 11911000 | H16: =SUMIF(①농산물raw!$D$6:$D$1135,$C16,①농산물raw!$H$6:$H$1135) -> 427800 | I16: O
A17: 15 | B17: 시작 | C17: 888-94-01728 | D17: 파밍데이즈 | E17: 네이버 | F17: =SUMIF(①농산물raw!$D$6:$D$1135,$C17,①농산물raw!$F$6:$F$1135) -> 30 | G17: =SUMIF(①농산물raw!$D$6:$D$1135,$C17,①농산물raw!$G$6:$G$1135) -> 599700 | H17: =SUMIF(①농산물raw!$D$6:$D$1135,$C17,①농산물raw!$H$6:$H$1135) -> 33980 | I17: O
A18: 16 | B18: 도약 | C18: 128-90-57082 | D18: 산골과수원 | E18: 롯데온 | F18: =SUMIF(①농산물raw!$D$6:$D$1135,$C18,①농산물raw!$F$6:$F$1135) -> 0 | G18: =SUMIF(①농산물raw!$D$6:$D$1135,$C18,①농산물raw!$G$6:$G$1135) -> 0 | H18: =SUMIF(①농산물raw!$D$6:$D$1135,$C18,①농산물raw!$H$6:$H$1135) -> 0
A19: 17 | B19: 도약 | C19: 626-86-01993 | D19: 농업회사법인 (주)자연의시간 | E19: 농가살리기 | F19: =SUMIF(①농산물raw!$D$6:$D$1135,$C19,①농산물raw!$F$6:$F$1135) -> 122 | G19: =SUMIF(①농산물raw!$D$6:$D$1135,$C19,①농산물raw!$G$6:$G$1135) -> 1749656 | H19: =SUMIF(①농산물raw!$D$6:$D$1135,$C19,①농산물raw!$H$6:$H$1135) -> 113680 | I19: O
A20: 18 | B20: 성장 | C20: 711-30-00994 | D20: 팜샐러드 | E20: 네이버 | F20: =SUMIF(①농산물raw!$D$6:$D$1135,$C20,①농산물raw!$F$6:$F$1135) -> 0 | G20: =SUMIF(①농산물raw!$D$6:$D$1135,$C20,①농산물raw!$G$6:$G$1135) -> 0 | H20: =SUMIF(①농산물raw!$D$6:$D$1135,$C20,①농산물raw!$H$6:$H$1135) -> 0
A21: 19 | B21: 도약 | C21: 186-96-01664 | D21: 쌍둥이농장 | E21: 지마켓 | F21: =SUMIF(①농산물raw!$D$6:$D$1135,$C21,①농산물raw!$F$6:$F$1135) -> 4 | G21: =SUMIF(①농산물raw!$D$6:$D$1135,$C21,①농산물raw!$G$6:$G$1135) -> 187600 | H21: =SUMIF(①농산물raw!$D$6:$D$1135,$C21,①농산물raw!$H$6:$H$1135) -> 0 | I21: O
A22: 20 | B22: 성장 | C22: 463-93-01691 | D22: 피스팜 | E22: 네이버 | F22: =SUMIF(①농산물raw!$D$6:$D$1135,$C22,①농산물raw!$F$6:$F$1135) -> 3 | G22: =SUMIF(①농산물raw!$D$6:$D$1135,$C22,①농산물raw!$G$6:$G$1135) -> 175000 | H22: =SUMIF(①농산물raw!$D$6:$D$1135,$C22,①농산물raw!$H$6:$H$1135) -> 0 | I22: O
A23: 21 | B23: 시작 | C23: 621-96-06105 | D23: HK팜 | E23: 네이버 | F23: =SUMIF(①농산물raw!$D$6:$D$1135,$C23,①농산물raw!$F$6:$F$1135) -> 0 | G23: =SUMIF(①농산물raw!$D$6:$D$1135,$C23,①농산물raw!$G$6:$G$1135) -> 0 | H23: =SUMIF(①농산물raw!$D$6:$D$1135,$C23,①농산물raw!$H$6:$H$1135) -> 0
A24: 22 | B24: 도약 | C24: 347-93-02082 | D24: 초록이들 | E24: 네이버 | F24: =SUMIF(①농산물raw!$D$6:$D$1135,$C24,①농산물raw!$F$6:$F$1135) -> 7267 | G24: =SUMIF(①농산물raw!$D$6:$D$1135,$C24,①농산물raw!$G$6:$G$1135) -> 112403300 | H24: =SUMIF(①농산물raw!$D$6:$D$1135,$C24,①농산물raw!$H$6:$H$1135) -> 3842570 | I24: O
A25: 23 | B25: 성장 | C25: 408-24-61681 | D25: 한국제다 | E25: 네이버 | F25: =SUMIF(①농산물raw!$D$6:$D$1135,$C25,①농산물raw!$F$6:$F$1135) -> 5 | G25: =SUMIF(①농산물raw!$D$6:$D$1135,$C25,①농산물raw!$G$6:$G$1135) -> 191000 | H25: =SUMIF(①농산물raw!$D$6:$D$1135,$C25,①농산물raw!$H$6:$H$1135) -> 13860 | I25: O
A26: 24 | B26: 도약 | C26: 226-81-48890 | D26: 정선아라리한과농원 영농조합법인 | E26: 롯데온 | F26: =SUMIF(①농산물raw!$D$6:$D$1135,$C26,①농산물raw!$F$6:$F$1135) -> 5 | G26: =SUMIF(①농산물raw!$D$6:$D$1135,$C26,①농산물raw!$G$6:$G$1135) -> 121200 | H26: =SUMIF(①농산물raw!$D$6:$D$1135,$C26,①농산물raw!$H$6:$H$1135) -> 22970 | I26: O
A27: 25 | B27: 도약 | C27: 412-81-24086 | D27: 영흥농산영농조합법인 | E27: 네이버 | F27: =SUMIF(①농산물raw!$D$6:$D$1135,$C27,①농산물raw!$F$6:$F$1135) -> 0 | G27: =SUMIF(①농산물raw!$D$6:$D$1135,$C27,①농산물raw!$G$6:$G$1135) -> 0 | H27: =SUMIF(①농산물raw!$D$6:$D$1135,$C27,①농산물raw!$H$6:$H$1135) -> 0
A28: 26 | B28: 도약 | C28: 142-33-00898 | D28: 어이딸부각 | E28: 지마켓 | F28: =SUMIF(①농산물raw!$D$6:$D$1135,$C28,①농산물raw!$F$6:$F$1135) -> 0 | G28: =SUMIF(①농산물raw!$D$6:$D$1135,$C28,①농산물raw!$G$6:$G$1135) -> 0 | H28: =SUMIF(①농산물raw!$D$6:$D$1135,$C28,①농산물raw!$H$6:$H$1135) -> 0 | I28: O
A29: 27 | B29: 도약 | C29: 144-92-00528 | D29: 햇터농장 | E29: 네이버 | F29: =SUMIF(①농산물raw!$D$6:$D$1135,$C29,①농산물raw!$F$6:$F$1135) -> 0 | G29: =SUMIF(①농산물raw!$D$6:$D$1135,$C29,①농산물raw!$G$6:$G$1135) -> 0 | H29: =SUMIF(①농산물raw!$D$6:$D$1135,$C29,①농산물raw!$H$6:$H$1135) -> 0
A30: 28 | B30: 시작 | C30: 753-27-02040 | D30: 해피팜 | E30: 네이버 | F30: =SUMIF(①농산물raw!$D$6:$D$1135,$C30,①농산물raw!$F$6:$F$1135) -> 8 | G30: =SUMIF(①농산물raw!$D$6:$D$1135,$C30,①농산물raw!$G$6:$G$1135) -> 272000 | H30: =SUMIF(①농산물raw!$D$6:$D$1135,$C30,①농산물raw!$H$6:$H$1135) -> 25000 | I30: O
A31: 29 | B31: 도약 | C31: 608-88-00253 | D31: 농업회사법인 주식회사 코리아식품 | E31: 네이버 | F31: =SUMIF(①농산물raw!$D$6:$D$1135,$C31,①농산물raw!$F$6:$F$1135) -> 5 | G31: =SUMIF(①농산물raw!$D$6:$D$1135,$C31,①농산물raw!$G$6:$G$1135) -> 103900 | H31: =SUMIF(①농산물raw!$D$6:$D$1135,$C31,①농산물raw!$H$6:$H$1135) -> 12280 | I31: O
A32: 30 | B32: 도약 | C32: 201-98-68634 | D32: 아침에계란 | E32: 네이버 | F32: =SUMIF(①농산물raw!$D$6:$D$1135,$C32,①농산물raw!$F$6:$F$1135) -> 761 | G32: =SUMIF(①농산물raw!$D$6:$D$1135,$C32,①농산물raw!$G$6:$G$1135) -> 46999200 | H32: =SUMIF(①농산물raw!$D$6:$D$1135,$C32,①농산물raw!$H$6:$H$1135) -> 3566200 | I32: O
A33: 31 | B33: 도약 | C33: 540-93-02100 | D33: 청운유통 | E33: 네이버 | F33: =SUMIF(①농산물raw!$D$6:$D$1135,$C33,①농산물raw!$F$6:$F$1135) -> 2026 | G33: =SUMIF(①농산물raw!$D$6:$D$1135,$C33,①농산물raw!$G$6:$G$1135) -> 53444700 | H33: =SUMIF(①농산물raw!$D$6:$D$1135,$C33,①농산물raw!$H$6:$H$1135) -> 3066340 | I33: O
A34: 32 | B34: 성장 | C34: 116-81-80195 | D34: 유한회사 못골농업회사 | E34: 네이버 | F34: =SUMIF(①농산물raw!$D$6:$D$1135,$C34,①농산물raw!$F$6:$F$1135) -> 78 | G34: =SUMIF(①농산물raw!$D$6:$D$1135,$C34,①농산물raw!$G$6:$G$1135) -> 2510500 | H34: =SUMIF(①농산물raw!$D$6:$D$1135,$C34,①농산물raw!$H$6:$H$1135) -> 119380 | I34: O
A35: 33 | B35: 시작 | C35: 208-22-52837 | D35: 소유농장 | E35: 네이버 | F35: =SUMIF(①농산물raw!$D$6:$D$1135,$C35,①농산물raw!$F$6:$F$1135) -> 10 | G35: =SUMIF(①농산물raw!$D$6:$D$1135,$C35,①농산물raw!$G$6:$G$1135) -> 538000 | H35: =SUMIF(①농산물raw!$D$6:$D$1135,$C35,①농산물raw!$H$6:$H$1135) -> 0 | I35: O
A36: 34 | B36: 도약 | C36: 412-90-50529 | D36: 행운가족농원 | E36: 네이버 | F36: =SUMIF(①농산물raw!$D$6:$D$1135,$C36,①농산물raw!$F$6:$F$1135) -> 0 | G36: =SUMIF(①농산물raw!$D$6:$D$1135,$C36,①농산물raw!$G$6:$G$1135) -> 0 | H36: =SUMIF(①농산물raw!$D$6:$D$1135,$C36,①농산물raw!$H$6:$H$1135) -> 0
A37: 35 | B37: 도약 | C37: 571-81-00383 | D37: 농부플러스 농업회사법인 주식회사 | E37: 지마켓 | F37: =SUMIF(①농산물raw!$D$6:$D$1135,$C37,①농산물raw!$F$6:$F$1135) -> 538 | G37: =SUMIF(①농산물raw!$D$6:$D$1135,$C37,①농산물raw!$G$6:$G$1135) -> 15772000 | H37: =SUMIF(①농산물raw!$D$6:$D$1135,$C37,①농산물raw!$H$6:$H$1135) -> 591780 | I37: O
A38: 36 | B38: 도약 | C38: 715-87-02493 | D38: 농업회삽법인 라이플로우 주식회사 | E38: 롯데온 | F38: =SUMIF(①농산물raw!$D$6:$D$1135,$C38,①농산물raw!$F$6:$F$1135) -> 33 | G38: =SUMIF(①농산물raw!$D$6:$D$1135,$C38,①농산물raw!$G$6:$G$1135) -> 1039600 | H38: =SUMIF(①농산물raw!$D$6:$D$1135,$C38,①농산물raw!$H$6:$H$1135) -> 199830 | I38: O
A39: 37 | B39: 도약 | C39: 191-97-01154 | D39: 파머레시피 | E39: 롯데온 | F39: =SUMIF(①농산물raw!$D$6:$D$1135,$C39,①농산물raw!$F$6:$F$1135) -> 1 | G39: =SUMIF(①농산물raw!$D$6:$D$1135,$C39,①농산물raw!$G$6:$G$1135) -> 8300 | H39: =SUMIF(①농산물raw!$D$6:$D$1135,$C39,①농산물raw!$H$6:$H$1135) -> 1540 | I39: O
A40: 38 | B40: 성장 | C40: 792-88-00316 | D40: 농업회사법인(주)새나라 | E40: 네이버 | F40: =SUMIF(①농산물raw!$D$6:$D$1135,$C40,①농산물raw!$F$6:$F$1135) -> 253 | G40: =SUMIF(①농산물raw!$D$6:$D$1135,$C40,①농산물raw!$G$6:$G$1135) -> 7943620 | H40: =SUMIF(①농산물raw!$D$6:$D$1135,$C40,①농산물raw!$H$6:$H$1135) -> 716030 | I40: O
...

Sheet ①농산물raw
A1: 2026 aT 농산물 온라인 마케터 업체 별 매출 보고
A2: 기간 : 07월 06일 ~ 07월 31일
A4: 합계 | F4: =SUM(F6:F1200) -> 226559 | G4: =SUM(G6:G1200) -> 2936214433 | H4: =SUM(H6:H1200) -> 163578655
A5: 유통사명 | B5: 품목분류 | C5: 사업자명 | D5: 사업자번호 | E5: 상품명 | F5: 판매 건수 | G5: 매출액 | H5: 판촉액
A6: 네이버 | B6: 가공식품 | C6: 농업회사법인(주)운림가 | D6: 412-81-31307 | E6: 운림가 55년전통 대용량 전라도 국산 배추 김장 포기 김치 5kg [원산지:국산] | F6: 2297 | G6: 110459500 | H6: 2090900
A7: 네이버 | B7: 농산물 | C7: 여주시농협조합공동사업법인 | D7: 126-82-11620 | E7: 여주시농협RPC 대왕님표 여주쌀 진상미 당일도정 25년 햅쌀 10kg, 1개 [원산지:국산(경기도 여주시)] | F7: 2393 | G7: 104954500 | H7: 4684290
A8: 네이버 | B8: 농산물 | C8: 별마루농원 | D8: 508-90-95905 | E8: 신비복숭아 황도 백도 황도복숭아 쫀득이 딱딱이 선물용 프리미엄 복숭아 3kg 별마루농원 [원산지:국산(경상북도 의성군)] | F8: 2057 | G8: 86769670 | H8: 4883600
A9: 네이버 | B9: 농산물 | C9: 초록이들 | D9: 347-93-02082 | E9: 초록이들 4kg 대용량 상추 유럽 샐러드 채소 유러피안 쌈 버터헤드 카이피라 프릴 양상추 [원산지:국산(충청남도 논산시)] | F9: 1842 | G9: 62322800 | H9: 1478320
A10: 네이버 | B10: 축산물 | C10: 두루푸드 | D10: 221-13-36518 | E10: 국민닭갈비 두루푸드 춘천닭갈비 택배 홈파티 캠핑요리 [원산지:닭고기 넓적다리(국산), 고추가루(국산), 기타(상세설명참조)] | F10: 2416 | G10: 53342360 | H10: 3359880
A11: 네이버 | B11: 가공식품 | C11: 농업회사법인(주)운림가 | D11: 412-81-31307 | E11: 운림가 55년전통 국산 알타리 총각김치 2kg [원산지:국산] | F11: 2743 | G11: 52666800 | H11: 164960
A12: 네이버 | B12: 농산물 | C12: 초록이들 | D12: 347-93-02082 | E12: [초록이들]500g/1kg 유럽 샐러드 채소 유러피안 상추 쌈 버터헤드 카이피라 프릴등 [원산지:국산(충청남도 논산시)] | F12: 5425 | G12: 50080500 | H12: 2364250
A13: 네이버 | B13: 가공식품 | C13: 농업회사법인(주)운림가 | D13: 412-81-31307 | E13: 운림가 55년전통 국산 전라도 묵은지 2kg 저온 숙성 익은 김치 [원산지:국산] | F13: 2199 | G13: 47591200 | H13: 251360
A14: 네이버 | B14: 축산물 | C14: 아침에계란 | D14: 201-98-68634 | E14: 아침에계란 청춘이란 난각번호1번 발효곡물 먹은 자연방사 유정란 20구 40구 60구 [원산지:국산(경상북도 영덕군)] | F14: 761 | G14: 46999200 | H14: 3566200
A15: 네이버 | B15: 가공식품 | C15: 농업회사법인(주)운림가 | D15: 412-81-31307 | E15: 운림가 55년전통 국내산 쪽 파김치 1kg [원산지:국산] | F15: 2217 | G15: 45657100 | H15: 191600
A16: 네이버 | B16: 농산물 | C16: 여주시농협조합공동사업법인 | D16: 126-82-11620 | E16: 여주시농협RPC 대왕님표 여주쌀 진상미 당일도정 25년 햅쌀 10kg, 2개 [원산지:국산(경기도 여주시)] | F16: 338 | G16: 44247000 | H16: 350000
A17: 네이버 | B17: 가공식품 | C17: 온드리 목장 | D17: 519-33-01006 | E17: 온드리목장 1kg 무가당 꾸덕한 그릭요거트 대용량 [원산지:국산(전라남도 화순군)] | F17: 1648 | G17: 42484960 | H17: 2608170
... A1111: 오아시스 | B1111: 농산물 | C1111: 맑은샘농업회사법인(주) | D1111: 131-86-09478 | E1111: 국내산 깻잎 (40g 또는 30장 내외) | F1111: 8592 | G1111: 9555860 | H1111: 96180
A1112: 오아시스 | B1112: 가공식품 | C1112: 열두달 | D1112: 622-81-28184 | E1112: 착즙 생강청(300g) | F1112: 75 | G1112: 1155000 | H1112: =21560+58520 -> 80080
A1113: 오아시스 | B1113: 가공식품 | C1113: 열두달 | D1113: 622-81-28184 | E1113: [열두달] 제주 유기농 청귤청 | F1113: 1 | G1113: 14940 | H1113: 0
A1114: 오아시스 | B1114: 가공식품 | C1114: 열두달 | D1114: 622-81-28184 | E1114: [열두달] 제로 생강청 | F1114: 0 | G1114: 0 | H1114: 0
A1115: 오아시스 | B1115: 가공식품 | C1115: 열두달 | D1115: 622-81-28184 | E1115: [열두달]1초 레몬수 | F1115: 0 | G1115: 0 | H1115: 0
A1116: 오아시스 | B1116: 가공식품 | C1116: 열두달 | D1116: 622-81-28184 | E1116: [열두달] 제주 무농약 레몬으로 만든 레몬청 | F1116: 0 | G1116: 0 | H1116: 0
A1117: 오아시스 | B1117: 가공식품 | C1117: 행복우리식품영농조합법인 | D1117: 307-81-28140 | E1117: 농부의 딸 현미 누룽지 | F1117: 1 | G1117: 12900 | H1117: =0+2580 -> 2580
A1118: 오아시스 | B1118: 가공식품 | C1118: 행복우리식품영농조합법인 | D1118: 307-81-28140 | E1118: 유기농 쌀누룽지 250g*2 | F1118: 4 | G1118: 51600 | H1118: 2580
A1119: 오아시스 | B1119: 가공식품 | C1119: 행복우리식품영농조합법인 | D1119: 307-81-28140 | E1119: 프리미엄 현미마죽(30gx20스틱) | F1119: 207 | G1119: 2691000 | H1119: =20800+261258 -> 282058
A1120: 오아시스 | B1120: 가공식품 | C1120: 행복우리식품영농조합법인 | D1120: 307-81-28140 | E1120: 조청 쌀강정 150g | F1120: 0 | G1120: 0 | H1120: 0
A1121: 오아시스 | B1121: 가공식품 | C1121: 행복우리식품영농조합법인 | D1121: 307-81-28140 | E1121: 조청 현미강정 150g | F1121: 0 | G1121: 0 | H1121: 0
A1122: 오아시스 | B1122: 가공식품 | C1122: 행복우리식품영농조합법인 | D1122: 307-81-28140 | E1122: 조청 쌀보리강정 150g | F1122: 1 | G1122: 6700 | H1122: =0+1340 -> 1340
A1123: 오아시스 | B1123: 가공식품 | C1123: 행복우리식품영농조합법인 | D1123: 307-81-28140 | E1123: 발아현미 미숫가루 | F1123: 0 | G1123: 0 | H1123: 0
A1124: 오아시스 | B1124: 가공식품 | C1124: 행복우리식품영농조합법인 | D1124: 307-81-28140 | E1124: 현미 양배추죽(30gx20스틱) | F1124: 175 | G1124: 2222500 | H1124: =35400+83682 -> 119082
A1125: 오아시스 | B1125: 가공식품 | C1125: 행복우리식품영농조합법인 | D1125: 307-81-28140 | E1125: 볶은 보리 | F1125: 0 | G1125: 0 | H1125: 0
A1126: 오아시스 | B1126: 가공식품 | C1126: 행복우리식품영농조합법인 | D1126: 307-81-28140 | E1126: 볶은 옥수수 | F1126: 0 | G1126: 0 | H1126: 0
A1127: 오아시스 | B1127: 가공식품 | C1127: 씨튼장애인직업재활센터(씨튼베이커리) | D1127: 409-82-16307 | E1127: [2봉묶음] 유기농 현미스낵 5종 | F1127: 1224 | G1127: 3690000 | H1127: =51200+123409 -> 174609
A1128: 오아시스 | B1128: 가공식품 | C1128: 씨튼장애인직업재활센터(씨튼베이커리) | D1128: 409-82-16307 | E1128: 유기농 현미시리얼 3종 240G [초코/해달별/채소] | F1128: 1727 | G1128: 13470600 | H1128: =182520+588631 -> 771151
A1129: 오아시스 | B1129: 가공식품 | C1129: 씨튼장애인직업재활센터(씨튼베이커리) | D1129: 409-82-16307 | E1129: [개당 2,900]우리밀로 만든 마늘빵 과자 (70g x 3개) | F1129: 859 | G1129: 2914100 | H1129: =32440+66209 -> 98649
A1130: 오아시스 | B1130: 농산물 | C1130: 명품남매농장 | D1130: 807-95-01634 | E1130: 명품남매농장 GAP 샤인머스켓 150g 1차농산물 세척 후 드세요 | F1130: 0 | G1130: 0 | H1130: 0
A1131: 오아시스 | B1131: 농산물 | C1131: 명품남매농장 | D1131: 807-95-01634 | E1131: 명품남매농장 GAP 건샤인머스켓 300g 1차농산물 세척 후 드세요 | F1131: 0 | G1131: 0 | H1131: 0
A1132: 오아시스 | B1132: 농산물 | C1132: 명품남매농장 | D1132: 807-95-01634 | E1132: 명품남매농장 GAP 건샤인머스켓 450g 1차농산물 세척 후 드세요 | F1132: 0 | G1132: 0 | H1132: 0
A1133: 오아시스 | B1133: 농산물 | C1133: 명품남매농장 | D1133: 807-95-01634 | E1133: 명품남매농장 GAP 건샤인머스켓 600g 1차농산물 세척 후 드세요 | F1133: 0 | G1133: 0 | H1133: 0
A1134: 오아시스 | B1134: 농산물 | C1134: 명품남매농장 | D1134: 807-95-01634 | E1134: 명품남매농장 GAP 건샤인머스켓 750g 1차농산물 세척 후 드세요 | F1134: 0 | G1134: 0 | H1134: 0
...

Sheet 유기농업체
F1: =SUM(F3:F57) -> 127651 | G1: =SUM(G3:G57) -> 646574890 | H1: =SUM(H3:H57) -> 20033931 | I1: 32
A2: NO | B2: 구분 | C2: 사업자등록번호 | D2: 업체명 | E2: 배정유통사 | F2: 판매건수 | G2: 매출액 | H2: 판촉액 | I2: 7월 실제 인입
A3: 1 | B3: 도약 | C3: 218-86-00721 | D3: 주식회사 아인스 | E3: 오아시스 | F3: =SUMIF(②유기농raw!$D$6:$D$180,$C3,②유기농raw!$F$6:$F$180) -> 12517 | G3: =SUMIF(②유기농raw!$D$6:$D$180,$C3,②유기농raw!$G$6:$G$180) -> 76900370 | H3: =SUMIF(②유기농raw!$D$6:$D$180,$C3,②유기농raw!$H$6:$H$180) -> 1028586 | I3: O
A4: 2 | B4: 도약 | C4: 225-90-26954 | D4: 풀무리농장 | E4: 네이버 | F4: =SUMIF(②유기농raw!$D$6:$D$180,$C4,②유기농raw!$F$6:$F$180) -> 175 | G4: =SUMIF(②유기농raw!$D$6:$D$180,$C4,②유기농raw!$G$6:$G$180) -> 6094000 | H4: =SUMIF(②유기농raw!$D$6:$D$180,$C4,②유기농raw!$H$6:$H$180) -> 886100 | I4: O
A5: 3 | B5: 시작 | C5: 326-37-00548 | D5: 파미농원 | E5: 오아시스 | F5: =SUMIF(②유기농raw!$D$6:$D$180,$C5,②유기농raw!$F$6:$F$180) -> 0 | G5: =SUMIF(②유기농raw!$D$6:$D$180,$C5,②유기농raw!$G$6:$G$180) -> 0 | H5: =SUMIF(②유기농raw!$D$6:$D$180,$C5,②유기농raw!$H$6:$H$180) -> 0
A6: 4 | B6: 시작 | C6: 497-41-01341 | D6: 국가대표상황버섯 | E6: 오아시스 | F6: =SUMIF(②유기농raw!$D$6:$D$180,$C6,②유기농raw!$F$6:$F$180) -> 0 | G6: =SUMIF(②유기농raw!$D$6:$D$180,$C6,②유기농raw!$G$6:$G$180) -> 0 | H6: =SUMIF(②유기농raw!$D$6:$D$180,$C6,②유기농raw!$H$6:$H$180) -> 0
A7: 5 | B7: 성장 | C7: 312-27-45552 | D7: 바우뜨락 | E7: 오아시스 | F7: =SUMIF(②유기농raw!$D$6:$D$180,$C7,②유기농raw!$F$6:$F$180) -> 17 | G7: =SUMIF(②유기농raw!$D$6:$D$180,$C7,②유기농raw!$G$6:$G$180) -> 657000 | H7: =SUMIF(②유기농raw!$D$6:$D$180,$C7,②유기농raw!$H$6:$H$180) -> 0 | I7: O
A8: 6 | B8: 도약 | C8: 201-86-47960 | D8: 다온365농업회사법인(주) | E8: 오아시스 | F8: =SUMIF(②유기농raw!$D$6:$D$180,$C8,②유기농raw!$F$6:$F$180) -> 0 | G8: =SUMIF(②유기농raw!$D$6:$D$180,$C8,②유기농raw!$G$6:$G$180) -> 0 | H8: =SUMIF(②유기농raw!$D$6:$D$180,$C8,②유기농raw!$H$6:$H$180) -> 0
A9: 7 | B9: 도약 | C9: 410-86-90042 | D9: 아름답게그린배영농조합법인 | E9: 네이버 | F9: =SUMIF(②유기농raw!$D$6:$D$180,$C9,②유기농raw!$F$6:$F$180) -> 17 | G9: =SUMIF(②유기농raw!$D$6:$D$180,$C9,②유기농raw!$G$6:$G$180) -> 565600 | H9: =SUMIF(②유기농raw!$D$6:$D$180,$C9,②유기농raw!$H$6:$H$180) -> 92660 | I9: O
A10: 8 | B10: 시작 | C10: 512-13-21395 | D10: 현재농원 | E10: 네이버 | F10: =SUMIF(②유기농raw!$D$6:$D$180,$C10,②유기농raw!$F$6:$F$180) -> 3 | G10: =SUMIF(②유기농raw!$D$6:$D$180,$C10,②유기농raw!$G$6:$G$180) -> 69150 | H10: =SUMIF(②유기농raw!$D$6:$D$180,$C10,②유기농raw!$H$6:$H$180) -> 11630 | I10: O
A11: 9 | B11: 도약 | C11: 745-96-00315 | D11: 해담는집 | E11: 오아시스 | F11: =SUMIF(②유기농raw!$D$6:$D$180,$C11,②유기농raw!$F$6:$F$180) -> 26 | G11: =SUMIF(②유기농raw!$D$6:$D$180,$C11,②유기농raw!$G$6:$G$180) -> 456200 | H11: =SUMIF(②유기농raw!$D$6:$D$180,$C11,②유기농raw!$H$6:$H$180) -> 57980 | I11: O
A12: 10 | B12: 도약 | C12: 386-96-00703 | D12: 여화원 | E12: 네이버 | F12: =SUMIF(②유기농raw!$D$6:$D$180,$C12,②유기농raw!$F$6:$F$180) -> 124 | G12: =SUMIF(②유기농raw!$D$6:$D$180,$C12,②유기농raw!$G$6:$G$180) -> 4122700 | H12: =SUMIF(②유기농raw!$D$6:$D$180,$C12,②유기농raw!$H$6:$H$180) -> 469620 | I12: O
A13: 11 | B13: 도약 | C13: 409-86-48791 | D13: 주식회사 유기농샵에프앤비 | E13: 오아시스 | F13: =SUMIF(②유기농raw!$D$6:$D$180,$C13,②유기농raw!$F$6:$F$180) -> 0 | G13: =SUMIF(②유기농raw!$D$6:$D$180,$C13,②유기농raw!$G$6:$G$180) -> 0 | H13: =SUMIF(②유기농raw!$D$6:$D$180,$C13,②유기농raw!$H$6:$H$180) -> 0
A14: 12 | B14: 도약 | C14: 556-72-00266 | D14: 제주오가닉스 | E14: 오아시스 | F14: =SUMIF(②유기농raw!$D$6:$D$180,$C14,②유기농raw!$F$6:$F$180) -> 0 | G14: =SUMIF(②유기농raw!$D$6:$D$180,$C14,②유기농raw!$G$6:$G$180) -> 0 | H14: =SUMIF(②유기농raw!$D$6:$D$180,$C14,②유기농raw!$H$6:$H$180) -> 0
A15: 13 | B15: 도약 | C15: 592-08-01799 | D15: 삼둥이농장 | E15: 오아시스 | F15: =SUMIF(②유기농raw!$D$6:$D$180,$C15,②유기농raw!$F$6:$F$180) -> 0 | G15: =SUMIF(②유기농raw!$D$6:$D$180,$C15,②유기농raw!$G$6:$G$180) -> 0 | H15: =SUMIF(②유기농raw!$D$6:$D$180,$C15,②유기농raw!$H$6:$H$180) -> 0
A16: 14 | B16: 도약 | C16: 680-87-00224 | D16: 다원팜농업회사법인유한회사 | E16: 오아시스 | F16: =SUMIF(②유기농raw!$D$6:$D$180,$C16,②유기농raw!$F$6:$F$180) -> 9330 | G16: =SUMIF(②유기농raw!$D$6:$D$180,$C16,②유기농raw!$G$6:$G$180) -> 19696150 | H16: =SUMIF(②유기농raw!$D$6:$D$180,$C16,②유기농raw!$H$6:$H$180) -> 1078686 | I16: O
A17: 15 | B17: 도약 | C17: 402-81-54069 | D17: 참식품주식회사 | E17: 네이버 | F17: =SUMIF(②유기농raw!$D$6:$D$180,$C17,②유기농raw!$F$6:$F$180) -> 268 | G17: =SUMIF(②유기농raw!$D$6:$D$180,$C17,②유기농raw!$G$6:$G$180) -> 7562100 | H17: =SUMIF(②유기농raw!$D$6:$D$180,$C17,②유기농raw!$H$6:$H$180) -> 880230 | I17: O
A18: 16 | B18: 시작 | C18: 252-86-02831 | D18: 농업회사법인주식회사한내담 | E18: 오아시스 | F18: =SUMIF(②유기농raw!$D$6:$D$180,$C18,②유기농raw!$F$6:$F$180) -> 0 | G18: =SUMIF(②유기농raw!$D$6:$D$180,$C18,②유기농raw!$G$6:$G$180) -> 0 | H18: =SUMIF(②유기농raw!$D$6:$D$180,$C18,②유기농raw!$H$6:$H$180) -> 0
A19: 17 | B19: 성장 | C19: 566-81-02884 | D19: 농업회사법인 주식회사 여주능서농원 | E19: 네이버 | F19: =SUMIF(②유기농raw!$D$6:$D$180,$C19,②유기농raw!$F$6:$F$180) -> 113 | G19: =SUMIF(②유기농raw!$D$6:$D$180,$C19,②유기농raw!$G$6:$G$180) -> 2551190 | H19: =SUMIF(②유기농raw!$D$6:$D$180,$C19,②유기농raw!$H$6:$H$180) -> 315770 | I19: O
A20: 18 | B20: 도약 | C20: 580-88-02822 | D20: 농업회사법인 나무컴퍼니 주식회사 | E20: 네이버 | F20: =SUMIF(②유기농raw!$D$6:$D$180,$C20,②유기농raw!$F$6:$F$180) -> 2203 | G20: =SUMIF(②유기농raw!$D$6:$D$180,$C20,②유기농raw!$G$6:$G$180) -> 40996160 | H20: =SUMIF(②유기농raw!$D$6:$D$180,$C20,②유기농raw!$H$6:$H$180) -> 4246920 | I20: O
A21: 19 | B21: 시작 | C21: 815-15-01628 | D21: 뭇별농장 | E21: 네이버 | F21: =SUMIF(②유기농raw!$D$6:$D$180,$C21,②유기농raw!$F$6:$F$180) -> 0 | G21: =SUMIF(②유기농raw!$D$6:$D$180,$C21,②유기농raw!$G$6:$G$180) -> 0 | H21: =SUMIF(②유기농raw!$D$6:$D$180,$C21,②유기농raw!$H$6:$H$180) -> 0
A22: 20 | B22: 도약 | C22: 502-81-55602 | D22: 농업법인회사 (주)초록원 | E22: 오아시스 | F22: =SUMIF(②유기농raw!$D$6:$D$180,$C22,②유기농raw!$F$6:$F$180) -> 1858 | G22: =SUMIF(②유기농raw!$D$6:$D$180,$C22,②유기농raw!$G$6:$G$180) -> 20363420 | H22: =SUMIF(②유기농raw!$D$6:$D$180,$C22,②유기농raw!$H$6:$H$180) -> 1072130 | I22: O
A23: 21 | B23: 도약 | C23: 654-88-01503 | D23: (주)밀알케이 | E23: 오아시스 | F23: =SUMIF(②유기농raw!$D$6:$D$180,$C23,②유기농raw!$F$6:$F$180) -> 656 | G23: =SUMIF(②유기농raw!$D$6:$D$180,$C23,②유기농raw!$G$6:$G$180) -> 3066000 | H23: =SUMIF(②유기농raw!$D$6:$D$180,$C23,②유기농raw!$H$6:$H$180) -> 0 | I23: O
A24: 22 | B24: 도약 | C24: 774-11-01498 | D24: 경성표고버섯농장 | E24: 네이버 | F24: =SUMIF(②유기농raw!$D$6:$D$180,$C24,②유기농raw!$F$6:$F$180) -> 173 | G24: =SUMIF(②유기농raw!$D$6:$D$180,$C24,②유기농raw!$G$6:$G$180) -> 3416470 | H24: =SUMIF(②유기농raw!$D$6:$D$180,$C24,②유기농raw!$H$6:$H$180) -> 365550 | I24: O
A25: 23 | B25: 도약 | C25: 416-81-44143 | D25: 도울 F&B | E25: 오아시스 | F25: =SUMIF(②유기농raw!$D$6:$D$180,$C25,②유기농raw!$F$6:$F$180) -> 1434 | G25: =SUMIF(②유기농raw!$D$6:$D$180,$C25,②유기농raw!$G$6:$G$180) -> 3330250 | H25: =SUMIF(②유기농raw!$D$6:$D$180,$C25,②유기농raw!$H$6:$H$180) -> 260996 | I25: O
A26: 24 | B26: 도약 | C26: 754-88-00876 | D26: 베리네이처 | E26: 오아시스 | F26: =SUMIF(②유기농raw!$D$6:$D$180,$C26,②유기농raw!$F$6:$F$180) -> 6303 | G26: =SUMIF(②유기농raw!$D$6:$D$180,$C26,②유기농raw!$G$6:$G$180) -> 18345130 | H26: =SUMIF(②유기농raw!$D$6:$D$180,$C26,②유기농raw!$H$6:$H$180) -> 1117281 | I26: O
A27: 25 | B27: 도약 | C27: 507-81-09103 | D27: 나래친환경영농조합법인 | E27: 네이버 | F27: =SUMIF(②유기농raw!$D$6:$D$180,$C27,②유기농raw!$F$6:$F$180) -> 58 | G27: =SUMIF(②유기농raw!$D$6:$D$180,$C27,②유기농raw!$G$6:$G$180) -> 3304000 | H27: =SUMIF(②유기농raw!$D$6:$D$180,$C27,②유기농raw!$H$6:$H$180) -> 550000 | I27: O
A28: 26 | B28: 시작 | C28: 190-97-01151 | D28: 지구별농장 | E28: 네이버 | F28: =SUMIF(②유기농raw!$D$6:$D$180,$C28,②유기농raw!$F$6:$F$180) -> 0 | G28: =SUMIF(②유기농raw!$D$6:$D$180,$C28,②유기농raw!$G$6:$G$180) -> 0 | H28: =SUMIF(②유기농raw!$D$6:$D$180,$C28,②유기농raw!$H$6:$H$180) -> 0
A29: 27 | B29: 성장 | C29: 706-01-03422 | D29: 아침농부 | E29: 네이버 | F29: =SUMIF(②유기농raw!$D$6:$D$180,$C29,②유기농raw!$F$6:$F$180) -> 245 | G29: =SUMIF(②유기농raw!$D$6:$D$180,$C29,②유기농raw!$G$6:$G$180) -> 5724000 | H29: =SUMIF(②유기농raw!$D$6:$D$180,$C29,②유기농raw!$H$6:$H$180) -> 0 | I29: O
A30: 28 | B30: 도약 | C30: 761-46-00855 | D30: 코스모스길 옆 상황버 | E30: 네이버 | F30: =SUMIF(②유기농raw!$D$6:$D$180,$C30,②유기농raw!$F$6:$F$180) -> 0 | G30: =SUMIF(②유기농raw!$D$6:$D$180,$C30,②유기농raw!$G$6:$G$180) -> 0 | H30: =SUMIF(②유기농raw!$D$6:$D$180,$C30,②유기농raw!$H$6:$H$180) -> 0
A31: 29 | B31: 성장 | C31: 522-17-00696 | D31: 엿공장 | E31: 오아시스 | F31: =SUMIF(②유기농raw!$D$6:$D$180,$C31,②유기농raw!$F$6:$F$180) -> 1 | G31: =SUMIF(②유기농raw!$D$6:$D$180,$C31,②유기농raw!$G$6:$G$180) -> 18500 | H31: =SUMIF(②유기농raw!$D$6:$D$180,$C31,②유기농raw!$H$6:$H$180) -> 3700 | I31: O
A32: 30 | B32: 도약 | C32: 685-88-00527 | D32: 농업회사법인주식회사다고 | E32: 오아시스 | F32: =SUMIF(②유기농raw!$D$6:$D$180,$C32,②유기농raw!$F$6:$F$180) -> 30 | G32: =SUMIF(②유기농raw!$D$6:$D$180,$C32,②유기농raw!$G$6:$G$180) -> 450000 | H32: =SUMIF(②유기농raw!$D$6:$D$180,$C32,②유기농raw!$H$6:$H$180) -> 90000 | I32: O
A33: 31 | B33: 도약 | C33: 132-81-55005 | D33: 농업회사법인 하늘농가(주) | E33: 오아시스 | F33: =SUMIF(②유기농raw!$D$6:$D$180,$C33,②유기농raw!$F$6:$F$180) -> 0 | G33: =SUMIF(②유기농raw!$D$6:$D$180,$C33,②유기농raw!$G$6:$G$180) -> 0 | H33: =SUMIF(②유기농raw!$D$6:$D$180,$C33,②유기농raw!$H$6:$H$180) -> 0
A34: 32 | B34: 도약 | C34: 515-81-53707 | D34: 농업회사법인 닥터애그 주식회사 | E34: 오아시스 | F34: =SUMIF(②유기농raw!$D$6:$D$180,$C34,②유기농raw!$F$6:$F$180) -> 73946 | G34: =SUMIF(②유기농raw!$D$6:$D$180,$C34,②유기농raw!$G$6:$G$180) -> 55219530 | H34: =SUMIF(②유기농raw!$D$6:$D$180,$C34,②유기농raw!$H$6:$H$180) -> 1006927 | I34: O
A35: 33 | B35: 성장 | C35: 220-88-07925 | D35: 농업회사법인 주식회사 떡찌니 | E35: 네이버 | F35: =SUMIF(②유기농raw!$D$6:$D$180,$C35,②유기농raw!$F$6:$F$180) -> 0 | G35: =SUMIF(②유기농raw!$D$6:$D$180,$C35,②유기농raw!$G$6:$G$180) -> 0 | H35: =SUMIF(②유기농raw!$D$6:$D$180,$C35,②유기농raw!$H$6:$H$180) -> 0
A36: 34 | B36: 도약 | C36: 311-81-44794 | D36: 농업회사법인내포(주) | E36: 오아시스 | F36: =SUMIF(②유기농raw!$D$6:$D$180,$C36,②유기농raw!$F$6:$F$180) -> 6 | G36: =SUMIF(②유기농raw!$D$6:$D$180,$C36,②유기농raw!$G$6:$G$180) -> 156000 | H36: =SUMIF(②유기농raw!$D$6:$D$180,$C36,②유기농raw!$H$6:$H$180) -> 31200 | I36: O
A37: 35 | B37: 성장 | C37: 848-99-01346 | D37: 옥수농원 | E37: 네이버 | F37: =SUMIF(②유기농raw!$D$6:$D$180,$C37,②유기농raw!$F$6:$F$180) -> 0 | G37: =SUMIF(②유기농raw!$D$6:$D$180,$C37,②유기농raw!$G$6:$G$180) -> 0 | H37: =SUMIF(②유기농raw!$D$6:$D$180,$C37,②유기농raw!$H$6:$H$180) -> 0
A38: 36 | B38: 성장 | C38: 829-88-01091 | D38: 스퀘어팜 농업회사법인주식회사 | E38: 오아시스 | F38: =SUMIF(②유기농raw!$D$6:$D$180,$C38,②유기농raw!$F$6:$F$180) -> 0 | G38: =SUMIF(②유기농raw!$D$6:$D$180,$C38,②유기농raw!$G$6:$G$180) -> 0 | H38: =SUMIF(②유기농raw!$D$6:$D$180,$C38,②유기농raw!$H$6:$H$180) -> 0
A39: 37 | B39: 도약 | C39: 126-18-96934 | D39: 굿그레인즈 | E39: 오아시스 | F39: =SUMIF(②유기농raw!$D$6:$D$180,$C39,②유기농raw!$F$6:$F$180) -> 11722 | G39: =SUMIF(②유기농raw!$D$6:$D$180,$C39,②유기농raw!$G$6:$G$180) -> 310136400 | H39: =SUMIF(②유기농raw!$D$6:$D$180,$C39,②유기농raw!$H$6:$H$180) -> 1185849 | I39: O
A40: 38 | B40: 시작 | C40: 109-36-80203 | D40: 내추럴참푸드 | E40: 오아시스 | F40: =SUMIF(②유기농raw!$D$6:$D$180,$C40,②유기농raw!$F$6:$F$180) -> 269 | G40: =SUMIF(②유기농raw!$D$6:$D$180,$C40,②유기농raw!$G$6:$G$180) -> 6583300 | H40: =SUMIF(②유기농raw!$D$6:$D$180,$C40,②유기농raw!$H$6:$H$180) -> 739046 | I40: O
...

Sheet ②유기농raw
A1: 2026 aT 농산물 온라인 마케터 업체 별 매출 보고
A2: 기간 : 07월 06일 ~ 07월 31일
A4: 합계 | F4: =SUM(F6:F1000) -> 127651 | G4: =SUM(G6:G1000) -> 646574890 | H4: =SUM(H6:H1000) -> 20033931
A5: 유통사명 | B5: 품목분류 | C5: 사업자명 | D5: 사업자번호 | E5: 상품명 | F5: 판매 건수 | G5: 매출액 | H5: 판촉액
A6: 네이버 | B6: 농산물 | C6: 농업회사법인주식회사구룡농원 | D6: 847-88-01726 | E6: 유기농 햇 찰옥수수 흑찰옥수수 미백옥수수 / 구룡농원 냉동 삶은 찐옥수수 강원도품종 [원산지:국산] | F6: 562 | G6: 18657800 | H6: 2139120 | I6: o
A7: 네이버 | B7: 농산물 | C7: 농업회사법인 나무컴퍼니 주식회사 | D7: 580-88-02822 | E7: [100% 국산 유기농] 25년산 호라산밀 카무트 카무트쌀 파로 곡물 1kg 택일 [원산지:상세설명에 표시] | F7: 400 | G7: 8568180 | H7: 997420 | I7: o
A8: 네이버 | B8: 농산물 | C8: 농업회사법인 나무컴퍼니 주식회사 | D8: 580-88-02822 | E8: 25년산 귀리 국산 유기농 귀리쌀 1kg [원산지:국산(전라남도 진도군)] | F8: 449 | G8: 7695920 | H8: 713840 | I8: o
A9: 네이버 | B9: 농산물 | C9: 풀무리농장 | D9: 225-90-26954 | E9: 풀무리농장 당일수확 친환경 유기농토마토2.5kg5kg [원산지:국산(강원도 영월군)] | F9: 175 | G9: 6094000 | H9: 886100 | I9: o
A10: 네이버 | B10: 농산물 | C10: 아침농부 | D10: 706-01-03422 | E10: 유기농 미니파프리카1.5kg (토양재배) [원산지:국산(충청남도 홍성군)] | F10: 245 | G10: 5724000 | H10: 0 | I10: o
A11: 네이버 | B11: 농산물 | C11: 농업회사법인 나무컴퍼니 주식회사 | D11: 580-88-02822 | E11: 25년 햇곡 국산 유기농 현미 쌀 2kg [원산지:국산(전라남도 진도군)] | F11: 258 | G11: 3957980 | H11: 322980 | I11: o
A12: 네이버 | B12: 농산물 | C12: 땅끝민지맘 | D12: 402-47-64035 | E12: 유기농 잡곡 2kg(1kg x 2팩) 혼합곡 [원산지:국산(전라남도 해남군)] | F12: 178 | G12: 3575260 | H12: 0 | I12: o
A13: 네이버 | B13: 농산물 | C13: 농업회사법인 나무컴퍼니 주식회사 | D13: 580-88-02822 | E13: 25년도 햇곡 기장쌀 국산 유기농 찰기장 좁쌀 1kg [원산지:국산(전라남도 진도군)] | F13: 143 | G13: 3398700 | H13: 338520 | I13: o
A14: 네이버 | B14: 농산물 | C14: 나래친환경영농조합법인 | D14: 507-81-09103 | E14: 유기농복숭아/백도/4.0kg/무료배송 [원산지:국산(경상북도 영덕군)] | F14: 58 | G14: 3304000 | H14: 550000 | I14: o
A15: 네이버 | B15: 농산물 | C15: 여화원 | D15: 386-96-00703 | E15: 유기농 반건조 청무화과 말랭이 100g /국산 유기농 명인 건무화과 건과일 말린 건조과일 [원산지:국산(전라남도 고흥군)] | F15: 87 | G15: 2855400 | H15: 312700 | I15: o
A16: 네이버 | B16: 농산물 | C16: 경성표고버섯농장 | D16: 774-11-01498 | E16: 참나무 표고버섯 유기농 슬라이스 건표고버섯 통 건표고버섯(200g) [원산지:국산(경상북도 성주군)] | F16: 132 | G16: 2821900 | H16: 314300 | I16: o
A17: 네이버 | B17: 농산물 | C17: 농업회사법인 나무컴퍼니 주식회사 | D17: 580-88-02822 | E17: 26년산 국산 유기농 보리 흑보리 찰보리 쌀 1kg [원산지:국산(전라남도 진도군)] | F17: 162 | G17: 2496180 | H17: 253520 | I17: o
... A180: 오아시스 | B180: 가공식품 | C180: (주)밀알케이 | D180: 654-88-01503 | E180: 유기농 파머스 팝콘 (70g x 1개) | F180: 656 | G180: 3066000 | H180: 0 | I180: o
