Workbook

Sheet 분석
B1: ※ 전체 기획전 결과
B3: 1. 해당 월 참여 상품 수 및 업체수
B4: 구분 | C4: 총 계 | D4: 농부가바로팜 | K4: 친환경
D5: 소 계 | E5: 네이버 | F5: 지마켓 | G5: 롯데ON | H5: 온누리마켓 | I5: 농가살리기 | J5: 오아시스 | K5: 소 계 | L5: 네이버 | M5: 오아시스
B6: 업체수 | C6: =D6+K6 -> 340 | D6: =SUM(E6:J6) -> 285 | E6: 136 | F6: 53 | G6: 47 | H6: 24 | I6: 9 | J6: 16 | K6: =SUM(L6:M6) -> 55 | L6: 26 | M6: 29
B7: 7월 | C7: =SUM(D7,K7) -> 218 | D7: =SUM(E7:J7) -> 186 | E7: 82 | F7: 36 | G7: 32 | H7: 17 | I7: 6 | J7: 13 | K7: =SUM(L7:M7) -> 32 | L7: 16 | M7: 16
B8: 상품수 | C8: =D8+K8 -> 1305 | D8: =SUM(E8:J8) -> 1130 | E8: 388 | F8: 258 | G8: 313 | H8: 55 | I8: 29 | J8: 87 | K8: =SUM(L8:M8) -> 175 | L8: 85 | M8: 90
B10: 2. 유통사 별 쿠폰 사용액
B11: 구분 | C11: 총 계 | D11: 농부가바로팜 | K11: 친환경
D12: 소 계 | E12: 네이버 | F12: 지마켓 | G12: 롯데ON | H12: 온누리마켓 | I12: 농가살리기 | J12: 오아시스 | K12: 소 계 | L12: 네이버 | M12: 오아시스
B13: 쿠폰 사용액 | C13: =D13+K13 -> #ERROR! | D13: =SUM(E13:J13) -> 98962900 | E13: =SUMIF('①농산물raw'!$A$6:$A$445,E$12,'①농산물raw'!$H$6:$H$445) -> 0 | F13: =SUMIF('①농산물raw'!$A$6:$A$445,F$12,'①농산물raw'!$H$6:$H$445) -> 76647920 | G13: =SUMIF('①농산물raw'!$A$6:$A$445,G$12,'①농산물raw'!$H$6:$H$445) -> 22314980 | H13: =SUMIF('①농산물raw'!$A$6:$A$445,H$12,'①농산물raw'!$H$6:$H$445) -> 0 | I13: =SUMIF('①농산물raw'!$A$6:$A$445,I$12,'①농산물raw'!$H$6:$H$445) -> 0 | J13: =SUMIF('①농산물raw'!$A$6:$A$445,J$12,'①농산물raw'!$H$6:$H$445) -> 0 | K13: =SUM(L13:M13) -> #ERROR! | L13: =SUMIF(②유기농raw!#REF!,L$12,②유기농raw!#REF!) -> #ERROR! | M13: =SUMIF(②유기농raw!#REF!,M$12,②유기농raw!#REF!) -> #ERROR!
B15: 3. 유통사 별 매출 분석
B16: 구분 | C16: 총 계 | D16: 농부가바로팜 | K16: 친환경
D17: 소 계 | E17: 네이버 | F17: 지마켓 | G17: 롯데ON | H17: 온누리마켓 | I17: 농가살리기 | J17: 오아시스 | K17: 소 계 | L17: 네이버 | M17: 오아시스
B18: 매출액 | C18: =D18+K18 -> #ERROR! | D18: =SUM(E18:J18) -> 1480449370 | E18: =SUMIF('①농산물raw'!$A$6:$A$445,E$17,'①농산물raw'!$G$6:$G$445) -> 0 | F18: =SUMIF('①농산물raw'!$A$6:$A$445,F$17,'①농산물raw'!$G$6:$G$445) -> 1348440770 | G18: =SUMIF('①농산물raw'!$A$6:$A$445,G$17,'①농산물raw'!$G$6:$G$445) -> 132008600 | H18: =SUMIF('①농산물raw'!$A$6:$A$445,H$17,'①농산물raw'!$G$6:$G$445) -> 0 | I18: =SUMIF('①농산물raw'!$A$6:$A$445,I$17,'①농산물raw'!$G$6:$G$445) -> 0 | J18: =SUMIF('①농산물raw'!$A$6:$A$445,J$17,'①농산물raw'!$G$6:$G$445) -> 0 | K18: =SUM(L18:M18) -> #ERROR! | L18: =SUMIF(②유기농raw!#REF!,L$17,②유기농raw!#REF!) -> #ERROR! | M18: =SUMIF(②유기농raw!#REF!,M$17,②유기농raw!#REF!) -> #ERROR!
B20: 4. 유통사 별 판매 건수
B21: 구분 | C21: 총 계 | D21: 농부가바로팜 | K21: 친환경
D22: 소 계 | E22: 네이버 | F22: 지마켓 | G22: 롯데ON | H22: 온누리마켓 | I22: 농가살리기 | J22: 오아시스 | K22: 소 계 | L22: 네이버 | M22: 오아시스
B23: 판매건수 | C23: =D23+K23 -> #ERROR! | D23: =SUM(E23:J23) -> 73605 | E23: =SUMIF('①농산물raw'!$A$6:$A$445,E$22,'①농산물raw'!$F$6:$F$445) -> 0 | F23: =SUMIF('①농산물raw'!$A$6:$A$445,F$22,'①농산물raw'!$F$6:$F$445) -> 68093 | G23: =SUMIF('①농산물raw'!$A$6:$A$445,G$22,'①농산물raw'!$F$6:$F$445) -> 5512 | H23: =SUMIF('①농산물raw'!$A$6:$A$445,H$22,'①농산물raw'!$F$6:$F$445) -> 0 | I23: =SUMIF('①농산물raw'!$A$6:$A$445,I$22,'①농산물raw'!$F$6:$F$445) -> 0 | J23: =SUMIF('①농산물raw'!$A$6:$A$445,J$22,'①농산물raw'!$F$6:$F$445) -> 0 | K23: =SUM(L23:M23) -> #ERROR! | L23: =SUMIF(②유기농raw!#REF!,L$22,②유기농raw!#REF!) -> #ERROR! | M23: =SUMIF(②유기농raw!#REF!,M$22,②유기농raw!#REF!) -> #ERROR!
B25: 5. 유통사별 품목별 쿠폰 사용액
B26: 구분 | C26: 총 계 | D26: 농부가바로팜 | K26: 친환경
D27: 소 계 | E27: 네이버 | F27: 지마켓 | G27: 롯데ON | H27: 온누리마켓 | I27: 농가살리기 | J27: 오아시스 | K27: 소 계 | L27: 네이버 | M27: 오아시스
B28: 총 계 | C28: =D28+K28 -> #ERROR! | D28: =SUM(E28:J28) -> 98962900 | E28: =SUM(E29:E31) -> 0 | F28: =SUM(F29:F31) -> 76647920 | G28: =SUM(G29:G31) -> 22314980 | H28: =SUM(H29:H31) -> 0 | I28: =SUM(I29:I31) -> 0 | J28: =SUM(J29:J31) -> 0 | K28: =SUM(L28:M28) -> #ERROR! | L28: =SUM(L29:L31) -> #ERROR! | M28: =SUM(M29:M31) -> #ERROR!
B29: 농산물 | C29: =D29+K29 -> #ERROR! | D29: =SUM(E29:J29) -> 49729610 | E29: =SUMIFS('①농산물raw'!$H$6:$H$445,'①농산물raw'!$A$6:$A$445,E$27,'①농산물raw'!$B$6:$B$445,$B29) -> 0 | F29: =SUMIFS('①농산물raw'!$H$6:$H$445,'①농산물raw'!$A$6:$A$445,F$27,'①농산물raw'!$B$6:$B$445,$B29) -> 40365730 | G29: =SUMIFS('①농산물raw'!$H$6:$H$445,'①농산물raw'!$A$6:$A$445,G$27,'①농산물raw'!$B$6:$B$445,$B29) -> 9363880 | H29: =SUMIFS('①농산물raw'!$H$6:$H$445,'①농산물raw'!$A$6:$A$445,H$27,'①농산물raw'!$B$6:$B$445,$B29) -> 0 | I29: =SUMIFS('①농산물raw'!$H$6:$H$445,'①농산물raw'!$A$6:$A$445,I$27,'①농산물raw'!$B$6:$B$445,$B29) -> 0 | J29: =SUMIFS('①농산물raw'!$H$6:$H$445,'①농산물raw'!$A$6:$A$445,J$27,'①농산물raw'!$B$6:$B$445,$B29) -> 0 | K29: =SUM(L29:M29) -> #ERROR! | L29: =SUMIFS(②유기농raw!#REF!,②유기농raw!#REF!,L$27,②유기농raw!#REF!,$B29) -> #ERROR! | M29: =SUMIFS(②유기농raw!#REF!,②유기농raw!#REF!,M$27,②유기농raw!#REF!,$B29) -> #ERROR!
B30: 축산물 | C30: =D30+K30 -> #ERROR! | D30: =SUM(E30:J30) -> 15309010 | E30: =SUMIFS('①농산물raw'!$H$6:$H$445,'①농산물raw'!$A$6:$A$445,E$27,'①농산물raw'!$B$6:$B$445,$B30) -> 0 | F30: =SUMIFS('①농산물raw'!$H$6:$H$445,'①농산물raw'!$A$6:$A$445,F$27,'①농산물raw'!$B$6:$B$445,$B30) -> 9906730 | G30: =SUMIFS('①농산물raw'!$H$6:$H$445,'①농산물raw'!$A$6:$A$445,G$27,'①농산물raw'!$B$6:$B$445,$B30) -> 5402280 | H30: =SUMIFS('①농산물raw'!$H$6:$H$445,'①농산물raw'!$A$6:$A$445,H$27,'①농산물raw'!$B$6:$B$445,$B30) -> 0 | I30: =SUMIFS('①농산물raw'!$H$6:$H$445,'①농산물raw'!$A$6:$A$445,I$27,'①농산물raw'!$B$6:$B$445,$B30) -> 0 | J30: =SUMIFS('①농산물raw'!$H$6:$H$445,'①농산물raw'!$A$6:$A$445,J$27,'①농산물raw'!$B$6:$B$445,$B30) -> 0 | K30: =SUM(L30:M30) -> #ERROR! | L30: =SUMIFS(②유기농raw!#REF!,②유기농raw!#REF!,L$27,②유기농raw!#REF!,$B30) -> #ERROR! | M30: =SUMIFS(②유기농raw!#REF!,②유기농raw!#REF!,M$27,②유기농raw!#REF!,$B30) -> #ERROR!
B31: 가공식품 | C31: =D31+K31 -> #ERROR! | D31: =SUM(E31:J31) -> 33924280 | E31: =SUMIFS('①농산물raw'!$H$6:$H$445,'①농산물raw'!$A$6:$A$445,E$27,'①농산물raw'!$B$6:$B$445,$B31) -> 0 | F31: =SUMIFS('①농산물raw'!$H$6:$H$445,'①농산물raw'!$A$6:$A$445,F$27,'①농산물raw'!$B$6:$B$445,$B31) -> 26375460 | G31: =SUMIFS('①농산물raw'!$H$6:$H$445,'①농산물raw'!$A$6:$A$445,G$27,'①농산물raw'!$B$6:$B$445,$B31) -> 7548820 | H31: =SUMIFS('①농산물raw'!$H$6:$H$445,'①농산물raw'!$A$6:$A$445,H$27,'①농산물raw'!$B$6:$B$445,$B31) -> 0 | I31: =SUMIFS('①농산물raw'!$H$6:$H$445,'①농산물raw'!$A$6:$A$445,I$27,'①농산물raw'!$B$6:$B$445,$B31) -> 0 | J31: =SUMIFS('①농산물raw'!$H$6:$H$445,'①농산물raw'!$A$6:$A$445,J$27,'①농산물raw'!$B$6:$B$445,$B31) -> 0 | K31: =SUM(L31:M31) -> #ERROR! | L31: =SUMIFS(②유기농raw!#REF!,②유기농raw!#REF!,L$27,②유기농raw!#REF!,$B31) -> #ERROR! | M31: =SUMIFS(②유기농raw!#REF!,②유기농raw!#REF!,M$27,②유기농raw!#REF!,$B31) -> #ERROR!
B33: 6. 유통사별 품목별 매출 분석
B34: 구분 | C34: 총 계 | D34: 농부가바로팜 | K34: 친환경
D35: 소 계 | E35: 네이버 | F35: 지마켓 | G35: 롯데ON | H35: 온누리마켓 | I35: 농가살리기 | J35: 오아시스 | K35: 소 계 | L35: 네이버 | M35: 오아시스
B36: 총 계 | C36: =D36+K36 -> #ERROR! | D36: =SUM(E36:J36) -> 1480449370 | E36: =SUM(E37:E39) -> 0 | F36: =SUM(F37:F39) -> 1348440770 | G36: =SUM(G37:G39) -> 132008600 | H36: =SUM(H37:H39) -> 0 | I36: =SUM(I37:I39) -> 0 | J36: =SUM(J37:J39) -> 0 | K36: =SUM(L36:M36) -> #ERROR! | L36: =SUM(L37:L39) -> #ERROR! | M36: =SUM(M37:M39) -> #ERROR!
B37: 농산물 | C37: =D37+K37 -> #ERROR! | D37: =SUM(E37:J37) -> 648042030 | E37: =SUMIFS('①농산물raw'!$G$6:$G$445,'①농산물raw'!$A$6:$A$445,E$35,'①농산물raw'!$B$6:$B$445,$B37) -> 0 | F37: =SUMIFS('①농산물raw'!$G$6:$G$445,'①농산물raw'!$A$6:$A$445,F$35,'①농산물raw'!$B$6:$B$445,$B37) -> 597566830 | G37: =SUMIFS('①농산물raw'!$G$6:$G$445,'①농산물raw'!$A$6:$A$445,G$35,'①농산물raw'!$B$6:$B$445,$B37) -> 50475200 | H37: =SUMIFS('①농산물raw'!$G$6:$G$445,'①농산물raw'!$A$6:$A$445,H$35,'①농산물raw'!$B$6:$B$445,$B37) -> 0 | I37: =SUMIFS('①농산물raw'!$G$6:$G$445,'①농산물raw'!$A$6:$A$445,I$35,'①농산물raw'!$B$6:$B$445,$B37) -> 0 | J37: =SUMIFS('①농산물raw'!$G$6:$G$445,'①농산물raw'!$A$6:$A$445,J$35,'①농산물raw'!$B$6:$B$445,$B37) -> 0 | K37: =SUM(L37:M37) -> #ERROR! | L37: =SUMIFS(②유기농raw!#REF!,②유기농raw!#REF!,L$35,②유기농raw!#REF!,$B37) -> #ERROR! | M37: =SUMIFS(②유기농raw!#REF!,②유기농raw!#REF!,M$35,②유기농raw!#REF!,$B37) -> #ERROR!
B38: 축산물 | C38: =D38+K38 -> #ERROR! | D38: =SUM(E38:J38) -> 154808000 | E38: =SUMIFS('①농산물raw'!$G$6:$G$445,'①농산물raw'!$A$6:$A$445,E$35,'①농산물raw'!$B$6:$B$445,$B38) -> 0 | F38: =SUMIFS('①농산물raw'!$G$6:$G$445,'①농산물raw'!$A$6:$A$445,F$35,'①농산물raw'!$B$6:$B$445,$B38) -> 115183100 | G38: =SUMIFS('①농산물raw'!$G$6:$G$445,'①농산물raw'!$A$6:$A$445,G$35,'①농산물raw'!$B$6:$B$445,$B38) -> 39624900 | H38: =SUMIFS('①농산물raw'!$G$6:$G$445,'①농산물raw'!$A$6:$A$445,H$35,'①농산물raw'!$B$6:$B$445,$B38) -> 0 | I38: =SUMIFS('①농산물raw'!$G$6:$G$445,'①농산물raw'!$A$6:$A$445,I$35,'①농산물raw'!$B$6:$B$445,$B38) -> 0 | J38: =SUMIFS('①농산물raw'!$G$6:$G$445,'①농산물raw'!$A$6:$A$445,J$35,'①농산물raw'!$B$6:$B$445,$B38) -> 0 | K38: =SUM(L38:M38) -> #ERROR! | L38: =SUMIFS(②유기농raw!#REF!,②유기농raw!#REF!,L$35,②유기농raw!#REF!,$B38) -> #ERROR! | M38: =SUMIFS(②유기농raw!#REF!,②유기농raw!#REF!,M$35,②유기농raw!#REF!,$B38) -> #ERROR!
B39: 가공식품 | C39: =D39+K39 -> #ERROR! | D39: =SUM(E39:J39) -> 677599340 | E39: =SUMIFS('①농산물raw'!$G$6:$G$445,'①농산물raw'!$A$6:$A$445,E$35,'①농산물raw'!$B$6:$B$445,$B39) -> 0 | F39: =SUMIFS('①농산물raw'!$G$6:$G$445,'①농산물raw'!$A$6:$A$445,F$35,'①농산물raw'!$B$6:$B$445,$B39) -> 635690840 | G39: =SUMIFS('①농산물raw'!$G$6:$G$445,'①농산물raw'!$A$6:$A$445,G$35,'①농산물raw'!$B$6:$B$445,$B39) -> 41908500 | H39: =SUMIFS('①농산물raw'!$G$6:$G$445,'①농산물raw'!$A$6:$A$445,H$35,'①농산물raw'!$B$6:$B$445,$B39) -> 0 | I39: =SUMIFS('①농산물raw'!$G$6:$G$445,'①농산물raw'!$A$6:$A$445,I$35,'①농산물raw'!$B$6:$B$445,$B39) -> 0 | J39: =SUMIFS('①농산물raw'!$G$6:$G$445,'①농산물raw'!$A$6:$A$445,J$35,'①농산물raw'!$B$6:$B$445,$B39) -> 0 | K39: =SUM(L39:M39) -> #ERROR! | L39: =SUMIFS(②유기농raw!#REF!,②유기농raw!#REF!,L$35,②유기농raw!#REF!,$B39) -> #ERROR! | M39: =SUMIFS(②유기농raw!#REF!,②유기농raw!#REF!,M$35,②유기농raw!#REF!,$B39) -> #ERROR!
B41: 7. 유통사별 품목별 판매 건수
B42: 구분 | C42: 총 계 | D42: 농부가바로팜 | K42: 친환경
D43: 소 계 | E43: 네이버 | F43: 지마켓 | G43: 롯데ON | H43: 온누리마켓 | I43: 농가살리기 | J43: 오아시스 | K43: 소 계 | L43: 네이버 | M43: 오아시스
B44: 총 계 | C44: =D44+K44 -> #ERROR! | D44: =SUM(E44:J44) -> 73605 | E44: =SUM(E45:E47) -> 0 | F44: =SUM(F45:F47) -> 68093 | G44: =SUM(G45:G47) -> 5512 | H44: =SUM(H45:H47) -> 0 | I44: =SUM(I45:I47) -> 0 | J44: =SUM(J45:J47) -> 0 | K44: =SUM(L44:M44) -> #ERROR! | L44: =SUM(L45:L47) -> #ERROR! | M44: =SUM(M45:M47) -> #ERROR!
B45: 농산물 | C45: =D45+K45 -> #ERROR! | D45: =SUM(E45:J45) -> 29436 | E45: =SUMIFS('①농산물raw'!$F$6:$F$445,'①농산물raw'!$A$6:$A$445,E$43,'①농산물raw'!$B$6:$B$445,$B45) -> 0 | F45: =SUMIFS('①농산물raw'!$F$6:$F$445,'①농산물raw'!$A$6:$A$445,F$43,'①농산물raw'!$B$6:$B$445,$B45) -> 26688 | G45: =SUMIFS('①농산물raw'!$F$6:$F$445,'①농산물raw'!$A$6:$A$445,G$43,'①농산물raw'!$B$6:$B$445,$B45) -> 2748 | H45: =SUMIFS('①농산물raw'!$F$6:$F$445,'①농산물raw'!$A$6:$A$445,H$43,'①농산물raw'!$B$6:$B$445,$B45) -> 0 | I45: =SUMIFS('①농산물raw'!$F$6:$F$445,'①농산물raw'!$A$6:$A$445,I$43,'①농산물raw'!$B$6:$B$445,$B45) -> 0 | J45: =SUMIFS('①농산물raw'!$F$6:$F$445,'①농산물raw'!$A$6:$A$445,J$43,'①농산물raw'!$B$6:$B$445,$B45) -> 0 | K45: =SUM(L45:M45) -> #ERROR! | L45: =SUMIFS(②유기농raw!#REF!,②유기농raw!#REF!,L$43,②유기농raw!#REF!,$B45) -> #ERROR! | M45: =SUMIFS(②유기농raw!#REF!,②유기농raw!#REF!,M$43,②유기농raw!#REF!,$B45) -> #ERROR!
B46: 축산물 | C46: =D46+K46 -> #ERROR! | D46: =SUM(E46:J46) -> 5469 | E46: =SUMIFS('①농산물raw'!$F$6:$F$445,'①농산물raw'!$A$6:$A$445,E$43,'①농산물raw'!$B$6:$B$445,$B46) -> 0 | F46: =SUMIFS('①농산물raw'!$F$6:$F$445,'①농산물raw'!$A$6:$A$445,F$43,'①농산물raw'!$B$6:$B$445,$B46) -> 4664 | G46: =SUMIFS('①농산물raw'!$F$6:$F$445,'①농산물raw'!$A$6:$A$445,G$43,'①농산물raw'!$B$6:$B$445,$B46) -> 805 | H46: =SUMIFS('①농산물raw'!$F$6:$F$445,'①농산물raw'!$A$6:$A$445,H$43,'①농산물raw'!$B$6:$B$445,$B46) -> 0 | I46: =SUMIFS('①농산물raw'!$F$6:$F$445,'①농산물raw'!$A$6:$A$445,I$43,'①농산물raw'!$B$6:$B$445,$B46) -> 0 | J46: =SUMIFS('①농산물raw'!$F$6:$F$445,'①농산물raw'!$A$6:$A$445,J$43,'①농산물raw'!$B$6:$B$445,$B46) -> 0 | K46: =SUM(L46:M46) -> #ERROR! | L46: =SUMIFS(②유기농raw!#REF!,②유기농raw!#REF!,L$43,②유기농raw!#REF!,$B46) -> #ERROR! | M46: =SUMIFS(②유기농raw!#REF!,②유기농raw!#REF!,M$43,②유기농raw!#REF!,$B46) -> #ERROR!
B47: 가공식품 | C47: =D47+K47 -> #ERROR! | D47: =SUM(E47:J47) -> 38700 | E47: =SUMIFS('①농산물raw'!$F$6:$F$445,'①농산물raw'!$A$6:$A$445,E$43,'①농산물raw'!$B$6:$B$445,$B47) -> 0 | F47: =SUMIFS('①농산물raw'!$F$6:$F$445,'①농산물raw'!$A$6:$A$445,F$43,'①농산물raw'!$B$6:$B$445,$B47) -> 36741 | G47: =SUMIFS('①농산물raw'!$F$6:$F$445,'①농산물raw'!$A$6:$A$445,G$43,'①농산물raw'!$B$6:$B$445,$B47) -> 1959 | H47: =SUMIFS('①농산물raw'!$F$6:$F$445,'①농산물raw'!$A$6:$A$445,H$43,'①농산물raw'!$B$6:$B$445,$B47) -> 0 | I47: =SUMIFS('①농산물raw'!$F$6:$F$445,'①농산물raw'!$A$6:$A$445,I$43,'①농산물raw'!$B$6:$B$445,$B47) -> 0 | J47: =SUMIFS('①농산물raw'!$F$6:$F$445,'①농산물raw'!$A$6:$A$445,J$43,'①농산물raw'!$B$6:$B$445,$B47) -> 0 | K47: =SUM(L47:M47) -> #ERROR! | L47: =SUMIFS(②유기농raw!#REF!,②유기농raw!#REF!,L$43,②유기농raw!#REF!,$B47) -> #ERROR! | M47: =SUMIFS(②유기농raw!#REF!,②유기농raw!#REF!,M$43,②유기농raw!#REF!,$B47) -> #ERROR!
...

Sheet 농산물업체
F1: =SUM(F3:F287) -> 475218 | G1: =SUM(G3:G287) -> 6227333500 | H1: =SUM(H3:H287) -> 266369319 | I1: =COUNTIF(I3:I500,"O") -> 186
A2: NO | B2: 구분 | C2: 사업자등록번호 | D2: 업체명 | E2: 배정유통사 | F2: 판매건수 | G2: 매출액 | H2: 판촉액 | I2: 7월 실제 인입
A3: 1 | B3: 도약 | C3: 511-87-00286 | D3: 농업회사법인 영주마실(주) | E3: 롯데온 | F3: =SUMIF('①농산물raw'!$D:$D,$C3,'①농산물raw'!$F:$F) -> 0 | G3: =SUMIF('①농산물raw'!$D:$D,$C3,'①농산물raw'!$G:$G) -> 0 | H3: =SUMIF('①농산물raw'!$D:$D,$C3,'①농산물raw'!$H:$H) -> 0
A4: 2 | B4: 도약 | C4: 302-81-25814 | D4: 영동감협동조합 | E4: 롯데온 | F4: =SUMIF('①농산물raw'!$D:$D,$C4,'①농산물raw'!$F:$F) -> 8 | G4: =SUMIF('①농산물raw'!$D:$D,$C4,'①농산물raw'!$G:$G) -> 316300 | H4: =SUMIF('①농산물raw'!$D:$D,$C4,'①농산물raw'!$H:$H) -> 46330 | I4: O
A5: 3 | B5: 도약 | C5: 449-92-01723 | D5: 채씨네표고농원 | E5: 네이버 | F5: =SUMIF('①농산물raw'!$D:$D,$C5,'①농산물raw'!$F:$F) -> 130 | G5: =SUMIF('①농산물raw'!$D:$D,$C5,'①농산물raw'!$G:$G) -> 4155000 | H5: =SUMIF('①농산물raw'!$D:$D,$C5,'①농산물raw'!$H:$H) -> 346200 | I5: O
A6: 4 | B6: 시작 | C6: 406-82-02051 | D6: 구천동농업협동조합 | E6: 네이버 | F6: =SUMIF('①농산물raw'!$D:$D,$C6,'①농산물raw'!$F:$F) -> 0 | G6: =SUMIF('①농산물raw'!$D:$D,$C6,'①농산물raw'!$G:$G) -> 0 | H6: =SUMIF('①농산물raw'!$D:$D,$C6,'①농산물raw'!$H:$H) -> 0
A7: 5 | B7: 성장 | C7: 529-44-01222 | D7: 나뚜라리농원 | E7: 네이버 | F7: =SUMIF('①농산물raw'!$D:$D,$C7,'①농산물raw'!$F:$F) -> 124 | G7: =SUMIF('①농산물raw'!$D:$D,$C7,'①농산물raw'!$G:$G) -> 5319400 | H7: =SUMIF('①농산물raw'!$D:$D,$C7,'①농산물raw'!$H:$H) -> 477360 | I7: O
A8: 6 | B8: 도약 | C8: 416-81-92591 | D8: 좋은세상협동조합 | E8: 롯데온 | F8: =SUMIF('①농산물raw'!$D:$D,$C8,'①농산물raw'!$F:$F) -> 0 | G8: =SUMIF('①농산물raw'!$D:$D,$C8,'①농산물raw'!$G:$G) -> 0 | H8: =SUMIF('①농산물raw'!$D:$D,$C8,'①농산물raw'!$H:$H) -> 0
A9: 7 | B9: 도약 | C9: 516-88-01860 | D9: 주식회사 농업회사법인 에상스팜 | E9: 롯데온 | F9: =SUMIF('①농산물raw'!$D:$D,$C9,'①농산물raw'!$F:$F) -> 1999 | G9: =SUMIF('①농산물raw'!$D:$D,$C9,'①농산물raw'!$G:$G) -> 23281100 | H9: =SUMIF('①농산물raw'!$D:$D,$C9,'①농산물raw'!$H:$H) -> 4157060 | I9: O
A10: 8 | B10: 시작 | C10: 709-22-01767 | D10: 푸드상상 | E10: 롯데온 | F10: =SUMIF('①농산물raw'!$D:$D,$C10,'①농산물raw'!$F:$F) -> 0 | G10: =SUMIF('①농산물raw'!$D:$D,$C10,'①농산물raw'!$G:$G) -> 0 | H10: =SUMIF('①농산물raw'!$D:$D,$C10,'①농산물raw'!$H:$H) -> 0
A11: 9 | B11: 시작 | C11: 104-12-14323 | D11: 교동앵무새힐링농장 | E11: 네이버 | F11: =SUMIF('①농산물raw'!$D:$D,$C11,'①농산물raw'!$F:$F) -> 0 | G11: =SUMIF('①농산물raw'!$D:$D,$C11,'①농산물raw'!$G:$G) -> 0 | H11: =SUMIF('①농산물raw'!$D:$D,$C11,'①농산물raw'!$H:$H) -> 0
A12: 10 | B12: 도약 | C12: 514-03-53195 | D12: 삼진식품 | E12: 롯데온 | F12: =SUMIF('①농산물raw'!$D:$D,$C12,'①농산물raw'!$F:$F) -> 0 | G12: =SUMIF('①농산물raw'!$D:$D,$C12,'①농산물raw'!$G:$G) -> 0 | H12: =SUMIF('①농산물raw'!$D:$D,$C12,'①농산물raw'!$H:$H) -> 0
A13: 11 | B13: 도약 | C13: 892-87-01864 | D13: 주식회사 마들 | E13: 지마켓 | F13: =SUMIF('①농산물raw'!$D:$D,$C13,'①농산물raw'!$F:$F) -> 253 | G13: =SUMIF('①농산물raw'!$D:$D,$C13,'①농산물raw'!$G:$G) -> 5220720 | H13: =SUMIF('①농산물raw'!$D:$D,$C13,'①농산물raw'!$H:$H) -> 278100 | I13: O
A14: 12 | B14: 도약 | C14: 803-88-01105 | D14: 오고농원(주) | E14: 네이버 | F14: =SUMIF('①농산물raw'!$D:$D,$C14,'①농산물raw'!$F:$F) -> 702 | G14: =SUMIF('①농산물raw'!$D:$D,$C14,'①농산물raw'!$G:$G) -> 31950500 | H14: =SUMIF('①농산물raw'!$D:$D,$C14,'①농산물raw'!$H:$H) -> 2604620 | I14: O
A15: 13 | B15: 도약 | C15: 488-88-03205 | D15: 농업회사법인 랑이네세상 주식회사 | E15: 네이버 | F15: =SUMIF('①농산물raw'!$D:$D,$C15,'①농산물raw'!$F:$F) -> 2007 | G15: =SUMIF('①농산물raw'!$D:$D,$C15,'①농산물raw'!$G:$G) -> 74676000 | H15: =SUMIF('①농산물raw'!$D:$D,$C15,'①농산물raw'!$H:$H) -> 4947920 | I15: O
A16: 14 | B16: 성장 | C16: 784-24-00666 | D16: 거창오미자 | E16: 네이버 | F16: =SUMIF('①농산물raw'!$D:$D,$C16,'①농산물raw'!$F:$F) -> 480 | G16: =SUMIF('①농산물raw'!$D:$D,$C16,'①농산물raw'!$G:$G) -> 18557000 | H16: =SUMIF('①농산물raw'!$D:$D,$C16,'①농산물raw'!$H:$H) -> 1065800 | I16: O
A17: 15 | B17: 시작 | C17: 888-94-01728 | D17: 파밍데이즈 | E17: 네이버 | F17: =SUMIF('①농산물raw'!$D:$D,$C17,'①농산물raw'!$F:$F) -> 30 | G17: =SUMIF('①농산물raw'!$D:$D,$C17,'①농산물raw'!$G:$G) -> 599700 | H17: =SUMIF('①농산물raw'!$D:$D,$C17,'①농산물raw'!$H:$H) -> 33980 | I17: O
A18: 16 | B18: 도약 | C18: 128-90-57082 | D18: 산골과수원 | E18: 롯데온 | F18: =SUMIF('①농산물raw'!$D:$D,$C18,'①농산물raw'!$F:$F) -> 0 | G18: =SUMIF('①농산물raw'!$D:$D,$C18,'①농산물raw'!$G:$G) -> 0 | H18: =SUMIF('①농산물raw'!$D:$D,$C18,'①농산물raw'!$H:$H) -> 0
A19: 17 | B19: 도약 | C19: 626-86-01993 | D19: 농업회사법인 (주)자연의시간 | E19: 농가살리기 | F19: =SUMIF('①농산물raw'!$D:$D,$C19,'①농산물raw'!$F:$F) -> 856 | G19: =SUMIF('①농산물raw'!$D:$D,$C19,'①농산물raw'!$G:$G) -> 10693525 | H19: =SUMIF('①농산물raw'!$D:$D,$C19,'①농산물raw'!$H:$H) -> 974340 | I19: O
A20: 18 | B20: 성장 | C20: 711-30-00994 | D20: 팜샐러드 | E20: 네이버 | F20: =SUMIF('①농산물raw'!$D:$D,$C20,'①농산물raw'!$F:$F) -> 0 | G20: =SUMIF('①농산물raw'!$D:$D,$C20,'①농산물raw'!$G:$G) -> 0 | H20: =SUMIF('①농산물raw'!$D:$D,$C20,'①농산물raw'!$H:$H) -> 0
A21: 19 | B21: 도약 | C21: 186-96-01664 | D21: 쌍둥이농장 | E21: 지마켓 | F21: =SUMIF('①농산물raw'!$D:$D,$C21,'①농산물raw'!$F:$F) -> 4 | G21: =SUMIF('①농산물raw'!$D:$D,$C21,'①농산물raw'!$G:$G) -> 187600 | H21: =SUMIF('①농산물raw'!$D:$D,$C21,'①농산물raw'!$H:$H) -> 0 | I21: O
A22: 20 | B22: 성장 | C22: 463-93-01691 | D22: 피스팜 | E22: 네이버 | F22: =SUMIF('①농산물raw'!$D:$D,$C22,'①농산물raw'!$F:$F) -> 5 | G22: =SUMIF('①농산물raw'!$D:$D,$C22,'①농산물raw'!$G:$G) -> 240000 | H22: =SUMIF('①농산물raw'!$D:$D,$C22,'①농산물raw'!$H:$H) -> 0 | I22: O
A23: 21 | B23: 시작 | C23: 621-96-06105 | D23: HK팜 | E23: 네이버 | F23: =SUMIF('①농산물raw'!$D:$D,$C23,'①농산물raw'!$F:$F) -> 0 | G23: =SUMIF('①농산물raw'!$D:$D,$C23,'①농산물raw'!$G:$G) -> 0 | H23: =SUMIF('①농산물raw'!$D:$D,$C23,'①농산물raw'!$H:$H) -> 0
A24: 22 | B24: 도약 | C24: 347-93-02082 | D24: 초록이들 | E24: 네이버 | F24: =SUMIF('①농산물raw'!$D:$D,$C24,'①농산물raw'!$F:$F) -> 18065 | G24: =SUMIF('①농산물raw'!$D:$D,$C24,'①농산물raw'!$G:$G) -> 271250400 | H24: =SUMIF('①농산물raw'!$D:$D,$C24,'①농산물raw'!$H:$H) -> 4473530 | I24: O
A25: 23 | B25: 성장 | C25: 408-24-61681 | D25: 한국제다 | E25: 네이버 | F25: =SUMIF('①농산물raw'!$D:$D,$C25,'①농산물raw'!$F:$F) -> 16 | G25: =SUMIF('①농산물raw'!$D:$D,$C25,'①농산물raw'!$G:$G) -> 591000 | H25: =SUMIF('①농산물raw'!$D:$D,$C25,'①농산물raw'!$H:$H) -> 63860 | I25: O
A26: 24 | B26: 도약 | C26: 226-81-48890 | D26: 정선아라리한과농원 영농조합법인 | E26: 롯데온 | F26: =SUMIF('①농산물raw'!$D:$D,$C26,'①농산물raw'!$F:$F) -> 11 | G26: =SUMIF('①농산물raw'!$D:$D,$C26,'①농산물raw'!$G:$G) -> 295400 | H26: =SUMIF('①농산물raw'!$D:$D,$C26,'①농산물raw'!$H:$H) -> 52610 | I26: O
A27: 25 | B27: 도약 | C27: 412-81-24086 | D27: 영흥농산영농조합법인 | E27: 네이버 | F27: =SUMIF('①농산물raw'!$D:$D,$C27,'①농산물raw'!$F:$F) -> 9428 | G27: =SUMIF('①농산물raw'!$D:$D,$C27,'①농산물raw'!$G:$G) -> 143143000 | H27: =SUMIF('①농산물raw'!$D:$D,$C27,'①농산물raw'!$H:$H) -> 5032180
A28: 26 | B28: 도약 | C28: 142-33-00898 | D28: 어이딸부각 | E28: 지마켓 | F28: =SUMIF('①농산물raw'!$D:$D,$C28,'①농산물raw'!$F:$F) -> 30 | G28: =SUMIF('①농산물raw'!$D:$D,$C28,'①농산물raw'!$G:$G) -> 690000 | H28: =SUMIF('①농산물raw'!$D:$D,$C28,'①농산물raw'!$H:$H) -> 10000 | I28: O
A29: 27 | B29: 도약 | C29: 144-92-00528 | D29: 햇터농장 | E29: 네이버 | F29: =SUMIF('①농산물raw'!$D:$D,$C29,'①농산물raw'!$F:$F) -> 0 | G29: =SUMIF('①농산물raw'!$D:$D,$C29,'①농산물raw'!$G:$G) -> 0 | H29: =SUMIF('①농산물raw'!$D:$D,$C29,'①농산물raw'!$H:$H) -> 0
A30: 28 | B30: 시작 | C30: 753-27-02040 | D30: 해피팜 | E30: 네이버 | F30: =SUMIF('①농산물raw'!$D:$D,$C30,'①농산물raw'!$F:$F) -> 14 | G30: =SUMIF('①농산물raw'!$D:$D,$C30,'①농산물raw'!$G:$G) -> 414000 | H30: =SUMIF('①농산물raw'!$D:$D,$C30,'①농산물raw'!$H:$H) -> 46000 | I30: O
A31: 29 | B31: 도약 | C31: 608-88-00253 | D31: 농업회사법인 주식회사 코리아식품 | E31: 네이버 | F31: =SUMIF('①농산물raw'!$D:$D,$C31,'①농산물raw'!$F:$F) -> 16 | G31: =SUMIF('①농산물raw'!$D:$D,$C31,'①농산물raw'!$G:$G) -> 451100 | H31: =SUMIF('①농산물raw'!$D:$D,$C31,'①농산물raw'!$H:$H) -> 34520 | I31: O
A32: 30 | B32: 도약 | C32: 201-98-68634 | D32: 아침에계란 | E32: 네이버 | F32: =SUMIF('①농산물raw'!$D:$D,$C32,'①농산물raw'!$F:$F) -> 1319 | G32: =SUMIF('①농산물raw'!$D:$D,$C32,'①농산물raw'!$G:$G) -> 92623400 | H32: =SUMIF('①농산물raw'!$D:$D,$C32,'①농산물raw'!$H:$H) -> 4710400 | I32: O
A33: 31 | B33: 도약 | C33: 540-93-02100 | D33: 청운유통 | E33: 네이버 | F33: =SUMIF('①농산물raw'!$D:$D,$C33,'①농산물raw'!$F:$F) -> 4527 | G33: =SUMIF('①농산물raw'!$D:$D,$C33,'①농산물raw'!$G:$G) -> 129056500 | H33: =SUMIF('①농산물raw'!$D:$D,$C33,'①농산물raw'!$H:$H) -> 4577170 | I33: O
A34: 32 | B34: 성장 | C34: 116-81-80195 | D34: 유한회사 못골농업회사 | E34: 네이버 | F34: =SUMIF('①농산물raw'!$D:$D,$C34,'①농산물raw'!$F:$F) -> 167 | G34: =SUMIF('①농산물raw'!$D:$D,$C34,'①농산물raw'!$G:$G) -> 5636300 | H34: =SUMIF('①농산물raw'!$D:$D,$C34,'①농산물raw'!$H:$H) -> 531110 | I34: O
A35: 33 | B35: 시작 | C35: 208-22-52837 | D35: 소유농장 | E35: 네이버 | F35: =SUMIF('①농산물raw'!$D:$D,$C35,'①농산물raw'!$F:$F) -> 31 | G35: =SUMIF('①농산물raw'!$D:$D,$C35,'①농산물raw'!$G:$G) -> 1695000 | H35: =SUMIF('①농산물raw'!$D:$D,$C35,'①농산물raw'!$H:$H) -> 121330 | I35: O
A36: 34 | B36: 도약 | C36: 412-90-50529 | D36: 행운가족농원 | E36: 네이버 | F36: =SUMIF('①농산물raw'!$D:$D,$C36,'①농산물raw'!$F:$F) -> 0 | G36: =SUMIF('①농산물raw'!$D:$D,$C36,'①농산물raw'!$G:$G) -> 0 | H36: =SUMIF('①농산물raw'!$D:$D,$C36,'①농산물raw'!$H:$H) -> 0
A37: 35 | B37: 도약 | C37: 571-81-00383 | D37: 농부플러스 농업회사법인 주식회사 | E37: 지마켓 | F37: =SUMIF('①농산물raw'!$D:$D,$C37,'①농산물raw'!$F:$F) -> 1222 | G37: =SUMIF('①농산물raw'!$D:$D,$C37,'①농산물raw'!$G:$G) -> 36507100 | H37: =SUMIF('①농산물raw'!$D:$D,$C37,'①농산물raw'!$H:$H) -> 694580 | I37: O
A38: 36 | B38: 도약 | C38: 715-87-02493 | D38: 농업회삽법인 라이플로우 주식회사 | E38: 롯데온 | F38: =SUMIF('①농산물raw'!$D:$D,$C38,'①농산물raw'!$F:$F) -> 76 | G38: =SUMIF('①농산물raw'!$D:$D,$C38,'①농산물raw'!$G:$G) -> 2312900 | H38: =SUMIF('①농산물raw'!$D:$D,$C38,'①농산물raw'!$H:$H) -> 434680 | I38: O
A39: 37 | B39: 도약 | C39: 191-97-01154 | D39: 파머레시피 | E39: 롯데온 | F39: =SUMIF('①농산물raw'!$D:$D,$C39,'①농산물raw'!$F:$F) -> 265 | G39: =SUMIF('①농산물raw'!$D:$D,$C39,'①농산물raw'!$G:$G) -> 12912030 | H39: =SUMIF('①농산물raw'!$D:$D,$C39,'①농산물raw'!$H:$H) -> 1332970 | I39: O
A40: 38 | B40: 성장 | C40: 792-88-00316 | D40: 농업회사법인(주)새나라 | E40: 네이버 | F40: =SUMIF('①농산물raw'!$D:$D,$C40,'①농산물raw'!$F:$F) -> 594 | G40: =SUMIF('①농산물raw'!$D:$D,$C40,'①농산물raw'!$G:$G) -> 19348530 | H40: =SUMIF('①농산물raw'!$D:$D,$C40,'①농산물raw'!$H:$H) -> 2220230 | I40: O
...

Sheet ①농산물raw
A1: 2026 aT 농산물 온라인 마케터 업체 별 매출 보고
A2: 기간 : 07월 06일 ~ 08월 31일
A4: 합계 | F4: =SUM(F6:F1397) -> 441191 | G4: =SUM(G6:G1397) -> 5428800390 | H4: =SUM(H6:H1397) -> 257635009
A5: 유통사명 | B5: 품목분류 | C5: 사업자명 | D5: 사업자번호 | E5: 상품명 | F5: 판매 건수 | G5: 매출액 | H5: 판촉액
A6: 지마켓 | B6: 가공식품 | C6: 주식회사 마들 | D6: 892-87-01864 | E6: 춘천 닭갈비 오리지널 1kg 국내산 닭다리살(닭다리살 함량 85%) | F6: 253 | G6: 5220720 | H6: 278100
A7: 지마켓 | B7: 가공식품 | C7: 쌍둥이농장 | D7: 186-96-01664 | E7: 산지직송 하미과메론 양구메론 경북고령 고당도 그린하미과 골드하미과3kg 5kg | F7: 4 | G7: 187600 | H7: 0
A8: 지마켓 | B8: 가공식품 | C8: 조양식품 | D8: 579-90-00021 | E8: (신선집중/15%+NH10%) 한상궁김치 겉절이 2kg / 출고당일생산 | F8: 21744 | G8: 287536270 | H8: 6140240
A9: 지마켓 | B9: 농산물 | C9: 농업회사법인머쉬그로(주) | D9: 113-87-00743 | E9: 최상등급품질 양송이버섯 1kg 2kg 산지직송 오후2시당일출고 무료배송 직접재배 산지직송 최대할인가 | F9: 26 | G9: 621000 | H9: 57600
A10: 지마켓 | B10: 농산물 | C10: 농업회사법인머쉬그로(주) | D10: 113-87-00743 | E10: 양송이 마이스터 재배 화이트 양송이버섯 못난이 꼬다마 구이용 피자용 매장사용 소포장 스프용 1kg 2kg | F10: 32 | G10: 480900 | H10: 27500
A11: 지마켓 | B11: 축산물 | C11: 두원식품(주) | D11: 606-81-52718 | E11: (신선집중) 국내산 한돈 프리미엄 대패 삼겹살 1.2kg | F11: 2382 | G11: 55053800 | H11: 4893300
A12: 지마켓 | B12: 축산물 | C12: 두원식품(주) | D12: 606-81-52718 | E12: 국내산 한돈 칼집 고추장 삼겹살 300g + 300g | F12: 3 | G12: 44700 | H12: 0
A13: 지마켓 | B13: 축산물 | C13: 두원식품(주) | D13: 606-81-52718 | E13: (신선집중) 국내산 한돈 한입 옛날 삼겹살 400g + 400g | F13: 100 | G13: 1718300 | H13: 134180
A14: 지마켓 | B14: 축산물 | C14: 두원식품(주) | D14: 606-81-52718 | E14: haccp인증 국내산 한돈 간장 LA돼지갈비 300g+300g | F14: 10 | G14: 137000 | H14: 8940
A15: 지마켓 | B15: 축산물 | C15: 두원식품(주) | D15: 606-81-52718 | E15: 국내산 한돈 프리미엄 대패 삼겹살 400g + 400g | F15: 9 | G15: 162100 | H15: 7560
A16: 지마켓 | B16: 축산물 | C16: 두원식품(주) | D16: 606-81-52718 | E16: haccp인증 국내산 한돈 고추장 주물럭 300g x6팩(총 1.8kg) | F16: 2 | G16: 65000 | H16: 6500
A17: 지마켓 | B17: 축산물 | C17: 두원식품(주) | D17: 606-81-52718 | E17: 국내산 한돈 고추장 주물럭 300g + 300g 제육볶음 | F17: 11 | G17: 157900 | H17: 11920
... A1454: 네이버 | B1454: 농산물 | C1454: 참외쀼 | D1454: 210-97-02245 | E1454: 농부부부가 키운 고당도 성주 참외 당일수확 5.5kg | F1454: 1 | G1454: 35000 | H1454: 0

Sheet 유기농업체
F1: =SUM(F3:F57) -> 280907 | G1: =SUM(G3:G57) -> 1453132570 | H1: =SUM(H3:H57) -> 44341569 | I1: 32
A2: NO | B2: 구분 | C2: 사업자등록번호 | D2: 업체명 | E2: 배정유통사 | F2: 판매건수 | G2: 매출액 | H2: 판촉액 | I2: 7월 실제 인입
A3: 1 | B3: 도약 | C3: 218-86-00721 | D3: 주식회사 아인스 | E3: 오아시스 | F3: =SUMIF('②유기농raw'!$D:$D,$C3,'②유기농raw'!$F:$F) -> 27317 | G3: =SUMIF('②유기농raw'!$D:$D,$C3,'②유기농raw'!$G:$G) -> 172019750 | H3: =SUMIF('②유기농raw'!$D:$D,$C3,'②유기농raw'!$H:$H) -> 2012484 | I3: O
A4: 2 | B4: 도약 | C4: 225-90-26954 | D4: 풀무리농장 | E4: 네이버 | F4: =SUMIF('②유기농raw'!$D:$D,$C4,'②유기농raw'!$F:$F) -> 423 | G4: =SUMIF('②유기농raw'!$D:$D,$C4,'②유기농raw'!$G:$G) -> 15579700 | H4: =SUMIF('②유기농raw'!$D:$D,$C4,'②유기농raw'!$H:$H) -> 1852660 | I4: O
A5: 3 | B5: 시작 | C5: 326-37-00548 | D5: 파미농원 | E5: 오아시스 | F5: =SUMIF('②유기농raw'!$D:$D,$C5,'②유기농raw'!$F:$F) -> 1 | G5: =SUMIF('②유기농raw'!$D:$D,$C5,'②유기농raw'!$G:$G) -> 14400 | H5: =SUMIF('②유기농raw'!$D:$D,$C5,'②유기농raw'!$H:$H) -> 2880
A6: 4 | B6: 시작 | C6: 497-41-01341 | D6: 국가대표상황버섯 | E6: 오아시스 | F6: =SUMIF('②유기농raw'!$D:$D,$C6,'②유기농raw'!$F:$F) -> 0 | G6: =SUMIF('②유기농raw'!$D:$D,$C6,'②유기농raw'!$G:$G) -> 0 | H6: =SUMIF('②유기농raw'!$D:$D,$C6,'②유기농raw'!$H:$H) -> 0
A7: 5 | B7: 성장 | C7: 312-27-45552 | D7: 바우뜨락 | E7: 오아시스 | F7: =SUMIF('②유기농raw'!$D:$D,$C7,'②유기농raw'!$F:$F) -> 44 | G7: =SUMIF('②유기농raw'!$D:$D,$C7,'②유기농raw'!$G:$G) -> 1787000 | H7: =SUMIF('②유기농raw'!$D:$D,$C7,'②유기농raw'!$H:$H) -> 155200 | I7: O
A8: 6 | B8: 도약 | C8: 201-86-47960 | D8: 다온365농업회사법인(주) | E8: 오아시스 | F8: =SUMIF('②유기농raw'!$D:$D,$C8,'②유기농raw'!$F:$F) -> 0 | G8: =SUMIF('②유기농raw'!$D:$D,$C8,'②유기농raw'!$G:$G) -> 0 | H8: =SUMIF('②유기농raw'!$D:$D,$C8,'②유기농raw'!$H:$H) -> 0
A9: 7 | B9: 도약 | C9: 410-86-90042 | D9: 아름답게그린배영농조합법인 | E9: 네이버 | F9: =SUMIF('②유기농raw'!$D:$D,$C9,'②유기농raw'!$F:$F) -> 40 | G9: =SUMIF('②유기농raw'!$D:$D,$C9,'②유기농raw'!$G:$G) -> 1322500 | H9: =SUMIF('②유기농raw'!$D:$D,$C9,'②유기농raw'!$H:$H) -> 207680 | I9: O
A10: 8 | B10: 시작 | C10: 512-13-21395 | D10: 현재농원 | E10: 네이버 | F10: =SUMIF('②유기농raw'!$D:$D,$C10,'②유기농raw'!$F:$F) -> 8 | G10: =SUMIF('②유기농raw'!$D:$D,$C10,'②유기농raw'!$G:$G) -> 168650 | H10: =SUMIF('②유기농raw'!$D:$D,$C10,'②유기농raw'!$H:$H) -> 24730 | I10: O
A11: 9 | B11: 도약 | C11: 745-96-00315 | D11: 해담는집 | E11: 오아시스 | F11: =SUMIF('②유기농raw'!$D:$D,$C11,'②유기농raw'!$F:$F) -> 68 | G11: =SUMIF('②유기농raw'!$D:$D,$C11,'②유기농raw'!$G:$G) -> 1101800 | H11: =SUMIF('②유기농raw'!$D:$D,$C11,'②유기농raw'!$H:$H) -> 115480 | I11: O
A12: 10 | B12: 도약 | C12: 386-96-00703 | D12: 여화원 | E12: 네이버 | F12: =SUMIF('②유기농raw'!$D:$D,$C12,'②유기농raw'!$F:$F) -> 287 | G12: =SUMIF('②유기농raw'!$D:$D,$C12,'②유기농raw'!$G:$G) -> 9430500 | H12: =SUMIF('②유기농raw'!$D:$D,$C12,'②유기농raw'!$H:$H) -> 1015420 | I12: O
A13: 11 | B13: 도약 | C13: 409-86-48791 | D13: 주식회사 유기농샵에프앤비 | E13: 오아시스 | F13: =SUMIF('②유기농raw'!$D:$D,$C13,'②유기농raw'!$F:$F) -> 0 | G13: =SUMIF('②유기농raw'!$D:$D,$C13,'②유기농raw'!$G:$G) -> 0 | H13: =SUMIF('②유기농raw'!$D:$D,$C13,'②유기농raw'!$H:$H) -> 0
A14: 12 | B14: 도약 | C14: 556-72-00266 | D14: 제주오가닉스 | E14: 오아시스 | F14: =SUMIF('②유기농raw'!$D:$D,$C14,'②유기농raw'!$F:$F) -> 0 | G14: =SUMIF('②유기농raw'!$D:$D,$C14,'②유기농raw'!$G:$G) -> 0 | H14: =SUMIF('②유기농raw'!$D:$D,$C14,'②유기농raw'!$H:$H) -> 0
A15: 13 | B15: 도약 | C15: 592-08-01799 | D15: 삼둥이농장 | E15: 오아시스 | F15: =SUMIF('②유기농raw'!$D:$D,$C15,'②유기농raw'!$F:$F) -> 0 | G15: =SUMIF('②유기농raw'!$D:$D,$C15,'②유기농raw'!$G:$G) -> 0 | H15: =SUMIF('②유기농raw'!$D:$D,$C15,'②유기농raw'!$H:$H) -> 0
A16: 14 | B16: 도약 | C16: 680-87-00224 | D16: 다원팜농업회사법인유한회사 | E16: 오아시스 | F16: =SUMIF('②유기농raw'!$D:$D,$C16,'②유기농raw'!$F:$F) -> 21696 | G16: =SUMIF('②유기농raw'!$D:$D,$C16,'②유기농raw'!$G:$G) -> 45354130 | H16: =SUMIF('②유기농raw'!$D:$D,$C16,'②유기농raw'!$H:$H) -> 2157497 | I16: O
A17: 15 | B17: 도약 | C17: 402-81-54069 | D17: 참식품주식회사 | E17: 네이버 | F17: =SUMIF('②유기농raw'!$D:$D,$C17,'②유기농raw'!$F:$F) -> 547 | G17: =SUMIF('②유기농raw'!$D:$D,$C17,'②유기농raw'!$G:$G) -> 14845800 | H17: =SUMIF('②유기농raw'!$D:$D,$C17,'②유기농raw'!$H:$H) -> 1669930 | I17: O
A18: 16 | B18: 시작 | C18: 252-86-02831 | D18: 농업회사법인주식회사한내담 | E18: 오아시스 | F18: =SUMIF('②유기농raw'!$D:$D,$C18,'②유기농raw'!$F:$F) -> 0 | G18: =SUMIF('②유기농raw'!$D:$D,$C18,'②유기농raw'!$G:$G) -> 0 | H18: =SUMIF('②유기농raw'!$D:$D,$C18,'②유기농raw'!$H:$H) -> 0
A19: 17 | B19: 성장 | C19: 566-81-02884 | D19: 농업회사법인 주식회사 여주능서농원 | E19: 네이버 | F19: =SUMIF('②유기농raw'!$D:$D,$C19,'②유기농raw'!$F:$F) -> 258 | G19: =SUMIF('②유기농raw'!$D:$D,$C19,'②유기농raw'!$G:$G) -> 5728190 | H19: =SUMIF('②유기농raw'!$D:$D,$C19,'②유기농raw'!$H:$H) -> 669670 | I19: O
A20: 18 | B20: 도약 | C20: 580-88-02822 | D20: 농업회사법인 나무컴퍼니 주식회사 | E20: 네이버 | F20: =SUMIF('②유기농raw'!$D:$D,$C20,'②유기농raw'!$F:$F) -> 4513 | G20: =SUMIF('②유기농raw'!$D:$D,$C20,'②유기농raw'!$G:$G) -> 81437410 | H20: =SUMIF('②유기농raw'!$D:$D,$C20,'②유기농raw'!$H:$H) -> 4726320 | I20: O
A21: 19 | B21: 시작 | C21: 815-15-01628 | D21: 뭇별농장 | E21: 네이버 | F21: =SUMIF('②유기농raw'!$D:$D,$C21,'②유기농raw'!$F:$F) -> 0 | G21: =SUMIF('②유기농raw'!$D:$D,$C21,'②유기농raw'!$G:$G) -> 0 | H21: =SUMIF('②유기농raw'!$D:$D,$C21,'②유기농raw'!$H:$H) -> 0
A22: 20 | B22: 도약 | C22: 502-81-55602 | D22: 농업법인회사 (주)초록원 | E22: 오아시스 | F22: =SUMIF('②유기농raw'!$D:$D,$C22,'②유기농raw'!$F:$F) -> 4106 | G22: =SUMIF('②유기농raw'!$D:$D,$C22,'②유기농raw'!$G:$G) -> 44964220 | H22: =SUMIF('②유기농raw'!$D:$D,$C22,'②유기농raw'!$H:$H) -> 1981384 | I22: O
A23: 21 | B23: 도약 | C23: 654-88-01503 | D23: (주)밀알케이 | E23: 오아시스 | F23: =SUMIF('②유기농raw'!$D:$D,$C23,'②유기농raw'!$F:$F) -> 1567 | G23: =SUMIF('②유기농raw'!$D:$D,$C23,'②유기농raw'!$G:$G) -> 7314600 | H23: =SUMIF('②유기농raw'!$D:$D,$C23,'②유기농raw'!$H:$H) -> 353700 | I23: O
A24: 22 | B24: 도약 | C24: 774-11-01498 | D24: 경성표고버섯농장 | E24: 네이버 | F24: =SUMIF('②유기농raw'!$D:$D,$C24,'②유기농raw'!$F:$F) -> 283 | G24: =SUMIF('②유기농raw'!$D:$D,$C24,'②유기농raw'!$G:$G) -> 5837350 | H24: =SUMIF('②유기농raw'!$D:$D,$C24,'②유기농raw'!$H:$H) -> 609310 | I24: O
A25: 23 | B25: 도약 | C25: 416-81-44143 | D25: 도울 F&B | E25: 오아시스 | F25: =SUMIF('②유기농raw'!$D:$D,$C25,'②유기농raw'!$F:$F) -> 3243 | G25: =SUMIF('②유기농raw'!$D:$D,$C25,'②유기농raw'!$G:$G) -> 7528400 | H25: =SUMIF('②유기농raw'!$D:$D,$C25,'②유기농raw'!$H:$H) -> 612556 | I25: O
A26: 24 | B26: 도약 | C26: 754-88-00876 | D26: 베리네이처 | E26: 오아시스 | F26: =SUMIF('②유기농raw'!$D:$D,$C26,'②유기농raw'!$F:$F) -> 14326 | G26: =SUMIF('②유기농raw'!$D:$D,$C26,'②유기농raw'!$G:$G) -> 41928380 | H26: =SUMIF('②유기농raw'!$D:$D,$C26,'②유기농raw'!$H:$H) -> 2130483 | I26: O
A27: 25 | B27: 도약 | C27: 507-81-09103 | D27: 나래친환경영농조합법인 | E27: 네이버 | F27: =SUMIF('②유기농raw'!$D:$D,$C27,'②유기농raw'!$F:$F) -> 82 | G27: =SUMIF('②유기농raw'!$D:$D,$C27,'②유기농raw'!$G:$G) -> 4760000 | H27: =SUMIF('②유기농raw'!$D:$D,$C27,'②유기농raw'!$H:$H) -> 720000 | I27: O
A28: 26 | B28: 시작 | C28: 190-97-01151 | D28: 지구별농장 | E28: 네이버 | F28: =SUMIF('②유기농raw'!$D:$D,$C28,'②유기농raw'!$F:$F) -> 0 | G28: =SUMIF('②유기농raw'!$D:$D,$C28,'②유기농raw'!$G:$G) -> 0 | H28: =SUMIF('②유기농raw'!$D:$D,$C28,'②유기농raw'!$H:$H) -> 0
A29: 27 | B29: 성장 | C29: 706-01-03422 | D29: 아침농부 | E29: 네이버 | F29: =SUMIF('②유기농raw'!$D:$D,$C29,'②유기농raw'!$F:$F) -> 520 | G29: =SUMIF('②유기농raw'!$D:$D,$C29,'②유기농raw'!$G:$G) -> 13123000 | H29: =SUMIF('②유기농raw'!$D:$D,$C29,'②유기농raw'!$H:$H) -> 1043580 | I29: O
A30: 28 | B30: 도약 | C30: 761-46-00855 | D30: 코스모스길 옆 상황버 | E30: 네이버 | F30: =SUMIF('②유기농raw'!$D:$D,$C30,'②유기농raw'!$F:$F) -> 0 | G30: =SUMIF('②유기농raw'!$D:$D,$C30,'②유기농raw'!$G:$G) -> 0 | H30: =SUMIF('②유기농raw'!$D:$D,$C30,'②유기농raw'!$H:$H) -> 0
A31: 29 | B31: 성장 | C31: 522-17-00696 | D31: 엿공장 | E31: 오아시스 | F31: =SUMIF('②유기농raw'!$D:$D,$C31,'②유기농raw'!$F:$F) -> 13 | G31: =SUMIF('②유기농raw'!$D:$D,$C31,'②유기농raw'!$G:$G) -> 249500 | H31: =SUMIF('②유기농raw'!$D:$D,$C31,'②유기농raw'!$H:$H) -> 36600 | I31: O
A32: 30 | B32: 도약 | C32: 685-88-00527 | D32: 농업회사법인주식회사다고 | E32: 오아시스 | F32: =SUMIF('②유기농raw'!$D:$D,$C32,'②유기농raw'!$F:$F) -> 37 | G32: =SUMIF('②유기농raw'!$D:$D,$C32,'②유기농raw'!$G:$G) -> 555000 | H32: =SUMIF('②유기농raw'!$D:$D,$C32,'②유기농raw'!$H:$H) -> 103000 | I32: O
A33: 31 | B33: 도약 | C33: 132-81-55005 | D33: 농업회사법인 하늘농가(주) | E33: 오아시스 | F33: =SUMIF('②유기농raw'!$D:$D,$C33,'②유기농raw'!$F:$F) -> 0 | G33: =SUMIF('②유기농raw'!$D:$D,$C33,'②유기농raw'!$G:$G) -> 0 | H33: =SUMIF('②유기농raw'!$D:$D,$C33,'②유기농raw'!$H:$H) -> 0
A34: 32 | B34: 도약 | C34: 515-81-53707 | D34: 농업회사법인 닥터애그 주식회사 | E34: 오아시스 | F34: =SUMIF('②유기농raw'!$D:$D,$C34,'②유기농raw'!$F:$F) -> 162090 | G34: =SUMIF('②유기농raw'!$D:$D,$C34,'②유기농raw'!$G:$G) -> 121036230 | H34: =SUMIF('②유기농raw'!$D:$D,$C34,'②유기농raw'!$H:$H) -> 2211447 | I34: O
A35: 33 | B35: 성장 | C35: 220-88-07925 | D35: 농업회사법인 주식회사 떡찌니 | E35: 네이버 | F35: =SUMIF('②유기농raw'!$D:$D,$C35,'②유기농raw'!$F:$F) -> 0 | G35: =SUMIF('②유기농raw'!$D:$D,$C35,'②유기농raw'!$G:$G) -> 0 | H35: =SUMIF('②유기농raw'!$D:$D,$C35,'②유기농raw'!$H:$H) -> 0
A36: 34 | B36: 도약 | C36: 311-81-44794 | D36: 농업회사법인내포(주) | E36: 오아시스 | F36: =SUMIF('②유기농raw'!$D:$D,$C36,'②유기농raw'!$F:$F) -> 8 | G36: =SUMIF('②유기농raw'!$D:$D,$C36,'②유기농raw'!$G:$G) -> 218000 | H36: =SUMIF('②유기농raw'!$D:$D,$C36,'②유기농raw'!$H:$H) -> 43600 | I36: O
A37: 35 | B37: 성장 | C37: 848-99-01346 | D37: 옥수농원 | E37: 네이버 | F37: =SUMIF('②유기농raw'!$D:$D,$C37,'②유기농raw'!$F:$F) -> 0 | G37: =SUMIF('②유기농raw'!$D:$D,$C37,'②유기농raw'!$G:$G) -> 0 | H37: =SUMIF('②유기농raw'!$D:$D,$C37,'②유기농raw'!$H:$H) -> 0
A38: 36 | B38: 성장 | C38: 829-88-01091 | D38: 스퀘어팜 농업회사법인주식회사 | E38: 오아시스 | F38: =SUMIF('②유기농raw'!$D:$D,$C38,'②유기농raw'!$F:$F) -> 0 | G38: =SUMIF('②유기농raw'!$D:$D,$C38,'②유기농raw'!$G:$G) -> 0 | H38: =SUMIF('②유기농raw'!$D:$D,$C38,'②유기농raw'!$H:$H) -> 0
A39: 37 | B39: 도약 | C39: 126-18-96934 | D39: 굿그레인즈 | E39: 오아시스 | F39: =SUMIF('②유기농raw'!$D:$D,$C39,'②유기농raw'!$F:$F) -> 26055 | G39: =SUMIF('②유기농raw'!$D:$D,$C39,'②유기농raw'!$G:$G) -> 681718500 | H39: =SUMIF('②유기농raw'!$D:$D,$C39,'②유기농raw'!$H:$H) -> 2748795 | I39: O
A40: 38 | B40: 시작 | C40: 109-36-80203 | D40: 내추럴참푸드 | E40: 오아시스 | F40: =SUMIF('②유기농raw'!$D:$D,$C40,'②유기농raw'!$F:$F) -> 544 | G40: =SUMIF('②유기농raw'!$D:$D,$C40,'②유기농raw'!$G:$G) -> 13688860 | H40: =SUMIF('②유기농raw'!$D:$D,$C40,'②유기농raw'!$H:$H) -> 1457959 | I40: O
...

Sheet ②유기농raw
A1: 2026 aT 농산물 온라인 마케터 업체 별 매출 보고
A2: 기간 : 07월 06일 ~ 08월 31일
A4: 합계 | F4: =SUM(F6:F807) -> 280907 | G4: =SUM(G6:G807) -> 1453132570 | H4: =SUM(H6:H807) -> 44341569
A5: 유통사명 | B5: 품목분류 | C5: 사업자명 | D5: 사업자번호 | E5: 상품명 | F5: 판매 건수 | G5: 매출액 | H5: 판촉액
A6: 오아시스 | B6: 가공식품 | C6: 푸르메다 | D6: 142-08-14196 | E6: 우유와함께 제주녹차라떼 | F6: 715 | G6: 4837900 | H6: 534820
A7: 오아시스 | B7: 가공식품 | C7: 푸르메다 | D7: 142-08-14196 | E7: 3초 보리 순아이티 (15입) | F7: 1221 | G7: 7982150 | H7: 850218
A8: 오아시스 | B8: 가공식품 | C8: 푸르메다 | D8: 142-08-14196 | E8: 유기농 제주 말차 ((20g×2입)×1개) | F8: 236 | G8: 4176000 | H8: 442255
A9: 오아시스 | B9: 가공식품 | C9: 해담는집 | D9: 745-96-00315 | E9: 해담는집 유기농 고춧가루 500g/200g(순한맛/보통맛/매운맛) | F9: 11 | G9: 434900 | H9: 45006
A10: 오아시스 | B10: 농산물 | C10: 해담는집 | D10: 745-96-00315 | E10: [해담는집] 유기농 고추씨 500g | F10: 5 | G10: 69500 | H10: 7282
A11: 오아시스 | B11: 농산물 | C11: 해담는집 | D11: 745-96-00315 | E11: [해담는집] 유기농 들깨 500g | F11: 2 | G11: 41800 | H11: 2590
A12: 오아시스 | B12: 가공식품 | C12: 해담는집 | D12: 745-96-00315 | E12: [해담는집]유기농 크러쉬드 레드페퍼 | F12: 41 | G12: 430500 | H12: 46702
A13: 오아시스 | B13: 가공식품 | C13: 해담는집 | D13: 745-96-00315 | E13: 유기농 메리골드 건조차 50g/꽃차/생화/식용꽃 | F13: 9 | G13: 125100 | H13: 13900
A14: 오아시스 | B14: 가공식품 | C14: 주식회사 베리네이처 | D14: 754-88-00876 | E14: 유기농 토핑 야채큐브 다진 비트 45g | F14: 2024 | G14: 4857600 | H14: 269694
A15: 오아시스 | B15: 가공식품 | C15: 주식회사 베리네이처 | D15: 754-88-00876 | E15: 유기농 토핑 야채큐브 다진 양배추 45g | F15: 1290 | G15: 2967000 | H15: 141606
A16: 오아시스 | B16: 가공식품 | C16: 주식회사 베리네이처 | D16: 754-88-00876 | E16: 유기농 토핑 야채큐브 다진 무 45g | F16: 1079 | G16: 2697500 | H16: 121065
A17: 오아시스 | B17: 가공식품 | C17: 주식회사 베리네이처 | D17: 754-88-00876 | E17: 무농약 토핑 야채큐브 다진 근대 45g | F17: 1161 | G17: 3250800 | H17: 168482
... A207: 네이버 | B207: 가공식품 | C207: 땅끝민지맘 | D207: 402-47-64035 | E207: 26년 국내산 해남 민지맘 무농약 작두콩차 270g(90g x 3팩) 선물용 | F207: 8 | G207: 208780 | H207: 0
