Workbook

Sheet 사용법
B2: 📖 사용법 — 이 순서대로만 하시면 됩니다
B3: aT 농산물 온라인 마케터 월별 실적 자동집계 시트 · 2026
B5: STEP 0. 사전 준비 — 처음 한 번만
B6: 0-1. 업체 명단을 먼저 다 등록하세요
B7: [농산물업체] · [유기농업체] 시트에 아래 5개 열만 입력합니다. 나머지 열은 전부 자동으로 채워집니다.
B8: • A 열 NO · B 열 구분(시작/성장/도약) · C 열 사업자등록번호 · D 열 업체명 · E 열 배정유통사
B9: ⚠️ 유통사명은 반드시 「롯데ON」으로 쓰세요 (「롯데온」 ✗). 유통사가 보내주는 RAW 표기에 맞춘 겁니다. B열·E열은 드롭다운이니 골라 쓰시면 됩니다.
B10: 0-2. 쿠폰 배정액을 넣으세요
B11: [설정] 시트의 노란 칸에 유통사별 쿠폰 배정액을 입력합니다. 잔여금액과 소진율이 자동 계산됩니다.
B12: 0-3. 7월 RAW를 넣으세요
B13: → STEP 1과 동일한 방법입니다. (7월 데이터는 이미 넣어뒀습니다.)
B15: STEP 1. 매월 RAW 관리 — 유통사에서 파일을 받으면
... B62: • 시트 이름을 바꾸지 마세요 → 모든 수식이 깨집니다.

Sheet 분석
B1: ※ 전체 기획전 결과
B2: 보고 기준월 | C2: ='설정'!$C$3 -> 8월 | D2: =IF('설정'!$C$3='설정'!$C$4,"","유기농: "&'설정'!$C$4) | E2: ※ 아래 「전체 기획전 결과」는 최신 입력월까지의 누적입니다.
B4: 1. 해당 월 참여 상품 수 및 업체수 (누적)
B5: 구분 | C5: 총 계 | D5: 농부가바로팜 | K5: 친환경
D6: 소 계 | E6: 네이버 | F6: 지마켓 | G6: 롯데ON | H6: 온누리마켓 | I6: 농가살리기 | J6: 오아시스 | K6: 소 계 | L6: 네이버 | M6: 오아시스
B7: 배정업체수 | C7: =IF(COUNT(D7,K7)=0,"",SUM(D7,K7)) -> 340 | D7: =IF(COUNT(E7:J7)=0,"",SUM(E7:J7)) -> 285 | E7: =COUNTIFS('농산물업체'!$E$3:$E$702,E$6) -> 136 | F7: =COUNTIFS('농산물업체'!$E$3:$E$702,F$6) -> 53 | G7: =COUNTIFS('농산물업체'!$E$3:$E$702,G$6) -> 47 | H7: =COUNTIFS('농산물업체'!$E$3:$E$702,H$6) -> 24 | I7: =COUNTIFS('농산물업체'!$E$3:$E$702,I$6) -> 9 | J7: =COUNTIFS('농산물업체'!$E$3:$E$702,J$6) -> 16 | K7: =IF(COUNT(L7:M7)=0,"",SUM(L7:M7)) -> 55 | L7: =COUNTIFS('유기농업체'!$E$3:$E$252,L$6) -> 26 | M7: =COUNTIFS('유기농업체'!$E$3:$E$252,M$6) -> 29
B8: 참여업체수 | C8: =IF(COUNT(D8,K8)=0,"",SUM(D8,K8)) -> 242 | D8: =IF(COUNT(E8:J8)=0,"",SUM(E8:J8)) -> 207 | E8: =COUNTIFS('농산물업체'!$E$3:$E$702,E$6,'농산물업체'!$S$3:$S$702,"O") -> 93 | F8: =COUNTIFS('농산물업체'!$E$3:$E$702,F$6,'농산물업체'!$S$3:$S$702,"O") -> 41 | G8: =COUNTIFS('농산물업체'!$E$3:$E$702,G$6,'농산물업체'!$S$3:$S$702,"O") -> 34 | H8: =COUNTIFS('농산물업체'!$E$3:$E$702,H$6,'농산물업체'!$S$3:$S$702,"O") -> 19 | I8: =COUNTIFS('농산물업체'!$E$3:$E$702,I$6,'농산물업체'!$S$3:$S$702,"O") -> 7 | J8: =COUNTIFS('농산물업체'!$E$3:$E$702,J$6,'농산물업체'!$S$3:$S$702,"O") -> 13 | K8: =IF(COUNT(L8:M8)=0,"",SUM(L8:M8)) -> 35 | L8: =COUNTIFS('유기농업체'!$E$3:$E$252,L$6,'유기농업체'!$S$3:$S$252,"O") -> 18 | M8: =COUNTIFS('유기농업체'!$E$3:$E$252,M$6,'유기농업체'!$S$3:$S$252,"O") -> 17
B9: 상품수 | C9: =IF(COUNT(D9,K9)=0,"",SUM(D9,K9)) -> 1651 | D9: =IF(COUNT(E9:J9)=0,"",SUM(E9:J9)) -> 1449 | E9: =IF('설정'!$B$3=0,"",CHOOSE('설정'!$B$3,COUNTIFS('RAW_농산물_7월'!$A:$A,E$6),COUNTIFS('RAW_농산물_8월'!$A:$A,E$6),COUNTIFS('RAW_농산물_9월'!$A:$A,E$6),COUNTIFS('RAW_농산물_10월'!$A:$A,E$6),COUNTIFS('RAW_농산물_11-12월'!$A:$A,E$6))) -> 614 | F9: =IF('설정'!$B$3=0,"",CHOOSE('설정'!$B$3,COUNTIFS('RAW_농산물_7월'!$A:$A,F$6),COUNTIFS('RAW_농산물_8월'!$A:$A,F$6),COUNTIFS('RAW_농산물_9월'!$A:$A,F$6),COUNTIFS('RAW_농산물_10월'!$A:$A,F$6),COUNTIFS('RAW_농산물_11-12월'!$A:$A,F$6))) -> 298 | G9: =IF('설정'!$B$3=0,"",CHOOSE('설정'!$B$3,COUNTIFS('RAW_농산물_7월'!$A:$A,G$6),COUNTIFS('RAW_농산물_8월'!$A:$A,G$6),COUNTIFS('RAW_농산물_9월'!$A:$A,G$6),COUNTIFS('RAW_농산물_10월'!$A:$A,G$6),COUNTIFS('RAW_농산물_11-12월'!$A:$A,G$6))) -> 349 | H9: =IF('설정'!$B$3=0,"",CHOOSE('설정'!$B$3,COUNTIFS('RAW_농산물_7월'!$A:$A,H$6),COUNTIFS('RAW_농산물_8월'!$A:$A,H$6),COUNTIFS('RAW_농산물_9월'!$A:$A,H$6),COUNTIFS('RAW_농산물_10월'!$A:$A,H$6),COUNTIFS('RAW_농산물_11-12월'!$A:$A,H$6))) -> 71 | I9: =IF('설정'!$B$3=0,"",CHOOSE('설정'!$B$3,COUNTIFS('RAW_농산물_7월'!$A:$A,I$6),COUNTIFS('RAW_농산물_8월'!$A:$A,I$6),COUNTIFS('RAW_농산물_9월'!$A:$A,I$6),COUNTIFS('RAW_농산물_10월'!$A:$A,I$6),COUNTIFS('RAW_농산물_11-12월'!$A:$A,I$6))) -> 30 | J9: =IF('설정'!$B$3=0,"",CHOOSE('설정'!$B$3,COUNTIFS('RAW_농산물_7월'!$A:$A,J$6),COUNTIFS('RAW_농산물_8월'!$A:$A,J$6),COUNTIFS('RAW_농산물_9월'!$A:$A,J$6),COUNTIFS('RAW_농산물_10월'!$A:$A,J$6),COUNTIFS('RAW_농산물_11-12월'!$A:$A,J$6))) -> 87 | K9: =IF(COUNT(L9:M9)=0,"",SUM(L9:M9)) -> 202 | L9: =IF('설정'!$B$4=0,"",CHOOSE('설정'!$B$4,COUNTIFS('RAW_유기농_7월'!$A:$A,L$6),COUNTIFS('RAW_유기농_8월'!$A:$A,L$6),COUNTIFS('RAW_유기농_9월'!$A:$A,L$6),COUNTIFS('RAW_유기농_10월'!$A:$A,L$6),COUNTIFS('RAW_유기농_11-12월'!$A:$A,L$6))) -> 111 | M9: =IF('설정'!$B$4=0,"",CHOOSE('설정'!$B$4,COUNTIFS('RAW_유기농_7월'!$A:$A,M$6),COUNTIFS('RAW_유기농_8월'!$A:$A,M$6),COUNTIFS('RAW_유기농_9월'!$A:$A,M$6),COUNTIFS('RAW_유기농_10월'!$A:$A,M$6),COUNTIFS('RAW_유기농_11-12월'!$A:$A,M$6))) -> 91
B10: ※ 참여업체수 = RAW에 실제 등재된 업체 (누적) / 배정업체수 = 업체 명단에 등록된 업체. 기관 보고 기준에 맞는 쪽을 쓰세요.
B12: 2. 유통사 별 쿠폰 사용액 (누적)
B13: 구분 | C13: 총 계 | D13: 농부가바로팜 | K13: 친환경
D14: 소 계 | E14: 네이버 | F14: 지마켓 | G14: 롯데ON | H14: 온누리마켓 | I14: 농가살리기 | J14: 오아시스 | K14: 소 계 | L14: 네이버 | M14: 오아시스
B15: 쿠폰 사용액 | C15: =IF(COUNT(D15,K15)=0,"",SUM(D15,K15)) -> 310710888 | D15: =IF(COUNT(E15:J15)=0,"",SUM(E15:J15)) -> 266369319 | E15: =IF('설정'!$B$3=0,"",CHOOSE('설정'!$B$3,SUMIFS('RAW_농산물_7월'!$H:$H,'RAW_농산물_7월'!$A:$A,E$14),SUMIFS('RAW_농산물_8월'!$H:$H,'RAW_농산물_8월'!$A:$A,E$14),SUMIFS('RAW_농산물_9월'!$H:$H,'RAW_농산물_9월'!$A:$A,E$14),SUMIFS('RAW_농산물_10월'!$H:$H,'RAW_농산물_10월'!$A:$A,E$14),SUMIFS('RAW_농산물_11-12월'!$H:$H,'RAW_농산물_11-12월'!$A:$A,E$14))) -> 90643090 | F15: =IF('설정'!$B$3=0,"",CHOOSE('설정'!$B$3,SUMIFS('RAW_농산물_7월'!$H:$H,'RAW_농산물_7월'!$A:$A,F$14),SUMIFS('RAW_농산물_8월'!$H:$H,'RAW_농산물_8월'!$A:$A,F$14),SUMIFS('RAW_농산물_9월'!$H:$H,'RAW_농산물_9월'!$A:$A,F$14),SUMIFS('RAW_농산물_10월'!$H:$H,'RAW_농산물_10월'!$A:$A,F$14),SUMIFS('RAW_농산물_11-12월'!$H:$H,'RAW_농산물_11-12월'!$A:$A,F$14))) -> 76647920 | G15: =IF('설정'!$B$3=0,"",CHOOSE('설정'!$B$3,SUMIFS('RAW_농산물_7월'!$H:$H,'RAW_농산물_7월'!$A:$A,G$14),SUMIFS('RAW_농산물_8월'!$H:$H,'RAW_농산물_8월'!$A:$A,G$14),SUMIFS('RAW_농산물_9월'!$H:$H,'RAW_농산물_9월'!$A:$A,G$14),SUMIFS('RAW_농산물_10월'!$H:$H,'RAW_농산물_10월'!$A:$A,G$14),SUMIFS('RAW_농산물_11-12월'!$H:$H,'RAW_농산물_11-12월'!$A:$A,G$14))) -> 52129220 | H15: =IF('설정'!$B$3=0,"",CHOOSE('설정'!$B$3,SUMIFS('RAW_농산물_7월'!$H:$H,'RAW_농산물_7월'!$A:$A,H$14),SUMIFS('RAW_농산물_8월'!$H:$H,'RAW_농산물_8월'!$A:$A,H$14),SUMIFS('RAW_농산물_9월'!$H:$H,'RAW_농산물_9월'!$A:$A,H$14),SUMIFS('RAW_농산물_10월'!$H:$H,'RAW_농산물_10월'!$A:$A,H$14),SUMIFS('RAW_농산물_11-12월'!$H:$H,'RAW_농산물_11-12월'!$A:$A,H$14))) -> 15501100 | I15: =IF('설정'!$B$3=0,"",CHOOSE('설정'!$B$3,SUMIFS('RAW_농산물_7월'!$H:$H,'RAW_농산물_7월'!$A:$A,I$14),SUMIFS('RAW_농산물_8월'!$H:$H,'RAW_농산물_8월'!$A:$A,I$14),SUMIFS('RAW_농산물_9월'!$H:$H,'RAW_농산물_9월'!$A:$A,I$14),SUMIFS('RAW_농산물_10월'!$H:$H,'RAW_농산물_10월'!$A:$A,I$14),SUMIFS('RAW_농산물_11-12월'!$H:$H,'RAW_농산물_11-12월'!$A:$A,I$14))) -> 15599960 | J15: =IF('설정'!$B$3=0,"",CHOOSE('설정'!$B$3,SUMIFS('RAW_농산물_7월'!$H:$H,'RAW_농산물_7월'!$A:$A,J$14),SUMIFS('RAW_농산물_8월'!$H:$H,'RAW_농산물_8월'!$A:$A,J$14),SUMIFS('RAW_농산물_9월'!$H:$H,'RAW_농산물_9월'!$A:$A,J$14),SUMIFS('RAW_농산물_10월'!$H:$H,'RAW_농산물_10월'!$A:$A,J$14),SUMIFS('RAW_농산물_11-12월'!$H:$H,'RAW_농산물_11-12월'!$A:$A,J$14))) -> 15848029 | K15: =IF(COUNT(L15:M15)=0,"",SUM(L15:M15)) -> 44341569 | L15: =IF('설정'!$B$4=0,"",CHOOSE('설정'!$B$4,SUMIFS('RAW_유기농_7월'!$H:$H,'RAW_유기농_7월'!$A:$A,L$14),SUMIFS('RAW_유기농_8월'!$H:$H,'RAW_유기농_8월'!$A:$A,L$14),SUMIFS('RAW_유기농_9월'!$H:$H,'RAW_유기농_9월'!$A:$A,L$14),SUMIFS('RAW_유기농_10월'!$H:$H,'RAW_유기농_10월'!$A:$A,L$14),SUMIFS('RAW_유기농_11-12월'!$H:$H,'RAW_유기농_11-12월'!$A:$A,L$14))) -> 24308290 | M15: =IF('설정'!$B$4=0,"",CHOOSE('설정'!$B$4,SUMIFS('RAW_유기농_7월'!$H:$H,'RAW_유기농_7월'!$A:$A,M$14),SUMIFS('RAW_유기농_8월'!$H:$H,'RAW_유기농_8월'!$A:$A,M$14),SUMIFS('RAW_유기농_9월'!$H:$H,'RAW_유기농_9월'!$A:$A,M$14),SUMIFS('RAW_유기농_10월'!$H:$H,'RAW_유기농_10월'!$A:$A,M$14),SUMIFS('RAW_유기농_11-12월'!$H:$H,'RAW_유기농_11-12월'!$A:$A,M$14))) -> 20033279
B17: 3. 유통사 별 매출 분석 (누적)
B18: 구분 | C18: 총 계 | D18: 농부가바로팜 | K18: 친환경
D19: 소 계 | E19: 네이버 | F19: 지마켓 | G19: 롯데ON | H19: 온누리마켓 | I19: 농가살리기 | J19: 오아시스 | K19: 소 계 | L19: 네이버 | M19: 오아시스
B20: 매출액 | C20: =IF(COUNT(D20,K20)=0,"",SUM(D20,K20)) -> 7680466070 | D20: =IF(COUNT(E20:J20)=0,"",SUM(E20:J20)) -> 6227333500 | E20: =IF('설정'!$B$3=0,"",CHOOSE('설정'!$B$3,SUMIFS('RAW_농산물_7월'!$G:$G,'RAW_농산물_7월'!$A:$A,E$19),SUMIFS('RAW_농산물_8월'!$G:$G,'RAW_농산물_8월'!$A:$A,E$19),SUMIFS('RAW_농산물_9월'!$G:$G,'RAW_농산물_9월'!$A:$A,E$19),SUMIFS('RAW_농산물_10월'!$G:$G,'RAW_농산물_10월'!$A:$A,E$19),SUMIFS('RAW_농산물_11-12월'!$G:$G,'RAW_농산물_11-12월'!$A:$A,E$19))) -> 2902192570 | F20: =IF('설정'!$B$3=0,"",CHOOSE('설정'!$B$3,SUMIFS('RAW_농산물_7월'!$G:$G,'RAW_농산물_7월'!$A:$A,F$19),SUMIFS('RAW_농산물_8월'!$G:$G,'RAW_농산물_8월'!$A:$A,F$19),SUMIFS('RAW_농산물_9월'!$G:$G,'RAW_농산물_9월'!$A:$A,F$19),SUMIFS('RAW_농산물_10월'!$G:$G,'RAW_농산물_10월'!$A:$A,F$19),SUMIFS('RAW_농산물_11-12월'!$G:$G,'RAW_농산물_11-12월'!$A:$A,F$19))) -> 1348440770 | G20: =IF('설정'!$B$3=0,"",CHOOSE('설정'!$B$3,SUMIFS('RAW_농산물_7월'!$G:$G,'RAW_농산물_7월'!$A:$A,G$19),SUMIFS('RAW_농산물_8월'!$G:$G,'RAW_농산물_8월'!$A:$A,G$19),SUMIFS('RAW_농산물_9월'!$G:$G,'RAW_농산물_9월'!$A:$A,G$19),SUMIFS('RAW_농산물_10월'!$G:$G,'RAW_농산물_10월'!$A:$A,G$19),SUMIFS('RAW_농산물_11-12월'!$G:$G,'RAW_농산물_11-12월'!$A:$A,G$19))) -> 344053620 | H20: =IF('설정'!$B$3=0,"",CHOOSE('설정'!$B$3,SUMIFS('RAW_농산물_7월'!$G:$G,'RAW_농산물_7월'!$A:$A,H$19),SUMIFS('RAW_농산물_8월'!$G:$G,'RAW_농산물_8월'!$A:$A,H$19),SUMIFS('RAW_농산물_9월'!$G:$G,'RAW_농산물_9월'!$A:$A,H$19),SUMIFS('RAW_농산물_10월'!$G:$G,'RAW_농산물_10월'!$A:$A,H$19),SUMIFS('RAW_농산물_11-12월'!$G:$G,'RAW_농산물_11-12월'!$A:$A,H$19))) -> 100008000 | I20: =IF('설정'!$B$3=0,"",CHOOSE('설정'!$B$3,SUMIFS('RAW_농산물_7월'!$G:$G,'RAW_농산물_7월'!$A:$A,I$19),SUMIFS('RAW_농산물_8월'!$G:$G,'RAW_농산물_8월'!$A:$A,I$19),SUMIFS('RAW_농산물_9월'!$G:$G,'RAW_농산물_9월'!$A:$A,I$19),SUMIFS('RAW_농산물_10월'!$G:$G,'RAW_농산물_10월'!$A:$A,I$19),SUMIFS('RAW_농산물_11-12월'!$G:$G,'RAW_농산물_11-12월'!$A:$A,I$19))) -> 470341670 | J20: =IF('설정'!$B$3=0,"",CHOOSE('설정'!$B$3,SUMIFS('RAW_농산물_7월'!$G:$G,'RAW_농산물_7월'!$A:$A,J$19),SUMIFS('RAW_농산물_8월'!$G:$G,'RAW_농산물_8월'!$A:$A,J$19),SUMIFS('RAW_농산물_9월'!$G:$G,'RAW_농산물_9월'!$A:$A,J$19),SUMIFS('RAW_농산물_10월'!$G:$G,'RAW_농산물_10월'!$A:$A,J$19),SUMIFS('RAW_농산물_11-12월'!$G:$G,'RAW_농산물_11-12월'!$A:$A,J$19))) -> 1062296870 | K20: =IF(COUNT(L20:M20)=0,"",SUM(L20:M20)) -> 1453132570 | L20: =IF('설정'!$B$4=0,"",CHOOSE('설정'!$B$4,SUMIFS('RAW_유기농_7월'!$G:$G,'RAW_유기농_7월'!$A:$A,L$19),SUMIFS('RAW_유기농_8월'!$G:$G,'RAW_유기농_8월'!$A:$A,L$19),SUMIFS('RAW_유기농_9월'!$G:$G,'RAW_유기농_9월'!$A:$A,L$19),SUMIFS('RAW_유기농_10월'!$G:$G,'RAW_유기농_10월'!$A:$A,L$19),SUMIFS('RAW_유기농_11-12월'!$G:$G,'RAW_유기농_11-12월'!$A:$A,L$19))) -> 271526720 | M20: =IF('설정'!$B$4=0,"",CHOOSE('설정'!$B$4,SUMIFS('RAW_유기농_7월'!$G:$G,'RAW_유기농_7월'!$A:$A,M$19),SUMIFS('RAW_유기농_8월'!$G:$G,'RAW_유기농_8월'!$A:$A,M$19),SUMIFS('RAW_유기농_9월'!$G:$G,'RAW_유기농_9월'!$A:$A,M$19),SUMIFS('RAW_유기농_10월'!$G:$G,'RAW_유기농_10월'!$A:$A,M$19),SUMIFS('RAW_유기농_11-12월'!$G:$G,'RAW_유기농_11-12월'!$A:$A,M$19))) -> 1181605850
B22: 4. 유통사 별 판매 건수 (누적)
B23: 구분 | C23: 총 계 | D23: 농부가바로팜 | K23: 친환경
D24: 소 계 | E24: 네이버 | F24: 지마켓 | G24: 롯데ON | H24: 온누리마켓 | I24: 농가살리기 | J24: 오아시스 | K24: 소 계 | L24: 네이버 | M24: 오아시스
B25: 판매건수 | C25: =IF(COUNT(D25,K25)=0,"",SUM(D25,K25)) -> 756125 | D25: =IF(COUNT(E25:J25)=0,"",SUM(E25:J25)) -> 475218 | E25: =IF('설정'!$B$3=0,"",CHOOSE('설정'!$B$3,SUMIFS('RAW_농산물_7월'!$F:$F,'RAW_농산물_7월'!$A:$A,E$24),SUMIFS('RAW_농산물_8월'!$F:$F,'RAW_농산물_8월'!$A:$A,E$24),SUMIFS('RAW_농산물_9월'!$F:$F,'RAW_농산물_9월'!$A:$A,E$24),SUMIFS('RAW_농산물_10월'!$F:$F,'RAW_농산물_10월'!$A:$A,E$24),SUMIFS('RAW_농산물_11-12월'!$F:$F,'RAW_농산물_11-12월'!$A:$A,E$24))) -> 108140 | F25: =IF('설정'!$B$3=0,"",CHOOSE('설정'!$B$3,SUMIFS('RAW_농산물_7월'!$F:$F,'RAW_농산물_7월'!$A:$A,F$24),SUMIFS('RAW_농산물_8월'!$F:$F,'RAW_농산물_8월'!$A:$A,F$24),SUMIFS('RAW_농산물_9월'!$F:$F,'RAW_농산물_9월'!$A:$A,F$24),SUMIFS('RAW_농산물_10월'!$F:$F,'RAW_농산물_10월'!$A:$A,F$24),SUMIFS('RAW_농산물_11-12월'!$F:$F,'RAW_농산물_11-12월'!$A:$A,F$24))) -> 68093 | G25: =IF('설정'!$B$3=0,"",CHOOSE('설정'!$B$3,SUMIFS('RAW_농산물_7월'!$F:$F,'RAW_농산물_7월'!$A:$A,G$24),SUMIFS('RAW_농산물_8월'!$F:$F,'RAW_농산물_8월'!$A:$A,G$24),SUMIFS('RAW_농산물_9월'!$F:$F,'RAW_농산물_9월'!$A:$A,G$24),SUMIFS('RAW_농산물_10월'!$F:$F,'RAW_농산물_10월'!$A:$A,G$24),SUMIFS('RAW_농산물_11-12월'!$F:$F,'RAW_농산물_11-12월'!$A:$A,G$24))) -> 13595 | H25: =IF('설정'!$B$3=0,"",CHOOSE('설정'!$B$3,SUMIFS('RAW_농산물_7월'!$F:$F,'RAW_농산물_7월'!$A:$A,H$24),SUMIFS('RAW_농산물_8월'!$F:$F,'RAW_농산물_8월'!$A:$A,H$24),SUMIFS('RAW_농산물_9월'!$F:$F,'RAW_농산물_9월'!$A:$A,H$24),SUMIFS('RAW_농산물_10월'!$F:$F,'RAW_농산물_10월'!$A:$A,H$24),SUMIFS('RAW_농산물_11-12월'!$F:$F,'RAW_농산물_11-12월'!$A:$A,H$24))) -> 3100 | I25: =IF('설정'!$B$3=0,"",CHOOSE('설정'!$B$3,SUMIFS('RAW_농산물_7월'!$F:$F,'RAW_농산물_7월'!$A:$A,I$24),SUMIFS('RAW_농산물_8월'!$F:$F,'RAW_농산물_8월'!$A:$A,I$24),SUMIFS('RAW_농산물_9월'!$F:$F,'RAW_농산물_9월'!$A:$A,I$24),SUMIFS('RAW_농산물_10월'!$F:$F,'RAW_농산물_10월'!$A:$A,I$24),SUMIFS('RAW_농산물_11-12월'!$F:$F,'RAW_농산물_11-12월'!$A:$A,I$24))) -> 30683 | J25: =IF('설정'!$B$3=0,"",CHOOSE('설정'!$B$3,SUMIFS('RAW_농산물_7월'!$F:$F,'RAW_농산물_7월'!$A:$A,J$24),SUMIFS('RAW_농산물_8월'!$F:$F,'RAW_농산물_8월'!$A:$A,J$24),SUMIFS('RAW_농산물_9월'!$F:$F,'RAW_농산물_9월'!$A:$A,J$24),SUMIFS('RAW_농산물_10월'!$F:$F,'RAW_농산물_10월'!$A:$A,J$24),SUMIFS('RAW_농산물_11-12월'!$F:$F,'RAW_농산물_11-12월'!$A:$A,J$24))) -> 251607 | K25: =IF(COUNT(L25:M25)=0,"",SUM(L25:M25)) -> 280907 | L25: =IF('설정'!$B$4=0,"",CHOOSE('설정'!$B$4,SUMIFS('RAW_유기농_7월'!$F:$F,'RAW_유기농_7월'!$A:$A,L$24),SUMIFS('RAW_유기농_8월'!$F:$F,'RAW_유기농_8월'!$A:$A,L$24),SUMIFS('RAW_유기농_9월'!$F:$F,'RAW_유기농_9월'!$A:$A,L$24),SUMIFS('RAW_유기농_10월'!$F:$F,'RAW_유기농_10월'!$A:$A,L$24),SUMIFS('RAW_유기농_11-12월'!$F:$F,'RAW_유기농_11-12월'!$A:$A,L$24))) -> 10898 | M25: =IF('설정'!$B$4=0,"",CHOOSE('설정'!$B$4,SUMIFS('RAW_유기농_7월'!$F:$F,'RAW_유기농_7월'!$A:$A,M$24),SUMIFS('RAW_유기농_8월'!$F:$F,'RAW_유기농_8월'!$A:$A,M$24),SUMIFS('RAW_유기농_9월'!$F:$F,'RAW_유기농_9월'!$A:$A,M$24),SUMIFS('RAW_유기농_10월'!$F:$F,'RAW_유기농_10월'!$A:$A,M$24),SUMIFS('RAW_유기농_11-12월'!$F:$F,'RAW_유기농_11-12월'!$A:$A,M$24))) -> 270009
B27: 5. 유통사별 품목별 쿠폰 사용액 (누적)
B28: 구분 | C28: 총 계 | D28: 농부가바로팜 | K28: 친환경
D29: 소 계 | E29: 네이버 | F29: 지마켓 | G29: 롯데ON | H29: 온누리마켓 | I29: 농가살리기 | J29: 오아시스 | K29: 소 계 | L29: 네이버 | M29: 오아시스
B30: 총 계 | C30: =IF(COUNT(D30,K30)=0,"",SUM(D30,K30)) -> 310710888 | D30: =IF(COUNT(E30:J30)=0,"",SUM(E30:J30)) -> 266369319 | E30: =IF(COUNT(E31:E33)=0,"",SUM(E31:E33)) -> 90643090 | F30: =IF(COUNT(F31:F33)=0,"",SUM(F31:F33)) -> 76647920 | G30: =IF(COUNT(G31:G33)=0,"",SUM(G31:G33)) -> 52129220 | H30: =IF(COUNT(H31:H33)=0,"",SUM(H31:H33)) -> 15501100 | I30: =IF(COUNT(I31:I33)=0,"",SUM(I31:I33)) -> 15599960 | J30: =IF(COUNT(J31:J33)=0,"",SUM(J31:J33)) -> 15848029 | K30: =IF(COUNT(L30:M30)=0,"",SUM(L30:M30)) -> 44341569 | L30: =IF(COUNT(L31:L33)=0,"",SUM(L31:L33)) -> 24308290 | M30: =IF(COUNT(M31:M33)=0,"",SUM(M31:M33)) -> 20033279
B31: 농산물 | C31: =IF(COUNT(D31,K31)=0,"",SUM(D31,K31)) -> 170160977 | D31: =IF(COUNT(E31:J31)=0,"",SUM(E31:J31)) -> 138762093 | E31: =IF('설정'!$B$3=0,"",CHOOSE('설정'!$B$3,SUMIFS('RAW_농산물_7월'!$H:$H,'RAW_농산물_7월'!$A:$A,E$29,'RAW_농산물_7월'!$B:$B,$B31),SUMIFS('RAW_농산물_8월'!$H:$H,'RAW_농산물_8월'!$A:$A,E$29,'RAW_농산물_8월'!$B:$B,$B31),SUMIFS('RAW_농산물_9월'!$H:$H,'RAW_농산물_9월'!$A:$A,E$29,'RAW_농산물_9월'!$B:$B,$B31),SUMIFS('RAW_농산물_10월'!$H:$H,'RAW_농산물_10월'!$A:$A,E$29,'RAW_농산물_10월'!$B:$B,$B31),SUMIFS('RAW_농산물_11-12월'!$H:$H,'RAW_농산물_11-12월'!$A:$A,E$29,'RAW_농산물_11-12월'!$B:$B,$B31))) -> 49239490 | F31: =IF('설정'!$B$3=0,"",CHOOSE('설정'!$B$3,SUMIFS('RAW_농산물_7월'!$H:$H,'RAW_농산물_7월'!$A:$A,F$29,'RAW_농산물_7월'!$B:$B,$B31),SUMIFS('RAW_농산물_8월'!$H:$H,'RAW_농산물_8월'!$A:$A,F$29,'RAW_농산물_8월'!$B:$B,$B31),SUMIFS('RAW_농산물_9월'!$H:$H,'RAW_농산물_9월'!$A:$A,F$29,'RAW_농산물_9월'!$B:$B,$B31),SUMIFS('RAW_농산물_10월'!$H:$H,'RAW_농산물_10월'!$A:$A,F$29,'RAW_농산물_10월'!$B:$B,$B31),SUMIFS('RAW_농산물_11-12월'!$H:$H,'RAW_농산물_11-12월'!$A:$A,F$29,'RAW_농산물_11-12월'!$B:$B,$B31))) -> 44507910 | G31: =IF('설정'!$B$3=0,"",CHOOSE('설정'!$B$3,SUMIFS('RAW_농산물_7월'!$H:$H,'RAW_농산물_7월'!$A:$A,G$29,'RAW_농산물_7월'!$B:$B,$B31),SUMIFS('RAW_농산물_8월'!$H:$H,'RAW_농산물_8월'!$A:$A,G$29,'RAW_농산물_8월'!$B:$B,$B31),SUMIFS('RAW_농산물_9월'!$H:$H,'RAW_농산물_9월'!$A:$A,G$29,'RAW_농산물_9월'!$B:$B,$B31),SUMIFS('RAW_농산물_10월'!$H:$H,'RAW_농산물_10월'!$A:$A,G$29,'RAW_농산물_10월'!$B:$B,$B31),SUMIFS('RAW_농산물_11-12월'!$H:$H,'RAW_농산물_11-12월'!$A:$A,G$29,'RAW_농산물_11-12월'!$B:$B,$B31))) -> 18790700 | H31: =IF('설정'!$B$3=0,"",CHOOSE('설정'!$B$3,SUMIFS('RAW_농산물_7월'!$H:$H,'RAW_농산물_7월'!$A:$A,H$29,'RAW_농산물_7월'!$B:$B,$B31),SUMIFS('RAW_농산물_8월'!$H:$H,'RAW_농산물_8월'!$A:$A,H$29,'RAW_농산물_8월'!$B:$B,$B31),SUMIFS('RAW_농산물_9월'!$H:$H,'RAW_농산물_9월'!$A:$A,H$29,'RAW_농산물_9월'!$B:$B,$B31),SUMIFS('RAW_농산물_10월'!$H:$H,'RAW_농산물_10월'!$A:$A,H$29,'RAW_농산물_10월'!$B:$B,$B31),SUMIFS('RAW_농산물_11-12월'!$H:$H,'RAW_농산물_11-12월'!$A:$A,H$29,'RAW_농산물_11-12월'!$B:$B,$B31))) -> 13890839 | I31: =IF('설정'!$B$3=0,"",CHOOSE('설정'!$B$3,SUMIFS('RAW_농산물_7월'!$H:$H,'RAW_농산물_7월'!$A:$A,I$29,'RAW_농산물_7월'!$B:$B,$B31),SUMIFS('RAW_농산물_8월'!$H:$H,'RAW_농산물_8월'!$A:$A,I$29,'RAW_농산물_8월'!$B:$B,$B31),SUMIFS('RAW_농산물_9월'!$H:$H,'RAW_농산물_9월'!$A:$A,I$29,'RAW_농산물_9월'!$B:$B,$B31),SUMIFS('RAW_농산물_10월'!$H:$H,'RAW_농산물_10월'!$A:$A,I$29,'RAW_농산물_10월'!$B:$B,$B31),SUMIFS('RAW_농산물_11-12월'!$H:$H,'RAW_농산물_11-12월'!$A:$A,I$29,'RAW_농산물_11-12월'!$B:$B,$B31))) -> 6040540 | J31: =IF('설정'!$B$3=0,"",CHOOSE('설정'!$B$3,SUMIFS('RAW_농산물_7월'!$H:$H,'RAW_농산물_7월'!$A:$A,J$29,'RAW_농산물_7월'!$B:$B,$B31),SUMIFS('RAW_농산물_8월'!$H:$H,'RAW_농산물_8월'!$A:$A,J$29,'RAW_농산물_8월'!$B:$B,$B31),SUMIFS('RAW_농산물_9월'!$H:$H,'RAW_농산물_9월'!$A:$A,J$29,'RAW_농산물_9월'!$B:$B,$B31),SUMIFS('RAW_농산물_10월'!$H:$H,'RAW_농산물_10월'!$A:$A,J$29,'RAW_농산물_10월'!$B:$B,$B31),SUMIFS('RAW_농산물_11-12월'!$H:$H,'RAW_농산물_11-12월'!$A:$A,J$29,'RAW_농산물_11-12월'!$B:$B,$B31))) -> 6292614 | K31: =IF(COUNT(L31:M31)=0,"",SUM(L31:M31)) -> 31398884 | L31: =IF('설정'!$B$4=0,"",CHOOSE('설정'!$B$4,SUMIFS('RAW_유기농_7월'!$H:$H,'RAW_유기농_7월'!$A:$A,L$29,'RAW_유기농_7월'!$B:$B,$B31),SUMIFS('RAW_유기농_8월'!$H:$H,'RAW_유기농_8월'!$A:$A,L$29,'RAW_유기농_8월'!$B:$B,$B31),SUMIFS('RAW_유기농_9월'!$H:$H,'RAW_유기농_9월'!$A:$A,L$29,'RAW_유기농_9월'!$B:$B,$B31),SUMIFS('RAW_유기농_10월'!$H:$H,'RAW_유기농_10월'!$A:$A,L$29,'RAW_유기농_10월'!$B:$B,$B31),SUMIFS('RAW_유기농_11-12월'!$H:$H,'RAW_유기농_11-12월'!$A:$A,L$29,'RAW_유기농_11-12월'!$B:$B,$B31))) -> 21139260 | M31: =IF('설정'!$B$4=0,"",CHOOSE('설정'!$B$4,SUMIFS('RAW_유기농_7월'!$H:$H,'RAW_유기농_7월'!$A:$A,M$29,'RAW_유기농_7월'!$B:$B,$B31),SUMIFS('RAW_유기농_8월'!$H:$H,'RAW_유기농_8월'!$A:$A,M$29,'RAW_유기농_8월'!$B:$B,$B31),SUMIFS('RAW_유기농_9월'!$H:$H,'RAW_유기농_9월'!$A:$A,M$29,'RAW_유기농_9월'!$B:$B,$B31),SUMIFS('RAW_유기농_10월'!$H:$H,'RAW_유기농_10월'!$A:$A,M$29,'RAW_유기농_10월'!$B:$B,$B31),SUMIFS('RAW_유기농_11-12월'!$H:$H,'RAW_유기농_11-12월'!$A:$A,M$29,'RAW_유기농_11-12월'!$B:$B,$B31))) -> 10259624
B32: 축산물 | C32: =IF(COUNT(D32,K32)=0,"",SUM(D32,K32)) -> 52806005 | D32: =IF(COUNT(E32:J32)=0,"",SUM(E32:J32)) -> 52329884 | E32: =IF('설정'!$B$3=0,"",CHOOSE('설정'!$B$3,SUMIFS('RAW_농산물_7월'!$H:$H,'RAW_농산물_7월'!$A:$A,E$29,'RAW_농산물_7월'!$B:$B,$B32),SUMIFS('RAW_농산물_8월'!$H:$H,'RAW_농산물_8월'!$A:$A,E$29,'RAW_농산물_8월'!$B:$B,$B32),SUMIFS('RAW_농산물_9월'!$H:$H,'RAW_농산물_9월'!$A:$A,E$29,'RAW_농산물_9월'!$B:$B,$B32),SUMIFS('RAW_농산물_10월'!$H:$H,'RAW_농산물_10월'!$A:$A,E$29,'RAW_농산물_10월'!$B:$B,$B32),SUMIFS('RAW_농산물_11-12월'!$H:$H,'RAW_농산물_11-12월'!$A:$A,E$29,'RAW_농산물_11-12월'!$B:$B,$B32))) -> 17926550 | F32: =IF('설정'!$B$3=0,"",CHOOSE('설정'!$B$3,SUMIFS('RAW_농산물_7월'!$H:$H,'RAW_농산물_7월'!$A:$A,F$29,'RAW_농산물_7월'!$B:$B,$B32),SUMIFS('RAW_농산물_8월'!$H:$H,'RAW_농산물_8월'!$A:$A,F$29,'RAW_농산물_8월'!$B:$B,$B32),SUMIFS('RAW_농산물_9월'!$H:$H,'RAW_농산물_9월'!$A:$A,F$29,'RAW_농산물_9월'!$B:$B,$B32),SUMIFS('RAW_농산물_10월'!$H:$H,'RAW_농산물_10월'!$A:$A,F$29,'RAW_농산물_10월'!$B:$B,$B32),SUMIFS('RAW_농산물_11-12월'!$H:$H,'RAW_농산물_11-12월'!$A:$A,F$29,'RAW_농산물_11-12월'!$B:$B,$B32))) -> 11023670 | G32: =IF('설정'!$B$3=0,"",CHOOSE('설정'!$B$3,SUMIFS('RAW_농산물_7월'!$H:$H,'RAW_농산물_7월'!$A:$A,G$29,'RAW_농산물_7월'!$B:$B,$B32),SUMIFS('RAW_농산물_8월'!$H:$H,'RAW_농산물_8월'!$A:$A,G$29,'RAW_농산물_8월'!$B:$B,$B32),SUMIFS('RAW_농산물_9월'!$H:$H,'RAW_농산물_9월'!$A:$A,G$29,'RAW_농산물_9월'!$B:$B,$B32),SUMIFS('RAW_농산물_10월'!$H:$H,'RAW_농산물_10월'!$A:$A,G$29,'RAW_농산물_10월'!$B:$B,$B32),SUMIFS('RAW_농산물_11-12월'!$H:$H,'RAW_농산물_11-12월'!$A:$A,G$29,'RAW_농산물_11-12월'!$B:$B,$B32))) -> 21130300 | H32: =IF('설정'!$B$3=0,"",CHOOSE('설정'!$B$3,SUMIFS('RAW_농산물_7월'!$H:$H,'RAW_농산물_7월'!$A:$A,H$29,'RAW_농산물_7월'!$B:$B,$B32),SUMIFS('RAW_농산물_8월'!$H:$H,'RAW_농산물_8월'!$A:$A,H$29,'RAW_농산물_8월'!$B:$B,$B32),SUMIFS('RAW_농산물_9월'!$H:$H,'RAW_농산물_9월'!$A:$A,H$29,'RAW_농산물_9월'!$B:$B,$B32),SUMIFS('RAW_농산물_10월'!$H:$H,'RAW_농산물_10월'!$A:$A,H$29,'RAW_농산물_10월'!$B:$B,$B32),SUMIFS('RAW_농산물_11-12월'!$H:$H,'RAW_농산물_11-12월'!$A:$A,H$29,'RAW_농산물_11-12월'!$B:$B,$B32))) -> 0 | I32: =IF('설정'!$B$3=0,"",CHOOSE('설정'!$B$3,SUMIFS('RAW_농산물_7월'!$H:$H,'RAW_농산물_7월'!$A:$A,I$29,'RAW_농산물_7월'!$B:$B,$B32),SUMIFS('RAW_농산물_8월'!$H:$H,'RAW_농산물_8월'!$A:$A,I$29,'RAW_농산물_8월'!$B:$B,$B32),SUMIFS('RAW_농산물_9월'!$H:$H,'RAW_농산물_9월'!$A:$A,I$29,'RAW_농산물_9월'!$B:$B,$B32),SUMIFS('RAW_농산물_10월'!$H:$H,'RAW_농산물_10월'!$A:$A,I$29,'RAW_농산물_10월'!$B:$B,$B32),SUMIFS('RAW_농산물_11-12월'!$H:$H,'RAW_농산물_11-12월'!$A:$A,I$29,'RAW_농산물_11-12월'!$B:$B,$B32))) -> 0 | J32: =IF('설정'!$B$3=0,"",CHOOSE('설정'!$B$3,SUMIFS('RAW_농산물_7월'!$H:$H,'RAW_농산물_7월'!$A:$A,J$29,'RAW_농산물_7월'!$B:$B,$B32),SUMIFS('RAW_농산물_8월'!$H:$H,'RAW_농산물_8월'!$A:$A,J$29,'RAW_농산물_8월'!$B:$B,$B32),SUMIFS('RAW_농산물_9월'!$H:$H,'RAW_농산물_9월'!$A:$A,J$29,'RAW_농산물_9월'!$B:$B,$B32),SUMIFS('RAW_농산물_10월'!$H:$H,'RAW_농산물_10월'!$A:$A,J$29,'RAW_농산물_10월'!$B:$B,$B32),SUMIFS('RAW_농산물_11-12월'!$H:$H,'RAW_농산물_11-12월'!$A:$A,J$29,'RAW_농산물_11-12월'!$B:$B,$B32))) -> 2249364 | K32: =IF(COUNT(L32:M32)=0,"",SUM(L32:M32)) -> 476121 | L32: =IF('설정'!$B$4=0,"",CHOOSE('설정'!$B$4,SUMIFS('RAW_유기농_7월'!$H:$H,'RAW_유기농_7월'!$A:$A,L$29,'RAW_유기농_7월'!$B:$B,$B32),SUMIFS('RAW_유기농_8월'!$H:$H,'RAW_유기농_8월'!$A:$A,L$29,'RAW_유기농_8월'!$B:$B,$B32),SUMIFS('RAW_유기농_9월'!$H:$H,'RAW_유기농_9월'!$A:$A,L$29,'RAW_유기농_9월'!$B:$B,$B32),SUMIFS('RAW_유기농_10월'!$H:$H,'RAW_유기농_10월'!$A:$A,L$29,'RAW_유기농_10월'!$B:$B,$B32),SUMIFS('RAW_유기농_11-12월'!$H:$H,'RAW_유기농_11-12월'!$A:$A,L$29,'RAW_유기농_11-12월'!$B:$B,$B32))) -> 25800 | M32: =IF('설정'!$B$4=0,"",CHOOSE('설정'!$B$4,SUMIFS('RAW_유기농_7월'!$H:$H,'RAW_유기농_7월'!$A:$A,M$29,'RAW_유기농_7월'!$B:$B,$B32),SUMIFS('RAW_유기농_8월'!$H:$H,'RAW_유기농_8월'!$A:$A,M$29,'RAW_유기농_8월'!$B:$B,$B32),SUMIFS('RAW_유기농_9월'!$H:$H,'RAW_유기농_9월'!$A:$A,M$29,'RAW_유기농_9월'!$B:$B,$B32),SUMIFS('RAW_유기농_10월'!$H:$H,'RAW_유기농_10월'!$A:$A,M$29,'RAW_유기농_10월'!$B:$B,$B32),SUMIFS('RAW_유기농_11-12월'!$H:$H,'RAW_유기농_11-12월'!$A:$A,M$29,'RAW_유기농_11-12월'!$B:$B,$B32))) -> 450321
B33: 가공식품 | C33: =IF(COUNT(D33,K33)=0,"",SUM(D33,K33)) -> 87743906 | D33: =IF(COUNT(E33:J33)=0,"",SUM(E33:J33)) -> 75277342 | E33: =IF('설정'!$B$3=0,"",CHOOSE('설정'!$B$3,SUMIFS('RAW_농산물_7월'!$H:$H,'RAW_농산물_7월'!$A:$A,E$29,'RAW_농산물_7월'!$B:$B,$B33),SUMIFS('RAW_농산물_8월'!$H:$H,'RAW_농산물_8월'!$A:$A,E$29,'RAW_농산물_8월'!$B:$B,$B33),SUMIFS('RAW_농산물_9월'!$H:$H,'RAW_농산물_9월'!$A:$A,E$29,'RAW_농산물_9월'!$B:$B,$B33),SUMIFS('RAW_농산물_10월'!$H:$H,'RAW_농산물_10월'!$A:$A,E$29,'RAW_농산물_10월'!$B:$B,$B33),SUMIFS('RAW_농산물_11-12월'!$H:$H,'RAW_농산물_11-12월'!$A:$A,E$29,'RAW_농산물_11-12월'!$B:$B,$B33))) -> 23477050 | F33: =IF('설정'!$B$3=0,"",CHOOSE('설정'!$B$3,SUMIFS('RAW_농산물_7월'!$H:$H,'RAW_농산물_7월'!$A:$A,F$29,'RAW_농산물_7월'!$B:$B,$B33),SUMIFS('RAW_농산물_8월'!$H:$H,'RAW_농산물_8월'!$A:$A,F$29,'RAW_농산물_8월'!$B:$B,$B33),SUMIFS('RAW_농산물_9월'!$H:$H,'RAW_농산물_9월'!$A:$A,F$29,'RAW_농산물_9월'!$B:$B,$B33),SUMIFS('RAW_농산물_10월'!$H:$H,'RAW_농산물_10월'!$A:$A,F$29,'RAW_농산물_10월'!$B:$B,$B33),SUMIFS('RAW_농산물_11-12월'!$H:$H,'RAW_농산물_11-12월'!$A:$A,F$29,'RAW_농산물_11-12월'!$B:$B,$B33))) -> 21116340 | G33: =IF('설정'!$B$3=0,"",CHOOSE('설정'!$B$3,SUMIFS('RAW_농산물_7월'!$H:$H,'RAW_농산물_7월'!$A:$A,G$29,'RAW_농산물_7월'!$B:$B,$B33),SUMIFS('RAW_농산물_8월'!$H:$H,'RAW_농산물_8월'!$A:$A,G$29,'RAW_농산물_8월'!$B:$B,$B33),SUMIFS('RAW_농산물_9월'!$H:$H,'RAW_농산물_9월'!$A:$A,G$29,'RAW_농산물_9월'!$B:$B,$B33),SUMIFS('RAW_농산물_10월'!$H:$H,'RAW_농산물_10월'!$A:$A,G$29,'RAW_농산물_10월'!$B:$B,$B33),SUMIFS('RAW_농산물_11-12월'!$H:$H,'RAW_농산물_11-12월'!$A:$A,G$29,'RAW_농산물_11-12월'!$B:$B,$B33))) -> 12208220 | H33: =IF('설정'!$B$3=0,"",CHOOSE('설정'!$B$3,SUMIFS('RAW_농산물_7월'!$H:$H,'RAW_농산물_7월'!$A:$A,H$29,'RAW_농산물_7월'!$B:$B,$B33),SUMIFS('RAW_농산물_8월'!$H:$H,'RAW_농산물_8월'!$A:$A,H$29,'RAW_농산물_8월'!$B:$B,$B33),SUMIFS('RAW_농산물_9월'!$H:$H,'RAW_농산물_9월'!$A:$A,H$29,'RAW_농산물_9월'!$B:$B,$B33),SUMIFS('RAW_농산물_10월'!$H:$H,'RAW_농산물_10월'!$A:$A,H$29,'RAW_농산물_10월'!$B:$B,$B33),SUMIFS('RAW_농산물_11-12월'!$H:$H,'RAW_농산물_11-12월'!$A:$A,H$29,'RAW_농산물_11-12월'!$B:$B,$B33))) -> 1610261 | I33: =IF('설정'!$B$3=0,"",CHOOSE('설정'!$B$3,SUMIFS('RAW_농산물_7월'!$H:$H,'RAW_농산물_7월'!$A:$A,I$29,'RAW_농산물_7월'!$B:$B,$B33),SUMIFS('RAW_농산물_8월'!$H:$H,'RAW_농산물_8월'!$A:$A,I$29,'RAW_농산물_8월'!$B:$B,$B33),SUMIFS('RAW_농산물_9월'!$H:$H,'RAW_농산물_9월'!$A:$A,I$29,'RAW_농산물_9월'!$B:$B,$B33),SUMIFS('RAW_농산물_10월'!$H:$H,'RAW_농산물_10월'!$A:$A,I$29,'RAW_농산물_10월'!$B:$B,$B33),SUMIFS('RAW_농산물_11-12월'!$H:$H,'RAW_농산물_11-12월'!$A:$A,I$29,'RAW_농산물_11-12월'!$B:$B,$B33))) -> 9559420 | J33: =IF('설정'!$B$3=0,"",CHOOSE('설정'!$B$3,SUMIFS('RAW_농산물_7월'!$H:$H,'RAW_농산물_7월'!$A:$A,J$29,'RAW_농산물_7월'!$B:$B,$B33),SUMIFS('RAW_농산물_8월'!$H:$H,'RAW_농산물_8월'!$A:$A,J$29,'RAW_농산물_8월'!$B:$B,$B33),SUMIFS('RAW_농산물_9월'!$H:$H,'RAW_농산물_9월'!$A:$A,J$29,'RAW_농산물_9월'!$B:$B,$B33),SUMIFS('RAW_농산물_10월'!$H:$H,'RAW_농산물_10월'!$A:$A,J$29,'RAW_농산물_10월'!$B:$B,$B33),SUMIFS('RAW_농산물_11-12월'!$H:$H,'RAW_농산물_11-12월'!$A:$A,J$29,'RAW_농산물_11-12월'!$B:$B,$B33))) -> 7306051 | K33: =IF(COUNT(L33:M33)=0,"",SUM(L33:M33)) -> 12466564 | L33: =IF('설정'!$B$4=0,"",CHOOSE('설정'!$B$4,SUMIFS('RAW_유기농_7월'!$H:$H,'RAW_유기농_7월'!$A:$A,L$29,'RAW_유기농_7월'!$B:$B,$B33),SUMIFS('RAW_유기농_8월'!$H:$H,'RAW_유기농_8월'!$A:$A,L$29,'RAW_유기농_8월'!$B:$B,$B33),SUMIFS('RAW_유기농_9월'!$H:$H,'RAW_유기농_9월'!$A:$A,L$29,'RAW_유기농_9월'!$B:$B,$B33),SUMIFS('RAW_유기농_10월'!$H:$H,'RAW_유기농_10월'!$A:$A,L$29,'RAW_유기농_10월'!$B:$B,$B33),SUMIFS('RAW_유기농_11-12월'!$H:$H,'RAW_유기농_11-12월'!$A:$A,L$29,'RAW_유기농_11-12월'!$B:$B,$B33))) -> 3143230 | M33: =IF('설정'!$B$4=0,"",CHOOSE('설정'!$B$4,SUMIFS('RAW_유기농_7월'!$H:$H,'RAW_유기농_7월'!$A:$A,M$29,'RAW_유기농_7월'!$B:$B,$B33),SUMIFS('RAW_유기농_8월'!$H:$H,'RAW_유기농_8월'!$A:$A,M$29,'RAW_유기농_8월'!$B:$B,$B33),SUMIFS('RAW_유기농_9월'!$H:$H,'RAW_유기농_9월'!$A:$A,M$29,'RAW_유기농_9월'!$B:$B,$B33),SUMIFS('RAW_유기농_10월'!$H:$H,'RAW_유기농_10월'!$A:$A,M$29,'RAW_유기농_10월'!$B:$B,$B33),SUMIFS('RAW_유기농_11-12월'!$H:$H,'RAW_유기농_11-12월'!$A:$A,M$29,'RAW_유기농_11-12월'!$B:$B,$B33))) -> 9323334
B35: 6. 유통사별 품목별 매출 분석 (누적)
B36: 구분 | C36: 총 계 | D36: 농부가바로팜 | K36: 친환경
D37: 소 계 | E37: 네이버 | F37: 지마켓 | G37: 롯데ON | H37: 온누리마켓 | I37: 농가살리기 | J37: 오아시스 | K37: 소 계 | L37: 네이버 | M37: 오아시스
B38: 총 계 | C38: =IF(COUNT(D38,K38)=0,"",SUM(D38,K38)) -> 7680466070 | D38: =IF(COUNT(E38:J38)=0,"",SUM(E38:J38)) -> 6227333500 | E38: =IF(COUNT(E39:E41)=0,"",SUM(E39:E41)) -> 2902192570 | F38: =IF(COUNT(F39:F41)=0,"",SUM(F39:F41)) -> 1348440770 | G38: =IF(COUNT(G39:G41)=0,"",SUM(G39:G41)) -> 344053620 | H38: =IF(COUNT(H39:H41)=0,"",SUM(H39:H41)) -> 100008000 | I38: =IF(COUNT(I39:I41)=0,"",SUM(I39:I41)) -> 470341670 | J38: =IF(COUNT(J39:J41)=0,"",SUM(J39:J41)) -> 1062296870 | K38: =IF(COUNT(L38:M38)=0,"",SUM(L38:M38)) -> 1453132570 | L38: =IF(COUNT(L39:L41)=0,"",SUM(L39:L41)) -> 271526720 | M38: =IF(COUNT(M39:M41)=0,"",SUM(M39:M41)) -> 1181605850
B39: 농산물 | C39: =IF(COUNT(D39,K39)=0,"",SUM(D39,K39)) -> 4286425011 | D39: =IF(COUNT(E39:J39)=0,"",SUM(E39:J39)) -> 3090856741 | E39: =IF('설정'!$B$3=0,"",CHOOSE('설정'!$B$3,SUMIFS('RAW_농산물_7월'!$G:$G,'RAW_농산물_7월'!$A:$A,E$37,'RAW_농산물_7월'!$B:$B,$B39),SUMIFS('RAW_농산물_8월'!$G:$G,'RAW_농산물_8월'!$A:$A,E$37,'RAW_농산물_8월'!$B:$B,$B39),SUMIFS('RAW_농산물_9월'!$G:$G,'RAW_농산물_9월'!$A:$A,E$37,'RAW_농산물_9월'!$B:$B,$B39),SUMIFS('RAW_농산물_10월'!$G:$G,'RAW_농산물_10월'!$A:$A,E$37,'RAW_농산물_10월'!$B:$B,$B39),SUMIFS('RAW_농산물_11-12월'!$G:$G,'RAW_농산물_11-12월'!$A:$A,E$37,'RAW_농산물_11-12월'!$B:$B,$B39))) -> 1472512820 | F39: =IF('설정'!$B$3=0,"",CHOOSE('설정'!$B$3,SUMIFS('RAW_농산물_7월'!$G:$G,'RAW_농산물_7월'!$A:$A,F$37,'RAW_농산물_7월'!$B:$B,$B39),SUMIFS('RAW_농산물_8월'!$G:$G,'RAW_농산물_8월'!$A:$A,F$37,'RAW_농산물_8월'!$B:$B,$B39),SUMIFS('RAW_농산물_9월'!$G:$G,'RAW_농산물_9월'!$A:$A,F$37,'RAW_농산물_9월'!$B:$B,$B39),SUMIFS('RAW_농산물_10월'!$G:$G,'RAW_농산물_10월'!$A:$A,F$37,'RAW_농산물_10월'!$B:$B,$B39),SUMIFS('RAW_농산물_11-12월'!$G:$G,'RAW_농산물_11-12월'!$A:$A,F$37,'RAW_농산물_11-12월'!$B:$B,$B39))) -> 653112810 | G39: =IF('설정'!$B$3=0,"",CHOOSE('설정'!$B$3,SUMIFS('RAW_농산물_7월'!$G:$G,'RAW_농산물_7월'!$A:$A,G$37,'RAW_농산물_7월'!$B:$B,$B39),SUMIFS('RAW_농산물_8월'!$G:$G,'RAW_농산물_8월'!$A:$A,G$37,'RAW_농산물_8월'!$B:$B,$B39),SUMIFS('RAW_농산물_9월'!$G:$G,'RAW_농산물_9월'!$A:$A,G$37,'RAW_농산물_9월'!$B:$B,$B39),SUMIFS('RAW_농산물_10월'!$G:$G,'RAW_농산물_10월'!$A:$A,G$37,'RAW_농산물_10월'!$B:$B,$B39),SUMIFS('RAW_농산물_11-12월'!$G:$G,'RAW_농산물_11-12월'!$A:$A,G$37,'RAW_농산물_11-12월'!$B:$B,$B39))) -> 104177000 | H39: =IF('설정'!$B$3=0,"",CHOOSE('설정'!$B$3,SUMIFS('RAW_농산물_7월'!$G:$G,'RAW_농산물_7월'!$A:$A,H$37,'RAW_농산물_7월'!$B:$B,$B39),SUMIFS('RAW_농산물_8월'!$G:$G,'RAW_농산물_8월'!$A:$A,H$37,'RAW_농산물_8월'!$B:$B,$B39),SUMIFS('RAW_농산물_9월'!$G:$G,'RAW_농산물_9월'!$A:$A,H$37,'RAW_농산물_9월'!$B:$B,$B39),SUMIFS('RAW_농산물_10월'!$G:$G,'RAW_농산물_10월'!$A:$A,H$37,'RAW_농산물_10월'!$B:$B,$B39),SUMIFS('RAW_농산물_11-12월'!$G:$G,'RAW_농산물_11-12월'!$A:$A,H$37,'RAW_농산물_11-12월'!$B:$B,$B39))) -> 88974300 | I39: =IF('설정'!$B$3=0,"",CHOOSE('설정'!$B$3,SUMIFS('RAW_농산물_7월'!$G:$G,'RAW_농산물_7월'!$A:$A,I$37,'RAW_농산물_7월'!$B:$B,$B39),SUMIFS('RAW_농산물_8월'!$G:$G,'RAW_농산물_8월'!$A:$A,I$37,'RAW_농산물_8월'!$B:$B,$B39),SUMIFS('RAW_농산물_9월'!$G:$G,'RAW_농산물_9월'!$A:$A,I$37,'RAW_농산물_9월'!$B:$B,$B39),SUMIFS('RAW_농산물_10월'!$G:$G,'RAW_농산물_10월'!$A:$A,I$37,'RAW_농산물_10월'!$B:$B,$B39),SUMIFS('RAW_농산물_11-12월'!$G:$G,'RAW_농산물_11-12월'!$A:$A,I$37,'RAW_농산물_11-12월'!$B:$B,$B39))) -> 66872001 | J39: =IF('설정'!$B$3=0,"",CHOOSE('설정'!$B$3,SUMIFS('RAW_농산물_7월'!$G:$G,'RAW_농산물_7월'!$A:$A,J$37,'RAW_농산물_7월'!$B:$B,$B39),SUMIFS('RAW_농산물_8월'!$G:$G,'RAW_농산물_8월'!$A:$A,J$37,'RAW_농산물_8월'!$B:$B,$B39),SUMIFS('RAW_농산물_9월'!$G:$G,'RAW_농산물_9월'!$A:$A,J$37,'RAW_농산물_9월'!$B:$B,$B39),SUMIFS('RAW_농산물_10월'!$G:$G,'RAW_농산물_10월'!$A:$A,J$37,'RAW_농산물_10월'!$B:$B,$B39),SUMIFS('RAW_농산물_11-12월'!$G:$G,'RAW_농산물_11-12월'!$A:$A,J$37,'RAW_농산물_11-12월'!$B:$B,$B39))) -> 705207810 | K39: =IF(COUNT(L39:M39)=0,"",SUM(L39:M39)) -> 1195568270 | L39: =IF('설정'!$B$4=0,"",CHOOSE('설정'!$B$4,SUMIFS('RAW_유기농_7월'!$G:$G,'RAW_유기농_7월'!$A:$A,L$37,'RAW_유기농_7월'!$B:$B,$B39),SUMIFS('RAW_유기농_8월'!$G:$G,'RAW_유기농_8월'!$A:$A,L$37,'RAW_유기농_8월'!$B:$B,$B39),SUMIFS('RAW_유기농_9월'!$G:$G,'RAW_유기농_9월'!$A:$A,L$37,'RAW_유기농_9월'!$B:$B,$B39),SUMIFS('RAW_유기농_10월'!$G:$G,'RAW_유기농_10월'!$A:$A,L$37,'RAW_유기농_10월'!$B:$B,$B39),SUMIFS('RAW_유기농_11-12월'!$G:$G,'RAW_유기농_11-12월'!$A:$A,L$37,'RAW_유기농_11-12월'!$B:$B,$B39))) -> 242284460 | M39: =IF('설정'!$B$4=0,"",CHOOSE('설정'!$B$4,SUMIFS('RAW_유기농_7월'!$G:$G,'RAW_유기농_7월'!$A:$A,M$37,'RAW_유기농_7월'!$B:$B,$B39),SUMIFS('RAW_유기농_8월'!$G:$G,'RAW_유기농_8월'!$A:$A,M$37,'RAW_유기농_8월'!$B:$B,$B39),SUMIFS('RAW_유기농_9월'!$G:$G,'RAW_유기농_9월'!$A:$A,M$37,'RAW_유기농_9월'!$B:$B,$B39),SUMIFS('RAW_유기농_10월'!$G:$G,'RAW_유기농_10월'!$A:$A,M$37,'RAW_유기농_10월'!$B:$B,$B39),SUMIFS('RAW_유기농_11-12월'!$G:$G,'RAW_유기농_11-12월'!$A:$A,M$37,'RAW_유기농_11-12월'!$B:$B,$B39))) -> 953283810
B40: 축산물 | C40: =IF(COUNT(D40,K40)=0,"",SUM(D40,K40)) -> 791748100 | D40: =IF(COUNT(E40:J40)=0,"",SUM(E40:J40)) -> 783864300 | E40: =IF('설정'!$B$3=0,"",CHOOSE('설정'!$B$3,SUMIFS('RAW_농산물_7월'!$G:$G,'RAW_농산물_7월'!$A:$A,E$37,'RAW_농산물_7월'!$B:$B,$B40),SUMIFS('RAW_농산물_8월'!$G:$G,'RAW_농산물_8월'!$A:$A,E$37,'RAW_농산물_8월'!$B:$B,$B40),SUMIFS('RAW_농산물_9월'!$G:$G,'RAW_농산물_9월'!$A:$A,E$37,'RAW_농산물_9월'!$B:$B,$B40),SUMIFS('RAW_농산물_10월'!$G:$G,'RAW_농산물_10월'!$A:$A,E$37,'RAW_농산물_10월'!$B:$B,$B40),SUMIFS('RAW_농산물_11-12월'!$G:$G,'RAW_농산물_11-12월'!$A:$A,E$37,'RAW_농산물_11-12월'!$B:$B,$B40))) -> 368913310 | F40: =IF('설정'!$B$3=0,"",CHOOSE('설정'!$B$3,SUMIFS('RAW_농산물_7월'!$G:$G,'RAW_농산물_7월'!$A:$A,F$37,'RAW_농산물_7월'!$B:$B,$B40),SUMIFS('RAW_농산물_8월'!$G:$G,'RAW_농산물_8월'!$A:$A,F$37,'RAW_농산물_8월'!$B:$B,$B40),SUMIFS('RAW_농산물_9월'!$G:$G,'RAW_농산물_9월'!$A:$A,F$37,'RAW_농산물_9월'!$B:$B,$B40),SUMIFS('RAW_농산물_10월'!$G:$G,'RAW_농산물_10월'!$A:$A,F$37,'RAW_농산물_10월'!$B:$B,$B40),SUMIFS('RAW_농산물_11-12월'!$G:$G,'RAW_농산물_11-12월'!$A:$A,F$37,'RAW_농산물_11-12월'!$B:$B,$B40))) -> 129058120 | G40: =IF('설정'!$B$3=0,"",CHOOSE('설정'!$B$3,SUMIFS('RAW_농산물_7월'!$G:$G,'RAW_농산물_7월'!$A:$A,G$37,'RAW_농산물_7월'!$B:$B,$B40),SUMIFS('RAW_농산물_8월'!$G:$G,'RAW_농산물_8월'!$A:$A,G$37,'RAW_농산물_8월'!$B:$B,$B40),SUMIFS('RAW_농산물_9월'!$G:$G,'RAW_농산물_9월'!$A:$A,G$37,'RAW_농산물_9월'!$B:$B,$B40),SUMIFS('RAW_농산물_10월'!$G:$G,'RAW_농산물_10월'!$A:$A,G$37,'RAW_농산물_10월'!$B:$B,$B40),SUMIFS('RAW_농산물_11-12월'!$G:$G,'RAW_농산물_11-12월'!$A:$A,G$37,'RAW_농산물_11-12월'!$B:$B,$B40))) -> 171052770 | H40: =IF('설정'!$B$3=0,"",CHOOSE('설정'!$B$3,SUMIFS('RAW_농산물_7월'!$G:$G,'RAW_농산물_7월'!$A:$A,H$37,'RAW_농산물_7월'!$B:$B,$B40),SUMIFS('RAW_농산물_8월'!$G:$G,'RAW_농산물_8월'!$A:$A,H$37,'RAW_농산물_8월'!$B:$B,$B40),SUMIFS('RAW_농산물_9월'!$G:$G,'RAW_농산물_9월'!$A:$A,H$37,'RAW_농산물_9월'!$B:$B,$B40),SUMIFS('RAW_농산물_10월'!$G:$G,'RAW_농산물_10월'!$A:$A,H$37,'RAW_농산물_10월'!$B:$B,$B40),SUMIFS('RAW_농산물_11-12월'!$G:$G,'RAW_농산물_11-12월'!$A:$A,H$37,'RAW_농산물_11-12월'!$B:$B,$B40))) -> 0 | I40: =IF('설정'!$B$3=0,"",CHOOSE('설정'!$B$3,SUMIFS('RAW_농산물_7월'!$G:$G,'RAW_농산물_7월'!$A:$A,I$37,'RAW_농산물_7월'!$B:$B,$B40),SUMIFS('RAW_농산물_8월'!$G:$G,'RAW_농산물_8월'!$A:$A,I$37,'RAW_농산물_8월'!$B:$B,$B40),SUMIFS('RAW_농산물_9월'!$G:$G,'RAW_농산물_9월'!$A:$A,I$37,'RAW_농산물_9월'!$B:$B,$B40),SUMIFS('RAW_농산물_10월'!$G:$G,'RAW_농산물_10월'!$A:$A,I$37,'RAW_농산물_10월'!$B:$B,$B40),SUMIFS('RAW_농산물_11-12월'!$G:$G,'RAW_농산물_11-12월'!$A:$A,I$37,'RAW_농산물_11-12월'!$B:$B,$B40))) -> 0 | J40: =IF('설정'!$B$3=0,"",CHOOSE('설정'!$B$3,SUMIFS('RAW_농산물_7월'!$G:$G,'RAW_농산물_7월'!$A:$A,J$37,'RAW_농산물_7월'!$B:$B,$B40),SUMIFS('RAW_농산물_8월'!$G:$G,'RAW_농산물_8월'!$A:$A,J$37,'RAW_농산물_8월'!$B:$B,$B40),SUMIFS('RAW_농산물_9월'!$G:$G,'RAW_농산물_9월'!$A:$A,J$37,'RAW_농산물_9월'!$B:$B,$B40),SUMIFS('RAW_농산물_10월'!$G:$G,'RAW_농산물_10월'!$A:$A,J$37,'RAW_농산물_10월'!$B:$B,$B40),SUMIFS('RAW_농산물_11-12월'!$G:$G,'RAW_농산물_11-12월'!$A:$A,J$37,'RAW_농산물_11-12월'!$B:$B,$B40))) -> 114840100 | K40: =IF(COUNT(L40:M40)=0,"",SUM(L40:M40)) -> 7883800 | L40: =IF('설정'!$B$4=0,"",CHOOSE('설정'!$B$4,SUMIFS('RAW_유기농_7월'!$G:$G,'RAW_유기농_7월'!$A:$A,L$37,'RAW_유기농_7월'!$B:$B,$B40),SUMIFS('RAW_유기농_8월'!$G:$G,'RAW_유기농_8월'!$A:$A,L$37,'RAW_유기농_8월'!$B:$B,$B40),SUMIFS('RAW_유기농_9월'!$G:$G,'RAW_유기농_9월'!$A:$A,L$37,'RAW_유기농_9월'!$B:$B,$B40),SUMIFS('RAW_유기농_10월'!$G:$G,'RAW_유기농_10월'!$A:$A,L$37,'RAW_유기농_10월'!$B:$B,$B40),SUMIFS('RAW_유기농_11-12월'!$G:$G,'RAW_유기농_11-12월'!$A:$A,L$37,'RAW_유기농_11-12월'!$B:$B,$B40))) -> 247000 | M40: =IF('설정'!$B$4=0,"",CHOOSE('설정'!$B$4,SUMIFS('RAW_유기농_7월'!$G:$G,'RAW_유기농_7월'!$A:$A,M$37,'RAW_유기농_7월'!$B:$B,$B40),SUMIFS('RAW_유기농_8월'!$G:$G,'RAW_유기농_8월'!$A:$A,M$37,'RAW_유기농_8월'!$B:$B,$B40),SUMIFS('RAW_유기농_9월'!$G:$G,'RAW_유기농_9월'!$A:$A,M$37,'RAW_유기농_9월'!$B:$B,$B40),SUMIFS('RAW_유기농_10월'!$G:$G,'RAW_유기농_10월'!$A:$A,M$37,'RAW_유기농_10월'!$B:$B,$B40),SUMIFS('RAW_유기농_11-12월'!$G:$G,'RAW_유기농_11-12월'!$A:$A,M$37,'RAW_유기농_11-12월'!$B:$B,$B40))) -> 7636800
B41: 가공식품 | C41: =IF(COUNT(D41,K41)=0,"",SUM(D41,K41)) -> 2602292959 | D41: =IF(COUNT(E41:J41)=0,"",SUM(E41:J41)) -> 2352612459 | E41: =IF('설정'!$B$3=0,"",CHOOSE('설정'!$B$3,SUMIFS('RAW_농산물_7월'!$G:$G,'RAW_농산물_7월'!$A:$A,E$37,'RAW_농산물_7월'!$B:$B,$B41),SUMIFS('RAW_농산물_8월'!$G:$G,'RAW_농산물_8월'!$A:$A,E$37,'RAW_농산물_8월'!$B:$B,$B41),SUMIFS('RAW_농산물_9월'!$G:$G,'RAW_농산물_9월'!$A:$A,E$37,'RAW_농산물_9월'!$B:$B,$B41),SUMIFS('RAW_농산물_10월'!$G:$G,'RAW_농산물_10월'!$A:$A,E$37,'RAW_농산물_10월'!$B:$B,$B41),SUMIFS('RAW_농산물_11-12월'!$G:$G,'RAW_농산물_11-12월'!$A:$A,E$37,'RAW_농산물_11-12월'!$B:$B,$B41))) -> 1060766440 | F41: =IF('설정'!$B$3=0,"",CHOOSE('설정'!$B$3,SUMIFS('RAW_농산물_7월'!$G:$G,'RAW_농산물_7월'!$A:$A,F$37,'RAW_농산물_7월'!$B:$B,$B41),SUMIFS('RAW_농산물_8월'!$G:$G,'RAW_농산물_8월'!$A:$A,F$37,'RAW_농산물_8월'!$B:$B,$B41),SUMIFS('RAW_농산물_9월'!$G:$G,'RAW_농산물_9월'!$A:$A,F$37,'RAW_농산물_9월'!$B:$B,$B41),SUMIFS('RAW_농산물_10월'!$G:$G,'RAW_농산물_10월'!$A:$A,F$37,'RAW_농산물_10월'!$B:$B,$B41),SUMIFS('RAW_농산물_11-12월'!$G:$G,'RAW_농산물_11-12월'!$A:$A,F$37,'RAW_농산물_11-12월'!$B:$B,$B41))) -> 566269840 | G41: =IF('설정'!$B$3=0,"",CHOOSE('설정'!$B$3,SUMIFS('RAW_농산물_7월'!$G:$G,'RAW_농산물_7월'!$A:$A,G$37,'RAW_농산물_7월'!$B:$B,$B41),SUMIFS('RAW_농산물_8월'!$G:$G,'RAW_농산물_8월'!$A:$A,G$37,'RAW_농산물_8월'!$B:$B,$B41),SUMIFS('RAW_농산물_9월'!$G:$G,'RAW_농산물_9월'!$A:$A,G$37,'RAW_농산물_9월'!$B:$B,$B41),SUMIFS('RAW_농산물_10월'!$G:$G,'RAW_농산물_10월'!$A:$A,G$37,'RAW_농산물_10월'!$B:$B,$B41),SUMIFS('RAW_농산물_11-12월'!$G:$G,'RAW_농산물_11-12월'!$A:$A,G$37,'RAW_농산물_11-12월'!$B:$B,$B41))) -> 68823850 | H41: =IF('설정'!$B$3=0,"",CHOOSE('설정'!$B$3,SUMIFS('RAW_농산물_7월'!$G:$G,'RAW_농산물_7월'!$A:$A,H$37,'RAW_농산물_7월'!$B:$B,$B41),SUMIFS('RAW_농산물_8월'!$G:$G,'RAW_농산물_8월'!$A:$A,H$37,'RAW_농산물_8월'!$B:$B,$B41),SUMIFS('RAW_농산물_9월'!$G:$G,'RAW_농산물_9월'!$A:$A,H$37,'RAW_농산물_9월'!$B:$B,$B41),SUMIFS('RAW_농산물_10월'!$G:$G,'RAW_농산물_10월'!$A:$A,H$37,'RAW_농산물_10월'!$B:$B,$B41),SUMIFS('RAW_농산물_11-12월'!$G:$G,'RAW_농산물_11-12월'!$A:$A,H$37,'RAW_농산물_11-12월'!$B:$B,$B41))) -> 11033700 | I41: =IF('설정'!$B$3=0,"",CHOOSE('설정'!$B$3,SUMIFS('RAW_농산물_7월'!$G:$G,'RAW_농산물_7월'!$A:$A,I$37,'RAW_농산물_7월'!$B:$B,$B41),SUMIFS('RAW_농산물_8월'!$G:$G,'RAW_농산물_8월'!$A:$A,I$37,'RAW_농산물_8월'!$B:$B,$B41),SUMIFS('RAW_농산물_9월'!$G:$G,'RAW_농산물_9월'!$A:$A,I$37,'RAW_농산물_9월'!$B:$B,$B41),SUMIFS('RAW_농산물_10월'!$G:$G,'RAW_농산물_10월'!$A:$A,I$37,'RAW_농산물_10월'!$B:$B,$B41),SUMIFS('RAW_농산물_11-12월'!$G:$G,'RAW_농산물_11-12월'!$A:$A,I$37,'RAW_농산물_11-12월'!$B:$B,$B41))) -> 403469669 | J41: =IF('설정'!$B$3=0,"",CHOOSE('설정'!$B$3,SUMIFS('RAW_농산물_7월'!$G:$G,'RAW_농산물_7월'!$A:$A,J$37,'RAW_농산물_7월'!$B:$B,$B41),SUMIFS('RAW_농산물_8월'!$G:$G,'RAW_농산물_8월'!$A:$A,J$37,'RAW_농산물_8월'!$B:$B,$B41),SUMIFS('RAW_농산물_9월'!$G:$G,'RAW_농산물_9월'!$A:$A,J$37,'RAW_농산물_9월'!$B:$B,$B41),SUMIFS('RAW_농산물_10월'!$G:$G,'RAW_농산물_10월'!$A:$A,J$37,'RAW_농산물_10월'!$B:$B,$B41),SUMIFS('RAW_농산물_11-12월'!$G:$G,'RAW_농산물_11-12월'!$A:$A,J$37,'RAW_농산물_11-12월'!$B:$B,$B41))) -> 242248960 | K41: =IF(COUNT(L41:M41)=0,"",SUM(L41:M41)) -> 249680500 | L41: =IF('설정'!$B$4=0,"",CHOOSE('설정'!$B$4,SUMIFS('RAW_유기농_7월'!$G:$G,'RAW_유기농_7월'!$A:$A,L$37,'RAW_유기농_7월'!$B:$B,$B41),SUMIFS('RAW_유기농_8월'!$G:$G,'RAW_유기농_8월'!$A:$A,L$37,'RAW_유기농_8월'!$B:$B,$B41),SUMIFS('RAW_유기농_9월'!$G:$G,'RAW_유기농_9월'!$A:$A,L$37,'RAW_유기농_9월'!$B:$B,$B41),SUMIFS('RAW_유기농_10월'!$G:$G,'RAW_유기농_10월'!$A:$A,L$37,'RAW_유기농_10월'!$B:$B,$B41),SUMIFS('RAW_유기농_11-12월'!$G:$G,'RAW_유기농_11-12월'!$A:$A,L$37,'RAW_유기농_11-12월'!$B:$B,$B41))) -> 28995260 | M41: =IF('설정'!$B$4=0,"",CHOOSE('설정'!$B$4,SUMIFS('RAW_유기농_7월'!$G:$G,'RAW_유기농_7월'!$A:$A,M$37,'RAW_유기농_7월'!$B:$B,$B41),SUMIFS('RAW_유기농_8월'!$G:$G,'RAW_유기농_8월'!$A:$A,M$37,'RAW_유기농_8월'!$B:$B,$B41),SUMIFS('RAW_유기농_9월'!$G:$G,'RAW_유기농_9월'!$A:$A,M$37,'RAW_유기농_9월'!$B:$B,$B41),SUMIFS('RAW_유기농_10월'!$G:$G,'RAW_유기농_10월'!$A:$A,M$37,'RAW_유기농_10월'!$B:$B,$B41),SUMIFS('RAW_유기농_11-12월'!$G:$G,'RAW_유기농_11-12월'!$A:$A,M$37,'RAW_유기농_11-12월'!$B:$B,$B41))) -> 220685240
B43: 7. 유통사별 품목별 판매 건수 (누적)
B44: 구분 | C44: 총 계 | D44: 농부가바로팜 | K44: 친환경
D45: 소 계 | E45: 네이버 | F45: 지마켓 | G45: 롯데ON | H45: 온누리마켓 | I45: 농가살리기 | J45: 오아시스 | K45: 소 계 | L45: 네이버 | M45: 오아시스
B46: 총 계 | C46: =IF(COUNT(D46,K46)=0,"",SUM(D46,K46)) -> 756125 | D46: =IF(COUNT(E46:J46)=0,"",SUM(E46:J46)) -> 475218 | E46: =IF(COUNT(E47:E49)=0,"",SUM(E47:E49)) -> 108140 | F46: =IF(COUNT(F47:F49)=0,"",SUM(F47:F49)) -> 68093 | G46: =IF(COUNT(G47:G49)=0,"",SUM(G47:G49)) -> 13595 | H46: =IF(COUNT(H47:H49)=0,"",SUM(H47:H49)) -> 3100 | I46: =IF(COUNT(I47:I49)=0,"",SUM(I47:I49)) -> 30683 | J46: =IF(COUNT(J47:J49)=0,"",SUM(J47:J49)) -> 251607 | K46: =IF(COUNT(L46:M46)=0,"",SUM(L46:M46)) -> 280907 | L46: =IF(COUNT(L47:L49)=0,"",SUM(L47:L49)) -> 10898 | M46: =IF(COUNT(M47:M49)=0,"",SUM(M47:M49)) -> 270009
B47: 농산물 | C47: =IF(COUNT(D47,K47)=0,"",SUM(D47,K47)) -> 521013 | D47: =IF(COUNT(E47:J47)=0,"",SUM(E47:J47)) -> 290861 | E47: =IF('설정'!$B$3=0,"",CHOOSE('설정'!$B$3,SUMIFS('RAW_농산물_7월'!$F:$F,'RAW_농산물_7월'!$A:$A,E$45,'RAW_농산물_7월'!$B:$B,$B47),SUMIFS('RAW_농산물_8월'!$F:$F,'RAW_농산물_8월'!$A:$A,E$45,'RAW_농산물_8월'!$B:$B,$B47),SUMIFS('RAW_농산물_9월'!$F:$F,'RAW_농산물_9월'!$A:$A,E$45,'RAW_농산물_9월'!$B:$B,$B47),SUMIFS('RAW_농산물_10월'!$F:$F,'RAW_농산물_10월'!$A:$A,E$45,'RAW_농산물_10월'!$B:$B,$B47),SUMIFS('RAW_농산물_11-12월'!$F:$F,'RAW_농산물_11-12월'!$A:$A,E$45,'RAW_농산물_11-12월'!$B:$B,$B47))) -> 54773 | F47: =IF('설정'!$B$3=0,"",CHOOSE('설정'!$B$3,SUMIFS('RAW_농산물_7월'!$F:$F,'RAW_농산물_7월'!$A:$A,F$45,'RAW_농산물_7월'!$B:$B,$B47),SUMIFS('RAW_농산물_8월'!$F:$F,'RAW_농산물_8월'!$A:$A,F$45,'RAW_농산물_8월'!$B:$B,$B47),SUMIFS('RAW_농산물_9월'!$F:$F,'RAW_농산물_9월'!$A:$A,F$45,'RAW_농산물_9월'!$B:$B,$B47),SUMIFS('RAW_농산물_10월'!$F:$F,'RAW_농산물_10월'!$A:$A,F$45,'RAW_농산물_10월'!$B:$B,$B47),SUMIFS('RAW_농산물_11-12월'!$F:$F,'RAW_농산물_11-12월'!$A:$A,F$45,'RAW_농산물_11-12월'!$B:$B,$B47))) -> 30320 | G47: =IF('설정'!$B$3=0,"",CHOOSE('설정'!$B$3,SUMIFS('RAW_농산물_7월'!$F:$F,'RAW_농산물_7월'!$A:$A,G$45,'RAW_농산물_7월'!$B:$B,$B47),SUMIFS('RAW_농산물_8월'!$F:$F,'RAW_농산물_8월'!$A:$A,G$45,'RAW_농산물_8월'!$B:$B,$B47),SUMIFS('RAW_농산물_9월'!$F:$F,'RAW_농산물_9월'!$A:$A,G$45,'RAW_농산물_9월'!$B:$B,$B47),SUMIFS('RAW_농산물_10월'!$F:$F,'RAW_농산물_10월'!$A:$A,G$45,'RAW_농산물_10월'!$B:$B,$B47),SUMIFS('RAW_농산물_11-12월'!$F:$F,'RAW_농산물_11-12월'!$A:$A,G$45,'RAW_농산물_11-12월'!$B:$B,$B47))) -> 6030 | H47: =IF('설정'!$B$3=0,"",CHOOSE('설정'!$B$3,SUMIFS('RAW_농산물_7월'!$F:$F,'RAW_농산물_7월'!$A:$A,H$45,'RAW_농산물_7월'!$B:$B,$B47),SUMIFS('RAW_농산물_8월'!$F:$F,'RAW_농산물_8월'!$A:$A,H$45,'RAW_농산물_8월'!$B:$B,$B47),SUMIFS('RAW_농산물_9월'!$F:$F,'RAW_농산물_9월'!$A:$A,H$45,'RAW_농산물_9월'!$B:$B,$B47),SUMIFS('RAW_농산물_10월'!$F:$F,'RAW_농산물_10월'!$A:$A,H$45,'RAW_농산물_10월'!$B:$B,$B47),SUMIFS('RAW_농산물_11-12월'!$F:$F,'RAW_농산물_11-12월'!$A:$A,H$45,'RAW_농산물_11-12월'!$B:$B,$B47))) -> 2612 | I47: =IF('설정'!$B$3=0,"",CHOOSE('설정'!$B$3,SUMIFS('RAW_농산물_7월'!$F:$F,'RAW_농산물_7월'!$A:$A,I$45,'RAW_농산물_7월'!$B:$B,$B47),SUMIFS('RAW_농산물_8월'!$F:$F,'RAW_농산물_8월'!$A:$A,I$45,'RAW_농산물_8월'!$B:$B,$B47),SUMIFS('RAW_농산물_9월'!$F:$F,'RAW_농산물_9월'!$A:$A,I$45,'RAW_농산물_9월'!$B:$B,$B47),SUMIFS('RAW_농산물_10월'!$F:$F,'RAW_농산물_10월'!$A:$A,I$45,'RAW_농산물_10월'!$B:$B,$B47),SUMIFS('RAW_농산물_11-12월'!$F:$F,'RAW_농산물_11-12월'!$A:$A,I$45,'RAW_농산물_11-12월'!$B:$B,$B47))) -> 4345 | J47: =IF('설정'!$B$3=0,"",CHOOSE('설정'!$B$3,SUMIFS('RAW_농산물_7월'!$F:$F,'RAW_농산물_7월'!$A:$A,J$45,'RAW_농산물_7월'!$B:$B,$B47),SUMIFS('RAW_농산물_8월'!$F:$F,'RAW_농산물_8월'!$A:$A,J$45,'RAW_농산물_8월'!$B:$B,$B47),SUMIFS('RAW_농산물_9월'!$F:$F,'RAW_농산물_9월'!$A:$A,J$45,'RAW_농산물_9월'!$B:$B,$B47),SUMIFS('RAW_농산물_10월'!$F:$F,'RAW_농산물_10월'!$A:$A,J$45,'RAW_농산물_10월'!$B:$B,$B47),SUMIFS('RAW_농산물_11-12월'!$F:$F,'RAW_농산물_11-12월'!$A:$A,J$45,'RAW_농산물_11-12월'!$B:$B,$B47))) -> 192781 | K47: =IF(COUNT(L47:M47)=0,"",SUM(L47:M47)) -> 230152 | L47: =IF('설정'!$B$4=0,"",CHOOSE('설정'!$B$4,SUMIFS('RAW_유기농_7월'!$F:$F,'RAW_유기농_7월'!$A:$A,L$45,'RAW_유기농_7월'!$B:$B,$B47),SUMIFS('RAW_유기농_8월'!$F:$F,'RAW_유기농_8월'!$A:$A,L$45,'RAW_유기농_8월'!$B:$B,$B47),SUMIFS('RAW_유기농_9월'!$F:$F,'RAW_유기농_9월'!$A:$A,L$45,'RAW_유기농_9월'!$B:$B,$B47),SUMIFS('RAW_유기농_10월'!$F:$F,'RAW_유기농_10월'!$A:$A,L$45,'RAW_유기농_10월'!$B:$B,$B47),SUMIFS('RAW_유기농_11-12월'!$F:$F,'RAW_유기농_11-12월'!$A:$A,L$45,'RAW_유기농_11-12월'!$B:$B,$B47))) -> 9770 | M47: =IF('설정'!$B$4=0,"",CHOOSE('설정'!$B$4,SUMIFS('RAW_유기농_7월'!$F:$F,'RAW_유기농_7월'!$A:$A,M$45,'RAW_유기농_7월'!$B:$B,$B47),SUMIFS('RAW_유기농_8월'!$F:$F,'RAW_유기농_8월'!$A:$A,M$45,'RAW_유기농_8월'!$B:$B,$B47),SUMIFS('RAW_유기농_9월'!$F:$F,'RAW_유기농_9월'!$A:$A,M$45,'RAW_유기농_9월'!$B:$B,$B47),SUMIFS('RAW_유기농_10월'!$F:$F,'RAW_유기농_10월'!$A:$A,M$45,'RAW_유기농_10월'!$B:$B,$B47),SUMIFS('RAW_유기농_11-12월'!$F:$F,'RAW_유기농_11-12월'!$A:$A,M$45,'RAW_유기농_11-12월'!$B:$B,$B47))) -> 220382
...

Sheet 농산물업체
E1: 합 계 → | F1: =SUM(F3:F702) -> 475218 | G1: =SUM(G3:G702) -> 6227333500 | H1: =SUM(H3:H702) -> 266369319 | I1: =COUNTIF(I3:I702,"O") -> 186 | J1: =COUNTIF(J3:J702,"O") -> 207 | K1: =COUNTIF(K3:K702,"O") -> 0 | L1: =COUNTIF(L3:L702,"O") -> 0 | M1: =COUNTIF(M3:M702,"O") -> 0 | N1: =SUM(N3:N702) -> 163578655 | O1: =SUM(O3:O702) -> 102790664 | P1: =SUM(P3:P702) -> 0 | Q1: =SUM(Q3:Q702) -> 0 | R1: =SUM(R3:R702) -> 0 | S1: =COUNTIF(S3:S702,"O") -> 207 | T1: =COUNTA(C3:C702)&"개사" -> 285개사 | U1: =SUM(U3:U702) -> 1449
A2: NO | B2: 구분 | C2: 사업자등록번호 | D2: 업체명 | E2: 배정유통사 | F2: 판매건수 (누적) | G2: 매출액 (누적) | H2: 판촉액 (누적) | I2: 7월 인입 | J2: 8월 인입 | K2: 9월 인입 | L2: 10월 인입 | M2: 11~12월 인입 | N2: 7월 판촉액 | O2: 8월 판촉액 | P2: 9월 판촉액 | Q2: 10월 판촉액 | R2: 11~12월 판촉액 | S2: 상품제출 | T2: 소진구간 | U2: _커버줄수
A3: 1 | B3: 도약 | C3: 511-87-00286 | D3: 농업회사법인 영주마실(주) | E3: 롯데ON | F3: =IF($C3="","",IF('설정'!$B$3=0,"",CHOOSE('설정'!$B$3,SUMIFS('RAW_농산물_7월'!$F:$F,'RAW_농산물_7월'!$D:$D,$C3,'RAW_농산물_7월'!$A:$A,$E3),SUMIFS('RAW_농산물_8월'!$F:$F,'RAW_농산물_8월'!$D:$D,$C3,'RAW_농산물_8월'!$A:$A,$E3),SUMIFS('RAW_농산물_9월'!$F:$F,'RAW_농산물_9월'!$D:$D,$C3,'RAW_농산물_9월'!$A:$A,$E3),SUMIFS('RAW_농산물_10월'!$F:$F,'RAW_농산물_10월'!$D:$D,$C3,'RAW_농산물_10월'!$A:$A,$E3),SUMIFS('RAW_농산물_11-12월'!$F:$F,'RAW_농산물_11-12월'!$D:$D,$C3,'RAW_농산물_11-12월'!$A:$A,$E3)))) -> 0 | G3: =IF($C3="","",IF('설정'!$B$3=0,"",CHOOSE('설정'!$B$3,SUMIFS('RAW_농산물_7월'!$G:$G,'RAW_농산물_7월'!$D:$D,$C3,'RAW_농산물_7월'!$A:$A,$E3),SUMIFS('RAW_농산물_8월'!$G:$G,'RAW_농산물_8월'!$D:$D,$C3,'RAW_농산물_8월'!$A:$A,$E3),SUMIFS('RAW_농산물_9월'!$G:$G,'RAW_농산물_9월'!$D:$D,$C3,'RAW_농산물_9월'!$A:$A,$E3),SUMIFS('RAW_농산물_10월'!$G:$G,'RAW_농산물_10월'!$D:$D,$C3,'RAW_농산물_10월'!$A:$A,$E3),SUMIFS('RAW_농산물_11-12월'!$G:$G,'RAW_농산물_11-12월'!$D:$D,$C3,'RAW_농산물_11-12월'!$A:$A,$E3)))) -> 0 | H3: =IF($C3="","",IF('설정'!$B$3=0,"",CHOOSE('설정'!$B$3,SUMIFS('RAW_농산물_7월'!$H:$H,'RAW_농산물_7월'!$D:$D,$C3,'RAW_농산물_7월'!$A:$A,$E3),SUMIFS('RAW_농산물_8월'!$H:$H,'RAW_농산물_8월'!$D:$D,$C3,'RAW_농산물_8월'!$A:$A,$E3),SUMIFS('RAW_농산물_9월'!$H:$H,'RAW_농산물_9월'!$D:$D,$C3,'RAW_농산물_9월'!$A:$A,$E3),SUMIFS('RAW_농산물_10월'!$H:$H,'RAW_농산물_10월'!$D:$D,$C3,'RAW_농산물_10월'!$A:$A,$E3),SUMIFS('RAW_농산물_11-12월'!$H:$H,'RAW_농산물_11-12월'!$D:$D,$C3,'RAW_농산물_11-12월'!$A:$A,$E3)))) -> 0 | I3: =IF($C3="","",IF(COUNTIFS('RAW_농산물_7월'!$D:$D,$C3,'RAW_농산물_7월'!$A:$A,$E3)>0,"O","")) | J3: =IF($C3="","",IF(COUNTIFS('RAW_농산물_8월'!$D:$D,$C3,'RAW_농산물_8월'!$A:$A,$E3)>0,"O","")) | K3: =IF($C3="","",IF(COUNTIFS('RAW_농산물_9월'!$D:$D,$C3,'RAW_농산물_9월'!$A:$A,$E3)>0,"O","")) | L3: =IF($C3="","",IF(COUNTIFS('RAW_농산물_10월'!$D:$D,$C3,'RAW_농산물_10월'!$A:$A,$E3)>0,"O","")) | M3: =IF($C3="","",IF(COUNTIFS('RAW_농산물_11-12월'!$D:$D,$C3,'RAW_농산물_11-12월'!$A:$A,$E3)>0,"O","")) | N3: =IF($C3="","",IF(COUNTA('RAW_농산물_7월'!$A:$A)<=1,"",SUMIFS('RAW_농산물_7월'!$H:$H,'RAW_농산물_7월'!$D:$D,$C3,'RAW_농산물_7월'!$A:$A,$E3))) -> 0 | O3: =IF($C3="","",IF(COUNTA('RAW_농산물_8월'!$A:$A)<=1,"",SUMIFS('RAW_농산물_8월'!$H:$H,'RAW_농산물_8월'!$D:$D,$C3,'RAW_농산물_8월'!$A:$A,$E3)-SUMIFS('RAW_농산물_7월'!$H:$H,'RAW_농산물_7월'!$D:$D,$C3,'RAW_농산물_7월'!$A:$A,$E3))) -> 0 | P3: =IF($C3="","",IF(COUNTA('RAW_농산물_9월'!$A:$A)<=1,"",SUMIFS('RAW_농산물_9월'!$H:$H,'RAW_농산물_9월'!$D:$D,$C3,'RAW_농산물_9월'!$A:$A,$E3)-SUMIFS('RAW_농산물_8월'!$H:$H,'RAW_농산물_8월'!$D:$D,$C3,'RAW_농산물_8월'!$A:$A,$E3))) | Q3: =IF($C3="","",IF(COUNTA('RAW_농산물_10월'!$A:$A)<=1,"",SUMIFS('RAW_농산물_10월'!$H:$H,'RAW_농산물_10월'!$D:$D,$C3,'RAW_농산물_10월'!$A:$A,$E3)-SUMIFS('RAW_농산물_9월'!$H:$H,'RAW_농산물_9월'!$D:$D,$C3,'RAW_농산물_9월'!$A:$A,$E3))) | R3: =IF($C3="","",IF(COUNTA('RAW_농산물_11-12월'!$A:$A)<=1,"",SUMIFS('RAW_농산물_11-12월'!$H:$H,'RAW_농산물_11-12월'!$D:$D,$C3,'RAW_농산물_11-12월'!$A:$A,$E3)-SUMIFS('RAW_농산물_10월'!$H:$H,'RAW_농산물_10월'!$D:$D,$C3,'RAW_농산물_10월'!$A:$A,$E3))) | S3: =IF($C3="","",IF(COUNTIF($I3:$M3,"O")>0,"O","")) | T3: =IF($C3="","",IF($H3=0,"미사용",IF($H3<500000,"50만원 미만",IF($H3<1000000,"100만원 미만",IF($H3<2000000,"200만원 미만",IF($H3<3000000,"300만원 미만",IF($H3<4000000,"400만원 미만",IF($H3<5000000,"500만원 미만",IF($H3<6000000,"600만원 미만",IF($H3<7000000,"700만원 미만",IF($H3<8000000,"800만원 미만",IF($H3<10000000,"1000만원 미만","1000만원 이상")))))))))))) -> 미사용 | U3: =IF($C3="",0,IF('설정'!$B$3=0,0,CHOOSE('설정'!$B$3,COUNTIFS('RAW_농산물_7월'!$D:$D,$C3,'RAW_농산물_7월'!$A:$A,$E3),COUNTIFS('RAW_농산물_8월'!$D:$D,$C3,'RAW_농산물_8월'!$A:$A,$E3),COUNTIFS('RAW_농산물_9월'!$D:$D,$C3,'RAW_농산물_9월'!$A:$A,$E3),COUNTIFS('RAW_농산물_10월'!$D:$D,$C3,'RAW_농산물_10월'!$A:$A,$E3),COUNTIFS('RAW_농산물_11-12월'!$D:$D,$C3,'RAW_농산물_11-12월'!$A:$A,$E3)))) -> 0
A4: 2 | B4: 도약 | C4: 302-81-25814 | D4: 영동감협동조합 | E4: 롯데ON | F4: =IF($C4="","",IF('설정'!$B$3=0,"",CHOOSE('설정'!$B$3,SUMIFS('RAW_농산물_7월'!$F:$F,'RAW_농산물_7월'!$D:$D,$C4,'RAW_농산물_7월'!$A:$A,$E4),SUMIFS('RAW_농산물_8월'!$F:$F,'RAW_농산물_8월'!$D:$D,$C4,'RAW_농산물_8월'!$A:$A,$E4),SUMIFS('RAW_농산물_9월'!$F:$F,'RAW_농산물_9월'!$D:$D,$C4,'RAW_농산물_9월'!$A:$A,$E4),SUMIFS('RAW_농산물_10월'!$F:$F,'RAW_농산물_10월'!$D:$D,$C4,'RAW_농산물_10월'!$A:$A,$E4),SUMIFS('RAW_농산물_11-12월'!$F:$F,'RAW_농산물_11-12월'!$D:$D,$C4,'RAW_농산물_11-12월'!$A:$A,$E4)))) -> 8 | G4: =IF($C4="","",IF('설정'!$B$3=0,"",CHOOSE('설정'!$B$3,SUMIFS('RAW_농산물_7월'!$G:$G,'RAW_농산물_7월'!$D:$D,$C4,'RAW_농산물_7월'!$A:$A,$E4),SUMIFS('RAW_농산물_8월'!$G:$G,'RAW_농산물_8월'!$D:$D,$C4,'RAW_농산물_8월'!$A:$A,$E4),SUMIFS('RAW_농산물_9월'!$G:$G,'RAW_농산물_9월'!$D:$D,$C4,'RAW_농산물_9월'!$A:$A,$E4),SUMIFS('RAW_농산물_10월'!$G:$G,'RAW_농산물_10월'!$D:$D,$C4,'RAW_농산물_10월'!$A:$A,$E4),SUMIFS('RAW_농산물_11-12월'!$G:$G,'RAW_농산물_11-12월'!$D:$D,$C4,'RAW_농산물_11-12월'!$A:$A,$E4)))) -> 316300 | H4: =IF($C4="","",IF('설정'!$B$3=0,"",CHOOSE('설정'!$B$3,SUMIFS('RAW_농산물_7월'!$H:$H,'RAW_농산물_7월'!$D:$D,$C4,'RAW_농산물_7월'!$A:$A,$E4),SUMIFS('RAW_농산물_8월'!$H:$H,'RAW_농산물_8월'!$D:$D,$C4,'RAW_농산물_8월'!$A:$A,$E4),SUMIFS('RAW_농산물_9월'!$H:$H,'RAW_농산물_9월'!$D:$D,$C4,'RAW_농산물_9월'!$A:$A,$E4),SUMIFS('RAW_농산물_10월'!$H:$H,'RAW_농산물_10월'!$D:$D,$C4,'RAW_농산물_10월'!$A:$A,$E4),SUMIFS('RAW_농산물_11-12월'!$H:$H,'RAW_농산물_11-12월'!$D:$D,$C4,'RAW_농산물_11-12월'!$A:$A,$E4)))) -> 46330 | I4: =IF($C4="","",IF(COUNTIFS('RAW_농산물_7월'!$D:$D,$C4,'RAW_농산물_7월'!$A:$A,$E4)>0,"O","")) -> O | J4: =IF($C4="","",IF(COUNTIFS('RAW_농산물_8월'!$D:$D,$C4,'RAW_농산물_8월'!$A:$A,$E4)>0,"O","")) -> O | K4: =IF($C4="","",IF(COUNTIFS('RAW_농산물_9월'!$D:$D,$C4,'RAW_농산물_9월'!$A:$A,$E4)>0,"O","")) | L4: =IF($C4="","",IF(COUNTIFS('RAW_농산물_10월'!$D:$D,$C4,'RAW_농산물_10월'!$A:$A,$E4)>0,"O","")) | M4: =IF($C4="","",IF(COUNTIFS('RAW_농산물_11-12월'!$D:$D,$C4,'RAW_농산물_11-12월'!$A:$A,$E4)>0,"O","")) | N4: =IF($C4="","",IF(COUNTA('RAW_농산물_7월'!$A:$A)<=1,"",SUMIFS('RAW_농산물_7월'!$H:$H,'RAW_농산물_7월'!$D:$D,$C4,'RAW_농산물_7월'!$A:$A,$E4))) -> 0 | O4: =IF($C4="","",IF(COUNTA('RAW_농산물_8월'!$A:$A)<=1,"",SUMIFS('RAW_농산물_8월'!$H:$H,'RAW_농산물_8월'!$D:$D,$C4,'RAW_농산물_8월'!$A:$A,$E4)-SUMIFS('RAW_농산물_7월'!$H:$H,'RAW_농산물_7월'!$D:$D,$C4,'RAW_농산물_7월'!$A:$A,$E4))) -> 46330 | P4: =IF($C4="","",IF(COUNTA('RAW_농산물_9월'!$A:$A)<=1,"",SUMIFS('RAW_농산물_9월'!$H:$H,'RAW_농산물_9월'!$D:$D,$C4,'RAW_농산물_9월'!$A:$A,$E4)-SUMIFS('RAW_농산물_8월'!$H:$H,'RAW_농산물_8월'!$D:$D,$C4,'RAW_농산물_8월'!$A:$A,$E4))) | Q4: =IF($C4="","",IF(COUNTA('RAW_농산물_10월'!$A:$A)<=1,"",SUMIFS('RAW_농산물_10월'!$H:$H,'RAW_농산물_10월'!$D:$D,$C4,'RAW_농산물_10월'!$A:$A,$E4)-SUMIFS('RAW_농산물_9월'!$H:$H,'RAW_농산물_9월'!$D:$D,$C4,'RAW_농산물_9월'!$A:$A,$E4))) | R4: =IF($C4="","",IF(COUNTA('RAW_농산물_11-12월'!$A:$A)<=1,"",SUMIFS('RAW_농산물_11-12월'!$H:$H,'RAW_농산물_11-12월'!$D:$D,$C4,'RAW_농산물_11-12월'!$A:$A,$E4)-SUMIFS('RAW_농산물_10월'!$H:$H,'RAW_농산물_10월'!$D:$D,$C4,'RAW_농산물_10월'!$A:$A,$E4))) | S4: =IF($C4="","",IF(COUNTIF($I4:$M4,"O")>0,"O","")) -> O | T4: =IF($C4="","",IF($H4=0,"미사용",IF($H4<500000,"50만원 미만",IF($H4<1000000,"100만원 미만",IF($H4<2000000,"200만원 미만",IF($H4<3000000,"300만원 미만",IF($H4<4000000,"400만원 미만",IF($H4<5000000,"500만원 미만",IF($H4<6000000,"600만원 미만",IF($H4<7000000,"700만원 미만",IF($H4<8000000,"800만원 미만",IF($H4<10000000,"1000만원 미만","1000만원 이상")))))))))))) -> 50만원 미만 | U4: =IF($C4="",0,IF('설정'!$B$3=0,0,CHOOSE('설정'!$B$3,COUNTIFS('RAW_농산물_7월'!$D:$D,$C4,'RAW_농산물_7월'!$A:$A,$E4),COUNTIFS('RAW_농산물_8월'!$D:$D,$C4,'RAW_농산물_8월'!$A:$A,$E4),COUNTIFS('RAW_농산물_9월'!$D:$D,$C4,'RAW_농산물_9월'!$A:$A,$E4),COUNTIFS('RAW_농산물_10월'!$D:$D,$C4,'RAW_농산물_10월'!$A:$A,$E4),COUNTIFS('RAW_농산물_11-12월'!$D:$D,$C4,'RAW_농산물_11-12월'!$A:$A,$E4)))) -> 10
A5: 3 | B5: 도약 | C5: 449-92-01723 | D5: 채씨네표고농원 | E5: 네이버 | F5: =IF($C5="","",IF('설정'!$B$3=0,"",CHOOSE('설정'!$B$3,SUMIFS('RAW_농산물_7월'!$F:$F,'RAW_농산물_7월'!$D:$D,$C5,'RAW_농산물_7월'!$A:$A,$E5),SUMIFS('RAW_농산물_8월'!$F:$F,'RAW_농산물_8월'!$D:$D,$C5,'RAW_농산물_8월'!$A:$A,$E5),SUMIFS('RAW_농산물_9월'!$F:$F,'RAW_농산물_9월'!$D:$D,$C5,'RAW_농산물_9월'!$A:$A,$E5),SUMIFS('RAW_농산물_10월'!$F:$F,'RAW_농산물_10월'!$D:$D,$C5,'RAW_농산물_10월'!$A:$A,$E5),SUMIFS('RAW_농산물_11-12월'!$F:$F,'RAW_농산물_11-12월'!$D:$D,$C5,'RAW_농산물_11-12월'!$A:$A,$E5)))) -> 130 | G5: =IF($C5="","",IF('설정'!$B$3=0,"",CHOOSE('설정'!$B$3,SUMIFS('RAW_농산물_7월'!$G:$G,'RAW_농산물_7월'!$D:$D,$C5,'RAW_농산물_7월'!$A:$A,$E5),SUMIFS('RAW_농산물_8월'!$G:$G,'RAW_농산물_8월'!$D:$D,$C5,'RAW_농산물_8월'!$A:$A,$E5),SUMIFS('RAW_농산물_9월'!$G:$G,'RAW_농산물_9월'!$D:$D,$C5,'RAW_농산물_9월'!$A:$A,$E5),SUMIFS('RAW_농산물_10월'!$G:$G,'RAW_농산물_10월'!$D:$D,$C5,'RAW_농산물_10월'!$A:$A,$E5),SUMIFS('RAW_농산물_11-12월'!$G:$G,'RAW_농산물_11-12월'!$D:$D,$C5,'RAW_농산물_11-12월'!$A:$A,$E5)))) -> 4155000 | H5: =IF($C5="","",IF('설정'!$B$3=0,"",CHOOSE('설정'!$B$3,SUMIFS('RAW_농산물_7월'!$H:$H,'RAW_농산물_7월'!$D:$D,$C5,'RAW_농산물_7월'!$A:$A,$E5),SUMIFS('RAW_농산물_8월'!$H:$H,'RAW_농산물_8월'!$D:$D,$C5,'RAW_농산물_8월'!$A:$A,$E5),SUMIFS('RAW_농산물_9월'!$H:$H,'RAW_농산물_9월'!$D:$D,$C5,'RAW_농산물_9월'!$A:$A,$E5),SUMIFS('RAW_농산물_10월'!$H:$H,'RAW_농산물_10월'!$D:$D,$C5,'RAW_농산물_10월'!$A:$A,$E5),SUMIFS('RAW_농산물_11-12월'!$H:$H,'RAW_농산물_11-12월'!$D:$D,$C5,'RAW_농산물_11-12월'!$A:$A,$E5)))) -> 346200 | I5: =IF($C5="","",IF(COUNTIFS('RAW_농산물_7월'!$D:$D,$C5,'RAW_농산물_7월'!$A:$A,$E5)>0,"O","")) -> O | J5: =IF($C5="","",IF(COUNTIFS('RAW_농산물_8월'!$D:$D,$C5,'RAW_농산물_8월'!$A:$A,$E5)>0,"O","")) -> O | K5: =IF($C5="","",IF(COUNTIFS('RAW_농산물_9월'!$D:$D,$C5,'RAW_농산물_9월'!$A:$A,$E5)>0,"O","")) | L5: =IF($C5="","",IF(COUNTIFS('RAW_농산물_10월'!$D:$D,$C5,'RAW_농산물_10월'!$A:$A,$E5)>0,"O","")) | M5: =IF($C5="","",IF(COUNTIFS('RAW_농산물_11-12월'!$D:$D,$C5,'RAW_농산물_11-12월'!$A:$A,$E5)>0,"O","")) | N5: =IF($C5="","",IF(COUNTA('RAW_농산물_7월'!$A:$A)<=1,"",SUMIFS('RAW_농산물_7월'!$H:$H,'RAW_농산물_7월'!$D:$D,$C5,'RAW_농산물_7월'!$A:$A,$E5))) -> 43900 | O5: =IF($C5="","",IF(COUNTA('RAW_농산물_8월'!$A:$A)<=1,"",SUMIFS('RAW_농산물_8월'!$H:$H,'RAW_농산물_8월'!$D:$D,$C5,'RAW_농산물_8월'!$A:$A,$E5)-SUMIFS('RAW_농산물_7월'!$H:$H,'RAW_농산물_7월'!$D:$D,$C5,'RAW_농산물_7월'!$A:$A,$E5))) -> 302300 | P5: =IF($C5="","",IF(COUNTA('RAW_농산물_9월'!$A:$A)<=1,"",SUMIFS('RAW_농산물_9월'!$H:$H,'RAW_농산물_9월'!$D:$D,$C5,'RAW_농산물_9월'!$A:$A,$E5)-SUMIFS('RAW_농산물_8월'!$H:$H,'RAW_농산물_8월'!$D:$D,$C5,'RAW_농산물_8월'!$A:$A,$E5))) | Q5: =IF($C5="","",IF(COUNTA('RAW_농산물_10월'!$A:$A)<=1,"",SUMIFS('RAW_농산물_10월'!$H:$H,'RAW_농산물_10월'!$D:$D,$C5,'RAW_농산물_10월'!$A:$A,$E5)-SUMIFS('RAW_농산물_9월'!$H:$H,'RAW_농산물_9월'!$D:$D,$C5,'RAW_농산물_9월'!$A:$A,$E5))) | R5: =IF($C5="","",IF(COUNTA('RAW_농산물_11-12월'!$A:$A)<=1,"",SUMIFS('RAW_농산물_11-12월'!$H:$H,'RAW_농산물_11-12월'!$D:$D,$C5,'RAW_농산물_11-12월'!$A:$A,$E5)-SUMIFS('RAW_농산물_10월'!$H:$H,'RAW_농산물_10월'!$D:$D,$C5,'RAW_농산물_10월'!$A:$A,$E5))) | S5: =IF($C5="","",IF(COUNTIF($I5:$M5,"O")>0,"O","")) -> O | T5: =IF($C5="","",IF($H5=0,"미사용",IF($H5<500000,"50만원 미만",IF($H5<1000000,"100만원 미만",IF($H5<2000000,"200만원 미만",IF($H5<3000000,"300만원 미만",IF($H5<4000000,"400만원 미만",IF($H5<5000000,"500만원 미만",IF($H5<6000000,"600만원 미만",IF($H5<7000000,"700만원 미만",IF($H5<8000000,"800만원 미만",IF($H5<10000000,"1000만원 미만","1000만원 이상")))))))))))) -> 50만원 미만 | U5: =IF($C5="",0,IF('설정'!$B$3=0,0,CHOOSE('설정'!$B$3,COUNTIFS('RAW_농산물_7월'!$D:$D,$C5,'RAW_농산물_7월'!$A:$A,$E5),COUNTIFS('RAW_농산물_8월'!$D:$D,$C5,'RAW_농산물_8월'!$A:$A,$E5),COUNTIFS('RAW_농산물_9월'!$D:$D,$C5,'RAW_농산물_9월'!$A:$A,$E5),COUNTIFS('RAW_농산물_10월'!$D:$D,$C5,'RAW_농산물_10월'!$A:$A,$E5),COUNTIFS('RAW_농산물_11-12월'!$D:$D,$C5,'RAW_농산물_11-12월'!$A:$A,$E5)))) -> 5
A6: 4 | B6: 시작 | C6: 406-82-02051 | D6: 구천동농업협동조합 | E6: 네이버 | F6: =IF($C6="","",IF('설정'!$B$3=0,"",CHOOSE('설정'!$B$3,SUMIFS('RAW_농산물_7월'!$F:$F,'RAW_농산물_7월'!$D:$D,$C6,'RAW_농산물_7월'!$A:$A,$E6),SUMIFS('RAW_농산물_8월'!$F:$F,'RAW_농산물_8월'!$D:$D,$C6,'RAW_농산물_8월'!$A:$A,$E6),SUMIFS('RAW_농산물_9월'!$F:$F,'RAW_농산물_9월'!$D:$D,$C6,'RAW_농산물_9월'!$A:$A,$E6),SUMIFS('RAW_농산물_10월'!$F:$F,'RAW_농산물_10월'!$D:$D,$C6,'RAW_농산물_10월'!$A:$A,$E6),SUMIFS('RAW_농산물_11-12월'!$F:$F,'RAW_농산물_11-12월'!$D:$D,$C6,'RAW_농산물_11-12월'!$A:$A,$E6)))) -> 0 | G6: =IF($C6="","",IF('설정'!$B$3=0,"",CHOOSE('설정'!$B$3,SUMIFS('RAW_농산물_7월'!$G:$G,'RAW_농산물_7월'!$D:$D,$C6,'RAW_농산물_7월'!$A:$A,$E6),SUMIFS('RAW_농산물_8월'!$G:$G,'RAW_농산물_8월'!$D:$D,$C6,'RAW_농산물_8월'!$A:$A,$E6),SUMIFS('RAW_농산물_9월'!$G:$G,'RAW_농산물_9월'!$D:$D,$C6,'RAW_농산물_9월'!$A:$A,$E6),SUMIFS('RAW_농산물_10월'!$G:$G,'RAW_농산물_10월'!$D:$D,$C6,'RAW_농산물_10월'!$A:$A,$E6),SUMIFS('RAW_농산물_11-12월'!$G:$G,'RAW_농산물_11-12월'!$D:$D,$C6,'RAW_농산물_11-12월'!$A:$A,$E6)))) -> 0 | H6: =IF($C6="","",IF('설정'!$B$3=0,"",CHOOSE('설정'!$B$3,SUMIFS('RAW_농산물_7월'!$H:$H,'RAW_농산물_7월'!$D:$D,$C6,'RAW_농산물_7월'!$A:$A,$E6),SUMIFS('RAW_농산물_8월'!$H:$H,'RAW_농산물_8월'!$D:$D,$C6,'RAW_농산물_8월'!$A:$A,$E6),SUMIFS('RAW_농산물_9월'!$H:$H,'RAW_농산물_9월'!$D:$D,$C6,'RAW_농산물_9월'!$A:$A,$E6),SUMIFS('RAW_농산물_10월'!$H:$H,'RAW_농산물_10월'!$D:$D,$C6,'RAW_농산물_10월'!$A:$A,$E6),SUMIFS('RAW_농산물_11-12월'!$H:$H,'RAW_농산물_11-12월'!$D:$D,$C6,'RAW_농산물_11-12월'!$A:$A,$E6)))) -> 0 | I6: =IF($C6="","",IF(COUNTIFS('RAW_농산물_7월'!$D:$D,$C6,'RAW_농산물_7월'!$A:$A,$E6)>0,"O","")) | J6: =IF($C6="","",IF(COUNTIFS('RAW_농산물_8월'!$D:$D,$C6,'RAW_농산물_8월'!$A:$A,$E6)>0,"O","")) -> O | K6: =IF($C6="","",IF(COUNTIFS('RAW_농산물_9월'!$D:$D,$C6,'RAW_농산물_9월'!$A:$A,$E6)>0,"O","")) | L6: =IF($C6="","",IF(COUNTIFS('RAW_농산물_10월'!$D:$D,$C6,'RAW_농산물_10월'!$A:$A,$E6)>0,"O","")) | M6: =IF($C6="","",IF(COUNTIFS('RAW_농산물_11-12월'!$D:$D,$C6,'RAW_농산물_11-12월'!$A:$A,$E6)>0,"O","")) | N6: =IF($C6="","",IF(COUNTA('RAW_농산물_7월'!$A:$A)<=1,"",SUMIFS('RAW_농산물_7월'!$H:$H,'RAW_농산물_7월'!$D:$D,$C6,'RAW_농산물_7월'!$A:$A,$E6))) -> 0 | O6: =IF($C6="","",IF(COUNTA('RAW_농산물_8월'!$A:$A)<=1,"",SUMIFS('RAW_농산물_8월'!$H:$H,'RAW_농산물_8월'!$D:$D,$C6,'RAW_농산물_8월'!$A:$A,$E6)-SUMIFS('RAW_농산물_7월'!$H:$H,'RAW_농산물_7월'!$D:$D,$C6,'RAW_농산물_7월'!$A:$A,$E6))) -> 0 | P6: =IF($C6="","",IF(COUNTA('RAW_농산물_9월'!$A:$A)<=1,"",SUMIFS('RAW_농산물_9월'!$H:$H,'RAW_농산물_9월'!$D:$D,$C6,'RAW_농산물_9월'!$A:$A,$E6)-SUMIFS('RAW_농산물_8월'!$H:$H,'RAW_농산물_8월'!$D:$D,$C6,'RAW_농산물_8월'!$A:$A,$E6))) | Q6: =IF($C6="","",IF(COUNTA('RAW_농산물_10월'!$A:$A)<=1,"",SUMIFS('RAW_농산물_10월'!$H:$H,'RAW_농산물_10월'!$D:$D,$C6,'RAW_농산물_10월'!$A:$A,$E6)-SUMIFS('RAW_농산물_9월'!$H:$H,'RAW_농산물_9월'!$D:$D,$C6,'RAW_농산물_9월'!$A:$A,$E6))) | R6: =IF($C6="","",IF(COUNTA('RAW_농산물_11-12월'!$A:$A)<=1,"",SUMIFS('RAW_농산물_11-12월'!$H:$H,'RAW_농산물_11-12월'!$D:$D,$C6,'RAW_농산물_11-12월'!$A:$A,$E6)-SUMIFS('RAW_농산물_10월'!$H:$H,'RAW_농산물_10월'!$D:$D,$C6,'RAW_농산물_10월'!$A:$A,$E6))) | S6: =IF($C6="","",IF(COUNTIF($I6:$M6,"O")>0,"O","")) -> O | T6: =IF($C6="","",IF($H6=0,"미사용",IF($H6<500000,"50만원 미만",IF($H6<1000000,"100만원 미만",IF($H6<2000000,"200만원 미만",IF($H6<3000000,"300만원 미만",IF($H6<4000000,"400만원 미만",IF($H6<5000000,"500만원 미만",IF($H6<6000000,"600만원 미만",IF($H6<7000000,"700만원 미만",IF($H6<8000000,"800만원 미만",IF($H6<10000000,"1000만원 미만","1000만원 이상")))))))))))) -> 미사용 | U6: =IF($C6="",0,IF('설정'!$B$3=0,0,CHOOSE('설정'!$B$3,COUNTIFS('RAW_농산물_7월'!$D:$D,$C6,'RAW_농산물_7월'!$A:$A,$E6),COUNTIFS('RAW_농산물_8월'!$D:$D,$C6,'RAW_농산물_8월'!$A:$A,$E6),COUNTIFS('RAW_농산물_9월'!$D:$D,$C6,'RAW_농산물_9월'!$A:$A,$E6),COUNTIFS('RAW_농산물_10월'!$D:$D,$C6,'RAW_농산물_10월'!$A:$A,$E6),COUNTIFS('RAW_농산물_11-12월'!$D:$D,$C6,'RAW_농산물_11-12월'!$A:$A,$E6)))) -> 1
